Workbook

Sheet survey
A1: type | B1: name | C1: label::English (en) | D1: label:: | E1: hint::English (en) | F1: hint:: | G1: required | H1: appearance | I1: constraint | J1: constraint_message | K1: relevant | L1: choice_filter | M1: parameters | N1: calculation | S1: Mandatory | U1: New question duration (sec) | V1: Estimated percentage of repondents | W1: Weighted time | X1: Weighted time for core vars
A2: start | B2: start | W2: =IF(U2<>"",U2*V2,"") | X2: =IF(AND(U2<>"",S2="yes"),U2*V2,"")
A3: end | B3: end | W3: =IF(U3<>"",U3*V3,"") | X3: =IF(AND(U3<>"",S3="yes"),U3*V3,"")
A4: today | B4: today | W4: =IF(U4<>"",U4*V4,"") | X4: =IF(AND(U4<>"",S4="yes"),U4*V4,"")
A5: deviceid | B5: deviceid | W5: =IF(U5<>"",U5*V5,"") | X5: =IF(AND(U5<>"",S5="yes"),U5*V5,"")
A6: audit | B6: audit
A7: calculate | B7: audio_random | N7: once(random())
A8: background-audio | B8: background-audio | K8: ${audio_random}<=0.02 | M8: quality=low
A9: select_one enumteam | B9: enum_team | C9: Enumerator team number or code
A10: select_one enumerator | B10: enumerator | C10: Name of enumerator | G10: true | L10: my_filter_admin=${enum_team} | S10: yes | W10: =IF(U10<>"",U10*V10,"") | X10: =IF(AND(U10<>"",S10="yes"),U10*V10,"")
A11: calculate | B11: enumerator_ | N11: jr:choice-name(${enumerator},'${enumerator}') | S11: yes | W11: =IF(U11<>"",U11*V11,"") | X11: =IF(AND(U11<>"",S11="yes"),U11*V11,"")
A13: note | B13: introduction | C13: Hello sir/ma'am, my name is ${enumerator_}. On behalf of the Food and Agriculture Organization of the United Nations (FAO), we are conducting a survey on household livelihoods and the ability to access food in your area. I would like to ask you some questions about your household. The survey usually takes 20 / 30 minutes to complete. Any information that you provide will be kept strictly confidential, only used for the purpose of the survey and will not be shown to other people. Your voluntary participation in the outcome of this interview is NOT IN ANY WAY linked to your personal chance of receiving any assistance. This is voluntary and you can choose not to answer any or all of the questions if you want. However, we hope that you will participate since your views are important. Do you have any questions? | E13: [INSTRUCTIONS: ADDRESS QUESTIONS FROM RESPONDENT, IF ANY.] | G13: false | S13: no | U13: 50.82254 | W13: =IF(U13<>"",U13*V13,"") -> 0 | X13: =IF(AND(U13<>"",S13="yes"),U13*V13,"")
A14: select_one yesno | B14: resp_agree | C14: Are you interested in participating in this survey? | G14: false | S14: yes | U14: 3.5 | V14: =1 -> 1 | W14: =IF(U14<>"",U14*V14,"") -> 3.5 | X14: =IF(AND(U14<>"",S14="yes"),U14*V14,"") -> 3.5
A15: geopoint | B15: gps_1 | C15: GPS INSTRUCTION: Take a GPS measurement. | E15: NOTE: It might take a few minutes for the tablet to register the GPS. Wait for it to load. If it takes longer than 3 minutes, skip to the next question. You can take the GPS reading at the end of the interview. | G15: false | K15: ${resp_agree} = '1' | U15: 0 | V15: 1 | W15: =IF(U15<>"",U15*V15,"") -> 0
A16: note | B16: Refusal | C16: Thank you for your time, you will be removed from today's survey. | G16: false | K16: ${resp_agree} = '2' | S16: no | U16: 0 | V16: 1 | W16: =IF(U16<>"",U16*V16,"") -> 0 | X16: =IF(AND(U16<>"",S16="yes"),U16*V16,"")
W17: =IF(U17<>"",U17*V17,"") | X17: =IF(AND(U17<>"",S17="yes"),U17*V17,"")
A18: begin_group | B18: eligibility | C18: ELIGIBILITY CRITERIA | G18: false | K18: ${resp_agree} = '1' | S18: yes | W18: =IF(U18<>"",U18*V18,"") | X18: =IF(AND(U18<>"",S18="yes"),U18*V18,"")
W19: =IF(U19<>"",U19*V19,"") | X19: =IF(AND(U19<>"",S19="yes"),U19*V19,"")
A20: text | B20: resp_firstname | C20: What is your first name? | E20: [INSTRUCTIONS: RECORD THE RESPONDENT'S FIRST NAME. ENTER 999 FOR REFUSED] | G20: true | S20: yes | U20: 10 | V20: =1 -> 1 | W20: =IF(U20<>"",U20*V20,"") -> 10 | X20: =IF(AND(U20<>"",S20="yes"),U20*V20,"") -> 10
A21: text | B21: resp_lastname | C21: What is your last name? | E21: [INSTRUCTIONS: RECORD THE RESPONDENT'S LAST NAME. ENTER 999 FOR REFUSED] | G21: true | S21: yes | U21: 10 | V21: =1 -> 1 | W21: =IF(U21<>"",U21*V21,"") -> 10 | X21: =IF(AND(U21<>"",S21="yes"),U21*V21,"") -> 10
V22: =1 -> 1 | W22: =IF(U22<>"",U22*V22,"") | X22: =IF(AND(U22<>"",S22="yes"),U22*V22,"")
A23: integer | B23: resp_age | C23: How old are you? | E23: [INSTRUCTIONS: RECORD AGE IN NUMBER OF YEARS. ROUND UP TO NEAREST WHOLE NUMBER. IF THE RESPONDENT GIVES BIRTH YEAR, REPEAT THE QUESTION. ENTER 888 FOR DON'T KNOW.] | G23: true | I23: (. >= 18 and . <= 100) or . = 888 | S23: yes | U23: 13.753073 | V23: =1 -> 1 | W23: =IF(U23<>"",U23*V23,"") -> 13.753073 | X23: =IF(AND(U23<>"",S23="yes"),U23*V23,"") -> 13.753073
V24: =1 -> 1 | W24: =IF(U24<>"",U24*V24,"") | X24: =IF(AND(U24<>"",S24="yes"),U24*V24,"")
A25: select_one gender | B25: resp_gender | C25: What is the gender of the respondent? | E25: [INSTRUCTIONS: DO NOT ASK THIS QUESTION OUT LOUD. SELECT THE GENDER OF THE RESPONDENT.] | G25: true | S25: no | U25: 2.1173561 | V25: =1 -> 1 | W25: =IF(U25<>"",U25*V25,"") -> 2.1173561 | X25: =IF(AND(U25<>"",S25="yes"),U25*V25,"")
V26: =1 -> 1 | W26: =IF(U26<>"",U26*V26,"") | X26: =IF(AND(U26<>"",S26="yes"),U26*V26,"")
A27: text | B27: phone_number_personal | C27: What is your phone number? | G27: true | H27: numbers | I27: regex(.,’^[0-9]{9}$’) | J27: Please enter the telephone number in the correct format, e.g. 076xxxxxx | S27: yes - panel | U27: 10 | V27: =1 -> 1 | W27: =IF(U27<>"",U27*V27,"") -> 10 | X27: =IF(AND(U27<>"",S27="yes"),U27*V27,"")
A28: select_one contact_info | B28: contact_2 | C28: Can you give me an additonal phone number belonging to you, a relative or a friend at which you can be reached? | G28: true | S28: yes - panel | U28: 10 | V28: =1 -> 1 | W28: =IF(U28<>"",U28*V28,"") -> 10 | X28: =IF(AND(U28<>"",S28="yes"),U28*V28,"")
A29: text | B29: phone_number_2 | C29: What is the additional phone number? | G29: true | H29: numbers | I29: regex(.,’^[0-9]{9}$’) | J29: Please enter the telephone number in the correct format, e.g. 076xxxxxx | K29: ${contact_2} = '1' or ${contact_2} = '2' | S29: yes - panel | U29: 10 | V29: =1 -> 1 | W29: =IF(U29<>"",U29*V29,"") -> 10 | X29: =IF(AND(U29<>"",S29="yes"),U29*V29,"")
A30: text | B30: contact_2_name | C30: What is the name of the contact? | G30: true | K30: ${contact_2} = '2' | S30: yes - panel | U30: 10 | V30: =1 -> 1 | W30: =IF(U30<>"",U30*V30,"") -> 10 | X30: =IF(AND(U30<>"",S30="yes"),U30*V30,"")
A31: select_one contact_info | B31: contact_3 | C31: Can you give me an additonal phone number belonging to you, a relative or a friend at which you can be reached? | G31: true | K31: ${contact_2} ='1' or ${contact_2} = '2' | S31: yes - panel | U31: 10 | V31: =1 -> 1 | W31: =IF(U31<>"",U31*V31,"") -> 10 | X31: =IF(AND(U31<>"",S31="yes"),U31*V31,"")
A32: text | B32: phone_number_3 | C32: What is the additional phone number? | G32: true | H32: numbers | I32: regex(.,’^[0-9]{9}$’) | J32: Please enter the telephone number in the correct format, e.g. 076xxxxxx | K32: ${contact_3} = '1' or ${contact_3} = '2' | S32: yes - panel | U32: 10 | V32: =1 -> 1 | W32: =IF(U32<>"",U32*V32,"") -> 10 | X32: =IF(AND(U32<>"",S32="yes"),U32*V32,"")
A33: text | B33: contact_3_name | C33: What is the name of the contact? | G33: true | K33: ${contact_3} = '2' | S33: yes - panel | U33: 10 | V33: =1 -> 1 | W33: =IF(U33<>"",U33*V33,"") -> 10 | X33: =IF(AND(U33<>"",S33="yes"),U33*V33,"")
V34: =1 -> 1 | W34: =IF(U34<>"",U34*V34,"") | X34: =IF(AND(U34<>"",S34="yes"),U34*V34,"")
A35: select_one admin1 | B35: adm1_pcode | C35: Currently, in which Regional does your household reside? | E35: [HINT: HOUSEHOLD CONSISTS OF ALL MEMBERS LIVING TOGETHER, SHARING RESOURCES & EATING FROM THE SAME POT.] | G35: true | H35: minimal | S35: yes | U35: 8.8 | V35: =1 -> 1 | W35: =IF(U35<>"",U35*V35,"") -> 8.8 | X35: =IF(AND(U35<>"",S35="yes"),U35*V35,"") -> 8.8
A36: calculate | B36: adm1_name | N36: jr:choice-name(${adm1_pcode},'${adm1_pcode}') | S36: yes | V36: =1 -> 1 | W36: =IF(U36<>"",U36*V36,"") | X36: =IF(AND(U36<>"",S36="yes"),U36*V36,"")
A37: select_one admin2 | B37: adm2_pcode | C37: Currently, in which District does your household reside? | G37: true | H37: minimal | L37: my_filter_admin=${adm1_pcode} | S37: yes | U37: 10.4 | V37: =1 -> 1 | W37: =IF(U37<>"",U37*V37,"") -> 10.4 | X37: =IF(AND(U37<>"",S37="yes"),U37*V37,"") -> 10.4
A38: calculate | B38: adm2_name | N38: jr:choice-name(${adm2_pcode},'${adm2_pcode}') | S38: yes | V38: =1 -> 1 | W38: =IF(U38<>"",U38*V38,"") | X38: =IF(AND(U38<>"",S38="yes"),U38*V38,"")
V39: =1 -> 1 | W39: =IF(U39<>"",U39*V39,"") | X39: =IF(AND(U39<>"",S39="yes"),U39*V39,"")
A40: select_one agricactivity | B40: hh_agricactivity | C40: Has anybody in your household produced crops or livestock for household consumption or for sale in the past 12 months, including household members currently away for transhumance? | E40: [INSTRUCTIONS: THIS IS THE MAIN SCREENING QUESTION.] [HINT FOR PROBING: Do you cultivate any plants to sale or consume? Do you raise any animals with the intent of selling or consuming them or their products like meat, milk, wool or leather? Is one of your household member currently away with cattle or other animals for transhumance?] | G40: true | S40: yes | U40: 31.372377 | V40: =1 -> 1 | W40: =IF(U40<>"",U40*V40,"") -> 31.372377 | X40: =IF(AND(U40<>"",S40="yes"),U40*V40,"") -> 31.372377
V41: =1 -> 1 | W41: =IF(U41<>"",U41*V41,"") | X41: =IF(AND(U41<>"",S41="yes"),U41*V41,"")
...

Sheet choices
A1: list_name | B1: name | C1: label::English (en) | D1: label:: | E1: my_filter_admin
A2: enumteam | B2: 1 | C2: Enumerator team 1
A3: enumteam | B3: 2 | C3: Enumerator team 2
A4: enumteam | B4: 3 | C4: Enumerator team 3
A5: enumteam | B5: 4 | C5: Enumerator team 4
A7: enumerator | B7: 1 | C7: enumerator name 1
A8: enumerator | B8: 2 | C8: enumerator name 2
A9: enumerator | B9: 3 | C9: enumerator name 3
A11: yes_no | B11: 1 | C11: YES
A12: yes_no | B12: 2 | C12: NO
A13: yes_no | B13: 3 | C13: DON'T KNOW
A14: yes_no | B14: 4 | C14: REFUSED
A16: continue | B16: continue | C16: continue
A18: yesno | B18: 1 | C18: Yes
A19: yesno | B19: 2 | C19: No
A21: language | B21: en | C21: English
A22: language | B22: fr | C22: French
A23: language | B23: … | C23: …
A25: gender | B25: 1 | C25: Male
A26: gender | B26: 2 | C26: Female
A27: gender | B27: 3 | C27: DON'T KNOW
A28: gender | B28: 4 | C28: REFUSED
A30: contact_info | B30: 1 | C30: YES - mine
A31: contact_info | B31: 2 | C31: YES - friend or relative
A32: contact_info | B32: 3 | C32: NO
A34: agricactivity | B34: 1 | C34: Yes - crop production
A35: agricactivity | B35: 2 | C35: Yes - livestock production
A36: agricactivity | B36: 3 | C36: Yes - both crop and livestock production
A37: agricactivity | B37: 4 | C37: No
A38: agricactivity | B38: 5 | C38: DON'T KNOW
... A85: residence | B85: 7 | C85: REFUSED
A87: asset_prod | B87: process | C87: Processing assets (e.g. grinding/crushing machine, mill, oil press)
A88: asset_prod | B88: farmmach | C88: Farm machinery (e.g. tractor, plough, sickle, etc.)
A89: asset_prod | B89: sewing | C89: Sewing machine or weaving tool
A90: asset_prod | B90: taxi | C90: Taxi
A91: asset_prod | B91: truck | C91: Truck
A92: asset_prod | B92: other | C92: Other productive machines or assets
A93: asset_prod | B93: none | C93: No productive machines or assets
A94: asset_prod | B94: dk | C94: DON'T KNOW
A95: asset_prod | B95: ref | C95: REFUSED
...

Sheet settings
A1: version | B1: default_language | C1: allow_choice_duplicates | D1: style
A2: vM6cWXyHNhR3djPbARkHWi | B2: English (en) | C2: yes | D2: theme-grid no-text-transform

Sheet Crop list
C3: Select top 10 crops | D3: Dataset code | E3: Label (EN)
C4: x | D4: 1.1 | E4: Rice
D5: 1.2 | E5: Wheat
D6: 1.3 | E6: Millet
D7: 1.4 | E7: Sorghum
C8: x | D8: 1.5 | E8: Maize
D9: 1.6 | E9: Barley
D10: 1.99 | E10: Other Cereal
C11: x | D11: 2.1 | E11: Cassava
D12: 2.2 | E12: Potatoe
C13: x | D13: 2.3 | E13: Sweet Potatoes
D14: 2.4 | E14: Yams
D15: 2.5 | E15: Carrots
D16: 2.6 | E16: Cocoyam
D17: 2.99 | E17: Other tubers
C18: x | D18: 3.1 | E18: Beans
D19: 3.2 | E19: Lentils
D20: 3.3 | E20: Peas
D21: 3.4 | E21: Soybeans
D22: 3.5 | E22: Chickpeas
D23: 3.6 | E23: Fava beans
D24: 3.7 | E24: Broad beans
D25: 3.99 | E25: Other pulses
D26: 4.1 | E26: Cabbage
D27: 4.2 | E27: Lettuce
D28: 4.3 | E28: Spinach-Amaranth
D29: 4.4 | E29: Cassava leaves
D30: 4.5 | E30: Potatoe leaves
... D37: 5.2 | E37: Cucumber
C38: x | D38: 5.3 | E38: Pumpkin
D39: 5.4 | E39: Eggplant/aubergine
D40: 5.5 | E40: Zucchini
C41: x | D41: 5.6 | E41: Okra
D42: 5.7 | E42: Bell pepper
D43: 5.8 | E43: Onions
D44: 5.9 | E44: Haricot
D45: 5.101 | E45: Green peas
D46: 5.11 | E46: Fava beans green
D47: 5.99 | E47: Other non leafy vegs
D48: 6.1 | E48: Orange
...

Sheet Additional information
C2: Original | D2: Replacement | E2: Comment | F2: Example
B3: FOR CORE QUESTIONS . (Mandatory to fill out) . | C3: phone number | D3: 076xxxxxx | E3: Type a phone number from your country in typical format, e.g. 77******* [please use exactly the number of characters that are found in a phone number]. | F3: 070******
C4: age | D4: 18 | E4: Minimum age of respondent (recommend 18 years old) | F4: 18
C5: ADMIN1 | D5: Regional | E5: The first subdivision of the country, after national level; region; province; governorate; etc. Only one word should be inputted - Do not include spaces. | F5: region
C6: ADMIN2 | D6: District | E6: The second subdivision of the country; district; municipality; LGA; etc. Only one word should be inputted - Do not include spaces. | F6: district
C7: reference year | D7: last year | E7: Comparison questions will need need a reference year. Select whether you want to use "last year" or "a normal year" as a baseline. A "normal year" should refers to an average year from the past 5 years - make sure to train the enumerators accordingly. | F7: a normal year
C8: season | D8: Last season | E8: Name the crop season(s) of interest if there are several cropping seasons in the country (e.g. Meher and Belg in Ethiopia, rainy season / flood-recession cropping / irrigated dry season in the Sahel). You can refer to the “last season” or “ongoing season". | F8: wet season
C9: season phase | D9: Recently finished | E9: Indicate the phase of the season at the time of data collection. If the harvest from the season has not yet occurred, the question on crop harvest (crp_harv_change) will include the word “expected” (where #expected or nothing# is located). If the harvest has occured, "expected" will not be inserted in the question. | F9: Harvesting
C10: local measurement unit | E10: Specify the local measurement unit for land size, other than acres, hectares, square meters and square feet. If no other unit of measurement is needed, keep this cell blank. | F10: Jeribs
C11: local measurement unit conversion | E11: Include the conversion of the local measurement unit to hectares. In other words, how many local measurement units are in 1 ha. | F11: 0.2
B12: FOR OPTIONAL QUESTIONS . (Fill out if applicable) . | C12: currency | D12: SLE | E12: The name of the main currency used nationally; USD; Naira; Rial; Pesos; etc. | F12: Naira
C13: MIN AMOUNT | D13: 1 | E13: The minimum amount for an income source should be set at 0 or any value below which it is not possible to do a transaction. For example, the smallest coin/banknote in a currency can be 1000, in which case you would set the minimum at 1000. Provide this input in the same currency as specified above. Only digits should be inputted. | F13: 5
C14: THRESHOLD | D14: 15000 | E14: The threshold salary should be calculated to flag outliers (responses that look suspiciously high). Using previous representative surveys for this population, a good estimate is the average plus three (3) standard deviations, which should give the threshold for the 3 or 4% highest income values. Provide this input in the same currency as specified above. Only digits should be inputted. | F14: 1200000
C15: local vegetables | D15: Okra, Potato leaves, Cassava leaves, Garden eggs , Tomatoes, Green, Krain krain,Llettuce, Cabbage,Carrot, Pepper, Onions, Cucumber, pumpkin | E15: Input some common local vegetables [to be used as examples in the food consumption score indicator]. | F15: eggplants, zucchini, cauliflower
C16: local fruits | D16: Banana, 0ranges, Plantain, Grape fruits, Avocado, Lemon, Guava, Pineapple, Water melon , Apple, Pawpaw | E16: Input some common local fruits [to be used as examples in the food consumption score indicator]. | F16: apples, bananas, oranges
B18: FILL OUT FOR QUESTIONNAIRE DURATION ESTIMATION . | C18: Expected percentage of respondents cultivating crops | D18: 0.91 | E18: If the survey is representative and has no quotas, write the proportion of rural households cultivating crops at country level, or if the survey follows a previous round with identical sample design, just report the percentage from the previous round. If you are using quotas, calculate the ratio of the quota over the minimum sample size at the level where the quota is implemented (so if you have a minimum sample size per strata of 110 with a quota of 100 crop producers, then it's 100/110 = 91% (the maximum you should write is 100%). | F18: 0.91
C19: Expected percentage of respondents raising livestock | D19: 0.91 | E19: If the survey is representative and has no quotas, write the proportion of rural households raising livestock at country level, or if the survey follows a previous round with identical sample design, just report the percentage from the previous round. If you are using quotas, calculate the ratio of the quota over the minimum sample size at the level where the quota is implemented (so if you have a minimum sample size of 110 but a quota of 100 livestock producers, then it's 100/110 = 91% (the maximum you should write is 100%) | F19: 0.91
C20: Expected percentage of respondents involved in fishery | D20: 0.05 | E20: If the survey is representative and has no quotas, write the proportion of rural households involved in fisheries or aquaculture, otherwise if you are using quotas, calculate the ratio of the quota over the sample size at the level where the quota is implemented. (so if you haven't set a quota, and you expect to have a representative proportion of fishermen, just write the percentage of fishermen in the population you are targeting, in the example to the right, 5%) | F20: 0.05
