Workbook

Sheet New Durations
A1: question | B1: duration | C1: responded % | D1: weighted time
A2: introduction | B2: 50.82254 | C2: 1 | D2: 50.82254
A3: agree | B3: 3.4964738 | C3: 0.79698741 | D3: 2.7866456
A4: resp_age | B4: 13.753073 | C4: 1 | D4: 13.753073
A5: resp_gender | B5: 2.1173561 | C5: 1 | D5: 2.1173561
A6: quotareached | B6: 2.28425 | C6: 0.79698741 | D6: 1.8205185
A7: hh_agricactivity | B7: 31.372377 | C7: 1 | D7: 31.372377
A8: hh_milieu | B8: 7.9225454 | C8: 0.15190348 | D8: 1.2034622
A9: hh_gender | B9: 10.085732 | C9: 1 | D9: 10.085732
A10: hh_education | B10: 12.894034 | C10: 1 | D10: 12.894034
A11: hh_wealth_water | B11: 15.265829 | C11: 0.63796463 | D11: 9.739059
A12: hh_wealth_toilet | B12: 15.123718 | C12: 0.59180156 | D12: 8.95024
A13: hh_wealthwall | B13: 12.821411 | C13: 0.15190348 | D13: 1.9476169
... A164: adm1_name | B164: 10.743817 | C164: 0.20301259 | D164: 2.1811302
A165: adm2_name | C165: 0 | D165: 0
A166: covid | B166: 56.471024 | C166: 0.20301259 | D166: 11.464329
A167: crp_landright | B167: 31 | C167: 0.0040467626 | D167: 0.12544964
A168: crp_seed | B168: 30.833334 | C168: 0.0040467626 | D168: 0.12477518
A169: crp_proddif | B169: 16.882986 | C169: 0.11848022 | D169: 2.0002998
A170: crp_salesdif | B170: 16.82699 | C170: 0.086630695 | D170: 1.4577339
A171: crp_saledif_2 | B171: 39.486874 | C171: 0.03139988 | D171: 1.2398831
A172: ls_proddif | B172: 15.938099 | C172: 0.10169365 | D172: 1.6208034
A173: ls_salesdif | B173: 13.330855 | C173: 0.060476619 | D173: 0.80620506
A174: ls_proc | B174: 16.437651 | C174: 0.0625 | D174: 1.0273532
A175: ls_proc_fac_state | B175: 8.666667 | C175: 0.00067446043 | D175: 0.005845324
A176: fish_proddif | B176: 12.523809 | C176: 0.001573741 | D176: 0.019709232
A177: cs_spentsavings | B177: 22.220184 | C177: 0.0081684652 | D177: 0.1815048
... A193: ls_proddif_2_covid19 | B193: 3.3438249 | C193: 1 | D193: 3.3438249

Sheet survey
A1: GeoPoll Submission Form | Z1: Change made
A2: FAO - Household Questionnaire | P2: Additional notes
A3: Q # | B3: Q Name | C3: Suggested Qname | D3: English | E3: Length | F3: French | G3: Length | H3: Q Type | I3: Randomize | J3: Conditional | K3: Programming Instructions | L3: Skip Pattern | M3: Default skip patterns & conditional | N3: Specify skip pattern variable (from blue text) | O3: UNIVERSE | Q3: Duration average (sec) | R3: Estimated percentage of repondents | S3: Weighted Duration | V3: Mandatory
A4: A. PRESENTATION OF THE SURVEY AND ELIGIBILITY CRITERIA SELECTION | V4: no
A5: NA | B5: Optin | D5: Optin | E5: =LEN(D5) -> 5 | F5: Optin | G5: =LEN(F5) -> 5 | H5: Open Ended | I5: NA | J5: NA | K5: Form Type - TextBox | L5: Any Response = phone_number | M5: NA | O5: ALL | Q5: 0 | S5: =Q5*R5 -> 0 | V5: no
A6: NA | B6: phone_number | C6: phone_number | D6: Input the phone number that you are contacting: | E6: =LEN(D6) -> 48 | F6: Saisir le numéro de téléphone que vous chercher à contacter: | G6: =LEN(F6) -> 61 | H6: Open Ended | I6: NA | J6: NA | K6: Form Type - TextBox | L6: Any Response = hh_id | M6: NA | O6: ALL | Q6: 0 | S6: =Q6*R6 -> 0 | V6: yes | Z6: New question
A7: NA | B7: hh_id | C7: hh_id | D7: Input the household ID, if applicable: | E7: =LEN(D7) -> 38 | F7: Le cas échéant, saisir l'identifiant du ménage: | G7: =LEN(F7) -> 47 | H7: Open Ended | I7: NA | J7: NA | K7: Form Type - TextBox | L7: Any Response = calldispo | M7: NA | O7: ALL | Q7: 0 | S7: =Q7*R7 -> 0 | V7: yes | Z7: New question
A8: NA | B8: calldispo | C8: calldispo | D8: Phone number: #CATI_MOBILENUMBER# 1)Someone answers 2)Answering machine 3)No answer 4)Hang up or refusal 5)Call back 6)Under review 7)Disconnected | E8: =LEN(D8) -> 146 | F8: Numéro de téléphone: #CATI_MOBILENUMBER# 1)Quelqu’un répond 2)Répondeur 3)Pas de réponse 4)Raccroche/Refuse 5)Doit être rappeler 6)À l’étude 7)Déconnecté | G8: =LEN(F8) -> 153 | H8: Single Choice | I8: NA | J8: NA | K8: Form Type - Buttons | L8: 1 = resp_language 2 = AnsweringMachine 3 = NoAnswer 4 = Refusal 5 = WhenCallBack 6 = UnderReview 7 = Disconnected | M8: NA | O8: ALL | Q8: 0 | S8: =Q8*R8 -> 0 | V8: no
A9: NA | B9: AnsweringMachine | C9: calldispo_answeringmachine | D9: Reached an answering machine. | E9: =LEN(D9) -> 29 | F9: L'appel a abouti sur un répondeur. | G9: =LEN(F9) -> 34 | H9: NA | I9: NA | J9: NA | K9: NA | L9: End Poll AnsweringMachine | M9: NA | O9: calldispo = 2 | Q9: 0 | S9: =Q9*R9 -> 0 | V9: no
A10: NA | B10: NoAnswer | C10: calldispo_noanswer | D10: Phone rang and no one answered. | E10: =LEN(D10) -> 31 | F10: Le téléphone a sonné et personne n'a répondu. | G10: =LEN(F10) -> 45 | H10: NA | I10: NA | J10: NA | K10: NA | L10: End Poll NoAnswer | M10: NA | O10: calldispo = 3 | Q10: 0 | S10: =Q10*R10 -> 0 | V10: no
A11: NA | B11: UnderReview | C11: calldispo_underreview | D11: Case needs review by a supervisor. | E11: =LEN(D11) -> 34 | F11: Le cas doit être examiné par un superviseur. | G11: =LEN(F11) -> 44 | H11: NA | I11: NA | J11: NA | K11: NA | L11: End Poll UnderReview | M11: NA | O11: calldispo = 6 | Q11: 0 | S11: =Q11*R11 -> 0 | V11: no
A12: NA | B12: Disconnected | C12: calldispo_disconnected | D12: Phone was disconnected or out of service. | E12: =LEN(D12) -> 41 | F12: Le téléphone est déconnecté ou hors service. | G12: =LEN(F12) -> 44 | H12: NA | I12: NA | J12: NA | K12: NA | L12: End Poll Disconnected | M12: NA | O12: calldispo = 7 | Q12: 0 | S12: =Q12*R12 -> 0 | V12: no
A13: NA | B13: resp_language | C13: resp_language | D13: Which language do you wish to proceed with? [OPERATOR: READ ANSWER CHOICES. SINGLE RESPONSE.] 1)English 2)other options [add as many as necessary] | E13: =LEN(D13) -> 148 | F13: Dans quelle langue souhaitez-vous que nous parlions? [OPÉRATEUR/OPÉRATRICE: LISEZ LES CHOIX, RÉPONSE UNIQUE] 1)Français 2)autre [ajouter autant d'options que nécessaire] | G13: =LEN(F13) -> 171 | H13: Single Choice | I13: NA | J13: NA | K13: Form Type - Buttons | L13: 1 = introduction [English] 2 = introduction [languages & add more if needed] | M13: For any response, go to introduction | O13: ALL | P13: Insert most common national languages here [max 4 for translation with GeoPoll]. Insérer ici les langues nationales les plus courantes [4 maximum pour la traduction avec GeoPoll]. | Q13: 3.0622325 | S13: =Q13*R13 -> 0 | V13: no
A14: NA | B14: introduction | C14: introduction | D14: Hello sir/ma'am, my name is #OPERATOR#, and I am calling from GeoPoll Polling Agency on behalf of the humanitarian organization called Food and Agriculture Organization of the United Nations (FAO). We are conducting a survey on households' ability to access food in your area and the impact of COVID-19 pandemic. I would like to ask you some questions about your household. The survey usually takes 15/20 minutes to complete. Any information that you provide will be kept strictly confidential, only used for the purpose of the survey and will not be shown to other people. No personal identifying information will be collected. Your voluntary participation in the outcome of this interview is NOT IN ANY WAY linked to your personal chance of receiving any assistance. This is voluntary and you can choose not to answer any or all of the questions if you want. However, we hope that you will participate since your views are important. You will receive #TOPUP#! of communication credit as an incentive for the participation of the survey. Please note that this call may be recorded for quality purposes. Do you have any questions? [OPERATOR: ADDRESS QUESTIONS FROM RESPONDENT, IF ANY.] 1)CONTINUE | E14: =LEN(D14) -> 1204 | F14: Bonjour Monsieur/Madame, mon nom est #OPERATOR#. Je vous appelle de la part de l'agence de sondage GeoPoll pour le compte de l'organisation humanitaire appelée l'Organisation des Nations Unies pour l'alimentation et l'agriculture (la FAO). Nous menons une enquête sur la capacité des ménages à accéder à la nourriture dans votre région et sur l'impact de la pandémie de covid-19. J'aimerais vous poser quelques questions sur votre ménage. L'enquête dure généralement entre 15 et 20 minutes. Toutes les informations que vous fournirez resteront strictement confidentielles; elles ne seront utilisées que pour cette enquête et ne seront pas communiquées à d'autres personnes. Aucune information permettant de vous identifier personnellement ne sera recueillie. Votre participation volontaire à cet entretien n'est en AUCUN CAS liée à la possibilité de recevoir une quelconque aide. Votre participation est volontaire et, si vous le souhaitez, vous pouvez choisir de ne pas répondre à une partie ou à la totalité des questions. Cependant, nous espérons que vous voudrez bien participer car votre avis est important. Vous recevrez #TOPUP#! de crédit téléphonique comme incitation à participer à l'enquête. Veuillez noter que cet appel peut être enregistré à des fins de contrôle de la qualité. Avez-vous des questions? [OPÉRATEUR/OPÉRATRICE: RÉPONDRE, LE CAS ÉCHÉANT, AUX QUESTIONS DE LA PERSONNE INTERROGÉE.] 1)CONTINUER | G14: =LEN(F14) -> 1424 | H14: Single Choice | I14: NA | J14: NA | K14: Form Type - Buttons | L14: 1 = Agree | M14: For any response, go to Agree | O14: ALL | P14: Set the amount of incentive here, if any. Le cas échéant, définir ici le montant de l'incitation. | Q14: 50.82254 | S14: =Q14*R14 -> 0 | V14: no
A15: NA | B15: Agree | C15: resp_agree | D15: Are you interested in participating in this survey? [OPERATOR: SINGLE RESPONSE] 1)Yes 2)Not now but another time in the week 3)No | E15: =LEN(D15) -> 134 | F15: Souhaitez-vous participer à cette enquête? [OPÉRATEUR/OPÉRATRICE: RÉPONSE UNIQUE] 1)Oui 2)Pas maintenant, mais à un autre moment de la semaine 3)Non | G15: =LEN(F15) -> 152 | H15: StartRecording | I15: NA | J15: NA | K15: Form Type - Buttons | L15: 1 = resp_firstname 2 = WhenCallBack 3 = resp_refusalwhy | M15: if Agree = 1, go to resp_firstname if Agree = 2, go to WhenCallBack if Agree = 3, go to resp_refusalwhy | O15: ALL | Q15: 3.4964738 | R15: 1 | S15: =Q15*R15 -> 3.4964738 | V15: no
A16: NA | B16: resp_refusalwhy | C16: resp_refusalwhy | D16: Please let us know why you have REFUSED to take the survey. [OPERATOR: SINGLE RESPONSE] 1)Not interested 2)Do not want to be recorded 3)Other [specify] | E16: =LEN(D16) -> 153 | F16: Pourriez-vous m'indiquer pourquoi vous refusez de répondre à l'enquête. [OPÉRATEUR/OPÉRATRICE: RÉPONSE UNIQUE] 1)Pas intéressé 2)Ne veut pas être enregistré 3)Autre [préciser] | G16: =LEN(F16) -> 178 | H16: Open Ended - Single Choice | I16: NA | J16: NA | K16: Form Type - RadioList | L16: Any Response = Refusal | M16: For any response, go to Refusal | O16: resp_agree = 3 | Q16: 0 | R16: 1 | S16: =Q16*R16 -> 0 | V16: no
A17: NA | B17: WhenCallBack | C17: resp_whencallback | D17: When would it be a good time to call you back? [RECORD HH/MM/DD/MM OF CALLBACK] | E17: =LEN(D17) -> 80 | F17: À quel moment pourrais-je vous rappeler? [ENREGISTRER HH/MM/JJ/MM DU RAPPEL] | G17: =LEN(F17) -> 77 | H17: Open Ended | I17: NA | J17: NA | K17: Form Type - TextBox set as demographic | L17: Any Response = CallbackMessageEN | M17: For any response, go to CallbackMessageEN | O17: resp_agree = 2 | Q17: 0 | R17: 1 | S17: =Q17*R17 -> 0 | V17: no
A18: NA | B18: CallbackMessageEN | C18: callbackmessage_en | D18: Thank you, we will call you back at #WhenCallBack# you requested. Thank you again and have a great day! [OPERATOR: ENTER CALL NOTES BELOW, WHO YOU SPOKE TO AND WHAT THEY SAID] | E18: =LEN(D18) -> 176 | F18: Merci, nous vous rappellerons à #WhenCallBack#. Merci encore et bonne journée! [OPÉRATEUR/OPÉRATRICE: SAISIR LES DONNÉES D'APPEL CI-DESSOUS, LE NOM DE LA PERSONNE À LAQUELLE VOUS AVEZ PARLÉ ET CE QU'ELLE A DIT] | G18: =LEN(F18) -> 211 | H18: Open Ended | I18: NA | J18: NA | K18: Form Type - TextBox | L18: End poll callback | M18: NA | O18: resp_agree = 2 | Q18: 0 | R18: 1 | S18: =Q18*R18 -> 0 | V18: no
A19: NA | B19: Ineligible | C19: NA | D19: You are ineligible for this survey. Thank you for your time and please look out for future GeoPoll surveys! For more information visit GeoPoll.com | E19: =LEN(D19) -> 146 | F19: Vous ne pouvez être retenu pour cette enquête. Merci pour votre temps et renseignez-vous sur les prochains sondages GeoPoll! Pour plus d'informations, consultez GeoPoll.com | G19: =LEN(F19) -> 172 | H19: NA | I19: NA | J19: NA | K19: NA | L19: End Poll Ineligible | M19: NA | O19: NA | Q19: 0 | R19: 1 | S19: =Q19*R19 -> 0 | V19: no
A20: NA | B20: Refusal | C20: NA | D20: Thank you for your time, you will be removed from today's survey. | E20: =LEN(D20) -> 65 | F20: Merci pour votre temps. Vous serez écarté de l'enquête d'aujourd'hui. | G20: =LEN(F20) -> 69 | H20: NA | I20: NA | J20: NA | K20: NA | L20: End poll declined | M20: NA | O20: calldispo = 4 | Q20: 0 | R20: 1 | S20: =Q20*R20 -> 0 | V20: no
A21: B. GENERAL INFORMATION & ELIGIBILITY CRITERIA
A22: NA | B22: resp_firstname | C22: resp_firstname | D22: What is your first name? [OPERATOR: RECORD THE RESPONDENT'S FIRST NAME. ENTER 999 FOR REFUSED.] | E22: =LEN(D22) -> 96 | F22: Quel est votre prénom ? [OPÉRATEUR/OPÉRATRICE: ENREGISTRER LE PRÉNOM DE LA PERSONNE INTÉRROGÉE. SAISIR 999 POUR REFUSÉ.] | G22: =LEN(F22) -> 122 | H22: Open Ended | I22: NA | J22: NA | K22: Form Type - TextBox | L22: Any Response = resp_lastname | M22: For any response, go to resp_lastname | O22: resp_agree = 1 | Q22: 10 | R22: =1 -> 1 | S22: =Q22*R22 -> 10 | V22: yes | Z22: new question
A23: NA | B23: resp_lastname | C23: resp_lastname | D23: What is your last name? [OPERATOR: RECORD THE RESPONDENT'S LAST NAME. ENTER 999 FOR REFUSED.] | E23: =LEN(D23) -> 95 | F23: Quel est votre nom de famille ? [OPÉRATEUR/OPÉRATRICE: ENREGISTRER LE NOM DE FAMILLE DE LA PERSONNE INTÉRROGÉE. SAISIR 999 POUR REFUSÉ.] | G23: =LEN(F23) -> 138 | H23: Open Ended | I23: NA | J23: NA | K23: Form Type - TextBox | L23: Any Response = resp_age | M23: For any response, go to resp_age | O23: resp_agree = 1 | Q23: 10 | R23: =1 -> 1 | S23: =Q23*R23 -> 10 | V23: yes | Z23: new question
A24: 1 | B24: resp_age | C24: resp_age | D24: How old are you? [OPERATOR: RECORD AGE IN NUMBER OF YEARS. ROUND UP TO NEAREST WHOLE NUMBER. IF THE RESPONDENT GIVES BIRTH YEAR, REPEAT THE QUESTION. ENTER 00 FOR DON'T KNOW.] | E24: =LEN(D24) -> 177 | F24: Quel âge avez-vous (en années) ? [OPÉRATEUR/OPÉRATRICE: ENREGISTRER L'ÂGE EN ANNÉES. ARRONDIR AU NOMBRE ENTIER LE PLUS PROCHE. SI LE RÉPONDANT DONNE SON ANNÉE DE NAISSANCE, RÉPÉTER LA QUESTION. SAISIR 00 pour JE NE SAIS PAS.] | G24: =LEN(F24) -> 226 | H24: Range | I24: NA | J24: NA | K24: Form Type - TextBox | L24: 0-17 = Ineligible 18-100 = resp_gender 00 = Ineligible | M24: Only respondents from 18-100 will be eligible for the surve. | O24: resp_agree = 1 | Q24: 13.753073 | R24: =1 -> 1 | S24: =Q24*R24 -> 13.753073 | V24: yes
A25: =A24+1 -> 2 | B25: resp_gender | C25: resp_gender | D25: What is the gender of the respondent? [OPERATOR: DO NOT ASK THIS QUESTIONNAIRE. LISTEN TO THE VOICE AND CHECK THE CORRECT BOX.] 1)Male 2)Female 3)DON'T KNOW 4)REFUSED | E25: =LEN(D25) -> 168 | F25: Quel est le sexe du répondant ? [OPÉRATEUR/OPÉRATRICE: ÉCOUTER LA VOIX ET DÉTERMINER SI LE RÉPONDANT EST UN HOMME OU UNE FEMME.] 1)Homme 2)Femme 3)NE SAIT PAS 4)REFUSÉ | G25: =LEN(F25) -> 171 | H25: Single Choice | I25: NA | J25: NA | K25: Form Type - Buttons | L25: 1-4 = phone_number_conf | M25: For any response, go to phone_number_conf | O25: resp_agree = 1 resp_age = 18-100 | Q25: 2.1173561 | R25: =1 -> 1 | S25: =Q25*R25 -> 2.1173561 | V25: yes
R26: =1 -> 1 | S26: =Q26*R26 -> 0
B27: phone_number_conf | C27: phone_number_conf | D27: Is the phone number I am calling you on yours or a household member's? [OPERATOR: SINGLE RESPONSE.] 1)YES 2)NO 3)DON'T KNOW 4)REFUSED | E27: =LEN(D27) -> 135 | F27: Le numéro de téléphone sur lequel je vous appelle est-il le vôtre ou celui d'un membre de votre famille ? [OPÉRATEUR/OPÉRATRICE: RÉPONSE UNIQUE.] 1)Oui 2)Non 3)NE SAIT PAS 4)REFUSÉ | G27: =LEN(F27) -> 182 | H27: Single Choice | I27: NA | J27: NA | K27: Form Type - Buttons | L27: 1 = contact_2 2 = phone_number_personal 3-4 = contact_2 | M27: if phone_number_conf = 1, go to contact_2 if phone_number_conf = 2, go to phone_number_personal if phone_number_conf = 3-4, go to contact_2 | O27: resp_agree = 1 resp_age = 18-100 | Q27: 10 | R27: =1 -> 1 | S27: =Q27*R27 -> 10 | V27: yes - panel | Z27: new question
B28: phone_number_personal | C28: phone_number_pers | D28: What is your phone number? | E28: =LEN(D28) -> 26 | F28: Quel est votre numéro de téléphone ? | G28: =LEN(F28) -> 36 | H28: Open Ended | I28: NA | J28: NA | K28: Form Type - TextBox | L28: Any Response = contact_2 | M28: For any response, go to contact_2 | O28: resp_agree = 1 resp_age = 18-100 phone_number_conf = 2 | Q28: 10 | R28: =1 -> 1 | S28: =Q28*R28 -> 10 | V28: yes - panel | Z28: new question
B29: contact_2 | C29: contact_2 | D29: Can you give me an additonal phone number belonging to you, a relative or a friend at which you can be reached? [OPERATOR: SINGLE RESPONSE.] 1)YES - mine 2)YES - friend or relative 3)NO 4)DON'T KNOW 5)REFUSED | E29: =LEN(D29) -> 211 | F29: Pouvez-vous me donner un autre numéro de téléphone, le vôtre, celui d'un parent ou d'un ami, auquel vous pouvez être joint ? [OPÉRATEUR/OPÉRATRICE: RÉPONSE UNIQUE.] 1)Oui - le mien 2)Oui - celui d'un ami ou d'un parent 3)Non 4)NE SAIT PAS 5)REFUSÉ | G29: =LEN(F29) -> 249 | H29: Single Choice | I29: NA | J29: NA | K29: Form Type - Buttons | L29: 1-2 = phone_number_2 3-5 = hh_admin1 | M29: if contact_2 = 1-2, go to phone_number_2 if contact_2 = 3-5, go to contact_3 | O29: resp_agree = 1 resp_age = 18-100 | Q29: 10 | R29: =1 -> 1 | S29: =Q29*R29 -> 10 | V29: yes - panel | Z29: new question
B30: phone_number_2 | C30: phone_number_2 | D30: What is the additional phone number? | E30: =LEN(D30) -> 36 | F30: Quel est cet autre numéro de téléphone ? | G30: =LEN(F30) -> 40 | H30: Open Ended | I30: NA | J30: NA | K30: Form Type - TextBox | L30: Any Response = contact_2_name | M30: For any response, go to contact_2_name | O30: resp_agree = 1 resp_age = 18-100 contact_2 = 1 | 2 | Q30: 10 | R30: =1 -> 1 | S30: =Q30*R30 -> 10 | V30: yes - panel | Z30: new question
B31: contact_2_name | C31: contact_2_name | D31: What is the name of the contact? | E31: =LEN(D31) -> 32 | F31: Quel est le nom du contact associé à ce numéro de téléphone ? | G31: =LEN(F31) -> 61 | H31: Open Ended | I31: NA | J31: Send if "contact_2" "Equals" "YES - friend or relative", if not satisfied go to "contact_3" | K31: Form Type - TextBox | L31: Any Response = contact_3 | M31: Asked if "contact_2" "Equals" "YES - friend or relative". Otherwise, it skips to "contact_3". For any response, go to contact_3 | O31: resp_agree = 1 resp_age = 18-100 contact_2 = 2 | Q31: 10 | R31: =1 -> 1 | S31: =Q31*R31 -> 10 | V31: yes - panel
B32: contact_3 | C32: contact_3 | D32: Can you give me an additonal phone number belonging to you, a relative or a friend at which you can be reached? [OPERATOR: SINGLE RESPONSE.] 1)YES - mine 2)YES - friend or relative 3)NO 4)DON'T KNOW 5)REFUSED | E32: =LEN(D32) -> 211 | F32: Pouvez-vous me donner un autre numéro de téléphone, le vôtre, celui d'un parent ou d'un ami, auquel vous pouvez être joint ? [OPÉRATEUR/OPÉRATRICE: RÉPONSE UNIQUE.] 1)Oui - le mien 2)Oui - celui d'un ami ou d'un parent 3)Non 4)NE SAIT PAS 5)REFUSÉ | G32: =LEN(F32) -> 249 | H32: Single Choice | I32: NA | J32: NA | K32: Form Type - Buttons | L32: 1-2= phone_number_3 3-5 = hh_admin1 | M32: if contact_3 = 1-2, go to phone_number_3 if contact_3 = 3-5, go to hh_admin1 | O32: resp_agree = 1 resp_age = 18-100 contact_2 = 1 | 2 | Q32: 10 | R32: =1 -> 1 | S32: =Q32*R32 -> 10 | V32: yes - panel | Z32: new question
B33: phone_number_3 | C33: phone_number_3 | D33: What is the additional phone number? | E33: =LEN(D33) -> 36 | F33: Quel est cet autre numéro de téléphone ? | G33: =LEN(F33) -> 40 | H33: Open Ended | I33: NA | J33: NA | K33: Form Type - TextBox | L33: Any Response = contact_3_name | M33: For any response, go to contact_3_name | O33: resp_agree = 1 resp_age = 18-100 contact_3 = 1 | 2 | Q33: 10 | R33: =1 -> 1 | S33: =Q33*R33 -> 10 | V33: yes - panel | Z33: new question
B34: contact_3_name | C34: phone_number_3_name | D34: What is the name of the contact? | E34: =LEN(D34) -> 32 | F34: Quel est le nom du contact associé à ce numéro de téléphone ? | G34: =LEN(F34) -> 61 | H34: Open Ended | I34: NA | J34: Send if "contact_3" "Equals" "YES - friend or relative", if not satisfied go to "hh_admin1" | K34: Form Type - TextBox | L34: Any Response = hh_admin1 | M34: Asked if "contact_3" "Equals" "YES - friend or relative". Otherwise, it skips to "hh_admin1". For any response, go to hh_admin1 | O34: resp_agree = 1 resp_age = 18-100 contact_3 = 2 | Q34: 10 | R34: =1 -> 1 | S34: =Q34*R34 -> 10 | V34: yes - panel
R35: =1 -> 1 | S35: =Q35*R35 -> 0
A36: 3 | B36: hh_admin1 | C36: hh_admin1 | D36: Currently, in which $ADMIN1$ does your household reside? [OPERATOR: SINGLE SELECTION.] [HINT: HOUSEHOLD CONSISTS OF ALL MEMBERS LIVING TOGETHER, SHARING RESOURCES & EATING FROM THE SAME POT.] 1) … 2) … 3)DON'T KNOW 4)REFUSED | E36: =LEN(D36) -> 229 | F36: Actuellement, dans quel $ADMIN1$ votre ménage vit-il ? [OPÉRATEUR/OPÉRATRICE: RÉPONSE UNIQUE.] [CONSEIL: LE MÉNAGE EST COMPOSÉ DE TOUTES LES PERSONNES VIVANT ENSEMBLE, PARTAGEANT LEURS RESSOURCES ET MANGEANT DANS UNE MARMITE COMMUNE.] 1)... 2)... 3)NE SAIT PAS 4)REFUSÉ | G36: =LEN(F36) -> 273 | H36: Single Choice | I36: NA | J36: NA | K36: Form Type - Buttons set Demographic - ADM1 | L36: 1 = hh_admin2_1 2 = hh_admin2_2 […] 3-4 = Ineligible | M36: The administrative information will be updated by GeoPoll based on the sample design document and the administrative boundaries provided by the dashboard team after the questionnaire validation. | O36: resp_agree = 1 resp_age = 18-100 | Q36: 8.8 | R36: =1 -> 1 | S36: =Q36*R36 -> 8.8 | V36: yes
A37: =A36+1 -> 4 | B37: hh_admin2_1 | C37: hh_admin2_1 | D37: Currently, in which $ADMIN2$ does your household reside? [OPERATOR: SINGLE RESPONSE.] 1) … 2) … 3)DON'T KNOW 4)REFUSED | E37: =LEN(D37) -> 123 | F37: Actuellement, dans quel $ADMIN2$ votre ménage vit-il ? [OPÉRATEUR/OPÉRATRICE: RÉPONSE UNIQUE.] 1)... 2)... 3)NE SAIT PAS 4)REFUSÉ | G37: =LEN(F37) -> 134 | H37: Single Choice | I37: NA | J37: NA | K37: Form Type - Buttons set Demographic - ADM2 | L37: 1-2 = quotareached 3-4 = Ineligible | O37: resp_agree = 1 resp_age = 18-100 hh_admin1 = 1 | Q37: 10.4 | R37: =1 -> 1 | S37: =Q37*R37 -> 10.4 | V37: yes
A38: 4 | B38: hh_admin2_2 | C38: hh_admin2_2 | D38: Currently, in which $ADMIN2$ does your household reside? [OPERATOR: SINGLE RESPONSE.] 1) … 2) … 3) DON'T KNOW 4) REFUSED | E38: =LEN(D38) -> 125 | F38: Actuellement, dans quel $ADMIN2$ votre ménage vit-il ? [OPÉRATEUR/OPÉRATRICE: RÉPONSE UNIQUE.] 1) ... 2) ... 3)NE SAIT PAS 4)REFUSÉ | G38: =LEN(F38) -> 135 | H38: Single Choice | I38: NA | J38: NA | K38: Form Type - Buttons set Demographic - ADM2 | L38: 1-2 = quotareached 3-4 = Ineligible | O38: resp_agree = 1 resp_age = 18-100 hh_admin1 = 2 | R38: =1 -> 1 | S38: =Q38*R38 -> 0 | V38: yes
A39: =A38+1 -> 5 | B39: quotareached | C39: quotareached | D39: [OPERATOR: DO NOT READ. ANSWER QUESTION BELOW.] THIS RESPONDENT REPORTED THEY LIVE IN: #ADM1# #ADM2# 1)THE GOAL FOR THIS LOCATION HAS BEEN ACHIEVED - END SURVEY 2)THE GOAL FOR THIS LOCATION IS OPEN - CONTINUE SURVEY | E39: =LEN(D39) -> 218 | F39: [OPÉRATEUR/OPÉRATRICE: NE PAS LIRE. RÉPONDRE À LA QUESTION EN DESSOUS.] CE RÉPONDANT DIT VIVRE À: #ADM1# #ADM2# 1)L'OBJECTIF DANS CETTE ZONE A ÉTÉ ATTEINT - FIN DU SONDAGE 2)L'OBJECTIF DANS CETTE ZONE N'EST PAS ENCORE ATTEINT - CONTINUER LE SONDAGE | G39: =LEN(F39) -> 251 | H39: Single Choice | I39: NA | J39: NA | K39: Form Type - Buttons | L39: 1 = End Poll Quota Reached 2 = hh_agricactivity | M39: If the quota has not been reached, continue the questionnaire. If it has, end of survey. | O39: resp_agree = 1 resp_age = 18-100 | Q39: 2.28425 | R39: =1 -> 1 | S39: =Q39*R39 -> 2.28425 | V39: no
A40: =A39+1 -> 6 | B40: hh_agricactivity | C40: hh_agricactivity | D40: Has anybody in your household been producing crops or livestock for household consumption or for sale in the past 12 months, including household members currently away for transhumance? [OPERATOR: SINGLE RESPONSE. THIS IS THE MAIN SCREENING QUESTION. THE RESPONDENT WILL HAVE TO ANSWER. DON'T FORGET TO PROBE ABOUT TRANSHUMANCE.] [HINT: HOUSEHOLD CONSISTS OF ALL MEMBERS LIVING TOGETHER, SHARING RESOURCES & EATING FROM THE SAME POT.] 1)Yes - crop production 2)Yes - livestock production 3)Yes - both crop and livestock production 4)No 5)DON'T KNOW 6)REFUSED | E40: =LEN(D40) -> 563 | F40: Est-ce que quelqu'un dans votre ménage a produit des cultures ou du bétail pour la consommation du ménage ou pour la vente au cours des 12 derniers mois, y compris des membres du ménage actuellement partis pour la transhumance ? [OPÉRATEUR/OPÉRATRICE: RÉPONSE UNIQUE. IL S'AGIT DE LA PRINCIPALE QUESTION DE SÉLECTION. LA PERSONNE INTERROGÉE DOIT Y RÉPONDRE. NE PAS OUBLIER DE MENTIONNER LA TRANSHUMANCE]. [CONSEIL: LE MÉNAGE EST COMPOSÉ DE TOUTES LES PERSONNES VIVANT ENSEMBLE, PARTAGEANT LEURS RESSOURCES ET MANGEANT DANS UNE MARMITE COMMUNE.] 1)Oui - production végétale 2)Oui - production animale 3)Oui - production végétale et animale 4)Non 5)NE SAIT PAS 6)REFUSÉ | G40: =LEN(F40) -> 671 | H40: Single Choice | I40: NA | J40: NA | K40: Form Type - Buttons | L40: 1-4 = hh_gender 5-6 = Ineligible | M40: if hh_agricactivity = 1-4, go to hh_gender. Otherwise, the respondent is ineligible. | O40: resp_agree = 1 resp_age = 18-100 quotareached = 2 | Q40: 31.372377 | R40: =1 -> 1 | S40: =Q40*R40 -> 31.372377 | V40: yes
...

Sheet Crop list
I2: Dernier numéro
C3: Select top 10 crops | D3: GeoPoll code | E3: Dataset code | F3: Label (EN) | G3: Label (FR) | I3: =MAX(D:D) -> 94
D4: 1 | E4: 1.1 | F4: Rice | G4: Riz
D5: 2 | E5: 1.2 | F5: Wheat | G5: Blé
D6: 3 | E6: 1.3 | F6: Millet | G6: Mil
D7: 4 | E7: 1.4 | F7: Sorghum | G7: Sorgho
D8: 5 | E8: 1.5 | F8: Maize | G8: Maïs
D9: 6 | E9: 1.6 | F9: Barley | G9: Orge
D10: 7 | E10: 1.99 | F10: Other Cereal | G10: Autres céréales
D11: 8 | E11: 2.1 | F11: Cassava | G11: Manioc
D12: 9 | E12: 2.2 | F12: Potatoe | G12: Pommes de terre
D13: 10 | E13: 2.3 | F13: Sweet Potatoes | G13: Patates douces
D14: 11 | E14: 2.4 | F14: Yams | G14: Ignames
D15: 12 | E15: 2.5 | F15: Carrots | G15: Carottes
... D93: 66 | E93: 10.99 | F93: Other non-food cash crop | G93: Autre culture de rente non alimentaire

Sheet Additional information
C2: Original EN / FR | D2: Replacement (EN) | E2: Remplacement (FR) | F2: Comment (EN) | G2: Comment (FR) | H2: Example (EN) | I2: Exemple (FR)
B3: FOR CORE QUESTIONS . (Mandatory to fill out) . | C3: ADMIN1 / ADMIN1 | F3: The first subdivision of the country, after national level; region; province; governorate; etc. | G3: La première subdivision du pays, après le niveau national ; par exemple, région ; province ; gouvernorat ; etc. | H3: region | I3: region
C4: ADMIN2 / ADMIN2 | F4: The second subdivision of the country; district; municipality; LGA; etc. | G4: La deuxième subdivision du pays ; par exemple, district, municipalité, LGA, etc. | H4: district | I4: district
C5: reference year / reference year FR | F5: Comparison questions will need need a reference year. Select whether you want to use "last year" or "a normal year" as a baseline. A "normal year" should refers to an average year from the past 5 years - make sure to train the enumerators accordingly. | G5: Les questions de comparaison auront besoin d'une année de référence. Choisissez si vous voulez utiliser "l'année dernière" ou "une année normale" comme année de référence. Une "année normale" doit correspondre à une année moyenne des 5 dernières années - veillez à former les recenseurs en conséquence. | H5: a normal year | I5: une année normale
C6: season / saison | F6: Name the crop season(s) of interest if there are several cropping seasons in the country (e.g. Meher and Belg in Ethiopia, rainy season / flood-recession cropping / irrigated dry season in the Sahel). You can refer to the “last season” or “ongoing season". | G6: Nommez la ou les saisons culturales concernée(s) en ANGLAIS s'il y en a plusieurs dans le pays (par exemple, Meher et Belg en Ethiopie, saison des pluies / cultures de décrue / saison sèche irriguée au Sahel). Vous pouvez vous référer à la "dernière saison" ou "saison actuelle". | H6: wet season | I6: saison des pluies
C7: season phase / phase de la saison | D7: =IF(E7="Pas encore en saison","Not yet in season",IF(E7="Préparation du terrain","Land preparation",IF(E7="Semis / plantation","Planting",IF(E7="Début de la croissance","Early growing",IF(E7="Croissance","Growing",IF(E7="Proche de la récolte","Maturing",IF(E7="Récolte","Harvesting",IF(E7="Post-récolte","Recently finished","")))))))) | F7: Indicate the phase of the season at the time of data collection. If the harvest from the season has not yet occurred, the question on crop harvest (crp_harv_change) will include the word “expected” (where #expected or nothing# is located). If the harvest has occured, "expected" will not be inserted in the question. | G7: Indiquez le stade de la saison culturale au moment de la collecte des données. Si la récolte de la saison n'a pas encore eu lieu, la question sur la récolte des cultures (crp_harv_change) inclura le mot "attendue" (là où se trouve #attendue ou rien#). Si la récolte a eu lieu, "attendue" ne sera pas inséré dans la question. | H7: Harvesting | I7: Récolte
C8: local measurement unit | F8: Specify the local measurement unit for land size, other than acres, hectares, square meters and square feet. If no other unit of measurement is needed, keep this cell blank. | G8: Indiquez l'unité utilisée localement pour mesurer la taille des terrains, autre que les acres, les hectares, les mètres carrés et les pieds carrés. Si aucune autre unité de mesure n'est nécessaire, garder cette cellule vide. | H8: Jeribs | I8: Jeribs
C9: local measurement unit conversion | D9: =IF(E9<>"",E9,"") | F9: Include the conversion of the local measurement unit to hectares. In other words, how many local measurement units are in 1 ha. | G9: Indiquez la conversion de l'unité de mesure locale en hectares. En d'autres termes, indiquez combien d'unités de mesure locales y a-t-il dans 1 ha. | H9: 0.2 | I9: 0.2
B10: FOR OPTIONAL QUESTIONS . (Fill out if applicable) . | C10: currency / devise | D10: =IF(E10="","",E10) | F10: The name of the main currency used nationally; USD; Naira; Rial; Pesos; etc. | G10: Nom de la principale devise utilisée au niveau national; par exemple, USD; Naira; Rial; Pesos; etc. | H10: Naira | I10: Naira
C11: MIN AMOUNT / MIN AMOUNT | D11: =IF(E11="","",E11) | F11: The minimum amount for an income source should be set at 0 or any value below which it is not possible to do a transaction. For example, the smallest coin/banknote in a currency can be 1000, in which case you would set the minimum at 1000. Provide this input in the same currency as specified above. Only digits should be inputted. | G11: Le montant minimum d'une source de revenu doit être fixé à 0 ou à toute valeur en dessous de laquelle il n'est pas possible d'effectuer une transaction. Par exemple, la plus petite pièce/billet d'une devise peut être de 1000, auquel cas vous fixerez le minimum à 1000. Cette saisie doit être effectuée dans la même devise que celle spécifiée ci-dessus. Seuls des chiffres doivent être saisis. | H11: 5 | I11: 5
C12: MAX AMOUNT / MAX AMOUNT | D12: =IF(E12="","",E12) | F12: Set the maximum amount for an income source over 3 months. It will not be possible for enumerators to input values above this amount in questions related to income amounts. Using previous representative surveys for this population, you can estimate this amount by using the mean income plus five (5) standard deviations, unless the country has high inflation. In the latter case, set the maximum value based on your country context (higher than the proposed approach). Provide this input in the same currency as specified above. Only digits should be inputted. | G12: Fixez le montant maximum pouvant être généré par une source de revenu sur 3 mois. Il ne sera pas possible pour les enquêteurs d'entrer des valeurs supérieures à ce montant dans les questions relatives aux montants des revenus. En vous basant sur des enquêtes précédentes représentatives de cette population, vous pouvez estimer ce montant en utilisant le revenu moyen plus cinq (5) écarts types, sauf si le pays connaît une forte inflation. Dans ce dernier cas, fixez la valeur maximale en fonction du contexte de votre pays (plus élevée que l'approche proposée). Cette saisie doit être effectuée dans la même devise que celle spécifiée ci-dessus. Seuls des chiffres doivent être saisis. | H12: 5000000 | I12: 5000000
C13: THRESHOLD / THRESHOLD | D13: =IF(E13="","",E13) | F13: The threshold salary should be calculated to flag outliers (responses that look suspiciously high). Using previous representative surveys for this population, a good estimate is the average plus three (3) standard deviations, which should give the threshold for the 3 or 4% highest income values. Provide this input in the same currency as specified above. Only digits should be inputted. | G13: Le salaire seuil doit être calculé pour signaler les valeurs aberrantes (réponses qui semblent suspectes). En utilisant des enquêtes précédentes représentatives de cette population, une bonne estimation est la moyenne plus deux écarts types, ce qui devrait dégager le seuil pour les 3 ou 4% des valeurs de revenu les plus élevées. Cette saisie doit être effectuée dans la même devise que celle spécifiée ci-dessus. Seuls des chiffres doivent être saisis. | H13: 1200000 | I13: 1200000
C14: local vegetables / légumes locaux | F14: Input some common local vegetables [to be used as examples in the food consumption score indicator]. | G14: Saisissez quelques légumes locaux courants [à utiliser comme exemples dans l'indicateur de score de consommation alimentaire]. | H14: eggplants, zucchini, cauliflower | I14: aubergines, courgettes, choux-fleurs
C15: local fruits / fruits locaux | F15: Input some common local fruits [to be used as examples in the food consumption score indicator]. | G15: Indiquez quelques fruits locaux courants [à utiliser comme exemples dans l'indicateur de score de consommation alimentaire]. | H15: apples, bananas, oranges | I15: pommes, bananes, oranges
B17: FILL OUT FOR QUESTIONNAIRE DURATION ESTIMATION . | C17: Expected percentage of respondents cultivating crops | D17: =IF(E17="","",E17) -> 0.91 | E17: 0.91 | F17: If the survey is representative and has no quotas, write the proportion of rural households cultivating crops at country level, or if the survey follows a previous round with identical sample design, just report the percentage from the previous round. If you are using quotas, calculate the ratio of the quota over the minimum sample size at the level where the quota is implemented (so if you have a minimum sample size per strata of 110 with a quota of 100 crop producers, then it's 100/110 = 91% (the maximum you should write is 100%). | G17: Si l'enquête est représentative et ne comporte pas de quotas, écrivez la proportion de ménages ruraux impliqués dans les cultures au niveau du pays, ou si l'enquête suit un cycle précédent avec un plan d'échantillonnage identique, indiquez simplement le pourcentage du cycle précédent. Si vous utilisez des quotas, calculez le rapport entre le quota et la taille minimale de l'échantillon au niveau où le quota est appliqué (ainsi, si vous avez une taille minimale d'échantillon par strate de 110 avec un quota de 100 producteurs de cultures, alors c'est 100/110 = 91% (le maximum que vous devez écrire est 100%). | H17: 0.91 | I17: 0.91
C18: Expected percentage of respondents raising livestock | D18: =IF(E18="","",E18) -> 0.91 | E18: 0.91 | F18: If the survey is representative and has no quotas, write the proportion of rural households raising livestock at country level, or if the survey follows a previous round with identical sample design, just report the percentage from the previous round. If you are using quotas, calculate the ratio of the quota over the minimum sample size at the level where the quota is implemented (so if you have a minimum sample size of 110 but a quota of 100 livestock producers, then it's 100/110 = 91% (the maximum you should write is 100%) | G18: Si l'enquête est représentative et ne comporte pas de quotas, écrivez la proportion de ménages ruraux impliqués dans l'élevage, ou si l'enquête suit un cycle précédent avec un plan d'échantillonnage identique, indiquez simplement le pourcentage du cycle précédent. Si vous utilisez des quotas, calculez le rapport entre le quota et la taille minimale de l'échantillon au niveau où le quota est appliqué (ainsi, si vous avez une taille minimale d'échantillon par strate de 110 avec un quota de 100 éleveurs, alors c'est 100/110 = 91% (le maximum que vous devez écrire est 100%). | H18: 0.91 | I18: 0.91
C19: Expected percentage of respondents involved in fishery | D19: =IF(E19="","",E19) -> 0.05 | E19: 0.05 | F19: If the survey is representative and has no quotas, write the proportion of rural households involved in fisheries or aquaculture, otherwise if you are using quotas, calculate the ratio of the quota over the sample size at the level where the quota is implemented. (so if you haven't set a quota, and you expect to have a representative proportion of fishermen, just write the percentage of fishermen in the population you are targeting, in the example to the right, 5%) | G19: Si l'enquête est représentative et ne comporte pas de quotas, écrivez la proportion de ménages ruraux impliqués dans la pêche ou l'aquaculture; sinon, si vous utilisez des quotas, calculez le rapport entre le quota et la taille de l'échantillon au niveau où le quota est appliqué (ainsi, si vous n'avez pas fixé de quota, et que vous pensez avoir une proportion représentative de pêcheurs, écrivez simplement le pourcentage de pêcheurs dans la population que vous ciblez, dans l'exemple à droite, 5%). | H19: 0.05 | I19: 0.05
