Workbook

Sheet survey
A1: GeoPoll Submission Form | AB1: Change made
A2: FAO - Household Questionnaire | R2: Additional notes
A3: Q # | B3: Q Name | C3: Suggested Qname | D3: English | E3: Length | F3: my_Burmese | G3: Length | H3: Q Type | I3: Randomize | J3: Conditional | K3: Programming Instructions | L3: Codes | M3: Skip Pattern | N3: GeoPoll Comments | O3: Default skip patterns & conditional | P3: Specify skip pattern variable [from blue text] | Q3: UNIVERSE | S3: Duration average [sec] | T3: Estimated percentage of repondents | U3: Weighted Duration | X3: Mandatory
A4: A. PRESENTATION OF THE SURVEY AND ELIGIBILITY CRITERIA SELECTION | X4: no
A5: NA | B5: Optin | D5: Optin | E5: =LEN(D5) | F5: Optin | G5: =LEN(F5) | H5: Open Ended | I5: NA | J5: NA | K5: Form Type - TextBox | L5: NA | M5: Any Response = calldispo | O5: NA | Q5: ALL | S5: 0 | U5: =S5*T5 | X5: no
A6: NA | B6: calldispo | C6: calldispo | D6: Phone number: #CATI_MOBILENUMBER# 1)Someone answers 2)Answering machine 3)No answer 4)Hang up or refusal 5)Call back 6)Under review 7)Disconnected | E6: =LEN(D6) | F6: ဖုန်းနံပါတ်- #CATI_MOBILENUMBER# 1)တစ်စုံတစ်ယောက်က ဖြေကြားသည် 2)ဖုန်းဖြေကြားစက် 3)မဖြေကြားပါ 4)ဖုန်းချလိုက်သည် သို့မဟုတ် ဖုန်းကိုင်ရန် ငြင်းဆိုသည် 5)ဖုန်းပြန်ခေါ်သည် 6)သုံးသပ်နေဆဲ 7)ဖုန်းလိုင်း ပြတ်တောက်သွားသည် | G6: =LEN(F6) | H6: Single Choice | I6: NA | J6: NA | K6: Form Type - Buttons | L6: NA | M6: 1 = resp_language 2 = AnsweringMachine 3 = NoAnswer 4 = Refusal 5 = WhenCallBack 6 = UnderReview 7 = Disconnected | O6: NA | Q6: ALL | S6: 0 | U6: =S6*T6 | X6: no
A7: NA | B7: AnsweringMachine | C7: calldispo_answeringmachine | D7: Reached an answering machine. | E7: =LEN(D7) | F7: ဖြေကြားစက်မှ ပြန်လည်ဖြေကြားခဲ့သည်။ | G7: =LEN(F7) | H7: NA | I7: NA | J7: NA | K7: NA | L7: NA | M7: End Poll AnsweringMachine | O7: NA | Q7: calldispo = 2 | S7: 0 | U7: =S7*T7 | X7: no
A8: NA | B8: NoAnswer | C8: calldispo_noanswer | D8: Phone rang and no one answered. | E8: =LEN(D8) | F8: ဖုန်းမြည်ပြီး မည်သူမှပြန်မဖြေပါ။ | G8: =LEN(F8) | H8: NA | I8: NA | J8: NA | K8: NA | L8: NA | M8: End Poll NoAnswer | O8: NA | Q8: calldispo = 3 | S8: 0 | U8: =S8*T8 | X8: no
A9: NA | B9: UnderReview | C9: calldispo_underreview | D9: Case needs review by a supervisor. | E9: =LEN(D9) | F9: ကိစ္စရပ်ကို ကြီးကြပ်သူက ပြန်လည်သုံးသပ်ရန်လိုအပ်သည်။ | G9: =LEN(F9) | H9: NA | I9: NA | J9: NA | K9: NA | L9: NA | M9: End Poll UnderReview | O9: NA | Q9: calldispo = 6 | S9: 0 | U9: =S9*T9 | X9: no
A10: NA | B10: Disconnected | C10: calldispo_disconnected | D10: Phone was disconnected or out of service. | E10: =LEN(D10) | F10: ဖုန်းလိုင်း ပြတ်တောက်သွားခဲ့သည် သို့မဟုတ် ဆက်သွယ်မှုဧရိယာပြင်ပဖြစ်နေခဲ့သည်။ | G10: =LEN(F10) | H10: NA | I10: NA | J10: NA | K10: NA | L10: NA | M10: End Poll Disconnected | O10: NA | Q10: calldispo = 7 | S10: 0 | U10: =S10*T10 | X10: no
A11: 1 | B11: resp_language | C11: resp_language | D11: Which language do you wish to proceed with? [OPERATOR: READ ANSWER CHOICES. SINGLE RESPONSE.] 1)Burmese 2)English [FOR TESTING ONLY] | E11: =LEN(D11) | F11: မည်သည့်ဘာသာစကားဖြင့် ဆက်လက်လုပ်ဆောင်လိုပါသလဲ။ [အော်ပရေတာ- အဖြေရွေးချယ်မှုများကို ဖတ်ရှုပါ။ တုံ့ပြန်မှုတစ်ခုသာ။] 1) ဗမာဘာသာ 2) အင်္ဂလိပ်ဘာသာ [စမ်းသပ်ရန်အတွက်သာ] | G11: =LEN(F11) | H11: Single Choice | I11: NA | J11: NA | K11: Form Type - Buttons | L11: NA | M11: 1 = introduction [Burmese] 2 = introduction [English] | O11: For any response, go to introduction | Q11: ALL | S11: 3.0622325 | U11: =S11*T11 | X11: no
A12: =A11+1 | B12: introduction | C12: introduction | D12: Hello sir/ma'am, my name is #OPERATOR#, and I am calling from GeoPoll Polling Agency on behalf of the humanitarian organization called Food and Agriculture Organization of the United Nations (FAO) and the World Food Programme (WFP). We are conducting a survey on household livelihoods and the ability to access food in your area. I would like to ask you some questions about your household. The survey usually takes 20/25 minutes to complete. Any information that you provide will be kept strictly confidential, only used for the purpose of the survey and will not be shown to other people. No personal identifying information will be collected. Your voluntary participation in the outcome of this interview is NOT IN ANY WAY linked to your personal chance of receiving any assistance. This is voluntary and you can choose not to answer any or all of the questions if you want. However, we hope that you will participate since your views are important. You will receive #TOPUP#! of communication credit as an incentive for the participation of the survey. Please note that this call may be recorded for quality purposes. Do you have any questions? [OPERATOR: ADDRESS QUESTIONS FROM RESPONDENT, IF ANY.] 1)CONTINUE | E12: =LEN(D12) | F12: မင်္ဂလာပါခင်ဗျာ၊ ကျွန်တော့်နာမည်ကတော့ #OPERATOR# ဖြစ်ပြီး ကုလသမဂ္ဂ စားနပ်ရိက္ခာနှင့်စိုက်ပျိုးရေးအဖွဲ့ (FAO) နှင့် ကုလသမဂ္ဂ ကမ္ဘာ့စားနပ်ရိက္ခာအစီအစဉ် (WFP) လို့ခေါ်တဲ့ လူသားချင်းစာနာမှုအဖွဲ့အစည်းကိုယ်စား GeoPoll Polling Agency ကနေ ခေါ်ဆိုတာဖြစ်ပါတယ်။ လူကြီးမင်း၏အိမ်ထောင်စုနှင့်ပတ်သက်ပြီး မေးခွန်းအချို့ မေးမြန်းလိုပါတယ်။ စစ်တမ်းပြီးမြောက်အောင်ဖြေဆိုရန်အတွက် အချိန် 20 မိနစ်/မိနစ် 25 ကြာမြင့်နိုင်ပါတယ်။ လူကြီးမင်းဖော်ပြသော မည်သည့်သတင်းအချက်အလက်ကိုမဆို တင်းကျပ်စွာ လျှို့ဝှက်ထားမည်ဖြစ်ပြီး စစ်တမ်း၏ရည်ရွယ်ချက်အတွက်သာ အသုံးပြုမည်ဖြစ်ကာ အခြားသူများထံ ပြသမည်မဟုတ်ပါ။ မည်သူမည်ဝါဖြစ်ကြောင်း ခွဲခြားသိရှိနိုင်သည့်အချက်အလက်များကို ကောက်ယူမည်မဟုတ်ပါ။ ဤအင်တာဗျူးရလဒ်အတွက် လူကြီးမင်း၏ဆန္ဒအလျောက်ပါဝင်မှုသည် အကူအညီတစ်စုံတစ်ရာရရှိနိုင်သည့် လူကြီးမင်း၏ကိုယ်ပိုင်အခွင့်အရေးနှင့် လုံးဝဆက်စပ်မှုမရှိပါ။ ဒီအင်တာဗျူးဟာ မိမိသဘောဆန္ဒအလျောက်ပါဝင်နိုင်တဲ့ အင်တာဗျူးဖြစ်ပြီး လူကြီးမင်းဆန္ဒရှိပါက မေးခွန်းတစ်စုံတစ်ခုကိုဖြစ်စေ သို့မဟုတ် မေးခွန်းအားလုံးကိုဖြစ်စေ မဖြေကြားရန် ရွေးချယ်နိုင်ပါတယ်။ သို့သော် လူကြီးမင်း၏အမြင်များသည် အရေးကြီးသောကြောင့် လူကြီးမင်းအနေနဲ့ ပါဝင်ပေးဖို့ ကျွန်တော်တို့ မျှော်လင့်ပါတယ်။ စစ်တမ်းတွင်ပါဝင်ခြင်းအတွက် လက်ဆောင်အဖြစ် ဖုန်းခေါ်ဆိုခွင့်ပမာဏ #TOPUP# ရရှိမှာ ဖြစ်ပါတယ်။ အရည် အသွေးကို ထိန်းသိမ်း ရန် ရည်ရွယ်ချက်အတွက် ဤခေါ်ဆိုမှုကို မှတ်တမ်းတင်ထားနိုင်သည်ကို ကျေးဇူးပြု၍ သတိပြုပါ။ မေးမြန်းလိုသည်များ ရှိပါသလား။ [အော်ပရေတာ- ဖြေဆိုသူထံမှ မေးခွန်းများရှိပါက ၎င်းတို့ကို ဖြေဆိုပါ။] 1) ရှေ့ဆက်ရန် | G12: =LEN(F12) | H12: Single Choice | I12: NA | J12: NA | K12: Form Type - Buttons | L12: NA | M12: 1 = Agree | O12: For any response, go to Agree | Q12: ALL | S12: 50.82254 | U12: =S12*T12 | X12: no
A13: =A12+1 | B13: Agree | C13: resp_agree | D13: Are you interested in participating in this survey? [OPERATOR: SINGLE RESPONSE] 1)Yes 2)Not now but another time in the week 3)No | E13: =LEN(D13) | F13: ဤစစ်တမ်းတွင်ပါဝင်ရန် စိတ်ဝင်စားပါသလား။ [အော်ပရေတာ- တုံ့ပြန်မှုတစ်ခုသာ] 1)ဟုတ် 2)ယခုစိတ်မဝင်စားသေးသော်လည်း တစ်ပတ်အတွင်း စစ်တမ်းနောက်တစ်ကြိမ်ကျင်းပသောအခါ ပါဝင်မည် 3)စိတ်မဝင်စားပါ | G13: =LEN(F13) | H13: StartRecording | I13: NA | J13: NA | K13: Form Type - Buttons | L13: NA | M13: 1 = resp_age 2 = WhenCallBack 3 = resp_refusalwhy | O13: if Agree = 1, go to resp_firstname if Agree = 2, go to WhenCallBack if Agree = 3, go to resp_refusalwhy | Q13: ALL | S13: 3.4964738 | T13: 1 | U13: =S13*T13 | X13: no
A14: NA | B14: resp_refusalwhy | C14: resp_refusalwhy | D14: Please let us know why you have REFUSED to take the survey. [OPERATOR: SINGLE RESPONSE] 1)Not interested 2)Do not want to be recorded 3)Other [specify] | E14: =LEN(D14) | F14: စစ်တမ်းဖြေဆိုရန် အဘယ်ကြောင့်ငြင်းဆန်သည်ကို ကျွန်ုပ်တို့အား အသိပေးပါ။ [အော်ပရေတာ- တုံ့ပြန်မှုတစ်ခုသာ] 1)စိတ်မဝင်စားသောကြောင့် 2)မှတ်တမ်းတင်ခြင်း ကို မပြုလုပ်ချင်​သော​ကြောင့် 3)အခြား [အသေးစိတ်ဖော်ပြပါ] | G14: =LEN(F14) | H14: Open Ended-Single Choice | I14: NA | J14: NA | K14: Form Type - RadioList | L14: NA | M14: Any Response = Refusal | O14: For any response, go to Refusal | Q14: resp_agree = 3 | S14: 0 | T14: 1 | U14: =S14*T14 | X14: no
A15: NA | B15: WhenCallBack | C15: resp_whencallback | D15: When would it be a good time to call you back? [RECORD HH/MM/DD/MM OF CALLBACK] | E15: =LEN(D15) | F15: လူကြီးမင်းအား မည်သည့်အချိန်တွင် ပြန်လည်ခေါ်ဆိုရန် အဆင်ပြေပါသလဲ။ [ပြန်လည်ခေါ်ဆိုမှု မှတ်တမ်း နာရီ /မိနစ် /ရက်/လ] | G15: =LEN(F15) | H15: Open Ended | I15: NA | J15: NA | K15: Form Type - TextBox IsCallBackdemographic | L15: NA | M15: Any Response = CallbackMessageEN | O15: For any response, go to CallbackMessageEN | Q15: resp_agree = 2 | S15: 0 | T15: 1 | U15: =S15*T15 | X15: no
A16: NA | B16: CallbackMessageEN | C16: callbackmessage_en | D16: Thank you, we will call you back at {WhenCallBack} you requested. Thank you again and have a great day! [OPERATOR: ENTER CALL NOTES BELOW, WHO YOU SPOKE TO AND WHAT THEY SAID] | E16: =LEN(D16) | F16: ကျေးဇူးတင်ပါတယ်။ လူကြီးမင်းတောင်းဆိုသော {WhenCallBack} တွင် ဖုန်းပြန်လည်ခေါ်ဆိုပါမယ်။ ကျေးဇူးထပ်မံတင်ရှိပါတယ်။ သာယာတဲ့နေ့လေးဖြစ်ပါစေ။ [အော်ပရေတာ- ဖုန်းခေါ်ဆိုမှုမှတ်တမ်းများကို အောက်တွင် ဖြည့်သွင်းပါ၊ သင်နှင့်စကားပြောဆိုခဲ့သူများနှင့် ၎င်းတို့ပြောဆိုခဲ့သည်များ] | G16: =LEN(F16) | H16: Open Ended | I16: NA | J16: NA | K16: Form Type - TextBox | L16: NA | M16: Any Response = End poll callback | O16: NA | Q16: resp_agree = 2 | S16: 0 | T16: 1 | U16: =S16*T16 | X16: no
A17: NA | B17: Ineligible | C17: NA | D17: You are ineligible for this survey. Thank you for your time and please look out for future GeoPoll surveys! For more information visit GeoPoll.com | E17: =LEN(D17) | F17: လူကြီးမင်းသည် ဤစစ်တမ်းအတွက် အရည်အချင်းမပြည့်မီပါ။ လူကြီးမင်း၏အချိန်ပေးမှုအတွက် ကျေးဇူးတင်ရှိပြီး နောင်တွင်လည်း GeoPoll စစ်တမ်းများကို ဖြေကြားပေးစေလိုပါတယ်။ ပိုမိုသိရှိလိုပါက GeoPoll.com သို့ ဝင်ရောက်ကြည့်ရှုပါ | G17: =LEN(F17) | H17: NA | I17: NA | J17: NA | K17: NA | L17: NA | M17: End Poll Ineligible | O17: NA | Q17: NA | S17: 0 | T17: 1 | U17: =S17*T17 | X17: no
A18: NA | B18: Refusal | C18: NA | D18: Thank you for your time, you will be removed from today's survey. | E18: =LEN(D18) | F18: လူကြီးမင်း၏အချိန်ပေးမှုအတွက် ကျေးဇူးတင်ပါတယ်၊ လူကြီးမင်းအား ယနေ့စစ်တမ်းမှ ဖယ်ထုတ်သွားမှာဖြစ်ပါတယ်။ | G18: =LEN(F18) | H18: NA | I18: NA | J18: NA | K18: NA | L18: NA | M18: End poll declined | O18: NA | Q18: calldispo = 4 | S18: 0 | T18: 1 | U18: =S18*T18 | X18: no
A19: B. GENERAL INFORMATION & ELIGIBILITY CRITERIA
A20: 4 | B20: resp_age | C20: resp_age | D20: How old are you? [OPERATOR: RECORD AGE IN NUMBER OF YEARS. ROUND UP TO NEAREST WHOLE NUMBER. IF THE RESPONDENT GIVES BIRTH YEAR, REPEAT THE QUESTION. ENTER 00 FOR DON'T KNOW.] | E20: =LEN(D20) | F20: အသက်ဘယ်လောက်ပါလဲ။ [အော်ပရေတာ- အသက်ကို နှစ်အရေအတွက်ဖြင့်မှတ်တမ်းတင်ပါ။ အနီးစပ်ဆုံးကိန်းပြည့်ကို ယူပါ။ အကယ်၍ ဖြေဆိုသူသည် မွေးဖွားသည့်ခုနှစ်ကိုပြောပါက မေးခွန်းကိုပြန်မေးပါ။ မသိပါဟု ဖြေဆိုပါက 00 ဟု ဖြည့်သွင်းပါ။] | G20: =LEN(F20) | H20: Range | I20: NA | J20: NA | K20: Form Type - TextBox | L20: NA | M20: 0-17 = Ineligible 18-100 = resp_gender 00 = Ineligible | O20: Only respondents from 18-100 will be eligible for the surve. | Q20: resp_agree = 1 | S20: 13.753073 | T20: =1 | U20: =S20*T20 | X20: yes
A21: =A20+1 | B21: resp_gender | C21: resp_gender | D21: What is the gender of the respondent? [OPERATOR: DO NOT ASK THIS QUESTION. LISTEN TO THE VOICE AND CHECK THE CORRECT BOX.] 1)Male 2)Female 3)DON'T KNOW 4)REFUSED | E21: =LEN(D21) | F21: ဖြေဆိုသူသည် ကျား သို့မဟုတ် မ ဖြစ်ပါသလား။ [အော်ပရေတာ- ထိုမေးခွန်းကို မမေးပါနှင့်။ အသံကိုနားထောင်ပြီး မှန်ကန်သောအကွက်တွင် အမှတ်ခြစ်ပါ။] 1)အမျိုးသား 2)အမျိုးသမီး 3)မသိပါ 4)ဖြေဆိုရန် ငြင်းဆန်သည် | G21: =LEN(F21) | H21: Single Choice | I21: NA | J21: NA | K21: Form Type - Buttons | L21: NA | M21: 1-4 = hh_admin1 | O21: For any response, go to phone_number_conf | Q21: resp_agree = 1 resp_age = 18-100 | S21: 2.1173561 | T21: =1 | U21: =S21*T21 | X21: yes
A22: =A21+1 | B22: hh_admin1 | C22: hh_admin1 | D22: Currently, in which State/Region does your household reside? [OPERATOR: SINGLE SELECTION.] [HINT: HOUSEHOLD CONSISTS OF ALL MEMBERS LIVING TOGETHER, SHARING RESOURCES & EATING FROM THE SAME POT.] 1)AYEYARWADY 2)BAGO 3)CHIN 4)KACHIN 5)KAYAH 6)KAYIN 7)MAGWAY 8)MANDALAY 9)MON 10)NAY PYI TAW 11)RAKHINE 12)SAGAING 13)SHAN 14)TANINTHARYI 15)YANGON 16)DON'T KNOW 17)REFUSED | E22: =LEN(D22) | F22: လက်ရှိအချိန်၌ လူကြီးမင်း၏အိမ်ထောင်စုသည် မည်သည့်ပြည်နယ်/တိုင်းဒေသကြီးတွင် နေထိုင်သနည်း။ [အော်ပရေတာ- ရွေးချယ်မှုတစ်ခုသာ။] [အရိပ်အမြွက် - အိမ်ထောင်စုတွင် အတူတကွနေထိုင်ကာ ရင်းမြစ်များကို မျှဝေသုံးစွဲပြီး တစ်အိုးတည်းစားသောက်သော မိသားစုဝင်များအားလုံး ပါဝင်သည်။] 1) ဧရာဝတီ 2) ပဲခူး 3) ချင်း 4) ကချင် 5) ကယား 6) ကရင် 7) မကွေး 8) မန္တလေး 9) မွန် 10) နေပြည်တော် 11) ရခိုင် 12) စစ်ကိုင်း 13) ရှမ်း 14) တနင်္သာရီ 15) ရန်ကုန် 16) မသိပါ 17) ဖြေဆိုရန် ငြင်းဆန်သည် | G22: =LEN(F22) | H22: Single Choice | I22: NA | J22: NA | K22: Form Type - Dropdown IsDemographic - ADM1 | L22: NA | M22: 1 = o_hh_admin3_1 2 = o_hh_admin3_2 3 = o_hh_admin3_3 4 = o_hh_admin3_4 5 = o_hh_admin3_5 6 = o_hh_admin3_6 7 = o_hh_admin3_7 8 = o_hh_admin3_8 9 = o_hh_admin3_9 10 = Ineligible 11 = o_hh_admin3_11 12 = o_hh_admin3_12 13 = o_hh_admin3_13 14 = o_hh_admin3_14 15 = o_hh_admin3_15 16,17 = Ineligible | O22: The administrative information will be updated by GeoPoll based on the sample design document and the administrative boundaries provided by the dashboard team after the questionnaire validation. | Q22: resp_agree = 1 resp_age = 18-100 | S22: 8.8 | T22: =1 | U22: =S22*T22 | X22: yes
A23: =A22+1 | B23: o_hh_admin3_1 | C23: o_hh_admin3 | D23: Currently, in which Township does your household reside? [OPERATOR: SINGLE RESPONSE.] 1)BOGALE 2)DANUBYU 3)DEDAYE 4)EINME 5)HINTHADA 6)INGAPU 7)KANGYIDAUNT 8)KYAIKLAT 9)KYANGIN 10)KYAUNGGON 11)KYONPYAW 12)LABUTTA 13)LEMYETHNA 14)MAUBIN 15)MAWLAMYINEGYUN 16)MYANAUNG 17)MYAUNGMYA 18)NGAPUDAW 19)NYAUNGDON 20)PANTANAW 21)PATHEIN 22)PYAPON 23)THABAUNG 24)WAKEMA 25)YEGYI 26)ZALUN 27)DON'T KNOW 28)REFUSED | E23: =LEN(D23) | F23: လက်ရှိအချိန်တွင် လူကြီးမင်း၏အိမ်ထောင်စုသည် မည်သည့်မြို့နယ်၌ နေထိုင်ပါသနည်း။ [အော်ပရေတာ- တုံ့ပြန်မှုတစ်ခုသာ။] 1)ဘိုကလေး 2)ဓနုဖြူ 3)ဒေးဒရဲ 4)အိမ်မဲ 5)ဟင်္သာတ 6)အင်္ဂပူ 7)ကန်ကြီးထောင့် 8)ကျိုက်လတ် 9)ကြံခင်း 10)ကျောင်းကုန်း 11)ကျုံပျော် 12)လပွတ္တာ 13)လေးမျက်နှာ 14)မအူပင် 15)မော်လမြိုင်ကျွန်း 16)မြန်အောင် 17)မြောင်းမြ 18)ငပုတော 19)ညောင်တုန်း 20)ပန်းတနော် 21)ပုသိမ် 22)ဖျာပုံ 23)သာပေါင်း 24)ဝါးခယ်မ 25)ရေကြည် 26)ဇလွန် 27)မသိပါ 28)ဖြေဆိုရန် ငြင်းဆန်သည် | G23: =LEN(F23) | H23: Single Choice | I23: NA | J23: NA | K23: Form Type - Dropdown IsDemographic - ADM3 | L23: NA | M23: 1-26 = quotareached 27-28 = quotareached | Q23: resp_agree = 1 resp_age = 18-100 hh_admin1 = 1 | S23: 10.4 | T23: =1 | U23: =S23*T23 | X23: yes
A24: =A23+1 | B24: o_hh_admin3_2 | C24: o_hh_admin3 | D24: Currently, in which Township does your household reside? [OPERATOR: SINGLE RESPONSE.] 1)BAGO 2)THANATPIN 3)KAWA 4)WAW 5)NYAUNGLEBIN 6)KYAUKTAGA 7)DAIK-U 8)SHWEGYIN 9)TAUNGOO 10)YEDASHE 11)KYAUKKYI 12)PHYU 13)OKTWIN 14)HTANTABIN 15)PYAY 16)PAUKKHAUNG 17)PADAUNG 18)PAUNGDE 19)THEGON 20)SHWEDAUNG 21)THAYARWADY 22)LETPADAN 23)MINHLA 24)OKPHO 25)ZIGON 26)NATTALIN 27)MONYO 28)GYOBINGAUK 29)DON'T KNOW 30)REFUSED | E24: =LEN(D24) | F24: လက်ရှိအချိန်တွင် လူကြီးမင်း၏အိမ်ထောင်စုသည် မည်သည့်မြို့နယ်၌ နေထိုင်ပါသနည်း။ [အော်ပရေတာ- တုံ့ပြန်မှုတစ်ခုသာ။] 1)ပဲခူး 2)သနပ်ပင် 3)ကဝ 4)ဝေါ 5)ညောင်လေးပင် 6)ကျောက်တံခါး 7)ဒိုက်ဦး 8)ရွှေကျင် 9)တောင်ငူ 10)ရေတာရှည် 11)ကျောက်ကြီး 12)ဖြူး 13)အုတ်တွင်း 14)ထန်းတပင် 15)ပြည် 16)ပေါက်ခေါင်း 17)ပန်းတောင်း 18)ပေါင်းတည် 19)သဲကုန်း 20)ရွှေတောင် 21)သာယာဝတီ 22)လက်ပံတန်း 23)မင်းလှ 24)အုတ်ဖို 25)ဇီးကုန်း 26)နတ်တလင်း 27)မိုးညို 28)ကြို့ပင်ကောက် 29)မသိပါ 30)ဖြေဆိုရန် ငြင်းဆန်သည် | G24: =LEN(F24) | H24: Single Choice | I24: NA | J24: NA | K24: Form Type - Dropdown IsDemographic - ADM3 | L24: NA | M24: 1-28 = quotareached 29-30 = quotareached
A25: =A24+1 | B25: o_hh_admin3_3 | C25: o_hh_admin3 | D25: Currently, in which Township does your household reside? [OPERATOR: SINGLE RESPONSE.] 1)FALAM 2)HAKHA 3)KANPETLET 4)MATUPI 5)MINDAT 6)PALETWA 7)TEDIM 8)THANTLANG 9)TONZANG 10)DON'T KNOW 11)REFUSED | E25: =LEN(D25) | F25: လက်ရှိအချိန်တွင် လူကြီးမင်း၏အိမ်ထောင်စုသည် မည်သည့်မြို့နယ်၌ နေထိုင်ပါသနည်း။ [အော်ပရေတာ- တုံ့ပြန်မှုတစ်ခုသာ။] 1)ဖလမ်း 2)ဟားခါး 3)ကန်ပက်လက် 4)မတူပီ 5)မင်းတပ် 6)ပလက်ဝ 7)တီးတိန် 8)ထန်တလန် 9)တွန်းဇန် 10)မသိပါ 11)ဖြေဆိုရန် ငြင်းဆန်သည် | G25: =LEN(F25) | H25: Single Choice | I25: NA | J25: NA | K25: Form Type - Dropdown IsDemographic - ADM3 | L25: NA | M25: 1-9 = quotareached 10-11 = quotareached
A26: =A25+1 | B26: o_hh_admin3_4 | C26: o_hh_admin3 | D26: Currently, in which Township does your household reside? [OPERATOR: SINGLE RESPONSE.] 1)BHAMO 2)CHIPWI 3)HPAKANT 4)INJANGYANG 5)KHAUNGLANHPU 6)MACHANBAW 7)MANSI 8)MOGAUNG 9)MOHNYIN 10)MOMAUK 11)MYITKYINA 12)NAWNGMUN 13)PUTA-O 14)SUMPRABUM 15)TANAI 16)TSAWLAW 17)WAINGMAW 18)DON'T KNOW 19)REFUSED | E26: =LEN(D26) | F26: လက်ရှိအချိန်တွင် လူကြီးမင်း၏အိမ်ထောင်စုသည် မည်သည့်မြို့နယ်၌ နေထိုင်ပါသနည်း။ [အော်ပရေတာ- တုံ့ပြန်မှုတစ်ခုသာ။] 1)ဗန်းမော် 2)ချီ​ဖွေ 3)ဖားကန့် 4)အင်ဂျန်းယန် 5)ခေါင်လန်ဖူး 6)မချမ်းဘော 7)မံစီ 8)မိုးကောင်း 9)မိုးညှင်း 10)မိုးမောက် 11)မြစ်ကြီးနား 12)နောင်မွန်း 13)ပူတာအို 14)ဆွမ်ပရာဘွမ် 15)တနိုင်း 16)ဆော့လော် 17)ဝိုင်းမော် 18)မသိပါ 19)ဖြေဆိုရန် ငြင်းဆန်သည် | G26: =LEN(F26) | H26: Single Choice | I26: NA | J26: NA | K26: Form Type - Dropdown IsDemographic - ADM3 | L26: NA | M26: 1-17 = quotareached 18-19 = quotareached
A27: =A26+1 | B27: o_hh_admin3_5 | C27: o_hh_admin3 | D27: Currently, in which Township does your household reside? [OPERATOR: SINGLE RESPONSE.] 1)BAWLAKE 2)DEMOSO 3)HPASAWNG 4)HPRUSO 5)LOIKAW 6)MESE 7)SHADAW 8)DON'T KNOW 9)REFUSED | E27: =LEN(D27) | F27: လက်ရှိအချိန်တွင် လူကြီးမင်း၏အိမ်ထောင်စုသည် မည်သည့်မြို့နယ်၌ နေထိုင်ပါသနည်း။ [အော်ပရေတာ- တုံ့ပြန်မှုတစ်ခုသာ။] 1)ဘောလခဲ 2)ဒီးမော့ဆို 3)ဖားဆောင်း 4)ဖရူဆို 5)လွိုင်ကော် 6)မယ်စဲ 7)ရှားတော 8)မသိပါ 9)ဖြေဆိုရန် ငြင်းဆန်သည် | G27: =LEN(F27) | H27: Single Choice | I27: NA | J27: NA | K27: Form Type - Dropdown IsDemographic - ADM3 | L27: NA | M27: 1-7 = quotareached 8-9 = quotareached
A28: =A27+1 | B28: o_hh_admin3_6 | C28: o_hh_admin3 | D28: Currently, in which Township does your household reside? [OPERATOR: SINGLE RESPONSE.] 1)HLAINGBWE 2)HPA-AN 3)HPAPUN 4)KAWKAREIK 5)KYAINSEIKGYI 6)MYAWADDY 7)THANDAUNGGYI 8)DON'T KNOW 9)REFUSED | E28: =LEN(D28) | F28: လက်ရှိအချိန်တွင် လူကြီးမင်း၏အိမ်ထောင်စုသည် မည်သည့်မြို့နယ်၌ နေထိုင်ပါသနည်း။ [အော်ပရေတာ- တုံ့ပြန်မှုတစ်ခုသာ။] 1)လှိုင်းဘွဲ့ 2)ဘားအံ 3)ဖာပွန် 4)ကော့ကရိတ် 5)ကြာအင်းဆိပ်ကြီး 6)မြဝတီ 7)သံတောင်ကြီး 8)မသိပါ 9)ဖြေဆိုရန် ငြင်းဆန်သည် | G28: =LEN(F28) | H28: Single Choice | I28: NA | J28: NA | K28: Form Type - Dropdown IsDemographic - ADM3 | L28: NA | M28: 1-7 = quotareached 8-9 = quotareached
A29: =A28+1 | B29: o_hh_admin3_7 | C29: o_hh_admin3 | D29: Currently, in which Township does your household reside? [OPERATOR: SINGLE RESPONSE.] 1)AUNGLAN 2)CHAUK 3)GANGAW 4)KAMMA 5)MAGWAY 6)MINBU 7)MINDON 8)MINHLA 9)MYAING 10)MYOTHIT 11)NATMAUK 12)NGAPE 13)PAKOKKU 14)PAUK 15)PWINTBYU 16)SALIN 17)SAW 18)SEIKPHYU 19)SIDOKTAYA 20)SINBAUNGWE 21)TAUNGDWINGYI 22)THAYET 23)TILIN 24)YENANGYAUNG 25)YESAGYO 26)DON'T KNOW 27)REFUSED | E29: =LEN(D29) | F29: လက်ရှိအချိန်တွင် လူကြီးမင်း၏အိမ်ထောင်စုသည် မည်သည့်မြို့နယ်၌ နေထိုင်ပါသနည်း။ [အော်ပရေတာ- တုံ့ပြန်မှုတစ်ခုသာ။] 1)အောင်လံ 2)ချောက် 3)ဂန့်ဂေါ 4)ကံမ 5)မကွေး 6) မင်းဘူး 7)မင်းတုန်း 8)မင်းလှ 9)မြိုင် 10) မြို့သစ် 11)နတ်မောက် 12)ငဖဲ 13)ပခုက္ကူ 14)ပေါက် 15)ပွင့်ဖြူ 16)စလင်း 17)ဆော 18)ဆိပ်ဖြူ 19)စေတုတ္ထရာ 20)ဆင်ပေါင်ဝဲ 21)တောင်တွင်းကြီး 22)သရက် 23)ထီးလင်း 24)ရေနံချောင်း 25)ရေစကြို 26)မသိပါ 27)ဖြေဆိုရန် ငြင်းဆန်သည် | G29: =LEN(F29) | H29: Single Choice | I29: NA | J29: NA | K29: Form Type - Dropdown IsDemographic - ADM3 | L29: NA | M29: 1-25 = quotareached 26-27 = quotareached
A30: =A29+1 | B30: o_hh_admin3_8 | C30: o_hh_admin3 | D30: Currently, in which Township does your household reside? [OPERATOR: SINGLE RESPONSE.] 1)KYAUKSE 2)PATHEINGYI 3)CHANAYETHAZAN 4)AUNGMYAYTHAZAN 5)YAMETHIN 6)MADAYA 7)THABEIKKYIN 8)MAHAAUNGMYAY 9)AMARAPURA 10)PYINOOLWIN 11)SINTGAING 12)CHANMYATHAZI 13)THAZI 14)TADA-U 15)MOGOKE 16)PYIGYITAGON 17)PYAWBWE 18)NYAUNG-U 19)MEIKTILA 20)MAHLAING 21)TAUNGTHA 22)MYITTHA 23)MYINGYAN 24)NATOGYI 25)SINGU 26)NGAZUN 27)KYAUKPADAUNG 28)WUNDWIN 29)DON'T KNOW 30)REFUSEDD | E30: =LEN(D30) | F30: လက်ရှိအချိန်တွင် လူကြီးမင်း၏အိမ်ထောင်စုသည် မည်သည့်မြို့နယ်၌ နေထိုင်ပါသနည်း။ [အော်ပရေတာ- တုံ့ပြန်မှုတစ်ခုသာ။] 1)ကျောက်ဆည် 2)ပုသိမ်ကြီး 3)ချမ်းအေးသာစံ 4)အောင်မြေသာစံ 5)ရမည်းသင်း 6)မတ္တရာ 7)သပိတ်ကျင်း 8)မဟာအောင်မြေ 9)အမရပူရ 10)ပြင်ဦးလွင် 11)စဉ့်ကိုင် 12)ချမ်းမြသာစည် 13)သာစည် 14)တံတားဦး 15)မိုးကုတ် 16)ပြည်ကြီးတံခွန် 17)ပျော်ဘွယ် 18)ညောင်ဦး 19)မိတ္ထီလာ 20)မလှိုင် 21)တောင်သာ 22)မြစ်သား 23)မြင်းခြံ 24)နွားထိုးကြီး 25)စဉ့်ကူး 26)ငါန်းဇွန် 27)ကျောက်ပန်းတောင်း 28)ဝမ်းတွင်း 29)မသိပါ 30)ဖြေဆိုရန် ငြင်းဆန်သည် | G30: =LEN(F30) | H30: Single Choice | I30: NA | J30: NA | K30: Form Type - Dropdown IsDemographic - ADM3 | L30: NA | M30: 1-28 = quotareached 29-30 = quotareached
A31: =A30+1 | B31: o_hh_admin3_9 | C31: o_hh_admin3 | D31: Currently, in which Township does your household reside? [OPERATOR: SINGLE RESPONSE.] 1)BILIN 2)CHAUNGZON 3)KYAIKMARAW 4)KYAIKTO 5)MAWLAMYINE 6)MUDON 7)PAUNG 8)THANBYUZAYAT 9)THATON 10)YE 11)DON'T KNOW 12)REFUSED | E31: =LEN(D31) | F31: လက်ရှိအချိန်တွင် လူကြီးမင်း၏အိမ်ထောင်စုသည် မည်သည့်မြို့နယ်၌ နေထိုင်ပါသနည်း။ [အော်ပရေတာ- တုံ့ပြန်မှုတစ်ခုသာ။] 1)ဘီးလင်း 2)ချောင်းဆုံ 3)ကျိုက်မရော 4)ကျိုက်ထို 5)မော်လမြိုင် 6)မုဒုံ 7)ပေါင် 8)သံဖြူဇရပ် 9)သထုံ 10)ရေး 11)မသိပါ 12)ဖြေဆိုရန် ငြင်းဆန်သည် | G31: =LEN(F31) | H31: Single Choice | I31: NA | J31: NA | K31: Form Type - Dropdown IsDemographic - ADM3 | L31: NA | M31: 1-10 = quotareached 11-12 = quotareached
A32: =A31+1 | B32: o_hh_admin3_11 | C32: o_hh_admin3 | D32: Currently, in which Township does your household reside? [OPERATOR: SINGLE RESPONSE.] 1)ANN 2)BUTHIDAUNG 3)GWA 4)KYAUKPYU 5)KYAUKTAW 6)MAUNGDAW 7)MINBYA 8)MRAUK-U 9)MUNAUNG 10)MYEBON 11)PAUKTAW 12)PONNAGYUN 13)RAMREE 14)RATHEDAUNG 15)SITTWE 16)THANDWE 17)TOUNGUP 18)DON'T KNOW 19)REFUSED | E32: =LEN(D32) | F32: လက်ရှိအချိန်တွင် လူကြီးမင်း၏အိမ်ထောင်စုသည် မည်သည့်မြို့နယ်၌ နေထိုင်ပါသနည်း။ [အော်ပရေတာ- တုံ့ပြန်မှုတစ်ခုသာ။] 1)အမ်း 2)ဘူးသီးတောင် 3)ဂွ 4)ကျောက်ဖြူ 5)ကျောက်တော် 6)မောင်တော 7)မင်းပြား 8)မြောက်ဦး 9)မာန်အောင် 10)မြေပုံ 11)ပေါက်တော 12)ပုဏ္ဏားကျွန်း 13)ရမ်းဗြဲ 14)ရသေ့တောင် 15)စစ်တွေ 16)သံတွဲ 17)တောင်ကုတ် 18)မသိပါ 19)ဖြေဆိုရန် ငြင်းဆန်သည် | G32: =LEN(F32) | H32: Single Choice | I32: NA | J32: NA | K32: Form Type - Dropdown IsDemographic - ADM3 | L32: NA | M32: 1-17 = quotareached 18-19 = quotareached
A33: =A32+1 | B33: o_hh_admin3_12 | C33: o_hh_admin3 | D33: Currently, in which Township does your household reside? [OPERATOR: SINGLE RESPONSE.] 1)SAGAING 2)MYINMU 3)MYAUNG 4)SHWEBO 5)KHIN-U 6)WETLET 7)KANBALU 8)KYUNHLA 9)YE-U 10)TABAYIN 11)TAZE 12)MONYWA 13)BUDALIN 14)AYADAW 15)CHAUNG-U 16)YINMARBIN 17)KANI 18)SALINGYI 19)PALE 20)KATHA 21)INDAW 22)TIGYAING 23)BANMAUK 24)KAWLIN 25)WUNTHO 26)PINLEBU 27)KALE 28)KALEWA 29)MINGIN 30)TAMU 31)MAWLAIK 32)PAUNGBYIN 33)HKAMTI 34)HOMALIN 35)LAY SHI 36)LAHE 37)NANYUN 38)DON'T KNOW 39)REFUSED | E33: =LEN(D33) | F33: လက်ရှိအချိန်တွင် လူကြီးမင်း၏အိမ်ထောင်စုသည် မည်သည့်မြို့နယ်၌ နေထိုင်ပါသနည်း။ [အော်ပရေတာ- တုံ့ပြန်မှုတစ်ခုသာ။] 1)စစ်ကိုင်း 2)မြင်းမူ 3)မြောင် 4)ရွှေဘို 5)ခင်ဦး 6)ဝက်လက် 7)ကန့်ဘလူ 8)ကျွန်းလှ 9)ရေဦး 10)ဒီပဲယင်း 11)တန့်ဆည် 12)မုံရွာ 13)ဘုတလင် 14)အရာတော် 15)ချောင်းဦး 16)ယင်းမာပင် 17)ကနီ 18)ဆားလင်းကြီး 19)ပုလဲ 20)ကသာ 21)အင်းတော် 22)ထီးချိုင့် 23)ဗန်းမောက် 24)ကောလင်း 25)ဝန်းသို 26)ပင်လည်ဘူး 27)ကလေး 28)ကလေးဝ 29)မင်းကင်း 30)တမူး 31)မော်လိုက် 32)ဖောင်းပြင် 33)ခန္တီး 34)ဟုမ္မလင်း 35)လေရှီး 36)လဟယ် 37)နန်းယွန်း 38)မသိပါ 39)ဖြေဆိုရန် ငြင်းဆန်သည် | G33: =LEN(F33) | H33: Single Choice | I33: NA | J33: NA | K33: Form Type - Dropdown IsDemographic - ADM3 | L33: NA | M33: 1-37 = quotareached 38-39 = quotareached
A34: =A33+1 | B34: o_hh_admin3_13 | C34: o_hh_admin3 | D34: Currently, in which Township does your household reside? [OPERATOR: SINGLE RESPONSE.] 1)TAUNGGYI 2)NYAUNGSHWE 3)HOPONG 4)HSIHSENG 5)KALAW 6)PINDAYA 7)YWANGAN 8)LAWKSAWK 9)PINLAUNG 10)PEKON 11)LOILEN 12)LAIHKA 13)NANSANG 14)KUNHING 15)KYETHI 16)MONGKAING 17)MONGHSU 18)LANGKHO 19)MONGNAI 20)MAWKMAI 21)MONGPAN 22)LASHIO 23)HSENI 24)MONGYAI 25)TANGYAN 26)PANGSANG 27)NARPHAN 28)PANGWAUN 29)MONGMAO 30)MUSE 31)NAMHKAN 32)KUTKAI 33)KYAUKME 34)NAWNGHKIO 35)HSIPAW 36)NAMTU 37)NAMHSAN 38)MONGMIT 39)MABEIN 40)MANTON 41)KUNLONG 42)HOPANG 43)LAUKKAING 44)KONKYAN 45)MATMAN 46)KENGTUNG 47)MONGKHET 48)MONGYANG 49)MONGLA 50)MONGHSAT 51)MONGPING 52)MONGTON 53)TACHILEIK 54)MONGHPYAK 55)MONGYAWNG 56)DON'T KNOW 57)REFUSED | E34: =LEN(D34) | F34: လက်ရှိအချိန်တွင် လူကြီးမင်း၏အိမ်ထောင်စုသည် မည်သည့်မြို့နယ်၌ နေထိုင်ပါသနည်း။ [အော်ပရေတာ- တုံ့ပြန်မှုတစ်ခုသာ။] 1)တောင်ကြီး 2)ညောင်ရွှေ 3)ဟိုပုံး 4)ဆီဆိုင် 5)ကလော 6)ပင်းတယ 7)ရွာငံ 8)ရပ်စောက် 9)ပင်လောင်း 10)ဖယ်ခုံ 11)လွိုင်လင် 12)လဲချား 13)နမ့်စန် 14)ကွန်ဟိန်း 15)ကျေးသီး 16)မိုင်းကိုင် 17)မိုင်းရှူး 18)လင်းခေး 19)မိုးနဲ 20)မောက်မယ် 21)မိုင်းပန် 22)လားရှိုး 23)သိန္နီ 24)မိုင်းရယ် 25)တန့်ယန်း 26)ပန်ဆန်း (ပန်ခမ်း) 27)နားဖန်း 28)ပန်ဝိုင် 29)မိုင်းမော 30)မူဆယ် 31)နမ့်ခမ်း 32)ကွတ်ခိုင် 33)ကျောက်မဲ 34)နောင်ချို 35)သီပေါ 36)နမ္မတူ 37)နမ့်ဆန် 38)မိုးမိတ် 39)မဘိမ်း 40)မန်တုံ 41)ကွမ်းလုံ 42)ဟိုပန် 43)လောက်ကိုင် 44)ကုန်းကြမ်း 45)မက်မန်း 46)ကျိုင်းတုံ 47)မိုင်းခတ် 48)မိုင်းယန်း 49)မိုင်းလား 50)မိုင်းဆတ် 51)မိုင်းပျဉ်း 52)မိုင်းတုံ 53)တာချီလိတ် 54)မိုင်းဖြတ် 55)မိုင်းယောင်း 56)မသိပါ 57)ဖြေဆိုရန် ငြင်းဆန်သည် | G34: =LEN(F34) | H34: Single Choice | I34: NA | J34: NA | K34: Form Type - Dropdown IsDemographic - ADM3 | L34: NA | M34: 1-55 = quotareached 56-57 = quotareached
A35: =A34+1 | B35: o_hh_admin3_14 | C35: o_hh_admin3 | D35: Currently, in which Township does your household reside? [OPERATOR: SINGLE RESPONSE.] 1)DAWEI 2)LAUNGLON 3)THAYETCHAUNG 4)YEBYU 5)MYEIK 6)KYUNSU 7)PALAW 8)TANINTHARYI 9)KAWTHOUNG 10)BOKPYIN 11)DON'T KNOW 12)REFUSED | E35: =LEN(D35) | F35: လက်ရှိအချိန်တွင် လူကြီးမင်း၏အိမ်ထောင်စုသည် မည်သည့်မြို့နယ်၌ နေထိုင်ပါသနည်း။ [အော်ပရေတာ- တုံ့ပြန်မှုတစ်ခုသာ။] 1)ထားဝယ် 2)လောင်းလုံး 3)သရက်ချောင်း 4)ရေဖြူ 5)မြိတ် 6)ကျွန်းစု 7)ပုလော 8)တနင်္သာရီ 9)ကော့သောင်း 10)ဘုတ်ပြင်း 11)မသိပါ 12)ဖြေဆိုရန် ငြင်းဆန်သည် | G35: =LEN(F35) | H35: Single Choice | I35: NA | J35: NA | K35: Form Type - Dropdown IsDemographic - ADM3 | L35: NA | M35: 1-10 = quotareached 11-12 = quotareached
A36: =A35+1 | B36: o_hh_admin3_15 | C36: o_hh_admin3 | D36: Currently, in which Township does your household reside? [OPERATOR: SINGLE RESPONSE.] 1)AHLONE 2)BAHAN 3)BOTAHTAUNG 4)COCOKYUN 5)DAGON 6)DAGON MYOTHIT [EAST] 7)DAGON MYOTHIT [NORTH] 8)DAGON MYOTHIT [SEIKKAN] 9)DAGON MYOTHIT [SOUTH] 10)DALA 11)DAWBON 12)HLAING 13)HLAINGTHARYA [EAST] 14)HLAINGTHARYA [WEST] 15)HLEGU 16)HMAWBI 17)HTANTABIN 18)INSEIN 19)KAMARYUT 20)KAWHMU 21)KAYAN 22)KUNGYANGON 23)KYAUKTADA 24)KYAUKTAN 25)KYEEMYINDAING 26)LANMADAW 27)LATHA 28)MAYANGONE 29)MINGALADON 30)MINGALARTAUNGNYUNT 31)NORTH OKKALAPA 32)PABEDAN 33)PAZUNDAUNG 34)SANCHAUNG 35)SEIKGYIKANAUNGTO 36)SHWEPYITHAR 37)SOUTH OKKALAPA 38)TAIKKYI 39)TAMWE 40)THAKETA 41)THANLYIN 42)THINGANGYUN 43)THONGWA 44)TWANTAY 45)YANKIN 46)DON'T KNOW 47)REFUSED | E36: =LEN(D36) | F36: လက်ရှိအချိန်တွင် လူကြီးမင်း၏အိမ်ထောင်စုသည် မည်သည့်မြို့နယ်၌ နေထိုင်ပါသနည်း။ [အော်ပရေတာ- တုံ့ပြန်မှုတစ်ခုသာ။] 1)အလုံ 2)ဗဟန်း 3)ဗိုလ်တထောင် 4)ကိုကိုးကျွန်း 5)ဒဂုံ 6)ဒဂုံမြို့သစ် [အရှေ့ပိုင်း] 7)ဒဂုံမြို့သစ် [မြောက်ပိုင်း] 8)ဒဂုံမြို့သစ် [ဆိပ်ကမ်း] 9)ဒဂုံမြို့သစ် [တောင်ပိုင်း] 10)ဒလ 11)ဒေါပုံ 12)လှိုင် 13)လှိုင်သာယာ [အရှေ့ပိုင်း] 14)လှိုင်သာယာ [အနောက်ပိုင်း] 15)လှည်းကူး 16)မှော်ဘီ 17)ထန်းတပင် 18)အင်းစိန် 19)ကမာရွတ် 20)ကော့မှုး 21)ခရမ်း 22)ကွမ်းခြံကုန်း 23)ကျောက်တံတား 24)ကျောက်တန်း 25)ကြည့်မြင်တိုင် 26)လမ်းမတော် 27)လသာ 28)မရမ်းကုန်း 29)မင်္ဂလာဒုံ 30)မင်္ဂလာတောင်ညွန့် 31)မြောက်ဥက္ကလာပ 32)ပန်းဘဲတန်း 33)ပုဇွန်တောင် 34)စမ်းချောင်း 35)ဆိပ်ကြီး/ခနောင်တို 36)ရွှေပြည်သာ 37)တောင်ဥက္ကလာပ 38)တိုက်ကြီး 39)တာမွေ 40)သာကေတ 41)သန်လျင် 42)သင်္ဃန်းကျွန်း 43)သုံးခွ 44)တွံတေး 45)ရန်ကင်း 46)မသိပါ 47)ဖြေဆိုရန် ငြင်းဆန်သည် | G36: =LEN(F36) | H36: Single Choice | I36: NA | J36: NA | K36: Form Type - Dropdown IsDemographic - ADM3 | L36: NA | M36: 1-4 = quotareached 5 = Ineligible 6-7 = quotareached 8 = Ineligible 9-22 = quotareached 23 = Ineligible 24-26 = quotareached 27 = Ineligible 28-45 = quotareached 46-47 = Ineligible
A37: =A36+1 | B37: quotareached | C37: quotareached | D37: [OPERATOR: DO NOT READ. ANSWER QUESTION BELOW.] THIS RESPONDENT REPORTED THEY LIVE IN: {ADM1} {ADM3} 1)THE GOAL FOR THIS LOCATION HAS BEEN ACHIEVED - END SURVEY 2)THE GOAL FOR THIS LOCATION IS OPEN - CONTINUE SURVEY | E37: =LEN(D37) | F37: [အော်ပရေတာ- မဖတ်ပါနှင့်။ အောက်ပါမေးခွန်းကို ဖြေဆိုပါ။] ဖြေဆိုသူသည် ၎င်းတို့နေထိုင်ရာအရပ်ကို ဤသို့ဖော်ပြခဲ့သည် {ADM1} {ADM3} 1)ဤနေရာအတွက် ရည်မှန်းချက် အောင်မြင်ခဲ့ပြီဖြစ်ပါသည်- စစ်တမ်းအား အဆုံးသတ်ရန် 2)ဤနေရာအတွက် ရည်မှန်းချက်ကို ကြိုးပမ်းနိုင်ဆဲဖြစ်ပါသည်- စစ်တမ်းအား ရှေ့ဆက်ရန် | G37: =LEN(F37) | H37: Single Choice | I37: NA | J37: NA | K37: Form Type - Buttons | L37: NA | M37: 1 = End Poll Quota Reached 2 = hh_agricactivity | O37: If the quota has not been reached, continue the questionnaire. If it has, end of survey. | Q37: resp_agree = 1 resp_age = 18-100 | S37: 2.28425 | T37: =1 | U37: =S37*T37 | X37: no
A38: =A37+1 | B38: hh_agricactivity | C38: hh_agricactivity | D38: Has anybody in your household produced crops or livestock for household consumption or for sale in the past 12 months, including household members currently away for transhumance? [OPERATOR: SINGLE RESPONSE. THIS IS THE MAIN SCREENING QUESTION.] [HINT FOR PROBING: Do you cultivate any plants to sell or consume? Do you raise any animals with the intent of selling or consuming them or their products like meat, milk, wool or leather? Is one of your household member currently away with cattle or other animals for transhumance?] [FISHING/AQUACULTURE IS NOT LIVESTOCK PRODUCTION. FLOWER PLANTING IS NOT CROP PRODUCTION] 1)Yes - crop production 2)Yes - livestock production 3)Yes - both crop and livestock production 4)No 5)DON'T KNOW 6)REFUSED | E38: =LEN(D38) | F38: ရွှေ့ပြောင်းမွေးမြူရေးအတွက် လက်ရှိ အဝေးတွင်ရောက်ရှိနေသော အိမ်ထောင်စုပါ မိသားစုဝင်အပါအဝင် လူကြီးမင်း၏အိမ်ထောင်စုထဲမှ တစ်ဦးတစ်ယောက်သည် လွန်ခဲ့သော 12 လအတွင်း အိမ်ထောင်စု စားသောက်ရန် သို့မဟုတ် ရောင်းချရန်အတွက် ကောက်ပဲသီးနှံများ စိုက်ပျိုးရေး သို့မဟုတ် မွေးမြူရေး လုပ်ကိုင်ခဲ့ပါသလား။ [အော်ပရေတာ- တုံ့ပြန်မှုတစ်ခုသာ။ ဤသည်မှာ အဓိကအကဲဖြတ်မေးခွန်းဖြစ်သည်။ ဖြေဆိုသူသည် မဖြေမနေရ ဖြေဆိုရမည်ဖြစ်သည်။ ရွှေ့ပြောင်းမွေးမြူးရေးအကြောင်း မေးမြန်းရန် မမေ့ပါနှင့်။] [အရိပ်အမြွက် - အိမ်ထောင်စုတွင် အတူတကွနေထိုင်ကာ ရင်းမြစ်များကို မျှဝေသုံးစွဲပြီး တစ်အိုးတည်းစားသောက်သော မိသားစုဝင်များအားလုံး ပါဝင်သည်။] [ငါးဖမ်းခြင်း/ငါးမွေးမြူရေးလုပ်ငန်းသည် တိရစ္ဆာန်မွေးမြူရေးမဟုတ်ပါ။ ပန်းစိုက်ပျိုးခြင်းသည် သီးနှံထုတ်လုပ်ခြင်းမဟုတ်ပါ] 1)လုပ်ကိုင်ပါသည် - ကောက်ပဲသီးနှံ စိုက်ပျိုးထုတ်လုပ်ရေး 2)လုပ်ကိုင်ပါသည် - မွေးမြူရေး 3)လုပ်ကိုင်ပါသည်- ကောက်ပဲသီးနှံစိုက်ပျိုးရေးနှင့် မွေးမြူရေးလုပ်ငန်းနှစ်ခုလုံး 4)မလုပ်ကိုင်ပါ 5)မသိပါ 6)ဖြေဆိုရန် ငြင်းဆန်သည် | G38: =LEN(F38) | H38: Single Choice | I38: NA | J38: NA | K38: Form Type - Buttons IsDemographic | L38: NA | M38: 1 = hh_agricactivity_Check1 2 = hh_agricactivity_Check2 3 = hh_agricactivity_Check3 4 = hh_agricactivity_Check4 5-6 = Ineligible | O38: if hh_agricactivity = 1-4, go to hh_gender. Otherwise, the respondent is ineligible. | Q38: resp_agree = 1 resp_age = 18-100 quotareached = 2 | S38: 31.372377 | T38: =1 | U38: =S38*T38 | X38: yes
A39: 23 | B39: hh_agricactivity_Check1 | C39: hh_agricactivity_Check1 | D39: You reported that you or someone in your household participated in crop production activities , but no one cared for animals/livestock for household income/consumption at any time during the past 12 months (1 year). Is this correct? [OPERATOR: IF YES, SELECT "NEXT". IF NO, GO BACK TO THE PREVIOUS QUESTION AND CORRECT THE ANSWER.] [FISHING/AQUACULTURE IS NOT LIVESTOCK PRODUCTION. FLOWER PLANTING IS NOT CROP PRODUCTION] 1)NEXT | E39: =LEN(D39) | F39: သင် သို့မဟုတ် သင့်အိမ်ထောင်စုရှိ တစ်စုံတစ်ဦးသည် လွန်ခဲ့သည့် 12 လ (1 နှစ်) အတွင်း ကောက်ပဲသီးနှံစိုက်ပျိုးရေး လုပ်ကိုင်ခဲ့သော်လည်း သင်၏ အိမ်ထောင်စု၏ ဝင်ငွေ/စားသုံးမှုအတွက် တိရစ္ဆာန်မွေးမြူရေးကို မပြုလုပ်ခဲ့ပါဟု ဖြေဆိုခဲ့သည်။ ထိုအချက်သည် မှန်ကန်ပါသလား။ [အော်ပရေတာ- ဟုတ်ပါက၊ "နောက်တစ်ခု" ကို ရွေးပါ။ မဟုတ်ပါက၊ ယခင်မေးခွန်းသို့ ပြန်သွားပြီး အဖြေကို ပြင်ပါ။] [ငါးဖမ်းခြင်း/ငါးမွေးမြူရေးလုပ်ငန်းသည် တိရစ္ဆာန်မွေးမြူရေးမဟုတ်ပါ။ ပန်းစိုက်ပျိုးခြင်းသည် သီးနှံထုတ်လုပ်ခြင်းမဟုတ်ပါ] 1) နောက်တစ်ခု | G39: =LEN(F39) | H39: Single Choice | I39: NA | J39: NA | K39: Form Type - Buttons | L39: NA | M39: 1 = o_cyclaffected | N39: 6/30/2023: Introduced internal validation /probe prompt to confirm the most accurate response possible has been coded at QName hh_agricactivity. These variables will not appear in the dataset.
A40: 24 | B40: hh_agricactivity_Check2 | C40: hh_agricactivity_Check2 | D40: You reported that you or someone in your household participated in livestock activities, but no one cultivated plants for household income/consumption at any time during the past 12 months (1 year). Is this correct? [OPERATOR: IF YES, SELECT "NEXT". IF NO, GO BACK TO THE PREVIOUS QUESTION AND CORRECT THE ANSWER.] [FISHING/AQUACULTURE IS NOT LIVESTOCK PRODUCTION. FLOWER PLANTING IS NOT CROP PRODUCTION] 1)NEXT | E40: =LEN(D40) | F40: သင် သို့မဟုတ် သင့်အိမ်ထောင်စုရှိ တစ်စုံတစ်ဦးသည် လွန်ခဲ့သည့် 12 လ (1 နှစ်) အတွင်း တိရစ္ဆာန်မွေးမြူရေး လုပ်ကိုင်ခဲ့သော်လည်း သင်၏ အိမ်ထောင်စု၏ ဝင်ငွေ/စားသုံးမှုအတွက် ကောက်ပဲသီးနှံစိုက်ပျိုးရေးကို မပြုလုပ်ခဲ့ပါဟု ဖြေဆိုခဲ့သည်။ ထိုအချက်သည် မှန်ကန်ပါသလား။ [အော်ပရေတာ- ဟုတ်ပါက၊ "နောက်တစ်ခု" ကို ရွေးပါ။ မဟုတ်ပါက၊ ယခင်မေးခွန်းသို့ ပြန်သွားပြီး အဖြေကို ပြင်ပါ။] [ငါးဖမ်းခြင်း/ငါးမွေးမြူရေးလုပ်ငန်းသည် တိရစ္ဆာန်မွေးမြူရေးမဟုတ်ပါ။ ပန်းစိုက်ပျိုးခြင်းသည် သီးနှံထုတ်လုပ်ခြင်းမဟုတ်ပါ] 1) နောက်တစ်ခု | G40: =LEN(F40) | H40: Single Choice | I40: NA | J40: NA | K40: Form Type - Buttons | L40: NA | M40: 1 = o_cyclaffected
...

Sheet New Durations
A1: question | B1: duration | C1: responded % | D1: weighted time
A2: introduction | B2: 50.82254 | C2: 1 | D2: 50.82254
A3: agree | B3: 3.4964738 | C3: 0.79698741 | D3: 2.7866456
A4: resp_age | B4: 13.753073 | C4: 1 | D4: 13.753073
A5: resp_gender | B5: 2.1173561 | C5: 1 | D5: 2.1173561
A6: quotareached | B6: 2.28425 | C6: 0.79698741 | D6: 1.8205185
A7: hh_agricactivity | B7: 31.372377 | C7: 1 | D7: 31.372377
A8: hh_milieu | B8: 7.9225454 | C8: 0.15190348 | D8: 1.2034622
A9: hh_gender | B9: 10.085732 | C9: 1 | D9: 10.085732
A10: hh_education | B10: 12.894034 | C10: 1 | D10: 12.894034
A11: hh_wealth_water | B11: 15.265829 | C11: 0.63796463 | D11: 9.739059
A12: hh_wealth_toilet | B12: 15.123718 | C12: 0.59180156 | D12: 8.95024
A13: hh_wealthwall | B13: 12.821411 | C13: 0.15190348 | D13: 1.9476169
... A164: adm1_name | B164: 10.743817 | C164: 0.20301259 | D164: 2.1811302
A165: adm2_name | C165: 0 | D165: 0
A166: covid | B166: 56.471024 | C166: 0.20301259 | D166: 11.464329
A167: crp_landright | B167: 31 | C167: 0.0040467626 | D167: 0.12544964
A168: crp_seed | B168: 30.833334 | C168: 0.0040467626 | D168: 0.12477518
A169: crp_proddif | B169: 16.882986 | C169: 0.11848022 | D169: 2.0002998
A170: crp_salesdif | B170: 16.82699 | C170: 0.086630695 | D170: 1.4577339
A171: crp_saledif_2 | B171: 39.486874 | C171: 0.03139988 | D171: 1.2398831
A172: ls_proddif | B172: 15.938099 | C172: 0.10169365 | D172: 1.6208034
A173: ls_salesdif | B173: 13.330855 | C173: 0.060476619 | D173: 0.80620506
A174: ls_proc | B174: 16.437651 | C174: 0.0625 | D174: 1.0273532
A175: ls_proc_fac_state | B175: 8.666667 | C175: 0.00067446043 | D175: 0.005845324
A176: fish_proddif | B176: 12.523809 | C176: 0.001573741 | D176: 0.019709232
A177: cs_spentsavings | B177: 22.220184 | C177: 0.0081684652 | D177: 0.1815048
... A193: ls_proddif_2_covid19 | B193: 3.3438249 | C193: 1 | D193: 3.3438249

Sheet Crop list
H2: Dernier numéro
C3: Select top 10 crops | D3: GeoPoll code | E3: Dataset code | F3: Label (EN) | H3: =MAX(D:D)
C4: x | D4: 1 | E4: 1.1 | F4: Rice
D5: 2 | E5: 1.2 | F5: Wheat
D6: 3 | E6: 1.3 | F6: Millet
D7: 4 | E7: 1.4 | F7: Sorghum
C8: x | D8: 5 | E8: 1.5 | F8: Maize
D9: 6 | E9: 1.6 | F9: Barley
D10: 7 | E10: 1.99 | F10: Other Cereal
D11: 8 | E11: 2.1 | F11: Cassava
C12: x | D12: 9 | E12: 2.2 | F12: Potatoe
D13: 10 | E13: 2.3 | F13: Sweet Potatoes
D14: 11 | E14: 2.4 | F14: Yams
D15: 12 | E15: 2.5 | F15: Carrots
D16: 13 | E16: 2.6 | F16: Cocoyam
D17: 14 | E17: 2.99 | F17: Other tubers
D18: 15 | E18: 3.1 | F18: Beans
D19: 16 | E19: 3.2 | F19: Lentils
D20: 17 | E20: 3.3 | F20: Peas
D21: 18 | E21: 3.4 | F21: Soybeans
D22: 76 | E22: 3.5 | F22: Chickpeas
D23: 77 | E23: 3.6 | F23: Fava beans
D24: 78 | E24: 3.7 | F24: Broad beans
D25: 19 | E25: 3.99 | F25: Other pulses
C26: x | D26: 20 | E26: 4.1 | F26: Cabbage
D27: 21 | E27: 4.2 | F27: Lettuce
D28: 22 | E28: 4.3 | F28: Spinach-Amaranth
D29: 23 | E29: 4.4 | F29: Cassava leaves
D30: 24 | E30: 4.5 | F30: Potatoe leaves
D31: 25 | E31: 4.6 | F31: Moringa
D32: 26 | E32: 4.7 | F32: Sorrel Hibiscus / Rosselle
D33: 79 | E33: 4.9 | F33: Green salad herbs (thyme, parsley, mint, rocca, other)
D34: 80 | E34: 4.101 | F34: Cauliflower
D35: 28 | E35: 4.99 | F35: Other leafy vegetables
C36: x | D36: 29 | E36: 5.1 | F36: Tomatoes
D37: 30 | E37: 5.2 | F37: Cucumber
D38: 31 | E38: 5.3 | F38: Pumpkin
D39: 32 | E39: 5.4 | F39: Eggplant/aubergine
D40: 33 | E40: 5.5 | F40: Zucchini
D41: 34 | E41: 5.6 | F41: Okra
...

Sheet Additional information
C2: Original | D2: Replacement | E2: Comment | F2: Examples
B3: FOR CORE QUESTIONS . (Mandatory to fill out) . | C3: ADMIN1 | D3: State/Region | E3: The first subdivision of the country, after national level; region; province; governorate; etc. | F3: region
C4: ADMIN2 | D4: Township | E4: The second subdivision of the country; district; municipality; LGA; etc. | F4: district
C5: reference year | D5: a normal year | E5: Comparison questions will need need a reference year. Select whether you want to use "last year" or "a normal year" as a baseline. A "normal year" should refers to an average year from the past 5 years - make sure to train the enumerators accordingly. | F5: a normal year
C6: season | D6: Last season | E6: Name the crop season(s) of interest if there are several cropping seasons in the country (e.g. Meher and Belg in Ethiopia, rainy season / flood-recession cropping / irrigated dry season in the Sahel). You can refer to the “last season” or “ongoing season". | F6: wet season
C7: season phase | D7: Harvesting | E7: Indicate the phase of the season at the time of data collection. If the harvest from the season has not yet occurred, the question on crop harvest (crp_harv_change) will include the word “expected” (where #expected or nothing# is located). If the harvest has occured, "expected" will not be inserted in the question. | F7: Harvesting
C8: local measurement unit | E8: Specify the local measurement unit for land size, other than acres, hectares, square meters and square feet. If no other unit of measurement is needed, keep this cell blank. | F8: Jeribs
C9: local measurement unit conversion | E9: Include the conversion of the local measurement unit to hectares. In other words, how many local measurement units are in 1 ha. | F9: 0.2
B10: FOR OPTIONAL QUESTIONS . (Fill out if applicable) . | C10: currency | D10: MMK | E10: The name of the main currency used nationally; USD; Naira; Rial; Pesos; etc. | F10: Naira
C11: MIN AMOUNT | D11: 250000 | E11: The minimum amount for an income source should be set at 0 or any value below which it is not possible to do a transaction. For example, the smallest coin/banknote in a currency can be 1000, in which case you would set the minimum at 1000. Provide this input in the same currency as specified above. Only digits should be inputted. | F11: 5
C12: MAX AMOUNT | D12: 800000 | E12: Set the maximum amount for an income source over 3 months. Enumerators will not be able to input values above this amount in questions related to income amounts. Using previous representative surveys for this population, you can estimate this amount by using the mean income plus five (5) standard deviations, unless the country has high inflation. In the latter case, set the maximum value based on your country context (higher than the proposed approach). Provide this input in the same currency as specified above. Only digits should be inputted. | F12: 5000000
C13: THRESHOLD | D13: 450000 | E13: The threshold salary should be calculated to flag outliers (responses that look suspiciously high). Using previous representative surveys for this population, a good estimate is the average plus three (3) standard deviations, which should give the threshold for the 3 or 4% highest income values. Provide this input in the same currency as specified above. Only digits should be inputted. | F13: 1200000
C14: local vegetables | E14: Input some common local vegetables [to be used as examples in the food consumption score indicator]. | F14: eggplants, zucchini, cauliflower
C15: local fruits | E15: Input some common local fruits [to be used as examples in the food consumption score indicator]. | F15: apples, bananas, oranges
B17: FILL OUT FOR QUESTIONNAIRE DURATION ESTIMATION . | C17: Expected percentage of respondents cultivating crops | D17: 0.75 | E17: If the survey is representative and has no quotas, write the proportion of rural households cultivating crops at country level, or if the survey follows a previous round with identical sample design, just report the percentage from the previous round. If you are using quotas, calculate the ratio of the quota over the minimum sample size at the level where the quota is implemented (so if you have a minimum sample size per strata of 110 with a quota of 100 crop producers, then it's 100/110 = 91% (the maximum you should write is 100%). | F17: 0.91
C18: Expected percentage of respondents raising livestock | D18: 0.2 | E18: If the survey is representative and has no quotas, write the proportion of rural households raising livestock at country level, or if the survey follows a previous round with identical sample design, just report the percentage from the previous round. If you are using quotas, calculate the ratio of the quota over the minimum sample size at the level where the quota is implemented (so if you have a minimum sample size of 110 but a quota of 100 livestock producers, then it's 100/110 = 91% (the maximum you should write is 100%) | F18: 0.91
C19: Expected percentage of respondents involved in fishery | D19: 0.05 | E19: If the survey is representative and has no quotas, write the proportion of rural households involved in fisheries or aquaculture, otherwise if you are using quotas, calculate the ratio of the quota over the sample size at the level where the quota is implemented. (so if you haven't set a quota, and you expect to have a representative proportion of fishermen, just write the percentage of fishermen in the population you are targeting, in the example to the right, 5%) | F19: 0.05

Sheet Admin 3 info
A1: adm3_name | B1: adm3_name_local | C1: adm3_pcode | D1: adm2_name | E1: adm2_pcode | F1: adm1_name | G1: adm1_pcode | H1: adm0_name | I1: adm0_ISO3 | J1: adm0_M49
A2: Ramree | B2: ရမ်းဗြဲ | C2: MMR012013 | D2: Kyaukpyu | E2: MMR012D003 | F2: Rakhine | G2: MMR012 | H2: Myanmar | I2: MMR | J2: 104
A3: Toungup | B3: တောင်ကုတ် | C3: MMR012016 | D3: Thandwe | E3: MMR012D004 | F3: Rakhine | G3: MMR012 | H3: Myanmar | I3: MMR | J3: 104
A4: Kyaukpyu | B4: ကျောက်ဖြူ | C4: MMR012011 | D4: Kyaukpyu | E4: MMR012D003 | F4: Rakhine | G4: MMR012 | H4: Myanmar | I4: MMR | J4: 104
A5: Labutta | B5: လပွတ္တာ | C5: MMR017016 | D5: Labutta | E5: MMR017D004 | F5: Ayeyarwady | G5: MMR017 | H5: Myanmar | I5: MMR | J5: 104
A6: Ngapudaw | B6: ငပုတော | C6: MMR017004 | D6: Pathein | E6: MMR017D001 | F6: Ayeyarwady | G6: MMR017 | H6: Myanmar | I6: MMR | J6: 104
A7: Bogale | B7: ဘိုကလေး | C7: MMR017024 | D7: Pyapon | E7: MMR017D006 | F7: Ayeyarwady | G7: MMR017 | H7: Myanmar | I7: MMR | J7: 104
A8: Thandwe | B8: သံတွဲ | C8: MMR012015 | D8: Thandwe | E8: MMR012D004 | F8: Rakhine | G8: MMR012 | H8: Myanmar | I8: MMR | J8: 104
A9: Bokpyin | B9: ဘုတ်ပြင်း | C9: MMR006010 | D9: Kawthoung | E9: MMR006D003 | F9: Tanintharyi | G9: MMR006 | H9: Myanmar | I9: MMR | J9: 104
A10: Ye | B10: ရေး | C10: MMR011006 | D10: Mawlamyine | E10: MMR011D001 | F10: Mon | G10: MMR011 | H10: Myanmar | I10: MMR | J10: 104
A11: Kungyangon | B11: ကွမ်းခြံကုန်း | C11: MMR013029 | D11: Yangon (South) | E11: MMR013D003 | F11: Yangon | G11: MMR013 | H11: Myanmar | I11: MMR | J11: 104
A12: Dedaye | B12: ဒေးဒရဲ | C12: MMR017026 | D12: Pyapon | E12: MMR017D006 | F12: Ayeyarwady | G12: MMR017 | H12: Myanmar | I12: MMR | J12: 104
A13: Pyapon | B13: ဖျာပုံ | C13: MMR017023 | D13: Pyapon | E13: MMR017D006 | F13: Ayeyarwady | G13: MMR017 | H13: Myanmar | I13: MMR | J13: 104
... A331: Muse | B331: မူဆယ် | C331: MMR015009 | D331: Muse | E331: MMR015D002 | F331: Shan | G331: MMR222 | H331: Myanmar | I331: MMR | J331: 104

Sheet Admin 2 info1
A1: adm2_name | B1: adm2_name_local | C1: adm2_pcode | D1: adm1_name | E1: adm1_pcode | F1: adm0_name | G1: adm0_ISO3
A2: Lashio | C2: MMR015D001 | D2: Shan | E2: MMR222 | F2: Myanmar | G2: MMR
A3: Kyaukme | C3: MMR015D003 | D3: Shan | E3: MMR222 | F3: Myanmar | G3: MMR
A4: Kokang Self-Administered Zone | C4: MMR015S002 | D4: Shan | E4: MMR222 | F4: Myanmar | G4: MMR
A5: Pa-O Self-Administered Zone | C5: MMR014S002 | D5: Shan | E5: MMR222 | F5: Myanmar | G5: MMR
A6: Loilen | C6: MMR014D002 | D6: Shan | E6: MMR222 | F6: Myanmar | G6: MMR
A7: Langkho | C7: MMR014D003 | D7: Shan | E7: MMR222 | F7: Myanmar | G7: MMR
A8: Danu Self-Administered Zone | C8: MMR014S001 | D8: Shan | E8: MMR222 | F8: Myanmar | G8: MMR
A9: Pa Laung Self-Administered Zone | C9: MMR015S001 | D9: Shan | E9: MMR222 | F9: Myanmar | G9: MMR
A10: Muse | C10: MMR015D002 | D10: Shan | E10: MMR222 | F10: Myanmar | G10: MMR
A11: Mongmit | C11: MMR015D008 | D11: Shan | E11: MMR222 | F11: Myanmar | G11: MMR
A12: Matman | C12: MMR015D007 | D12: Shan | E12: MMR222 | F12: Myanmar | G12: MMR
A13: Hopang | C13: MMR015D006 | D13: Shan | E13: MMR222 | F13: Myanmar | G13: MMR
... A81: Hinthada | C81: MMR017D002 | D81: Ayeyarwady | E81: MMR017 | F81: Myanmar | G81: MMR

Sheet Admin 2 info
A1: adm2_name | B1: adm2_name_local | C1: adm2_pcode | D1: adm1_name | E1: adm1_pcode | F1: adm0_name | G1: adm0_ISO3
A2: Lashio | C2: MMR015D001 | D2: Shan | E2: MMR222 | F2: Myanmar | G2: MMR
A3: Kyaukme | C3: MMR015D003 | D3: Shan | E3: MMR222 | F3: Myanmar | G3: MMR
A4: Kokang Self-Administered Zone | C4: MMR015S002 | D4: Shan | E4: MMR222 | F4: Myanmar | G4: MMR
A5: Pa-O Self-Administered Zone | C5: MMR014S002 | D5: Shan | E5: MMR222 | F5: Myanmar | G5: MMR
A6: Loilen | C6: MMR014D002 | D6: Shan | E6: MMR222 | F6: Myanmar | G6: MMR
A7: Langkho | C7: MMR014D003 | D7: Shan | E7: MMR222 | F7: Myanmar | G7: MMR
A8: Danu Self-Administered Zone | C8: MMR014S001 | D8: Shan | E8: MMR222 | F8: Myanmar | G8: MMR
A9: Pa Laung Self-Administered Zone | C9: MMR015S001 | D9: Shan | E9: MMR222 | F9: Myanmar | G9: MMR
A10: Muse | C10: MMR015D002 | D10: Shan | E10: MMR222 | F10: Myanmar | G10: MMR
A11: Mongmit | C11: MMR015D008 | D11: Shan | E11: MMR222 | F11: Myanmar | G11: MMR
A12: Matman | C12: MMR015D007 | D12: Shan | E12: MMR222 | F12: Myanmar | G12: MMR
A13: Hopang | C13: MMR015D006 | D13: Shan | E13: MMR222 | F13: Myanmar | G13: MMR
... A81: Kyaukse | C81: MMR010D003 | D81: Mandalay | E81: MMR010 | F81: Myanmar | G81: MMR
