Workbook

Sheet survey
A1: GeoPoll Submission Form
A2: FAO - Household Questionnaire | P2: Additional notes
A3: Q # | B3: Q Name | C3: Suggested Qname | D3: English | E3: Length | F3: French | G3: Length | H3: Q Type | I3: Randomize | J3: Conditional | K3: Programming Instructions | L3: Skip Pattern | M3: Codes | N3: Default skip patterns & conditional | O3: Specify skip pattern variable (from blue text) | Q3: Estimated percentage of repondents | T3: Mandatory | X3: Duration (sec) | Y3: Weighted duration | Z3: Core questions only
A4: A. PRESENTATION OF THE SURVEY AND ELIGIBILITY CRITERIA SELECTION | T4: no | Y4: =IF(X4="","",X4*V4) | Z4: =IF(T4="yes",Y4,"")
A5: NA | B5: Optin | D5: Optin | E5: =LEN(D5) -> 5 | F5: Optin | G5: =LEN(F5) -> 5 | H5: Open Ended | I5: NA | J5: NA | K5: Form Type - TextBox | L5: Any Response = phone_number | M5: NA | N5: NA | T5: no | X5: 0 | Y5: =IF(X5="","",X5*Q5) -> 0 | Z5: =IF(T5="yes",Y5,"")
A6: NA | B6: phone_number | C6: phone_number | D6: Input the phone number that you are contacting: | E6: =LEN(D6) -> 48 | F6: Saisir le numéro de téléphone que vous chercher à contacter: | G6: =LEN(F6) -> 61 | H6: Open Ended | I6: NA | J6: NA | K6: Form Type - TextBox | L6: Any Response = calldispo | M6: NA | N6: NA | T6: yes | X6: 0 | Y6: =IF(X6="","",X6*Q6) -> 0 | Z6: =IF(T6="yes",Y6,"") -> 0
A7: NA | B7: calldispo | C7: calldispo | D7: Phone number: #CATI_MOBILENUMBER# 1)Someone answers 2)Answering machine 3)No answer 4)Hang up or refusal 5)Call back 6)Under review 7)Disconnected | E7: =LEN(D7) -> 146 | F7: Numéro de téléphone: #CATI_MOBILENUMBER# 1)Quelqu’un répond 2)Répondeur 3)Pas de réponse 4)Raccroche/Refuse 5)Doit être rappelé 6)À l’étude 7)Déconnecté | G7: =LEN(F7) -> 152 | H7: Single Choice | I7: NA | J7: NA | K7: Form Type - Buttons | L7: 1 = resp_language 2 = AnsweringMachine 3 = NoAnswer 4 = Refusal 5 = WhenCallBack 6 = UnderReview 7 = Disconnected | M7: NA | N7: NA | T7: no | X7: 14.695308 | Y7: =IF(X7="","",X7*Q7) -> 0 | Z7: =IF(T7="yes",Y7,"")
A8: NA | B8: AnsweringMachine | C8: calldispo_answeringmachine | D8: Reached an answering machine. | E8: =LEN(D8) -> 29 | F8: L'appel a abouti sur un répondeur/une messagerie. | G8: =LEN(F8) -> 49 | H8: NA | I8: NA | J8: NA | K8: NA | L8: End Poll AnsweringMachine | M8: NA | N8: NA | T8: no | X8: 0 | Y8: =IF(X8="","",X8*Q8) -> 0 | Z8: =IF(T8="yes",Y8,"")
A9: NA | B9: NoAnswer | C9: calldispo_noanswer | D9: Phone rang and no one answered. | E9: =LEN(D9) -> 31 | F9: Le téléphone a sonné et personne n'a répondu. | G9: =LEN(F9) -> 45 | H9: NA | I9: NA | J9: NA | K9: NA | L9: End Poll NoAnswer | M9: NA | N9: NA | T9: no | X9: 0 | Y9: =IF(X9="","",X9*Q9) -> 0 | Z9: =IF(T9="yes",Y9,"")
A10: NA | B10: UnderReview | C10: calldispo_underreview | D10: Case needs review by a supervisor. | E10: =LEN(D10) -> 34 | F10: Le cas doit être examiné par un superviseur. | G10: =LEN(F10) -> 44 | H10: NA | I10: NA | J10: NA | K10: NA | L10: End Poll UnderReview | M10: NA | N10: NA | T10: no | X10: 0 | Y10: =IF(X10="","",X10*Q10) -> 0 | Z10: =IF(T10="yes",Y10,"")
A11: NA | B11: Disconnected | C11: calldispo_disconnected | D11: Phone was disconnected or out of service. | E11: =LEN(D11) -> 41 | F11: Le téléphone est déconnecté ou hors service. | G11: =LEN(F11) -> 44 | H11: NA | I11: NA | J11: NA | K11: NA | L11: End Poll Disconnected | M11: NA | N11: NA | T11: no | X11: 0 | Y11: =IF(X11="","",X11*Q11) -> 0 | Z11: =IF(T11="yes",Y11,"")
A12: NA | B12: resp_language | C12: resp_language | D12: Which language do you wish to proceed with? [OPERATOR: READ ANSWER CHOICES. SINGLE RESPONSE.] 1)English 2)other options [add as many as necessary] | E12: =LEN(D12) -> 148 | F12: Quelle langue souhaitez-vous utiliser? [OPÉRATEUR/OPÉRATRICE: LIRE LES CHOIX, RÉPONSE UNIQUE] 1)Français 2)autre [ajouter autant d'options que nécessaire] | G12: =LEN(F12) -> 156 | H12: Single Choice | I12: NA | J12: NA | K12: Form Type - Buttons | L12: 1 = introduction [English] 2 = introduction [languages & add more if needed] | M12: NA | N12: For any response, go to introduction | P12: Insert most common national languages here [max 4 for translation with GeoPoll]. | T12: no | X12: 3.1032724 | Y12: =IF(X12="","",X12*Q12) -> 0 | Z12: =IF(T12="yes",Y12,"")
A13: NA | B13: introduction | C13: introduction | D13: Hello sir/ma'am, my name is #OPERATOR#, and I am calling from GeoPoll Polling Agency on behalf of the Food and Agriculture Organization of the United Nations [FAO]. We are conducting a survey on household livelihoods and the ability to access food in your area. I would like to ask you some questions about your household. The survey usually takes 15/20 minutes to complete. Any information that you provide will be kept strictly confidential, only used for the purpose of the survey and will not be shown to other people. Your voluntary participation in the outcome of this interview is NOT IN ANY WAY linked to your personal chance of receiving any assistance. This is voluntary and you can choose not to answer any or all of the questions if you want. However, we hope that you will participate since your views are important. You will receive #TOPUP#! of communication credit as an incentive for the participation of the survey. Please note that this call may be recorded for quality purposes. Do you have any questions? [OPERATOR: ADDRESS QUESTIONS FROM RESPONDENT, IF ANY.] 1)CONTINUE | E13: =LEN(D13) -> 1098 | F13: Bonjour Monsieur/Madame, mon nom est #OPERATOR#. Je vous appelle de la part de l'agence de sondage GeoPoll pour le compte de l'Organisation des Nations Unies pour l'alimentation et l'agriculture [la FAO]. Nous menons une enquête sur les moyens d'existence et la capacité des ménages à accéder à la nourriture dans votre région. J'aimerais vous poser quelques questions sur votre ménage. L'enquête dure généralement entre 15 et 20 minutes. Toutes les informations que vous fournirez resteront strictement confidentielles; elles ne seront utilisées que dans le cadre de cette enquête et ne seront pas communiquées à d'autres personnes. Votre participation volontaire à cet entretien n'est en AUCUN CAS liée à la possibilité de recevoir une quelconque aide. Votre participation est volontaire et, si vous le souhaitez, vous pouvez choisir de ne pas répondre à une partie ou à la totalité des questions. Cependant, nous espérons que vous voudrez bien participer car votre avis est important. Vous recevrez #TOPUP#! de crédit téléphonique comme incitation à participer à l'enquête. Veuillez noter que cet appel peut être enregistré à des fins de contrôle qualité. Avez-vous des questions? [OPÉRATEUR/OPÉRATRICE: LE CAS ÉCHÉANT, RÉPONDRE AUX QUESTIONS DE LA PERSONNE INTERROGÉE.] 1)CONTINUER | G13: =LEN(F13) -> 1293 | H13: Single Choice | I13: NA | J13: NA | K13: Form Type - Buttons | L13: 1 = Agree | M13: NA | N13: For any response, go to Agree | P13: Set the amount of incentive here, if any. | T13: no | X13: 37.418449 | Y13: =IF(X13="","",X13*Q13) -> 0 | Z13: =IF(T13="yes",Y13,"")
A14: NA | B14: Agree | C14: resp_agree | D14: Are you interested in participating in this survey? [OPERATOR: SINGLE RESPONSE] 1)Yes 2)Not now but another time in the week 3)No | E14: =LEN(D14) -> 134 | F14: Souhaitez-vous participer à cette enquête? [OPÉRATEUR/OPÉRATRICE: RÉPONSE UNIQUE] 1)Oui 2)Pas maintenant, mais à un autre moment de la semaine 3)Non | G14: =LEN(F14) -> 152 | H14: StartRecording | I14: NA | J14: NA | K14: Form Type - Buttons | L14: 1 = resp_firstname 2 = WhenCallBack 3 = resp_refusalwhy | M14: NA | N14: if Agree = 1, go to resp_firstname if Agree = 2, go to WhenCallBack if Agree = 3, go to resp_refusalwhy | Q14: 1 | T14: no | X14: 3.8059516 | Y14: =IF(X14="","",X14*Q14) -> 3.8059516 | Z14: =IF(T14="yes",Y14,"")
A15: NA | B15: resp_refusalwhy | C15: resp_refusalwhy | D15: Please let us know why you have REFUSED to take the survey. [OPERATOR: SINGLE RESPONSE] 1)Not interested 2)Do not want to be recorded 3)Other [specify] | E15: =LEN(D15) -> 153 | F15: Pourriez-vous m'indiquer pourquoi vous refusez de répondre à l'enquête. [OPÉRATEUR/OPÉRATRICE: RÉPONSE UNIQUE] 1)Pas intéressé 2)Ne veut pas être enregistré 3)Autre [préciser] | G15: =LEN(F15) -> 178 | H15: Open Ended - Single Choice | I15: NA | J15: NA | K15: Form Type - RadioList | L15: Any Response = Refusal | M15: NA | N15: For any response, go to Refusal | Q15: 1 | T15: no | X15: 0 | Y15: =IF(X15="","",X15*Q15) -> 0 | Z15: =IF(T15="yes",Y15,"")
A16: NA | B16: WhenCallBack | C16: resp_whencallback | D16: When would it be a good time to call you back? [RECORD HH/MM/DD/MM OF CALLBACK] | E16: =LEN(D16) -> 80 | F16: À quel moment pourrais-je vous rappeler? [ENREGISTRER HH/MM/JJ/MM DU RAPPEL] | G16: =LEN(F16) -> 77 | H16: Open Ended | I16: NA | J16: NA | K16: Form Type - TextBox IsCallBackDemographic | L16: Any Response = CallbackMessageEN | M16: NA | N16: For any response, go to CallbackMessageEN | Q16: 1 | T16: no | X16: 0 | Y16: =IF(X16="","",X16*Q16) -> 0 | Z16: =IF(T16="yes",Y16,"")
A17: NA | B17: CallbackMessageEN | C17: callbackmessage_en | D17: Thank you, we will call you back at {WhenCallBack} you requested. Thank you again and have a great day! [OPERATOR: ENTER CALL NOTES BELOW, WHO YOU SPOKE TO AND WHAT THEY SAID] | E17: =LEN(D17) -> 176 | F17: Merci, nous vous rappellerons à {WhenCallBack}. Merci encore et bonne journée! [OPÉRATEUR/OPÉRATRICE: SAISIR LES DONNÉES D'APPEL CI-DESSOUS, LE NOM DE LA PERSONNE À LAQUELLE VOUS AVEZ PARLÉ ET CE QU'ELLE A DIT] | G17: =LEN(F17) -> 211 | H17: Open Ended | I17: NA | J17: NA | K17: Form Type - TextBox | L17: Any Response = End poll callback | M17: NA | N17: NA | Q17: 1 | T17: no | X17: 0 | Y17: =IF(X17="","",X17*Q17) -> 0 | Z17: =IF(T17="yes",Y17,"")
A18: NA | B18: Ineligible | C18: NA | D18: You are ineligible for this survey. Thank you for your time and please look out for future surveys! | E18: =LEN(D18) -> 99 | F18: Vous êtes inéligible pour participer à cette enquête. Merci pour votre temps et renseignez-vous sur les prochains sondages! | G18: =LEN(F18) -> 123 | H18: NA | I18: NA | J18: NA | K18: NA | L18: End Poll Ineligible | M18: NA | N18: NA | Q18: 1 | T18: no | X18: 0 | Y18: =IF(X18="","",X18*Q18) -> 0 | Z18: =IF(T18="yes",Y18,"")
A19: NA | B19: Refusal | C19: NA | D19: Thank you for your time, you will be removed from today's survey. | E19: =LEN(D19) -> 65 | F19: Merci pour votre temps. Vous allez être retiré de l'enquête d'aujourd'hui. | G19: =LEN(F19) -> 74 | H19: NA | I19: NA | J19: NA | K19: NA | L19: End poll declined | M19: NA | N19: NA | Q19: 1 | T19: no | X19: 0 | Y19: =IF(X19="","",X19*Q19) -> 0 | Z19: =IF(T19="yes",Y19,"")
A20: B. GENERAL INFORMATION & ELIGIBILITY CRITERIA | Y20: =IF(X20="","",X20*Q20) | Z20: =IF(T20="yes",Y20,"")
A21: NA | B21: resp_firstname | C21: resp_firstname | D21: What is your first name? [OPERATOR: RECORD THE RESPONDENT'S FIRST NAME. ENTER 999 FOR REFUSED.] | E21: =LEN(D21) -> 96 | F21: Quel est votre prénom? [OPÉRATEUR/OPÉRATRICE: SAISIR LE PRÉNOM DE LA PERSONNE INTÉRROGÉE. SAISIR 999 POUR REFUSÉ.] | G21: =LEN(F21) -> 116 | H21: Open Ended | I21: NA | J21: NA | K21: Form Type - TextBox | L21: Any Response = resp_lastname | M21: NA | N21: For any response, go to resp_lastname | Q21: =1 -> 1 | T21: yes | X21: 25.874027 | Y21: =IF(X21="","",X21*Q21) -> 25.874027 | Z21: =IF(T21="yes",Y21,"") -> 25.874027
A22: NA | B22: resp_lastname | C22: resp_lastname | D22: What is your last name? [OPERATOR: RECORD THE RESPONDENT'S LAST NAME. ENTER 999 FOR REFUSED.] | E22: =LEN(D22) -> 95 | F22: Quel est votre nom de famille? [OPÉRATEUR/OPÉRATRICE: SAISIR LE NOM DE FAMILLE DE LA PERSONNE INTÉRROGÉE. SAISIR 999 POUR REFUSÉ.] | G22: =LEN(F22) -> 132 | H22: Open Ended | I22: NA | J22: NA | K22: Form Type - TextBox | L22: Any Response = resp_age | M22: NA | N22: For any response, go to resp_age | Q22: =1 -> 1 | T22: yes | X22: 8.5994816 | Y22: =IF(X22="","",X22*Q22) -> 8.5994816 | Z22: =IF(T22="yes",Y22,"") -> 8.5994816
A23: 1 | B23: resp_age | C23: resp_age | D23: How old are you? [OPERATOR: RECORD AGE IN NUMBER OF YEARS. ROUND UP TO NEAREST WHOLE NUMBER. IF THE RESPONDENT GIVES BIRTH YEAR, REPEAT THE QUESTION. ENTER 00 FOR DON'T KNOW.] | E23: =LEN(D23) -> 177 | F23: Quel âge avez-vous [en années]? [OPÉRATEUR/OPÉRATRICE: SAISIR L'ÂGE EN ANNÉES. ARRONDIR AU NOMBRE ENTIER LE PLUS PROCHE. SI LE RÉPONDANT DONNE SON ANNÉE DE NAISSANCE, RÉPÉTER LA QUESTION. SAISIR 00 POUR "NE SAIT PAS".] | G23: =LEN(F23) -> 219 | H23: Range | I23: NA | J23: NA | K23: Form Type - TextBox | L23: 0-17 = Ineligible 18-100 = resp_gender 00 = Ineligible | M23: NA | N23: Only respondents from 18-100 will be eligible for the survey. | Q23: =1 -> 1 | T23: yes | X23: 9.8907185 | Y23: =IF(X23="","",X23*Q23) -> 9.8907185 | Z23: =IF(T23="yes",Y23,"") -> 9.8907185
A24: =A23+1 -> 2 | B24: resp_gender | C24: resp_gender | D24: What is the gender of the respondent? [OPERATOR: DO NOT ASK THIS QUESTION OUT LOUD. LISTEN TO THE VOICE AND SELECT THE GENDER.] 1)Male 2)Female 3)DON'T KNOW 4)REFUSED | E24: =LEN(D24) -> 168 | F24: Quel est le sexe du répondant? [OPÉRATEUR/OPÉRATRICE: NE PAS POSER CETTE QUESTION À VOIX HAUTE. ÉCOUTER LA VOIX ET DÉTERMINER LE SEXE.] 1)Homme 2)Femme 3)NE SAIT PAS 4)REFUSÉ | G24: =LEN(F24) -> 178 | H24: Single Choice | I24: NA | J24: NA | K24: Form Type - Buttons | L24: 1-4 = phone_number_conf | M24: NA | N24: For any response, go to phone_number_conf | Q24: =1 -> 1 | T24: yes | X24: 1.7156482 | Y24: =IF(X24="","",X24*Q24) -> 1.7156482 | Z24: =IF(T24="yes",Y24,"") -> 1.7156482
Q25: =1 -> 1 | Y25: =IF(X25="","",X25*Q25) | Z25: =IF(T25="yes",Y25,"")
B26: phone_number_conf | C26: phone_number_conf | D26: Is the phone number I am calling you on yours or a household members? [OPERATOR: SINGLE RESPONSE.] 1)YES 2)NO 3)DON'T KNOW 4)REFUSED | E26: =LEN(D26) -> 134 | F26: Le numéro de téléphone sur lequel je vous appelle est-il le vôtre ou celui d'un membre de votre famille? [OPÉRATEUR/OPÉRATRICE: RÉPONSE UNIQUE.] 1)Oui 2)Non 3)NE SAIT PAS 4)REFUSÉ | G26: =LEN(F26) -> 181 | H26: Single Choice | I26: NA | J26: NA | K26: Form Type - Buttons | L26: 1 = contact_2 2 = phone_number_personal 3-4 = contact_2 | M26: NA | N26: if phone_number_conf = 1, go to contact_2 if phone_number_conf = 2, go to phone_number_personal if phone_number_conf = 3-4, go to contact_2 | Q26: =1 -> 1 | T26: yes - panel | X26: 6.375237 | Y26: =IF(X26="","",X26*Q26) -> 6.375237 | Z26: =IF(T26="yes",Y26,"")
B27: phone_number_personal | C27: phone_number_pers | D27: What is your phone number? [OPERATOR: RECORD THE NUMBER GIVEN] | E27: =LEN(D27) -> 63 | F27: Quel est votre numéro de téléphone? [OPÉRATEUR/OPÉRATRICE: SAISIR LE NUMERO.] | G27: =LEN(F27) -> 78 | H27: Open Ended | I27: NA | J27: NA | K27: Form Type - TextBox | L27: Any Response = contact_2 | M27: NA | N27: For any response, go to contact_2 | Q27: =1 -> 1 | T27: yes - panel | X27: 28.700001 | Y27: =IF(X27="","",X27*Q27) -> 28.700001 | Z27: =IF(T27="yes",Y27,"")
B28: contact_2 | C28: contact_2 | D28: Can you give me an additonal phone number belonging to you, a relative or a friend at which you can be reached? [OPERATOR: SINGLE RESPONSE.] 1)YES - mine 2)YES - friend or relative 3)NO 4)DON'T KNOW 5)REFUSED | E28: =LEN(D28) -> 211 | F28: Pouvez-vous me donner un autre numéro de téléphone, le vôtre, celui d'un parent ou d'un ami, auquel vous pouvez être joint? [OPÉRATEUR/OPÉRATRICE: RÉPONSE UNIQUE.] 1)Oui - le mien 2)Oui - celui d'un ami ou d'un parent 3)Non 4)NE SAIT PAS 5)REFUSÉ | G28: =LEN(F28) -> 248 | H28: Single Choice | I28: NA | J28: NA | K28: Form Type - Buttons | L28: 1-2 = phone_number_2 3-5 = hh_admin1 | M28: NA | N28: if contact_2 = 1-2, go to phone_number_2 if contact_2 = 3-5, go to contact_3 | Q28: =1 -> 1 | T28: yes - panel | X28: 10.141817 | Y28: =IF(X28="","",X28*Q28) -> 10.141817 | Z28: =IF(T28="yes",Y28,"")
B29: phone_number_2 | C29: phone_number_2 | D29: What is the additional phone number? [OPERATOR: RECORD THE NUMBER GIVEN] | E29: =LEN(D29) -> 73 | F29: Quel est cet autre numéro de téléphone? [OPÉRATEUR/OPÉRATRICE: SAISIR LE NUMERO.] | G29: =LEN(F29) -> 82 | H29: Open Ended | I29: NA | J29: NA | K29: Form Type - TextBox | L29: Any Response = contact_2_name | M29: NA | N29: For any response, go to contact_2_name | Q29: =1 -> 1 | T29: yes - panel | X29: 21.659983 | Y29: =IF(X29="","",X29*Q29) -> 21.659983 | Z29: =IF(T29="yes",Y29,"")
B30: contact_2_name | C30: contact_2_name | D30: What is the name of the contact? [OPERATOR: RECORD THE NAME OF THE CONTACT FOR THE PHONE NUMBER.] | E30: =LEN(D30) -> 98 | F30: Quel est le nom du contact associé à ce numéro de téléphone? [OPÉRATEUR/OPÉRATRICE: SAISIR LENOM DU CONTACT POUR CE NUMERO DE TÉLÉPHONE.] | G30: =LEN(F30) -> 138 | H30: Open Ended | I30: NA | J30: Send if "contact_2" "Equals" "YES - friend or relative", if not satisfied go to "contact_3" | K30: Form Type - TextBox | L30: Any Response = contact_3 | M30: NA | N30: Asked if "contact_2" "Equals" "YES - friend or relative". Otherwise, it skips to "contact_3". For any response, go to contact_3 | Q30: =1 -> 1 | T30: yes - panel | X30: 11.821796 | Y30: =IF(X30="","",X30*Q30) -> 11.821796 | Z30: =IF(T30="yes",Y30,"")
B31: contact_3 | C31: contact_3 | D31: Can you give me an additonal phone number belonging to you, a relative or a friend at which you can be reached? [OPERATOR: SINGLE RESPONSE.] 1)YES - mine 2)YES - friend or relative 3)NO 4)DON'T KNOW 5)REFUSED | E31: =LEN(D31) -> 211 | F31: Pouvez-vous me donner un autre numéro de téléphone, le vôtre, celui d'un parent ou d'un ami, auquel vous pouvez être joint? [OPÉRATEUR/OPÉRATRICE: RÉPONSE UNIQUE.] 1)Oui - le mien 2)Oui - celui d'un ami ou d'un parent 3)Non 4)NE SAIT PAS 5)REFUSÉ | G31: =LEN(F31) -> 248 | H31: Single Choice | I31: NA | J31: NA | K31: Form Type - Buttons | L31: 1-2= phone_number_3 3-5 = hh_admin1 | M31: NA | N31: if contact_3 = 1-2, go to phone_number_3 if contact_3 = 3-5, go to hh_admin1 | Q31: =1 -> 1 | T31: yes - panel | X31: 3.163594 | Y31: =IF(X31="","",X31*Q31) -> 3.163594 | Z31: =IF(T31="yes",Y31,"")
B32: phone_number_3 | C32: phone_number_3 | D32: What is the additional phone number? [OPERATOR: RECORD THE NUMBER GIVEN] | E32: =LEN(D32) -> 73 | F32: Quel est cet autre numéro de téléphone? [OPÉRATEUR/OPÉRATRICE: SAISIR LE NUMERO.] | G32: =LEN(F32) -> 82 | H32: Open Ended | I32: NA | J32: NA | K32: Form Type - TextBox | L32: Any Response = contact_3_name | M32: NA | N32: For any response, go to contact_3_name | Q32: =1 -> 1 | T32: yes - panel | X32: 10.830144 | Y32: =IF(X32="","",X32*Q32) -> 10.830144 | Z32: =IF(T32="yes",Y32,"")
B33: contact_3_name | C33: phone_number_3_name | D33: What is the name of the contact? [OPERATOR: RECORD THE NAME OF THE CONTACT FOR THE PHONE NUMBER.] | E33: =LEN(D33) -> 98 | F33: Quel est le nom du contact associé à ce numéro de téléphone? [OPÉRATEUR/OPÉRATRICE: SAISIR LENOM DU CONTACT POUR CE NUMERO DE TÉLÉPHONE.] | G33: =LEN(F33) -> 138 | H33: Open Ended | I33: NA | J33: Send if "contact_3" "Equals" "YES - friend or relative", if not satisfied go to "hh_admin1" | K33: Form Type - TextBox | L33: Any Response = hh_admin1 | M33: NA | N33: Asked if "contact_3" "Equals" "YES - friend or relative". Otherwise, it skips to "hh_admin1". For any response, go to hh_admin1 | Q33: =1 -> 1 | T33: yes - panel | X33: 11.260417 | Y33: =IF(X33="","",X33*Q33) -> 11.260417 | Z33: =IF(T33="yes",Y33,"")
Q34: =1 -> 1 | Y34: =IF(X34="","",X34*Q34) | Z34: =IF(T34="yes",Y34,"")
A35: 3 | B35: hh_admin1 | C35: hh_admin1 | D35: Currently, in which region does your household reside? [hint: household consists of all members living together, sharing resources & eating from the same pot.] [OPERATOR: SINGLE SELECTION.] 1)BAS-UELE 2)EQUATEUR 3)HAUT-KATANGA 4)HAUT-LOMAMI 5)HAUT-UELE 6)ITURI 7)KASAI 8)KASAI-CENTRAL 9)KASAI-ORIENTAL 10)KINSHASA 11)KONGO CENTRAL 12)KWANGO 13)KWILU 14)LOMAMI 15)LUALABA 16)MAI-NDOMBE 17)MANIEMA 18)MONGALA 19)NORD-KIVU 20)NORD-UBANGI 21)SANKURU 22)SUD-KIVU 23)SUD-UBANGI 24)TANGANYIKA 25)TSHOPO 26)TSHUAPA 27)DON'T KNOW 28)REFUSED | E35: =LEN(D35) -> 533 | F35: Actuellement, dans quel region votre ménage vit-il ? [conseil: le ménage est composé de toutes les personnes vivant ensemble, partageant leurs ressources et mangeant dans une marmite commune.] [OPÉRATEUR/OPÉRATRICE: RÉPONSE UNIQUE.] 1)BAS-UELE 2)EQUATEUR 3)HAUT-KATANGA 4)HAUT-LOMAMI 5)HAUT-UELE 6)ITURI 7)KASAI 8)KASAI-CENTRAL 9)KASAI-ORIENTAL 10)KINSHASA 11)KONGO CENTRAL 12)KWANGO 13)KWILU 14)LOMAMI 15)LUALABA 16)MAI-NDOMBE 17)MANIEMA 18)MONGALA 19)NORD-KIVU 20)NORD-UBANGI 21)SANKURU 22)SUD-KIVU 23)SUD-UBANGI 24)TANGANYIKA 25)TSHOPO 26)TSHUAPA 27)DON'T KNOW 28)REFUSED | G35: =LEN(F35) -> 576 | H35: Single Choice | I35: NA | J35: NA | K35: Form Type - Buttons IsDemographic - ADM1 | L35: 1 = hh_admin2_1 2-3 = Ineligible | M35: NA | N35: The administrative information will be updated by GeoPoll based on the sample design document and the administrative boundaries provided by the dashboard team after the questionnaire validation. | Q35: =1 -> 1 | T35: yes | X35: 13.957259 | Y35: =IF(X35="","",X35*Q35) -> 13.957259 | Z35: =IF(T35="yes",Y35,"") -> 13.957259
A36: =A35+1 -> 4 | B36: hh_admin2_1 | C36: hh_admin2_1 | D36: Currently, in which territory do your household live in? [OPERATOR: DO NOT READ THE OPTIONS. SINGLE SELECTION] 1)ARIWARA 2)ARU 3)ARU CITY 4)BUNIA 5)DJUGU 6)INGBOKOLO 7)IRUMU 8)MAHAGI 9)MAHAGI CITY 10)MAMBASA 11)MONGWALU 12)DON'T KNOW 13)REFUSED | E36: =LEN(D36) -> 247 | F36: Dans quelle territoire vit votre ménage actuellement? [OPERATEUR/OPERATRICE: NE LISEZ PAS LES OPTIONS. SEULEMENT UNE REPONSE] 1)ARIWARA 2)ARU 3)ARU CITY 4)BUNIA 5)DJUGU 6)INGBOKOLO 7)IRUMU 8)MAHAGI 9)MAHAGI CITY 10)MAMBASA 11)MONGWALU 12) NE SAIT PAS 13)REFUSE | G36: =LEN(F36) -> 262 | H36: Single Choice | I36: NA | J36: NA | K36: Form Type - Buttons IsDemographic - ADM2 | L36: 1 = hh_agricactivity 2-3 = Ineligible | M36: NA | Q36: =1 -> 1 | T36: yes | X36: 7.954999 | Y36: =IF(X36="","",X36*Q36) -> 7.954999 | Z36: =IF(T36="yes",Y36,"") -> 7.954999
B37: hh_admin2_2 | D37: Currently, in which territory do your household live in? [OPERATOR: DO NOT READ THE OPTIONS. SINGLE SELECTION] 1)DEKESE 2)ILEBO 3)ILEBO CITY 4)KAMONIA 5)LUEBO 6)LUEBO CITY 7)MWEKA 8)TSHIKAPA 9)DON'T KNOW 10)REFUSED | F37: Dans quelle territoire vit votre ménage actuellement? [OPERATEUR/OPERATRICE: NE LISEZ PAS LES OPTIONS. SEULEMENT UNE REPONSE] 1)DEKESE 2)ILEBO 3)ILEBO CITY 4)KAMONIA 5)LUEBO 6)LUEBO CITY 7)MWEKA 8)TSHIKAPA 9)NE SAIT PAS 10)REFUSE | H37: Single Choice
B38: hh_admin2_3 | D38: Currently, in which territory do your household live in? [OPERATOR: DO NOT READ THE OPTIONS. SINGLE SELECTION] 1)DEMBA 2)DIBAYA 3)DMBELENGE 4)KANANGA 5)KAZUMBA 6)LUIZA 7)TSHIMBULU 8)DON'T KNOW 9)REFUSED | F38: Dans quelle territoire vit votre ménage actuellement? [OPERATEUR/OPERATRICE: NE LISEZ PAS LES OPTIONS. SEULEMENT UNE REPONSE] 1)DEMBA 2)DIBAYA 3)DMBELENGE 4)KANANGA 5)KAZUMBA 6)LUIZA 7)TSHIMBULU 8)NE SAIT PAS 9)REFUSE | H38: Single Choice
B39: hh_admin2_4 | D39: Currently, in which territory do your household live in? [OPERATOR: DO NOT READ THE OPTIONS. SINGLE SELECTION] 1)KABEYA-KAMWANGA 2)KATANDA 3)LUKALABA 4)LUPATAPATA 5)MBUJI-MAYI 6)MIABI 7)MIABI CITY 8)TSHILENGE 9)TSHILENGE CITY 10)DON'T KNOW 11)REFUSED | F39: Dans quelle territoire vit votre ménage actuellement? [OPERATEUR/OPERATRICE: NE LISEZ PAS LES OPTIONS. SEULEMENT UNE REPONSE] 1)KABEYA-KAMWANGA 2)KATANDA 3)LUKALABA 4)LUPATAPATA 5)MBUJI-MAYI 6)MIABI 7)MIABI CITY 8)TSHILENGE 9)TSHILENGE CITY 10)NE SAIT PAS 11)REFUSE | H39: Single Choice
B40: hh_admin2_5 | D40: Currently, in which territory do your household live in? [OPERATOR: DO NOT READ THE OPTIONS. SINGLE SELECTION] 1)BENI 2)BUTEMBO 3)GOMA 4)LUBERO 5)MASISI 6)NYIRAGONGO 7)OICHA 8)OICHA CITY 9)RUTSHURU 10)RUTSHURU CITY 11)WALIKAME 12)DON'T KNOW 13)REFUSED | F40: Dans quelle territoire vit votre ménage actuellement? [OPERATEUR/OPERATRICE: NE LISEZ PAS LES OPTIONS. SEULEMENT UNE REPONSE] 1)BENI 2)BUTEMBO 3)GOMA 4)LUBERO 5)MASISI 6)NYIRAGONGO 7)OICHA 8)OICHA CITY 9)RUTSHURU 10)RUTSHURU CITY 11)WALIKAME 12)NE SAIT PAS 13)REFUSE | H40: Single Choice
...

Sheet New Durations
A1: question | B1: duration | C1: responded % | D1: weighted time
A2: introduction | B2: 50.82254 | C2: 1 | D2: 50.82254
A3: agree | B3: 3.4964738 | C3: 0.79698741 | D3: 2.7866456
A4: resp_age | B4: 13.753073 | C4: 1 | D4: 13.753073
A5: resp_gender | B5: 2.1173561 | C5: 1 | D5: 2.1173561
A6: quotareached | B6: 2.28425 | C6: 0.79698741 | D6: 1.8205185
A7: hh_agricactivity | B7: 31.372377 | C7: 1 | D7: 31.372377
A8: hh_milieu | B8: 7.9225454 | C8: 0.15190348 | D8: 1.2034622
A9: hh_gender | B9: 10.085732 | C9: 1 | D9: 10.085732
A10: hh_education | B10: 12.894034 | C10: 1 | D10: 12.894034
A11: hh_wealth_water | B11: 15.265829 | C11: 0.63796463 | D11: 9.739059
A12: hh_wealth_toilet | B12: 15.123718 | C12: 0.59180156 | D12: 8.95024
A13: hh_wealthwall | B13: 12.821411 | C13: 0.15190348 | D13: 1.9476169
... A164: adm1_name | B164: 10.743817 | C164: 0.20301259 | D164: 2.1811302
A165: adm2_name | C165: 0 | D165: 0
A166: covid | B166: 56.471024 | C166: 0.20301259 | D166: 11.464329
A167: crp_landright | B167: 31 | C167: 0.0040467626 | D167: 0.12544964
A168: crp_seed | B168: 30.833334 | C168: 0.0040467626 | D168: 0.12477518
A169: crp_proddif | B169: 16.882986 | C169: 0.11848022 | D169: 2.0002998
A170: crp_salesdif | B170: 16.82699 | C170: 0.086630695 | D170: 1.4577339
A171: crp_saledif_2 | B171: 39.486874 | C171: 0.03139988 | D171: 1.2398831
A172: ls_proddif | B172: 15.938099 | C172: 0.10169365 | D172: 1.6208034
A173: ls_salesdif | B173: 13.330855 | C173: 0.060476619 | D173: 0.80620506
A174: ls_proc | B174: 16.437651 | C174: 0.0625 | D174: 1.0273532
A175: ls_proc_fac_state | B175: 8.666667 | C175: 0.00067446043 | D175: 0.005845324
A176: fish_proddif | B176: 12.523809 | C176: 0.001573741 | D176: 0.019709232
A177: cs_spentsavings | B177: 22.220184 | C177: 0.0081684652 | D177: 0.1815048
... A193: ls_proddif_2_covid19 | B193: 3.3438249 | C193: 1 | D193: 3.3438249

Sheet Crop list
C3: Select top 10 crops | D3: GeoPoll code | E3: Dataset code | F3: Label (EN) | G3: Label (FR)
C4: x | D4: {=_xlfn.SEQUENCE(90,1,1,1)} -> 1 | E4: 1.1 | F4: Rice | G4: Riz
D5: 2 | E5: 1.2 | F5: Wheat | G5: Blé
C6: x | D6: 3 | E6: 1.3 | F6: Millet | G6: Mil
C7: x | D7: 4 | E7: 1.4 | F7: Sorghum | G7: Sorgho
C8: x | D8: 5 | E8: 1.5 | F8: Maize | G8: Maïs
D9: 6 | E9: 1.6 | F9: Barley | G9: Orge
D10: 7 | E10: 1.99 | F10: Other Cereal | G10: Autres céréales
C11: x | D11: 8 | E11: 2.1 | F11: Cassava | G11: Manioc
C12: x | D12: 9 | E12: 2.2 | F12: Potatoe | G12: Pommes de terre
D13: 10 | E13: 2.3 | F13: Sweet Potatoes | G13: Patates douces
D14: 11 | E14: 2.4 | F14: Yams | G14: Ignames
D15: 12 | E15: 2.5 | F15: Carrots | G15: Carottes
D16: 13 | E16: 2.6 | F16: Cocoyam | G16: Chou caraïbe
D17: 14 | E17: 2.99 | F17: Other tubers | G17: Autres tubercules
C18: x | D18: 15 | E18: 3.1 | F18: Beans | G18: Haricots
D19: 16 | E19: 3.2 | F19: Lentils | G19: Lentilles
D20: 17 | E20: 3.3 | F20: Peas | G20: Pois
C21: x | D21: 18 | E21: 3.4 | F21: Soybeans | G21: Soja
D22: 19 | E22: 3.5 | F22: Chickpeas | G22: Pois chiches
D23: 20 | E23: 3.6 | F23: Fava beans | G23: Fève
D24: 21 | E24: 3.7 | F24: Broad beans | G24: Fève large
D25: 22 | E25: 3.99 | F25: Other pulses | G25: Autres légumineuses
D26: 23 | E26: 4.1 | F26: Cabbage | G26: Choux
D27: 24 | E27: 4.2 | F27: Lettuce | G27: Laitue
D28: 25 | E28: 4.3 | F28: Spinach-Amaranth | G28: Epinards-Amaranthe
D29: 26 | E29: 4.4 | F29: Cassava leaves | G29: Feuilles de manioc
D30: 27 | E30: 4.5 | F30: Potatoe leaves | G30: Feuilles de pomme de terre
D31: 28 | E31: 4.6 | F31: Moringa | G31: Moringa
D32: 29 | E32: 4.7 | F32: Sorrel Hibiscus / Rosselle | G32: Oseille Hibiscus / Rosselle
D33: 30 | E33: 4.9 | F33: Green salad herbs [thyme, parsley, mint, rocca, other] | G33: Herbes aromatiques [thym, persil, menthe, rocca, autres]
... D53: 50 | E53: 7.1 | F53: Sweet Banana | G53: Banane douce
C54: x | D54: 51 | E54: 7.2 | F54: Plantains | G54: Banane plantain
C55: x | D55: 52 | E55: 7.3 | F55: Papaya | G55: Papaye
D56: 53 | E56: 7.4 | F56: Mango | G56: Mangue
D57: 54 | E57: 7.5 | F57: Guava | G57: Goyave
D58: 55 | E58: 7.6 | F58: Pineapple | G58: Ananas
D59: 56 | E59: 7.7 | F59: Avocado | G59: Avocat
D60: 57 | E60: 7.8 | F60: Water Melon | G60: Pastèques
D61: 58 | E61: 7.9 | F61: Dates | G61: Dattes
...

Sheet Additional information
C2: Original EN / FR | D2: Replacement (EN) | E2: Remplacement (FR) | F2: Comment (EN) | G2: Commentaire (FR) | H2: Examples (EN) | I2: Exemples (FR)
B3: FOR CORE QUESTIONS . (Mandatory to fill out) . | C3: ADMIN1 | D3: Province | E3: Province | F3: The first subdivision of the country, after national level; region; province; governorate; etc. | G3: La première subdivision du pays, après le niveau national ; par exemple, région ; province ; gouvernorat ; etc. | H3: region | I3: region
C4: ADMIN2 | D4: Territory | E4: Territoire | F4: The second subdivision of the country; district; municipality; LGA; etc. | G4: La deuxième subdivision du pays ; par exemple, district, municipalité, LGA, etc. | H4: district | I4: district
C5: reference year | D5: last year | E5: l'année dernière | F5: Comparison questions will need need a reference year. Select whether you want to use "last year" or "a normal year" as a baseline. A "normal year" should refers to an average year from the past 5 years - make sure to train the enumerators accordingly. | G5: Les questions de comparaison auront besoin d'une année de référence. Choisissez si vous voulez utiliser "l'année dernière" ou "une année normale" comme année de référence. Une "année normale" doit correspondre à une année moyenne des 5 dernières années - veillez à former les recenseurs en conséquence. | H5: a normal year | I5: une année normale
C6: season | D6: Rainy season | E6: Saison des pluies | F6: Name the crop season(s) of interest if there are several cropping seasons in the country (e.g. Meher and Belg in Ethiopia, rainy season / flood-recession cropping / irrigated dry season in the Sahel). You can refer to the “last season” or “ongoing season". | G6: Nommez la ou les saisons culturales concernée(s) en ANGLAIS s'il y en a plusieurs dans le pays (par exemple, Meher et Belg en Ethiopie, saison des pluies / cultures de décrue / saison sèche irriguée au Sahel). Vous pouvez vous référer à la "dernière saison" ou "saison actuelle". | H6: wet season | I6: saison des pluies
C7: season phase | D7: Maturing | E7: Proche de la récolte | F7: Indicate the phase of the season at the time of data collection. If the harvest from the season has not yet occurred, the question on crop harvest (crp_harv_change) will include the word “expected” (where #expected or nothing# is located). If the harvest has occured, "expected" will not be inserted in the question. | G7: Indiquez le stade de la saison culturale au moment de la collecte des données. Si la récolte de la saison n'a pas encore eu lieu, la question sur la récolte des cultures (crp_harv_change) inclura le mot "attendue" (là où se trouve #attendue ou rien#). Si la récolte a eu lieu, "attendue" ne sera pas inséré dans la question. | H7: Harvesting | I7: Récolte
C8: local measurement unit | F8: Specify the local measurement unit for land size, other than acres, hectares, square meters and square feet. If no other unit of measurement is needed, keep this cell blank. | G8: Indiquez l'unité utilisée localement pour mesurer la taille des terrains, autre que les acres, les hectares, les mètres carrés et les pieds carrés. Si aucune autre unité de mesure n'est nécessaire, garder cette cellule vide. | H8: Jeribs | I8: Jeribs
C9: local measurement unit conversion | D9: =IF(E9<>"",E9,"") | F9: Include the conversion of the local measurement unit to hectares. In other words, how many local measurement units are in 1 ha. | G9: Indiquez la conversion de l'unité de mesure locale en hectares. En d'autres termes, indiquez combien d'unités de mesure locales y a-t-il dans 1 ha. | H9: 0.2 | I9: 0.2
B10: FOR OPTIONAL QUESTIONS . (Fill out if applicable) . | C10: currency | D10: CDF | E10: CDF | F10: The name of the main currency used nationally; USD; Naira; Rial; Pesos; etc. | G10: Nom de la principale devise utilisée au niveau national; par exemple, USD; Naira; Rial; Pesos; etc. | H10: Naira | I10: Naira
C11: MIN AMOUNT | D11: 1 | E11: 1 | F11: The minimum amount for an income source should be set at 0 or any value below which it is not possible to do a transaction. For example, the smallest coin/banknote in a currency can be 1000, in which case you would set the minimum at 1000. Provide this input in the same currency as specified above. Only digits should be inputted. | G11: Le montant minimum d'une source de revenu doit être fixé à 0 ou à toute valeur en dessous de laquelle il n'est pas possible d'effectuer une transaction. Par exemple, la plus petite pièce/billet d'une devise peut être de 1000, auquel cas vous fixerez le minimum à 1000. Cette saisie doit être effectuée dans la même devise que celle spécifiée ci-dessus. Seuls des chiffres doivent être saisis. | H11: 5 | I11: 5
C12: MAX AMOUNT | D12: 10000000 | E12: 10000000 | F12: Set the maximum amount for an income source over 3 months. Enumerators will not be able to input values above this amount in questions related to income amounts. Using previous representative surveys for this population, you can estimate this amount by using the mean income plus five (5) standard deviations, unless the country has high inflation. In the latter case, set the maximum value based on your country context (higher than the proposed approach). Provide this input in the same currency as specified above. Only digits should be inputted. | G12: Fixez le montant maximum pouvant être généré par une source de revenu sur 3 mois. Il ne sera pas possible pour les enquêteurs d'entrer des valeurs supérieures à ce montant dans les questions relatives aux montants des revenus. En vous basant sur des enquêtes précédentes représentatives de cette population, vous pouvez estimer ce montant en utilisant le revenu moyen plus cinq (5) écarts types, sauf si le pays connaît une forte inflation. Dans ce dernier cas, fixez la valeur maximale en fonction du contexte de votre pays (plus élevée que l'approche proposée). Cette saisie doit être effectuée dans la même devise que celle spécifiée ci-dessus. Seuls des chiffres doivent être saisis. | H12: 5000000 | I12: 5000000
C13: THRESHOLD | D13: 2000000 | E13: 2000000 | F13: The threshold salary should be calculated to flag outliers (responses that look suspiciously high). Using previous representative surveys for this population, a good estimate is the average plus three (3) standard deviations, which should give the threshold for the 3 or 4% highest income values. Provide this input in the same currency as specified above. Only digits should be inputted. | G13: Le salaire seuil doit être calculé pour signaler les valeurs aberrantes (réponses qui semblent suspectes). En utilisant des enquêtes précédentes représentatives de cette population, une bonne estimation est la moyenne plus deux écarts types, ce qui devrait dégager le seuil pour les 3 ou 4% des valeurs de revenu les plus élevées. Cette saisie doit être effectuée dans la même devise que celle spécifiée ci-dessus. Seuls des chiffres doivent être saisis. | H13: 1200000 | I13: 1200000
C14: local vegetables | D14: Funbwa, spinach, cabbage, carrot | E14: Fumbwa, épinard, choux, carottes | F14: Input some common local vegetables [to be used as examples in the food consumption score indicator]. | G14: Saisissez quelques légumes locaux courants [à utiliser comme exemples dans l'indicateur de score de consommation alimentaire]. | H14: eggplants, zucchini, cauliflower | I14: aubergines, courgettes, choux-fleurs
C15: local fruits | D15: bananas, oranges, mangos | E15: bananes, oranges, mangues | F15: Input some common local fruits [to be used as examples in the food consumption score indicator]. | G15: Indiquez quelques fruits locaux courants [à utiliser comme exemples dans l'indicateur de score de consommation alimentaire]. | H15: apples, bananas, oranges | I15: pommes, bananes, oranges
B17: FILL OUT FOR QUESTIONNAIRE DURATION ESTIMATION . | C17: Expected percentage of respondents cultivating crops | D17: =IF(E17="","",E17) -> 0.75 | E17: 0.75 | F17: If the survey is representative and has no quotas, write the proportion of rural households cultivating crops at country level, or if the survey follows a previous round with identical sample design, just report the percentage from the previous round. If you are using quotas, calculate the ratio of the quota over the minimum sample size at the level where the quota is implemented (so if you have a minimum sample size per strata of 110 with a quota of 100 crop producers, then it's 100/110 = 91% (the maximum you should write is 100%). | G17: Si l'enquête est représentative et ne comporte pas de quotas, écrivez la proportion de ménages ruraux impliqués dans les cultures au niveau du pays, ou si l'enquête suit un cycle précédent avec un plan d'échantillonnage identique, indiquez simplement le pourcentage du cycle précédent. Si vous utilisez des quotas, calculez le rapport entre le quota et la taille minimale de l'échantillon au niveau où le quota est appliqué (ainsi, si vous avez une taille minimale d'échantillon par strate de 110 avec un quota de 100 producteurs de cultures, alors c'est 100/110 = 91% (le maximum que vous devez écrire est 100%). | H17: 0.91 | I17: 0.91
C18: Expected percentage of respondents raising livestock | D18: =IF(E18="","",E18) -> 0.2 | E18: 0.2 | F18: If the survey is representative and has no quotas, write the proportion of rural households raising livestock at country level, or if the survey follows a previous round with identical sample design, just report the percentage from the previous round. If you are using quotas, calculate the ratio of the quota over the minimum sample size at the level where the quota is implemented (so if you have a minimum sample size of 110 but a quota of 100 livestock producers, then it's 100/110 = 91% (the maximum you should write is 100%) | G18: Si l'enquête est représentative et ne comporte pas de quotas, écrivez la proportion de ménages ruraux impliqués dans l'élevage, ou si l'enquête suit un cycle précédent avec un plan d'échantillonnage identique, indiquez simplement le pourcentage du cycle précédent. Si vous utilisez des quotas, calculez le rapport entre le quota et la taille minimale de l'échantillon au niveau où le quota est appliqué (ainsi, si vous avez une taille minimale d'échantillon par strate de 110 avec un quota de 100 éleveurs, alors c'est 100/110 = 91% (le maximum que vous devez écrire est 100%). | H18: 0.91 | I18: 0.91
C19: Expected percentage of respondents involved in fishery | D19: =IF(E19="","",E19) -> 0.05 | E19: 0.05 | F19: If the survey is representative and has no quotas, write the proportion of rural households involved in fisheries or aquaculture, otherwise if you are using quotas, calculate the ratio of the quota over the sample size at the level where the quota is implemented. (so if you haven't set a quota, and you expect to have a representative proportion of fishermen, just write the percentage of fishermen in the population you are targeting, in the example to the right, 5%) | G19: Si l'enquête est représentative et ne comporte pas de quotas, écrivez la proportion de ménages ruraux impliqués dans la pêche ou l'aquaculture; sinon, si vous utilisez des quotas, calculez le rapport entre le quota et la taille de l'échantillon au niveau où le quota est appliqué (ainsi, si vous n'avez pas fixé de quota, et que vous pensez avoir une proportion représentative de pêcheurs, écrivez simplement le pourcentage de pêcheurs dans la population que vous ciblez, dans l'exemple à droite, 5%). | H19: 0.05 | I19: 0.05

Sheet Admin 2 info1
A1: adm2_name | B1: adm2_name_local | C1: adm2_pcode | D1: adm1_name | E1: adm1_pcode | F1: adm0_name | G1: adm0_ISO3
A2: Gemena | B2: Gemena | C2: CD4202 | D2: Sud-Ubangi | E2: CD42 | F2: Democratic Republic of the Congo | G2: COD
A3: Gbadolite | B3: Gbadolite | C3: CD4301 | D3: Nord-Ubangi | E3: CD43 | F3: Democratic Republic of the Congo | G3: COD
A4: Fizi | B4: Fizi | C4: CD6210 | D4: Sud-Kivu | E4: CD62 | F4: Democratic Republic of the Congo | G4: COD
A5: Feshi | B5: Feshi | C5: CD3103 | D5: Kwango | E5: CD31 | F5: Democratic Republic of the Congo | G5: COD
A6: Faradje | B6: Faradje | C6: CD5307 | D6: Haut-Uele | E6: CD53 | F6: Democratic Republic of the Congo | G6: COD
A7: Dungu | B7: Dungu | C7: CD5305 | D7: Haut-Uele | E7: CD53 | F7: Democratic Republic of the Congo | G7: COD
A8: Djugu | B8: Djugu | C8: CD5405 | D8: Ituri | E8: CD54 | F8: Democratic Republic of the Congo | G8: COD
A9: Djolu | B9: Djolu | C9: CD4504 | D9: Tshuapa | E9: CD45 | F9: Democratic Republic of the Congo | G9: COD
A10: Dingila | B10: Dingila | C10: CD5210 | D10: Bas-Uele | E10: CD52 | F10: Democratic Republic of the Congo | G10: COD
A11: Dimbelenge | B11: Dimbelenge | C11: CD9107 | D11: Kasaï-Central | E11: CD91 | F11: Democratic Republic of the Congo | G11: COD
A12: Dilolo | B12: Dilolo | C12: CD7205 | D12: Lualaba | E12: CD72 | F12: Democratic Republic of the Congo | G12: COD
... A190: Goma | B190: Goma | C190: CD6101 | D190: Nord-Kivu | E190: CD61 | F190: Democratic Republic of the Congo | G190: COD
