Workbook

Sheet survey
A1: type | B1: name | C1: label::English (en) | D1: label::French (fr) | E1: label::Haoussa (ha) | F1: label::Djerma (dj) | G1: label::Peulh (pe) | H1: label::Kanuri (kr) | I1: label::Tamachek (ta) | J1: label:: | K1: hint::English (en) | L1: hint::French (fr) | M1: hint::Haoussa (ha) | N1: hint::Djerma (dj) | O1: hint::Peulh (pe) | P1: hint::Kanuri (kr) | Q1: hint::Tamachek (ta) | R1: hint:: | S1: required | T1: appearance | U1: constraint | V1: constraint_message | W1: relevant | X1: choice_filter | Y1: parameters | Z1: calculation | AE1: Mandatory | AG1: New question duration (sec) | AH1: Estimated percentage of repondents | AI1: Weighted time | AJ1: Weighted time for core vars
A2: start | B2: start | AI2: =IF(AG2<>"",AG2*AH2,"") | AJ2: =IF(AND(AG2<>"",AE2="yes"),AG2*AH2,"")
A3: end | B3: end | AI3: =IF(AG3<>"",AG3*AH3,"") | AJ3: =IF(AND(AG3<>"",AE3="yes"),AG3*AH3,"")
A4: today | B4: today | AI4: =IF(AG4<>"",AG4*AH4,"") | AJ4: =IF(AND(AG4<>"",AE4="yes"),AG4*AH4,"")
A5: deviceid | B5: deviceid | AI5: =IF(AG5<>"",AG5*AH5,"") | AJ5: =IF(AND(AG5<>"",AE5="yes"),AG5*AH5,"")
A6: audit | B6: audit
A7: calculate | B7: audio_random | Z7: once(random())
A8: background-audio | B8: background-audio | W8: ${audio_random}<=0.02 | Y8: quality=low
A9: select_one enumerator | B9: enumerator | C9: Name of enumerator | D9: Nom de l'énquêteur | E9: Sunan mai tambaya | F9: Ay mayo no ti….. | G9: Innde ƴamoowo | H9: Tchou kulachimaye | I9: essim nimissesten | S9: true | T9: autocomplete | AE9: yes | AI9: =IF(AG9<>"",AG9*AH9,"") | AJ9: =IF(AND(AG9<>"",AE9="yes"),AG9*AH9,"")
A10: calculate | B10: enumerator_ | Z10: jr:choice-name(${enumerator},'${enumerator}') | AE10: yes | AI10: =IF(AG10<>"",AG10*AH10,"") | AJ10: =IF(AND(AG10<>"",AE10="yes"),AG10*AH10,"")
A12: note | B12: introduction | C12: Hello sir/ma'am, my name is ${enumerator_}. On behalf of the Food and Agriculture Organization of the United Nations (FAO), we are conducting a survey on household livelihoods and the ability to access food in your area. I would like to ask you some questions about your household. The survey usually takes 20 / 30 minutes to complete. Any information that you provide will be kept strictly confidential, only used for the purpose of the survey and will not be shown to other people. Your voluntary participation in the outcome of this interview is NOT IN ANY WAY linked to your personal chance of receiving any assistance. This is voluntary and you can choose not to answer any or all of the questions if you want. However, we hope that you will participate since your views are important. Do you have any questions? | D12: Bonjour Monsieur/Madame, mon nom est ${enumerator_}. Nous sommes ici de la part de l'Organisation des Nations Unies pour l'alimentation et l'agriculture (la FAO). Nous menons une enquête sur les moyens d'existence et la capacité des ménages à accéder à la nourriture dans votre région. J'aimerais vous poser quelques questions sur votre ménage. L'enquête dure généralement entre 20 / 30 minutes. Toutes les informations que vous fournirez resteront strictement confidentielles; elles ne seront utilisées que dans le cadre de cette enquête et ne seront pas communiquées à d'autres personnes. Votre participation volontaire à cet entretien n'est en AUCUN CAS liée à la possibilité de recevoir une quelconque aide. Votre participation est volontaire et, si vous le souhaitez, vous pouvez choisir de ne pas répondre à une partie ou à la totalité des questions. Cependant, nous espérons que vous voudrez bien participer car votre avis est important. Avez-vous des questions? | E12: Sannu Sir/Madam, sunana ${enumerator_}. Muna nan a madadin Hukumar Abinci da Aikin Noma ta Majalisar Dinkin Duniya (FAO). Muna gudanar da bincike kan abubuwan rayuwa da iyawar gidaje don samun abinci a yankinku. Ina so in yi muku 'yan tambayoyi game da gidan ku. Binciken gabaɗaya yana ɗauka tsakanin mintuna 20/30. Duk bayanan da kuka bayar za a kiyaye su sosai; za a yi amfani da su ne kawai a cikin mahallin wannan binciken kuma ba za a sanar da su ga wasu mutane ba. Kasancewar ku na son rai a cikin wannan hirar ba ta da alaƙa da yuwuwar samun kowane taimako. Shigar da ku na son rai ne kuma, idan kuna so, za ku iya zaɓar kada ku amsa wasu ko duk tambayoyin. Koyaya, muna fatan za ku yarda ku shiga saboda ra'ayin ku yana da mahimmanci. Kuna da wasu tambayoyi? | F12: Mataran go albora/weybora, ay ma ti ${enumerator_}. no ne ayma aran ke Anduniya Fu Beero Kan Ga haw goy nda Mee Nwaari nda Farmoo fondara. Iri goga keki ga bey matan kan kina aran goga bafuney da da mo mata ga aran ga dou me gnwari aran koira ra,iri ga bai iri ma hanyan fo te aran se aran wane almiyalo bon. Aran gonda dama irma fakarey keyna. fahamayey kulu kan aran giri no si goro kala tugurey ;isi goy dey kala hayaney wo fondara boro kulu no si ma rey.da aran ga ba aran ma fouro siguiro ra manti gakasiney du yan kulu se no.aran siguiro ra furo yanwo hima ga te aran bayi koirey ra,da aran si ba manti dole no aran ma tu wala aran matu giarey ga ama dey iri ga gnwarey aran ma tu iri se zakan aran tu yanwo ga beri iri ga.i ga samba aran se keyan noru furo yanwo se .wa bey mo kan iri ga hini ga keyan wo sambu iri ma du ga hagoy da hayan ka iri goga te se no. da aran gonda hayan iri goga hangane aran se. koy da gine? | G12: "Salaamaleykum, binndin'a, isii na ${enumerator_}. Mi bulaaku nan FAO, haa dem ɓeyn'ɗoo oo wi'ɗin'a. Mi ko'booj'o foyƴi bunnudeejeede e wooɗɗudeede e nganndu'e, o faydii mi ko'banndu'ɓe laasiri e toɗɗu oo. Minnde heɗɗoɗo gannde mon ɗemngal wooɗo ko'o huuɗa ndu'ɓe. Mon ɗemɗeɗe yenndi njiidiyaaɗi e laaɓe 20/30. Nde wondudee mi woɗɗaa waɗde nde, mi tawa'ɗe neɗɗo kala. Yaɓɓe wooɗo laaɓe laasiri nii goɗɗiɗo e nde, ka'i kadi ɗum konnde jaaɓi e humpitoondi. Woɗɗo lunniri kala ɗemɗe mi njemra e entenɗa nii kadi. En entenɗa kadi e heɗɗo ngam wooɗɗoo saka mon kala. Kanko, mon ganndaa oo kadi hannde en, sabu nganndu'e nii yahdu mum waɗtoojal. E leɗɓeɗe ɗemngal kadi, woɗɗi njiɗtanteede sundeende. To mo jiɗɗo njiɗɗaa?" | H12: Salaamaleykum, ɓarka da yin asalin kuyanga, sunana ${enumerator_}. Muna hanyar FAO, an samu nasara a gari. Muna gudanar da hanyoyin rayuwarmu da ikirarin kudin jiki a yankin ku. Ina so ka yi min tambayoyin da za ku amsa game da gida. Yanayin rayuwa ya mayar da 20/30 da dari. Duk da cewa za ku amsa, muna son ku yin amfani da shawarwarku. Duk da cewa ku yin kulle-kulle ko duk wani tambayoyi. Hakanan kuma muna son ku ɓoye. Amma, muna yin tsokaci domin rashin amsa ba shi da wani damar samun sadarwa. Ku yiba, idan kun bincike wani tambaya? | I12: Tagodayam nak issinine enumerator. Nahade fell assagawar yigan tegawar titawene inken firgan wassamalan fao. Nosadou iken sistinan ikalnine fel tagawere in guiwanan dik akal nawan. Aré adawounaga issistinan wiyade fell iguiwananawan. Asostan idakal agudiyan 20/30 ən minitan. Isalan dak wi mad tifim adakamin aylan garenaɣ, imba damatkalan ad-daɣ tabarat tan asostan əd imba diqilan atiwalaɣen ye idinat iyad. Wala iyan asostan ən nawadim wa rika atwisiɣim. Tihawt nawan ən tiridawt daɣ liɣitan ən asostan wen wareqel daɣ WALA IYAT tabarat tartayat əd tabaɣor nadinat ye agaraw ən atamosan tilalt. Eqal tiridawt əd tadobem atikisam iba nəliɣi ye asostan meɣ asostanan dak afal tarham awen. Agudendaɣ, norda as atigišam falas erhet nawan eqal ayfan. Tilam asostan ? | K12: [INSTRUCTIONS: ADDRESS QUESTIONS FROM RESPONDENT, IF ANY.] | L12: [OPÉRATEUR/OPÉRATRICE: LE CAS ÉCHÉANT, RÉPONDRE AUX QUESTIONS DE LA PERSONNE INTERROGÉE.] | M12: [mai tambaya: IDAN AKWAI, AN AYI TAMBAYA GA MUTUM DA ZA A SHIRIYA.] | N12: Ha ko: da tou ko yarda, i ga tou a wana ha yan wo sé | O12: [GAƊOOWO GOLLAL NGAL DEBBO NAA GORKO SE HEƁAAKA, NOOTO ƳAMƊE ƳAMAAƊO ON .] | P12: Kasuma/kamu aw kwa Am njade diyonadu korowa jawuwadu tchadunaro waltou | Q12: amachaghal / timachaghalte : astouwirilen adajawab awedan yissistanane wintawaganen yawedan wassihor dastiwigune | S12: false | AE12: no | AG12: 50.82254 | AI12: =IF(AG12<>"",AG12*AH12,"") -> 0 | AJ12: =IF(AND(AG12<>"",AE12="yes"),AG12*AH12,"")
A13: select_one yesno | B13: resp_agree | C13: Are you interested in participating in this survey? | D13: Souhaitez-vous participer à cette enquête? | E13: KU na so ku shiga wannan binciken? | F13: Aran ga ba aran ma furo iri hayan siguiro ra? | G13: Adayidi wonude e ngol humpitigol naa? | H13: Nyiye kulashi korobe adəro rəbtaadə məradənəma wa? | I13: Tardede Assintide? | S13: false | AE13: yes | AG13: 3.5 | AH13: =1 -> 1 | AI13: =IF(AG13<>"",AG13*AH13,"") -> 3.5 | AJ13: =IF(AND(AG13<>"",AE13="yes"),AG13*AH13,"") -> 3.5
A14: geopoint | B14: gps_1 | C14: GPS INSTRUCTION: Take a GPS measurement. | D14: INSTRUCTION : Récupérer les coordonnées GPS. | E14: Umarni: Daukar labarun gidan da na'oura | F14: Koira fo no aran go ga tou ir sé? | G14: TINNDINOORE : ɗum ada ko GPS wurtini. | I14: Tissousinte :ibazadou raquaman in tissidik koul | K14: NOTE: It might take a few minutes for the tablet to register the GPS. Wait for it to load. If it takes longer than 3 minutes, skip to the next question. You can take the GPS reading at the end of the interview. | L14: REMARQUE : L'enregistrement des coordonnées peut prendre quelques temps - il faudra peut-être patienter quelques minutes. Si cela prend plus de 3 minutes, passez à la question suivante. Vous pouvez récupérer les coordonnées GPS à la fin de l'entretien. | M14: JAWABI: Saurar bayanin jiranin GPS za a iya daukar da kwanakin lokacin - za a iya girmama minti biyu. Idan ya dauka minti biyu, tafiya zuwa tambaya ta biyu. Zaka iya samun bayanin GPS bayanin ya gaba da magana. | N14: Labarey: Batama labarey sambu yan wo ga hine ga sambu lokatchi kayna. Aran ga hine suru kayna. Da bissa minti 3, i ma to ha yan fo ga, ir ga yé ga ka labarey din ga, dir bane | O14: PAHME : adol seedaaji no waawi adugo wakkati seɗɗa - haani neɗɗo munya mintaaje seɗɗa. Senii wittake mintaaje 3, haani wittoo e ƴamal yeesowal. Haani adon ko wurtinaa nder GPS se ƴame ɗen ngaynaama | P14: Barka da zuwa! Amsa tawa ayamatu daga samun maganin kayan haƙi kamar dauke da lokaci. Za a iya daukan su bayan minti goma sha uku. Idan aka dauka mafi goma sha uku, duba wuraren sauran tambayan kuma za ka iya samun koordinatun GPS bayan an taimaka. | Q14: Tissousinte : issijil in tissidik ifrag adidkil arate nalwak - ichil adagou awedan tazedarte namazay ghour issistanete assimos ass issistan Di id kal karad minutatane widi adaki awedan sisistan wahadan idi amaran ifrag awedan adibiz raquaman in tissidik ghour agharid in sistanane | S14: false | W14: ${resp_agree} = '1' | AG14: 0 | AH14: 1 | AI14: =IF(AG14<>"",AG14*AH14,"") -> 0
A15: note | B15: Refusal | C15: Thank you for your time, you will be removed from today's survey. | D15: Merci pour votre temps. Vous serez écarté de l'enquête d'aujourd'hui. | E15: Mum gode da lokacin da kuka bamu. ZA'ah cireka daga binciken yau. | F15: Fondo goy nda lokoco kan aran na iri no, iri ga aran ka hayaney siguiro ra hunkuna. | G15: Mi yanti, min nonditan’on {WhenCallBack}. Mi yanti kaden gnan leiin djam | H15: Loktunəm kənjoro nyiro askəra, nya suro kulashi kuye adən tutuluwin. | I15: Nidjake alharadjene, nikaskayine dague issistane ikna yallah achal. | S15: false | W15: ${resp_agree} = '2' | AE15: no | AG15: 0 | AH15: 1 | AI15: =IF(AG15<>"",AG15*AH15,"") -> 0 | AJ15: =IF(AND(AG15<>"",AE15="yes"),AG15*AH15,"")
AI16: =IF(AG16<>"",AG16*AH16,"") | AJ16: =IF(AND(AG16<>"",AE16="yes"),AG16*AH16,"")
A17: begin_group | B17: eligibility | C17: ELIGIBILITY CRITERIA | D17: CRITÈRES D'ÉLIGIBILITÉ | E17: wa'adin zabé | F17: soubane yan Alhalo | G17: LAABI CUƁIRƊI | I17: anamod wan wassitag imidkil | S17: false | W17: ${resp_agree} = '1' | AE17: yes | AI17: =IF(AG17<>"",AG17*AH17,"") | AJ17: =IF(AND(AG17<>"",AE17="yes"),AG17*AH17,"")
AI18: =IF(AG18<>"",AG18*AH18,"") | AJ18: =IF(AND(AG18<>"",AE18="yes"),AG18*AH18,"")
A19: text | B19: resp_firstname | C19: What is your first name? | D19: Quel est votre prénom? | E19: Menene Sunanka ? | F19: Mate no iga aran ce da? | G19: Noy won innde mon? | H19: Abi suwum buroi yo? | I19: Əndek əsim ən-nak ? | K19: [INSTRUCTIONS: RECORD THE RESPONDENT'S FIRST NAME. ENTER 999 FOR REFUSED] | L19: [INSTRUCTIONS : SAISIR LE PRÉNOM DE LA PERSONNE INTÉRROGÉE. SAISIR 999 POUR REFUSÉ.] | M19: [MAI GUDANARWA: SHIGAR DA SUNAN FARKON MAI BADA AMSAR. SHIGAR DA 999 A MADADIN ƘIN AMINCEWA.] | N19: [Hantum ka : wa bora mayo hantoum.wa hantum 999 da bora wandji] | O19: [TINNDINOOJE : WINNDE INNDE NEƊƊO ƳAMAAƊO OON. WINNDEE NDER MASSIN 999 TO SALAKE.] | P19: [ ƘWAREWAƊI : SU BUROI JAWAU MAYE IKK3. IKK3 999 WAA NOMAA.] | Q19: [tissousinte : SAQAYMU ƏSIM ƏN WA ATIWASASTANAN. IGIŠ 999 FAL TUGINT.] | S19: true | AE19: yes | AG19: 10 | AH19: =1 -> 1 | AI19: =IF(AG19<>"",AG19*AH19,"") -> 10 | AJ19: =IF(AND(AG19<>"",AE19="yes"),AG19*AH19,"") -> 10
A20: text | B20: resp_lastname | C20: What is your last name? | D20: Quel est votre nom de famille? | E20: Menene sunanka na ƙarshe? | F20: Ifo ti aran baba mayo? | G20: Noy wani indéé bam’ma / abbaa’ma | H20: Abi suwum darai yo? | I20: Əndek əsim ən alɣayal inak ? | K20: [INSTRUCTIONS: RECORD THE RESPONDENT'S LAST NAME. ENTER 999 FOR REFUSED] | L20: [INSTRUCTIONS : SAISIR LE PRÉNOM DE LA PERSONNE INTÉRROGÉE. SAISIR 999 POUR REFUSÉ.] | M20: Umarni: sunan may bada amsawar. rubuta 999 DON HANA.] | N20: [Hantum ka : wa bora mayo hantoum.wa hantum 999 da bora wandji.] | O20: [TINNDINOOJE : WINNDE INNDE NEƊƊO ƳAMAAƊO OON. WINNDEE NDER MASSIN 999 TO SALAKE.] | P20: [ ƘWAREWAƊI : SU DARAI JAWAU MAYE IKK3. IKK3 999 WAA NOMAA.] | Q20: [tissousinte : SAQAYMU ƏSIM ƏN WA ATIWASASTANAN. IGIŠ 999 FAL TUGINT.] | S20: true | AE20: yes | AG20: 10 | AH20: =1 -> 1 | AI20: =IF(AG20<>"",AG20*AH20,"") -> 10 | AJ20: =IF(AND(AG20<>"",AE20="yes"),AG20*AH20,"") -> 10
AH21: =1 -> 1 | AI21: =IF(AG21<>"",AG21*AH21,"") | AJ21: =IF(AND(AG21<>"",AE21="yes"),AG21*AH21,"")
A22: integer | B22: resp_age | C22: How old are you? | D22: Quel âge avez-vous (en années)? | E22: Shekarunka nawa? | F22: Aran guiri marge? | G22: Duuɓi mon foti? | H22: Saan3m ndawo? | I22: Maniket elan nak ? | K22: [INSTRUCTIONS: RECORD AGE IN NUMBER OF YEARS. ROUND UP TO NEAREST WHOLE NUMBER. IF THE RESPONDENT GIVES BIRTH YEAR, REPEAT THE QUESTION. ENTER 888 FOR DON'T KNOW.] | L22: [INSTRUCTIONS : SAISIR L'ÂGE EN ANNÉES. ARRONDIR AU NOMBRE ENTIER LE PLUS PROCHE. SI LE RÉPONDANT DONNE SON ANNÉE DE NAISSANCE, RÉPÉTER LA QUESTION. SAISIR 888 POUR JE NE SAIS PAS.] | S22: true | U22: (. >= 18 and . <= 100) or . = 888 | AE22: yes | AG22: 13.753073 | AH22: =1 -> 1 | AI22: =IF(AG22<>"",AG22*AH22,"") -> 13.753073 | AJ22: =IF(AND(AG22<>"",AE22="yes"),AG22*AH22,"") -> 13.753073
AH23: =1 -> 1 | AI23: =IF(AG23<>"",AG23*AH23,"") | AJ23: =IF(AND(AG23<>"",AE23="yes"),AG23*AH23,"")
A24: select_one gender | B24: resp_gender | C24: What is the gender of the respondent? | D24: Quel est le sexe du répondant? | E24: Menene jinsin mai amsawar? | F24: Aran wanne tu ka albor no wala weybor? | G24: A débbo naa a gorko? | H24: Jawau mad3 kamu la kongaa? | I24: Indek awa eqal awadim wa itawasastanan? | K24: [INSTRUCTIONS: DO NOT ASK THIS QUESTION OUT LOUD. SELECT THE GENDER OF THE RESPONDENT.] | L24: [OPÉRATEUR/OPÉRATRICE: NE PAS POSER CETTE QUESTION À VOIX HAUTE. INDIQUER LE SEXE DU RÉPONDANT.] | M24: [MAI GUDANARWA: SHIGAR DA SUNAN ƘARSHEN MAI BADA AMSAR. SHIGAR DA 999 A MADADIN ƘIN AMINCEWA.] | N24: [HANTUM ka :wa guirey hantum ,WA GUIREY HANTUM TAK da tu ka na inga heyyan guiro no aran se.WA YEGA HANYANWO KI.WA HANTUM 00 JAN GA BEY YAN SE.] | O24: [GOLLOOWO: TAA ƳAMEE NANNDI ƊE ƳAMƊE. HETTINDE HAALA JOOMUM DE MBINNDON]. | P24: [KUNDOMA: WOND3 KORO ADAA DIMI. K3RINNE DAI JIRE MADAA GONE | Q24: [tissousinte : WAR TIGED ASOSTAN WEN. SIDIRGIN YE TAMASLAQ IZAR IKIS EHAN WA AHUSKEN]. | S24: true | AE24: yes | AG24: 2.1173561 | AH24: =1 -> 1 | AI24: =IF(AG24<>"",AG24*AH24,"") -> 2.1173561 | AJ24: =IF(AND(AG24<>"",AE24="yes"),AG24*AH24,"") -> 2.1173561
AH25: =1 -> 1 | AI25: =IF(AG25<>"",AG25*AH25,"") | AJ25: =IF(AND(AG25<>"",AE25="yes"),AG25*AH25,"")
A26: text | B26: phone_number_personal | C26: What is your phone number? | D26: Quel est votre numéro de téléphone ? | E26: Wacce ce ita lambar wayar?? | F26: Ifo ti aran telfon lamba? | G26: Bataanan limoro mada? | H26: Abi lamba wayamme? | I26: Indek numoro nak wa telefone ? | S26: true | T26: numbers | U26: regex(.,’^[0-9]{11}$’) | V26: Please enter the telephone number in the correct format, e.g. nan | AE26: yes - panel | AG26: 10 | AH26: =1 -> 1 | AI26: =IF(AG26<>"",AG26*AH26,"") -> 10 | AJ26: =IF(AND(AG26<>"",AE26="yes"),AG26*AH26,"")
A27: select_one contact_info | B27: contact_2 | C27: Can you give me an additional phone number belonging to you, another household member or a close relation living outside of the household at which you can be reached? | D27: Pouvez-vous me donner un numéro de téléphone supplémentaire, le vôtre, celui d'un autre membre du ménage ou d’un proche vivant en dehors du ménage, auquel vous pouvez être joint? | E27: Zaku iya ba mu wata lambar ku ko ta wani mutunan tchikin guida wanda ku ke da halaka da shi | F27: Da aran gonda lamba hinkanté aran ma ir no, da a siino aran ma ir no ara boro mano wané kan bon ir ga hine ga dou aran. | G27: Haak’kan limoro gnon ko mi wawta mondima ; ba limoro korédjima non ; na limoro hii’go ma non ? | H27: Lamba salulaye kanum aw kam fadoye kamaskinum aw korinube fondikinna! | I27: tifragam didoutakfim raquam nawedan iyan chilan nichikagh nawan madey inmehiz nawan iyan dirwirtanamaham aghiwan assimikan ataghrou awedan | S27: true | AE27: yes - panel | AG27: 10 | AH27: =1 -> 1 | AI27: =IF(AG27<>"",AG27*AH27,"") -> 10 | AJ27: =IF(AND(AG27<>"",AE27="yes"),AG27*AH27,"")
A28: text | B28: phone_number_2 | C28: What is the additional phone number? | D28: Quel est cet autre numéro de téléphone ? | E28: Wacce ce ita lambar wayar?? | F28: Ifo ti lamba wodine? | G28: Won’kan limoro guel guidaa? | H28: Abi lamba wayaye gade madoo? | I28: Indek numoro wa telefone iyan? | S28: true | T28: numbers | U28: regex(.,’^[0-9]{11}$’) | V28: Please enter the telephone number in the correct format, e.g. nan | W28: ${contact_2} = '1' or ${contact_2} = '2' or ${contact_2} = '3' | AE28: yes - panel | AG28: 10 | AH28: =1 -> 1 | AI28: =IF(AG28<>"",AG28*AH28,"") -> 10 | AJ28: =IF(AND(AG28<>"",AE28="yes"),AG28*AH28,"")
A29: text | B29: contact_2_name | C29: What is the name of the contact? | D29: Quel est le nom du contact associé à ce numéro de téléphone ? | E29: Menene sunan mai lambar?? | F29: Mayi fo no go hantum lamba dine bon? | G29: Won’kan indé djom limoro on? | H29: Abi su K3manz3ye? | S29: true | W29: ${contact_2} = '2' or ${contact_2} = '3' | AE29: yes - panel | AG29: 10 | AH29: =1 -> 1 | AI29: =IF(AG29<>"",AG29*AH29,"") -> 10 | AJ29: =IF(AND(AG29<>"",AE29="yes"),AG29*AH29,"")
A30: select_one contact_info | B30: contact_3 | C30: Can you give me an additional phone number belonging to you, another household member or a close relation living outside of the household at which you can be reached? | D30: Pouvez-vous me donner un numéro de téléphone supplémentaire, le vôtre, celui d'un autre membre du ménage ou d’un proche vivant en dehors du ménage, auquel vous pouvez être joint? | E30: Zaku iya ba mu wata lambar ku ko ta wani mutunan tchikin guida wanda ku ke da halaka da shi | F30: Da aran gonda lamba hinkanté aran ma ir no, da a siino aran ma ir no ara boro mano wané kan bon ir ga hine ga dou aran. | G30: Iɗon mbaawi hokkugoyam lammba celalol gooɗom, ɗum mooɗon, ɗum goɗɗo gonuɗo nder hoggo ngon naa banndiraawo mooɗom gom laatiiɗo wana nder hoggo mooɗon wuuri, noddeteeɗo heɓa'on ? | H30: Lamba salulaye kanum aw kam fadoye kamaskinum aw korinube fondikinna! | I30: tifragam didoutakfim raquam nawedan iyan chilan nichikagh nawan madey inmehiz nawan iyan dirwirtanamaham aghiwan assimikan ataghrou awedan | S30: true | W30: ${contact_2} = '1' or ${contact_2} = '2' or ${contact_2} = '3' | AE30: yes - panel | AG30: 10 | AH30: =1 -> 1 | AI30: =IF(AG30<>"",AG30*AH30,"") -> 10 | AJ30: =IF(AND(AG30<>"",AE30="yes"),AG30*AH30,"")
A31: text | B31: phone_number_3 | C31: What is the additional phone number? | D31: Quel est cet autre numéro de téléphone ? | E31: Wacce ce ita lambar wayar?? | F31: Ifo ti lamba wodine? | G31: Ngale won limoro noddirga ɓeydoowa? | H31: Abi lamba wayaye gade madoo? | I31: Indek numoro wa telefone iyan? | S31: true | T31: numbers | U31: regex(.,’^[0-9]{11}$’) | V31: Please enter the telephone number in the correct format, e.g. nan | W31: ${contact_3} = '1' or ${contact_3} = '2' or ${contact_3} = '3' | AE31: yes - panel | AG31: 10 | AH31: =1 -> 1 | AI31: =IF(AG31<>"",AG31*AH31,"") -> 10 | AJ31: =IF(AND(AG31<>"",AE31="yes"),AG31*AH31,"")
A32: text | B32: contact_3_name | C32: What is the name of the contact? | D32: Quel est le nom du contact associé à ce numéro de téléphone ? | E32: Menene sunan mai lambar?? | F32: Mayi fo no go hantum lamba dine bon? | G32: Won’kan indé djom limoro on? | H32: Abi su K3manz3ye? | I32: Indek əsim ən numoro? | S32: true | W32: ${contact_3} = '2' or ${contact_3} = '3' | AE32: yes - panel | AG32: 10 | AH32: =1 -> 1 | AI32: =IF(AG32<>"",AG32*AH32,"") -> 10 | AJ32: =IF(AND(AG32<>"",AE32="yes"),AG32*AH32,"")
AH33: =1 -> 1 | AI33: =IF(AG33<>"",AG33*AH33,"") | AJ33: =IF(AND(AG33<>"",AE33="yes"),AG33*AH33,"")
A34: select_one admin1 | B34: adm1_pcode | C34: Currently, in which Region does your household reside? | D34: Actuellement, dans quel Region votre ménage vit-il ? | E34: A halin yanzu, a wanne Yanki gidanka yake? | F34: Sohon ra,koira fo ra no aran almiyalo go? | G34: Noy hourou mo’gonda an heii korédjima hiité? | H34: K3rmaroo, lardilan fatomanumd3 kara? | I34: Amaradaɣ, indek akal wadaɣ izaɣa alɣayal inak ? | K34: [HINT: HOUSEHOLD CONSISTS OF ALL MEMBERS LIVING TOGETHER, SHARING RESOURCES & EATING FROM THE SAME POT.] | L34: [NOTE : LE MÉNAGE EST COMPOSÉ DE TOUTES LES PERSONNES VIVANT ENSEMBLE, PARTAGEANT LEURS RESSOURCES ET MANGEANT DANS UNE MARMITE COMMUNE.] | M34: [NUSARAWA: GIDA YA ƘUNSHI DUKKAN WAƊANDA SUKE ZAUNE A WURI GUDA, SUKE RARRABA ABABEN TA'AMMULI & SUKE KUMA CI A TUKUNYA ƊAYA.] | N34: Cabe yan :almiyalo ti borrey kulu kan go nangu fo,iga koy keki ga dan tchar ra ga nwaa nongu fo] | O34: [TINNDINOOJE : JAWAABU GOOTO]. [MAANAA: ƁAADE NDEN FUH HAWTU JAWDI E ƳAAMEE LEY NOKKU GOOTO]. | P34: [LAI: FATOMADONI SAIMA AM SAMMA FATOFALLIN DASAUNAMAD3, KUMBUWA RAZAUWA SAMMA ROKKO FAIDATEN.] | Q34: [ASIKIN : ALƔAYAL EQAL AYERTAYAN ƏS ADINAT WI IDARNEN DAK, TUZANEN ANAFATAN ƏD TATAN DAƔ AKOS IYAN]. | S34: true | T34: autocomplete | AE34: yes | AG34: 8.8 | AH34: =1 -> 1 | AI34: =IF(AG34<>"",AG34*AH34,"") -> 8.8 | AJ34: =IF(AND(AG34<>"",AE34="yes"),AG34*AH34,"") -> 8.8
A35: calculate | B35: adm1_name | Z35: jr:choice-name(${adm1_pcode},'${adm1_pcode}') | AE35: yes | AH35: =1 -> 1 | AI35: =IF(AG35<>"",AG35*AH35,"") | AJ35: =IF(AND(AG35<>"",AE35="yes"),AG35*AH35,"")
A36: select_one admin2 | B36: adm2_pcode | C36: Currently, in which Department does your household reside? | D36: Actuellement, dans quel Department votre ménage vit-il ? | E36: A halin yanzu, a wanne Sashi gidanka yake? | F36: Sohon, Iri mee ciino bon, dapatema fo ra no aran almiyalo goga bafuney? | G36: Der département oy hourou mon wonnii ? | H36: K3rmaroo, nashailan fatomad3 kara? | I36: Amaradaɣ, indek akal wadaɣ izaɣ alɣayal inak ? | S36: true | T36: autocomplete | X36: my_filter_admin=${adm1_pcode} | AE36: yes | AG36: 10.4 | AH36: =1 -> 1 | AI36: =IF(AG36<>"",AG36*AH36,"") -> 10.4 | AJ36: =IF(AND(AG36<>"",AE36="yes"),AG36*AH36,"") -> 10.4
A37: calculate | B37: adm2_name | Z37: jr:choice-name(${adm2_pcode},'${adm2_pcode}') | AE37: yes | AH37: =1 -> 1 | AI37: =IF(AG37<>"",AG37*AH37,"") | AJ37: =IF(AND(AG37<>"",AE37="yes"),AG37*AH37,"")
AH38: =1 -> 1 | AI38: =IF(AG38<>"",AG38*AH38,"") | AJ38: =IF(AND(AG38<>"",AE38="yes"),AG38*AH38,"")
A39: select_one agricactivity | B39: hh_agricactivity | C39: Has anybody in your household produced crops or livestock for household consumption or for sale in the past 12 months, including household members currently away for transhumance? | D39: Est-ce que quelqu'un dans votre ménage a produit des cultures ou du bétail pour la consommation du ménage ou pour la vente au cours des 12 derniers mois, y compris des membres du ménage actuellement partis pour la transhumance ? | E39: Shin akwai wani a cikin gidan ku da ya samu anfanin gona ko dabobi don anfanin gida ko sayarwa a cikin watani goma sha biyu da suka shige,game da yan gidan a halin yanzu ba su huce daji ba ? | F39: Borfo aran wane almiyalo ra fari wala na almane kuruu windo nwaro se wala nerandi se handu wey kindi hinka kan bissa ra,I ra hada weykanyan go sadji sohon me kino bon? | G39: Der korédjima no wo’di mo réé’mi na mo wadii bissadjé ko naafii baadéé mon lein’bii sam’po hei di’di bintiidé ; | H39: Fatomaima nandon kulo aw dabba doni sha faidaturo aw lodoro g3naz3na suro k3ntawwa 12 koz3na ad3lan bawa, har fatomadoni tsinyero lezanadin kunten? | I39: Yala awadim daɣ alɣayal nawan igyak əsigyak meɣ arizeg fal ašaško ən alɣayal meɣ fal ašinš daɣ 12 uran wihin okaynen, daɣ ahan adinat nalɣayal amaradaɣ daɣ asikil ? | K39: [INSTRUCTIONS: THIS IS THE MAIN SCREENING QUESTION.] [HINT FOR PROBING: Do you cultivate any plants to sale or consume? Do you raise any animals with the intent of selling or consuming them or their products like meat, milk, wool or leather? Is one of your household member currently away with cattle or other animals for transhumance?] | L39: [INSTRUCTIONS : IL S'AGIT DE LA PRINCIPALE QUESTION DE SÉLECTION.] [CONSEILS POUR PRÉCISER : Cultivez-vous des végétaux afin de les vendre ou de les consommer ? Élevez-vous des animaux afin de les vendre ou de les consommer, y compris les produits issus de l'élevage, comme la viande, le lait, la laine ou le cuir ? L'un des membres de votre ménage est-il actuellement parti avec du bétail pour la transhumance ?] | M39: [ma aikaci/ ma aikacia :Tambaya zabe ] [shawarwari don bayanawa: kuna shuka dian itace ne domin sayarwa ko kuma don ci Kuna kiwon bisashe ne domin sayarwa ko kuma don anfani da su,hata da kayayakin da suka shafi abin da ya fito daga kiwo kamar nama,madara,ulu ko kuma fata ;daya daga cikin en gidan ku sun tafi da dabobi daji ne a halin yanzu don kiwo?] | N39: [Hantum ka : Hayyan bero kan iri ga te aran se wane bon dey no.] [ALAMA : Aran ga fari no nerandi wal nwari se ? Aran ga almane kuruu nerandi wala nwari se, ira hada heykulu kan ga funu almane ga, danga hame,waa, couro ? Sohon me kino bon aran wane koireyze fo koy sadji no da almaney ?] | O39: [TINNDINOOJE : JAWAABU GOOTO. WO ƳAMNGAL GOOTAL CUƁEETE. ƳAMAAƊO ON NA HAANI JAABO. TA NJEGGITON ƳAMUDE E EGGOL DU.] [MAANAA : ƁAADE NDEN FUH HAWTU JAWDI WOOƊI E LE'AL GOOTAL ƁE ƝAAMDATA]. Rèmal mon gan tchan’nol non na gan gna’mal no ? Dourwol bissadjé ma gan tchan’nol non na gan gna’mal no ? | P39: [LAI: FATOMADONI SAIMA AM SAMMA FATOFALLIN DASAUNAMAD3, KUMBUWA RAZAUWA SAMMA ROKKO FAIDATEN.] | Q39: [EMASESTƏN : ALƏƔI IYANDAƔ. AMOS ASOSTAN WA ATIWASANAN DAƔ UKIS. AWADIM WA ATIWASASTANAN ANIHAGA ADISUDMIR. WAHIN TITUWAM ASISTINAM ƏN ASOSTAN FAL MISUKAL]. [ASIKIN : ALƔAYAL EQAL AYERTAYAN ƏN ADINAT WI IDARNEN DAK, TUZANEN TANFOTEN ƏD TATANEN DAƔ AKOS IYANDAƔ]. | S39: true | AE39: yes | AG39: 31.372377 | AH39: =1 -> 1 | AI39: =IF(AG39<>"",AG39*AH39,"") -> 31.372377 | AJ39: =IF(AND(AG39<>"",AE39="yes"),AG39*AH39,"") -> 31.372377
A40: select_one yes_no | B40: hh_fish | C40: Has anybody in your household been engaged in aquatic production [fish catch or aquaculture farming] for household consumption or for sales in the past 12 months? | D40: Quelqu'un dans votre ménage a-t-il été impliqué dans la production aquatique [prise de poisson ou aquaculture] pour la consommation du ménage ou pour la vente au cours des 12 derniers mois? | E40: Wani ne a cikin garinka ya take da alƙawarin baki [bakin samaki ko ayyuka] don tunaniya ko sahuwa tun 12 kafin shekarun baya? | F40: Aran almiyalo ra boro gono kan ga hamissa di wal kan ga hamissa biri gwayan wala néré yan sé djiro kan bissa ra? | G40: Nder hoggo mooɗon goɗɗo no woowi gollideego nder keɓal barke nder ndiyam [nanngol liƴƴi naa n ou fuu gollal keɓal barke nder ndiyam] ngam nyaamndu hoggo naa connol nder ɗii lebbi 12 bittiiɗi ? | H40: Churo koro ay ti churo Kinda 12 Kowouna allan kamdolaa buni tayi kumbu aw lade buni tchiran kassu nin tchilado yuworo gaana mbeyiya | I40: kalatimal awedan daghewan nawan askala igaz ichighil wanabaz in moudaran wine naman chila in kifitan madey anabal waygan daghamass naman fil agana wadikalan tetaye nassan madey inazanassan ghour marawadan dichine wintilkamate | K40: [HINT FOR PROBING: It should not include sports fishing. It should be about production of aquatic products [fish catch or aquaculture farming] for household consumption or sales.] | L40: [CONSEIL LORS DU SONDAGE : cette question et réponse ne devraient pas inclure la pêche sportive. Il s'agit plutôt de la production de produits aquatiques [prise de poisson ou aquaculture] pour la consommation ou la vente des ménages.] | M40: [TAMBAYAR WADANDAYE: wanga tambayoyin ba su chahi ma su zuwa kama kifi dan son ray ba, an'ma sun chahi ma su sana'ar kama kifi [bakin samaki ko ayyuka] don tunkarar ko sahu ko sahiyar saƙo].] | N40: [Konkonsa yamar yan'wo : hayan'wo da tou yan 'wo fataoutchi darbey yan na ga goune, manti] | O40: POOƊOL HAKKILO WAKKATI ETOL PUƊƊIRGOL : ƴamal ngal e nootal ngal haana njahda liƴƴaaki fijooɓe. No keɓal barke faro fuu ko tawaa nder ndiyeele [nanngol liƴƴi naa fuu gollal keɓal barke nder ndiyam] ngam nyaamndu naa connol hoggooji/gure] | P40: (Haware kala kan kuladachidi ma'ri: Jande koro koro atti ama buniwi tchare kubu nanga yeh rounjou, ama buni tchariri galanga nagoro koro koro a ti kan za nini) | Q40: inissikha ghour imidkil : issistan widi daljawab nete wirtaniha ichighil wan Aman . wirtaniha har arate wadikalan abaz imoudaran wine aman chilanabaz in kifitan madey anabal waygan daghamass naman ikalan arate izamatchine madey dinzanzine | S40: true | AE40: no | AG40: 17 | AH40: =1 -> 1 | AI40: =IF(AG40<>"",AG40*AH40,"") -> 17
AH41: =1 -> 1 | AI41: =IF(AG41<>"",AG41*AH41,"") | AJ41: =IF(AND(AG41<>"",AE41="yes"),AG41*AH41,"")
...

Sheet choices
A1: list_name | B1: name | C1: label::English (en) | D1: label::French (fr) | E1: label::Haoussa (ha) | F1: label::Djerma (dj) | G1: label::Peulh (pe) | H1: label::Kanuri (kr) | I1: label::Tamachek (ta) | J1: my_filter_admin
A2: enumteam | B2: 1 | C2: Enumerator team 1 | D2: Équipe d'enquêteurs 1 | E2: Équipe d'enquêteurs 1 | F2: Équipe d'enquêteurs 1 | G2: Équipe d'enquêteurs 1 | H2: Équipe d'enquêteurs 1 | I2: Équipe d'enquêteurs 1
A3: enumteam | B3: 2 | C3: Enumerator team 2 | D3: Équipe d'enquêteurs 2 | E3: Équipe d'enquêteurs 2 | F3: Équipe d'enquêteurs 2 | G3: Équipe d'enquêteurs 2 | H3: Équipe d'enquêteurs 2 | I3: Équipe d'enquêteurs 2
A4: enumteam | B4: 3 | C4: Enumerator team 3 | D4: Équipe d'enquêteurs 3 | E4: Équipe d'enquêteurs 3 | F4: Équipe d'enquêteurs 3 | G4: Équipe d'enquêteurs 3 | H4: Équipe d'enquêteurs 3 | I4: Équipe d'enquêteurs 3
A5: enumteam | B5: 4 | C5: Enumerator team 4 | D5: Équipe d'enquêteurs 4 | E5: Équipe d'enquêteurs 4 | F5: Équipe d'enquêteurs 4 | G5: Équipe d'enquêteurs 4 | H5: Équipe d'enquêteurs 4 | I5: Équipe d'enquêteurs 4
A7: enumerator | B7: NER1 | C7: ABDOULAYE WORGO Salissou | D7: ABDOULAYE WORGO Salissou | E7: ABDOULAYE WORGO Salissou | F7: ABDOULAYE WORGO Salissou | G7: ABDOULAYE WORGO Salissou | H7: ABDOULAYE WORGO Salissou | I7: ABDOULAYE WORGO Salissou
A8: enumerator | B8: NER2 | C8: AMADOU GUIMBARI Rachidou | D8: AMADOU GUIMBARI Rachidou | E8: AMADOU GUIMBARI Rachidou | F8: AMADOU GUIMBARI Rachidou | G8: AMADOU GUIMBARI Rachidou | H8: AMADOU GUIMBARI Rachidou | I8: AMADOU GUIMBARI Rachidou
A9: enumerator | B9: NER3 | C9: ADAMOU TASSAOU Djamilatou | D9: ADAMOU TASSAOU Djamilatou | E9: ADAMOU TASSAOU Djamilatou | F9: ADAMOU TASSAOU Djamilatou | G9: ADAMOU TASSAOU Djamilatou | H9: ADAMOU TASSAOU Djamilatou | I9: ADAMOU TASSAOU Djamilatou
A10: enumerator | B10: NER4 | C10: DJIBO HAMIDOU Nafissatou | D10: DJIBO HAMIDOU Nafissatou | E10: DJIBO HAMIDOU Nafissatou | F10: DJIBO HAMIDOU Nafissatou | G10: DJIBO HAMIDOU Nafissatou | H10: DJIBO HAMIDOU Nafissatou | I10: DJIBO HAMIDOU Nafissatou
A11: enumerator | B11: NER5 | C11: HAMED MOUSSA MANTALA Ahmoudou | D11: HAMED MOUSSA MANTALA Ahmoudou | E11: HAMED MOUSSA MANTALA Ahmoudou | F11: HAMED MOUSSA MANTALA Ahmoudou | G11: HAMED MOUSSA MANTALA Ahmoudou | H11: HAMED MOUSSA MANTALA Ahmoudou | I11: HAMED MOUSSA MANTALA Ahmoudou
A12: enumerator | B12: NER6 | C12: IBRAHIM MALAM HAROUNA Mabrouka | D12: IBRAHIM MALAM HAROUNA Mabrouka | E12: IBRAHIM MALAM HAROUNA Mabrouka | F12: IBRAHIM MALAM HAROUNA Mabrouka | G12: IBRAHIM MALAM HAROUNA Mabrouka | H12: IBRAHIM MALAM HAROUNA Mabrouka | I12: IBRAHIM MALAM HAROUNA Mabrouka
A13: enumerator | B13: NER7 | C13: INOUSSA GALADIMA Lawaye | D13: INOUSSA GALADIMA Lawaye | E13: INOUSSA GALADIMA Lawaye | F13: INOUSSA GALADIMA Lawaye | G13: INOUSSA GALADIMA Lawaye | H13: INOUSSA GALADIMA Lawaye | I13: INOUSSA GALADIMA Lawaye
A14: enumerator | B14: NER8 | C14: KIARI Attouman | D14: KIARI Attouman | E14: KIARI Attouman | F14: KIARI Attouman | G14: KIARI Attouman | H14: KIARI Attouman | I14: KIARI Attouman
A15: enumerator | B15: NER9 | C15: MAIMOUNA MAIFADA | D15: MAIMOUNA MAIFADA | E15: MAIMOUNA MAIFADA | F15: MAIMOUNA MAIFADA | G15: MAIMOUNA MAIFADA | H15: MAIMOUNA MAIFADA | I15: MAIMOUNA MAIFADA
A16: enumerator | B16: NER10 | C16: MOHAMAR YOUSSOUFOU MAIGA Bintou | D16: MOHAMAR YOUSSOUFOU MAIGA Bintou | E16: MOHAMAR YOUSSOUFOU MAIGA Bintou | F16: MOHAMAR YOUSSOUFOU MAIGA Bintou | G16: MOHAMAR YOUSSOUFOU MAIGA Bintou | H16: MOHAMAR YOUSSOUFOU MAIGA Bintou | I16: MOHAMAR YOUSSOUFOU MAIGA Bintou
A17: enumerator | B17: NER11 | C17: NOUHOU Hassane | D17: NOUHOU Hassane | E17: NOUHOU Hassane | F17: NOUHOU Hassane | G17: NOUHOU Hassane | H17: NOUHOU Hassane | I17: NOUHOU Hassane
A18: enumerator | B18: NER12 | C18: SALHA MAHAMADOU Djamila | D18: SALHA MAHAMADOU Djamila | E18: SALHA MAHAMADOU Djamila | F18: SALHA MAHAMADOU Djamila | G18: SALHA MAHAMADOU Djamila | H18: SALHA MAHAMADOU Djamila | I18: SALHA MAHAMADOU Djamila
... A22: enumerator | B22: NER16 | C22: SOUMANA SALEY Moussa | D22: SOUMANA SALEY Moussa | E22: SOUMANA SALEY Moussa | F22: SOUMANA SALEY Moussa | G22: SOUMANA SALEY Moussa | H22: SOUMANA SALEY Moussa | I22: SOUMANA SALEY Moussa
A24: yes_no | B24: 1 | C24: Yes | D24: Oui | E24: EH | F24: AHO | G24: Ayyo | H24: Aa | I24: Iyo
A25: yes_no | B25: 2 | C25: No | D25: Non | E25: Ah'Ah | F25: Ah ah | G25: AA’A | H25: A'ah | I25: Baybo
A26: yes_no | B26: 3 | C26: DON'T KNOW | D26: NE SAIT PAS | E26: BAN SANI BA | F26: djan ga beyyan | G26: ANNDA | H26: NOZA NYI | I26: WARISENAƔ
A27: yes_no | B27: 4 | C27: REFUSED | D27: REFUSÉ | E27: ƘIN amsawa | F27: Wanjii ga tuyyan | G27: SALAADE | H27: WAANO | I27: UGAY
A29: continue | B29: continue | C29: continue | D29: continuez
A31: yesno | B31: 1 | C31: Yes | D31: Oui | E31: EH | F31: AHO | G31: Ayyo | H31: Aa | I31: Iyo
A32: yesno | B32: 2 | C32: No | D32: Non | E32: Ah'Ah | F32: Ah ah | G32: AA’A | H32: A'ah | I32: Baybo
A34: language | B34: en | C34: English | D34: English | E34: English | F34: English | G34: English | H34: English | I34: English
A35: language | B35: fr | C35: French | D35: Français | E35: Français | F35: Français | G35: Français | H35: Français | I35: Français
A36: language | B36: haoussa | C36: Haoussa | D36: Haoussa | E36: Haoussa | F36: Haoussa | G36: Haoussa | H36: Haoussa | I36: Haoussa
A37: language | B37: zerma | C37: Zerma | D37: Zerma | E37: Zerma | F37: Zerma | G37: Zerma | H37: Zerma | I37: Zerma
A38: language | B38: kanuri | C38: Kanuri | D38: Kanuri | E38: Kanuri | F38: Kanuri | G38: Kanuri | H38: Kanuri | I38: Kanuri
A39: language | B39: tamachek | C39: Tamachek | D39: Tamachek | E39: Tamachek | F39: Tamachek | G39: Tamachek | H39: Tamachek | I39: Tamachek
A40: language | B40: peulh | C40: Peulh | D40: Peulh | E40: Peulh | F40: Peulh | G40: Peulh | H40: Peulh | I40: Peulh
A41: language | B41: autre | C41: Autre | D41: Autre | E41: Autre | F41: Autre | G41: Autre | H41: Autre | I41: Autre
A43: gender | B43: 1 | C43: Male | D43: Homme | E43: Namiji | F43: Alboro | G43: Gorko | H43: Kongaa | I43: Ahalis
A44: gender | B44: 2 | C44: Female | D44: Femme | E44: Mace | F44: Wayboro | G44: Debbo | H44: Kamu | I44: Tamaƭ
A45: gender | B45: 3 | C45: DON'T KNOW | D45: NE SAIT PAS | E45: BAN SANI BA | F45: djan ga beyyan | G45: ANNDA | H45: NOZA NYI | I45: WARISENAƔ
A46: gender | B46: 4 | C46: REFUSED | D46: REFUSÉ | E46: ƘIN amsawa | F46: Wanjii ga tuyyan | G46: SALAADE | H46: WAANO | I46: UGAY
A48: contact_info | B48: 1 | C48: YES - mine | D48: Oui - le mien | E48: EH - tawa | F48: AHO - Ay wane no | G48: Ayyo- guel’am | H48: ADAI-kakke | I48: YO -inaw.
A49: contact_info | B49: 2 | C49: YES - other household member | D49: Oui - un autre membre du ménage | E49: EH - wani mutum a iyale | F49: Aho-iri kwara borfo | G49: Ayyo-guel’korédji am | H49: ADAI- Am fannimiye gadeso | I49: IYO – Adinat iyad ən amazaɣ
A50: contact_info | B50: 3 | C50: YES - friend or relative [non household member] | D50: Oui - celui d'un ami ou d'un parent [non membre du ménage] | E50: EH-Wani aboki ko dan uwa [da bai cikin iyalin ku] | F50: aho -ay tshoro fo wala gneyze [kan manti iri koireyze] | G50: Ayyo-guel’hii’go am | H50: ADAI- bawo-yalla fatoye | I50: IYO – alɣayalan wi winan adoban
...

Sheet Feuil1
A1: list_name | B1: name | C1: label:: | D1: my_filter_admin
A2: admin2 | B2: NE001001 | C2: Aderbissinat | D2: NE001
A3: admin2 | B3: NE001002 | C3: Arlit | D3: NE001
A4: admin2 | B4: NE001003 | C4: Bilma | D4: NE001
A5: admin2 | B5: NE001004 | C5: Iferouane | D5: NE001
A6: admin2 | B6: NE001005 | C6: In-Gall | D6: NE001
A7: admin2 | B7: NE001006 | C7: Tchirozérine | D7: NE001
A8: admin2 | B8: NE002001 | C8: Bosso | D8: NE002
A9: admin2 | B9: NE002002 | C9: Diffa | D9: NE002
A10: admin2 | B10: NE002003 | C10: Goudoumaria | D10: NE002
A11: admin2 | B11: NE002004 | C11: Maïné Soroa | D11: NE002
A12: admin2 | B12: NE002005 | C12: Ngourti | D12: NE002
... A64: admin2 | B64: NE007010 | C64: Tasker | D64: NE007

Sheet settings
A1: version | B1: default_language | C1: allow_choice_duplicates | D1: style
A2: vM6cWXyHNhR3djPbARkHWi | B2: French (fr) | C2: yes | D2: theme-grid no-text-transform

Sheet Crop list
C3: Select top 10 crops | D3: Dataset code | E3: Label (EN) | F3: Label (FR)
C4: x | D4: 1.1 | E4: Rice | F4: Riz
D5: 1.2 | E5: Wheat | F5: Blé
D6: 1.3 | E6: Millet | F6: Mil
D7: 1.4 | E7: Sorghum | F7: Sorgho
C8: x | D8: 1.5 | E8: Maize | F8: Maïs
D9: 1.6 | E9: Barley | F9: Orge
D10: 1.99 | E10: Other Cereal | F10: Autres céréales
C11: x | D11: 2.1 | E11: Cassava | F11: Manioc
C12: x | D12: 2.2 | E12: Potatoe | F12: Pommes de terre
D13: 2.3 | E13: Sweet Potatoes | F13: Patates douces
D14: 2.4 | E14: Yams | F14: Ignames
C15: x | D15: 2.5 | E15: Carrots | F15: Carottes
D16: 2.6 | E16: Cocoyam | F16: Chou caraïbe
D17: 2.99 | E17: Other tubers | F17: Autres tubercules
D18: 3.1 | E18: Beans | F18: Haricots
D19: 3.2 | E19: Lentils | F19: Lentilles
D20: 3.3 | E20: Peas | F20: Pois
D21: 3.4 | E21: Soybeans | F21: Soja
D22: 3.5 | E22: Chickpeas | F22: Pois chiches
D23: 3.6 | E23: Fava beans | F23: Fève
D24: 3.7 | E24: Broad beans | F24: Fève large
D25: 3.99 | E25: Other pulses | F25: Autres légumineuses
C26: x | D26: 4.1 | E26: Cabbage | F26: Choux
C27: x | D27: 4.2 | E27: Lettuce | F27: Laitue
D28: 4.3 | E28: Spinach-Amaranth | F28: Epinards-Amaranthe
D29: 4.4 | E29: Cassava leaves | F29: Feuilles de manioc
D30: 4.5 | E30: Potatoe leaves | F30: Feuilles de pomme de terre
C31: x | D31: 4.6 | E31: Moringa | F31: Moringa
D32: 4.7 | E32: Sorrel Hibiscus / Rosselle | F32: Oseille Hibiscus / Rosselle
D33: 4.9 | E33: Green salad herbs (thyme, parsley, mint, rocca, other) | F33: Herbes aromatiques (thym, persil, menthe, rocca, autres)
D34: 4.101 | E34: Cauliflower | F34: Choux-fleur
D35: 4.99 | E35: Other leafy vegetables | F35: Autres légumes à feuilles
C36: x | D36: 5.1 | E36: Tomatoes | F36: Tomates
D37: 5.2 | E37: Cucumber | F37: Concombre
D38: 5.3 | E38: Pumpkin | F38: Citrouille
D39: 5.4 | E39: Eggplant/aubergine | F39: Aubergines/aubergines
D40: 5.5 | E40: Zucchini | F40: Courgettes
D41: 5.6 | E41: Okra | F41: Okra
D42: 5.7 | E42: Bell pepper | F42: Poivron
...

Sheet Additional information
C2: Original | D2: Replacement (FR) | E2: Replacement (EN) | F2: Comment (FR) | G2: Comment (EN) | H2: Exemple (FR) | I2: Example(EN)
B3: FOR CORE QUESTIONS . (Mandatory to fill out) . | C3: phone number | F3: Tapez un numéro de téléphone dans le format typique du pays, par exemple 77******* [veuillez écrire le nombre exact de chiffres qu'il y a dans un numéro de téléphone]. | G3: Type a phone number from your country in typical format, e.g. 77******* [please use exactly the number of characters that are found in a phone number]. | H3: 070****** | I3: 070******
C4: age | D4: 18 | E4: 18 | F4: Âge minimum du répondant (nous recommandons 18 ans) | G4: Minimum age of respondent (recommend 18 years old) | H4: 18 | I4: 18
C5: ADMIN1 | D5: Region | E5: Region | F5: La première subdivision du pays, après le niveau national ; par exemple, région ; province ; gouvernorat ; etc. Un seul mot doit être saisi - Ne pas inclure d'espaces. | G5: The first subdivision of the country, after national level; region; province; governorate; etc. Only one word should be inputted - Do not include spaces. | H5: region | I5: region
C6: ADMIN2 | D6: Department | E6: Department | F6: La deuxième subdivision du pays ; par exemple, district, municipalité, LGA, etc. Un seul mot doit être saisi - Ne pas inclure d'espaces. | G6: The second subdivision of the country; district; municipality; LGA; etc. Only one word should be inputted - Do not include spaces. | H6: district | I6: district
C7: reference year | D7: une année normale | E7: a normal year | F7: Les questions de comparaison auront besoin d'une année de référence. Choisissez si vous voulez utiliser "l'année dernière" ou "une année normale" comme année de référence. Une "année normale" doit correspondre à une année moyenne des 5 dernières années - veillez à former les recenseurs en conséquence. | G7: Comparison questions will need need a reference year. Select whether you want to use "last year" or "a normal year" as a baseline. A "normal year" should refers to an average year from the past 5 years - make sure to train the enumerators accordingly. | H7: une année normale | I7: a normal year
C8: season | D8: saison irrigue' | E8: irrigated season | F8: Nommez la ou les saisons culturales concernée(s) en ANGLAIS s'il y en a plusieurs dans le pays (par exemple, Meher et Belg en Ethiopie, saison des pluies / cultures de décrue / saison sèche irriguée au Sahel). Vous pouvez vous référer à la "dernière saison" ou "saison actuelle". | G8: Name the crop season(s) of interest if there are several cropping seasons in the country (e.g. Meher and Belg in Ethiopia, rainy season / flood-recession cropping / irrigated dry season in the Sahel). You can refer to the “last season” or “ongoing season". | H8: saison des pluies | I8: wet season
C9: season phase | D9: Post-récolte | E9: Recently finished | F9: Indiquez le stade de la saison culturale au moment de la collecte des données. Si la récolte de la saison n'a pas encore eu lieu, la question sur la récolte des cultures (crp_harv_change) inclura le mot "attendue" (là où se trouve #attendue ou rien#). Si la récolte a eu lieu, "attendue" ne sera pas inséré dans la question. | G9: Indicate the phase of the season at the time of data collection. If the harvest from the season has not yet occurred, the question on crop harvest (crp_harv_change) will include the word “expected” (where #expected or nothing# is located). If the harvest has occured, "expected" will not be inserted in the question. | H9: Récolte | I9: Harvesting
C10: local measurement unit | F10: Indiquez l'unité utilisée localement pour mesurer la taille des terrains, autre que les acres, les hectares, les mètres carrés et les pieds carrés. Si aucune autre unité de mesure n'est nécessaire, garder cette cellule vide. | G10: Specify the local measurement unit for land size, other than acres, hectares, square meters and square feet. If no other unit of measurement is needed, keep this cell blank. | H10: Jeribs | I10: Jeribs
C11: local measurement unit conversion | F11: Indiquez la conversion de l'unité de mesure locale en hectares. En d'autres termes, indiquez combien d'unités de mesure locales y a-t-il dans 1 ha. | G11: Include the conversion of the local measurement unit to hectares. In other words, how many local measurement units are in 1 ha. | H11: 0.2 | I11: 0.2
B12: FOR OPTIONAL QUESTIONS . (Fill out if applicable) . | C12: currency | D12: Francs CFA | E12: Francs CFA | F12: Nom de la principale devise utilisée au niveau national; par exemple, USD; Naira; Rial; Pesos; etc. | G12: The name of the main currency used nationally; USD; Naira; Rial; Pesos; etc. | H12: Naira | I12: Naira
C13: MIN AMOUNT | D13: 5 | E13: 5 | F13: Le montant minimum d'une source de revenu doit être fixé à 0 ou à toute valeur en dessous de laquelle il n'est pas possible d'effectuer une transaction. Par exemple, la plus petite pièce/billet d'une devise peut être de 1000, auquel cas vous fixerez le minimum à 1000. Cette saisie doit être effectuée dans la même devise que celle spécifiée ci-dessus. Seuls des chiffres doivent être saisis. | G13: The minimum amount for an income source should be set at 0 or any value below which it is not possible to do a transaction. For example, the smallest coin/banknote in a currency can be 1000, in which case you would set the minimum at 1000. Provide this input in the same currency as specified above. Only digits should be inputted. | H13: 5 | I13: 5
C14: THRESHOLD | D14: 450000 | E14: 450000 | F14: Le salaire seuil doit être calculé pour signaler les valeurs aberrantes (réponses qui semblent suspectes). En utilisant des enquêtes précédentes représentatives de cette population, une bonne estimation est la moyenne plus deux écarts types, ce qui devrait dégager le seuil pour les 3 ou 4% des valeurs de revenu les plus élevées. Cette saisie doit être effectuée dans la même devise que celle spécifiée ci-dessus. Seuls des chiffres doivent être saisis. | G14: The threshold salary should be calculated to flag outliers (responses that look suspiciously high). Using previous representative surveys for this population, a good estimate is the average plus three (3) standard deviations, which should give the threshold for the 3 or 4% highest income values. Provide this input in the same currency as specified above. Only digits should be inputted. | H14: 1200000 | I14: 1200000
C15: local vegetables | D15: moringa, oseille, chou, tomate, laitue, concombre, courgette, aubergine, carotte | E15: moringa, oseille, chou, tomate, laitue, concombre, courgette, aubergine, carotte | F15: Saisissez quelques légumes locaux courants [à utiliser comme exemples dans l'indicateur de score de consommation alimentaire]. | G15: Input some common local vegetables [to be used as examples in the food consumption score indicator]. | H15: aubergines, courgettes, choux-fleurs | I15: eggplants, zucchini, cauliflower
C16: local fruits | D16: Mangue, pastèque, banane, ananas, dattes, orange, melon | E16: Mangue, pastèque, banane, ananas, dattes, orange, melon | F16: Indiquez quelques fruits locaux courants [à utiliser comme exemples dans l'indicateur de score de consommation alimentaire]. | G16: Input some common local fruits [to be used as examples in the food consumption score indicator]. | H16: pommes, bananes, oranges | I16: apples, bananas, oranges
B18: FILL OUT FOR QUESTIONNAIRE DURATION ESTIMATION . | C18: Expected percentage of respondents cultivating crops | D18: 0.91 | E18: 0.91 | F18: Si l'enquête est représentative et ne comporte pas de quotas, écrivez la proportion de ménages ruraux impliqués dans les cultures au niveau du pays, ou si l'enquête suit un cycle précédent avec un plan d'échantillonnage identique, indiquez simplement le pourcentage du cycle précédent. Si vous utilisez des quotas, calculez le rapport entre le quota et la taille minimale de l'échantillon au niveau où le quota est appliqué (ainsi, si vous avez une taille minimale d'échantillon par strate de 110 avec un quota de 100 producteurs de cultures, alors c'est 100/110 = 91% (le maximum que vous devez écrire est 100%). | G18: If the survey is representative and has no quotas, write the proportion of rural households cultivating crops at country level, or if the survey follows a previous round with identical sample design, just report the percentage from the previous round. If you are using quotas, calculate the ratio of the quota over the minimum sample size at the level where the quota is implemented (so if you have a minimum sample size per strata of 110 with a quota of 100 crop producers, then it's 100/110 = 91% (the maximum you should write is 100%). | H18: 0.91 | I18: 0.91
C19: Expected percentage of respondents raising livestock | D19: 0.91 | E19: 0.91 | F19: Si l'enquête est représentative et ne comporte pas de quotas, écrivez la proportion de ménages ruraux impliqués dans l'élevage, ou si l'enquête suit un cycle précédent avec un plan d'échantillonnage identique, indiquez simplement le pourcentage du cycle précédent. Si vous utilisez des quotas, calculez le rapport entre le quota et la taille minimale de l'échantillon au niveau où le quota est appliqué (ainsi, si vous avez une taille minimale d'échantillon par strate de 110 avec un quota de 100 éleveurs, alors c'est 100/110 = 91% (le maximum que vous devez écrire est 100%). | G19: If the survey is representative and has no quotas, write the proportion of rural households raising livestock at country level, or if the survey follows a previous round with identical sample design, just report the percentage from the previous round. If you are using quotas, calculate the ratio of the quota over the minimum sample size at the level where the quota is implemented (so if you have a minimum sample size of 110 but a quota of 100 livestock producers, then it's 100/110 = 91% (the maximum you should write is 100%) | H19: 0.91 | I19: 0.91
C20: Expected percentage of respondents involved in fishery | D20: 0.05 | E20: 0.05 | F20: Si l'enquête est représentative et ne comporte pas de quotas, écrivez la proportion de ménages ruraux impliqués dans la pêche ou l'aquaculture; sinon, si vous utilisez des quotas, calculez le rapport entre le quota et la taille de l'échantillon au niveau où le quota est appliqué (ainsi, si vous n'avez pas fixé de quota, et que vous pensez avoir une proportion représentative de pêcheurs, écrivez simplement le pourcentage de pêcheurs dans la population que vous ciblez, dans l'exemple à droite, 5%). | G20: If the survey is representative and has no quotas, write the proportion of rural households involved in fisheries or aquaculture, otherwise if you are using quotas, calculate the ratio of the quota over the sample size at the level where the quota is implemented. (so if you haven't set a quota, and you expect to have a representative proportion of fishermen, just write the percentage of fishermen in the population you are targeting, in the example to the right, 5%) | H20: 0.05 | I20: 0.05
