Workbook

Sheet survey
A1: GeoPoll Submission Form
A2: FAO - Household Questionnaire | N2: Additional notes
A3: Q # | B3: Q Name | C3: Suggested Qname | D3: English | E3: Length | F3: Q Type | G3: Randomize | H3: Conditional | I3: Programming Instructions | J3: Skip Pattern | K3: Codes | L3: Default skip patterns & conditional | M3: Specify skip pattern variable (from blue text) | O3: Estimated percentage of repondents | R3: Mandatory | V3: Duration (sec) | W3: Weighted duration | X3: Core questions only
A4: A. PRESENTATION OF THE SURVEY AND ELIGIBILITY CRITERIA SELECTION | R4: no | W4: =IF(V4="","",V4*T4) | X4: =IF(R4="yes",W4,"")
A5: NA | B5: Optin | D5: Optin | E5: =LEN(D5) -> 5 | F5: Open Ended | G5: NA | H5: NA | I5: Form Type - TextBox | J5: Any Response = phone_number | K5: NA | L5: NA | R5: no | V5: 0 | W5: =IF(V5="","",V5*O5) -> 0 | X5: =IF(R5="yes",W5,"")
A6: NA | B6: phone_number | C6: phone_number | D6: Input the phone number that you are contacting: | E6: =LEN(D6) -> 48 | F6: Open Ended | G6: NA | H6: NA | I6: Form Type - TextBox | J6: Any Response = calldispo | K6: NA | L6: NA | R6: yes | V6: 0 | W6: =IF(V6="","",V6*O6) -> 0 | X6: =IF(R6="yes",W6,"") -> 0
A7: NA | B7: calldispo | C7: calldispo | D7: Phone number: #CATI_MOBILENUMBER# 1)Someone answers 2)Answering machine 3)No answer 4)Hang up or refusal 5)Call back 6)Under review 7)Disconnected | E7: =LEN(D7) -> 146 | F7: Single Choice | G7: NA | H7: NA | I7: Form Type - Buttons | J7: 1 = resp_language 2 = AnsweringMachine 3 = NoAnswer 4 = Refusal 5 = WhenCallBack 6 = UnderReview 7 = Disconnected | K7: NA | L7: NA | R7: no | V7: 14.695308 | W7: =IF(V7="","",V7*O7) -> 0 | X7: =IF(R7="yes",W7,"")
A8: NA | B8: AnsweringMachine | C8: calldispo_answeringmachine | D8: Reached an answering machine. | E8: =LEN(D8) -> 29 | F8: NA | G8: NA | H8: NA | I8: NA | J8: End Poll AnsweringMachine | K8: NA | L8: NA | R8: no | V8: 0 | W8: =IF(V8="","",V8*O8) -> 0 | X8: =IF(R8="yes",W8,"")
A9: NA | B9: NoAnswer | C9: calldispo_noanswer | D9: Phone rang and no one answered. | E9: =LEN(D9) -> 31 | F9: NA | G9: NA | H9: NA | I9: NA | J9: End Poll NoAnswer | K9: NA | L9: NA | R9: no | V9: 0 | W9: =IF(V9="","",V9*O9) -> 0 | X9: =IF(R9="yes",W9,"")
A10: NA | B10: UnderReview | C10: calldispo_underreview | D10: Case needs review by a supervisor. | E10: =LEN(D10) -> 34 | F10: NA | G10: NA | H10: NA | I10: NA | J10: End Poll UnderReview | K10: NA | L10: NA | R10: no | V10: 0 | W10: =IF(V10="","",V10*O10) -> 0 | X10: =IF(R10="yes",W10,"")
A11: NA | B11: Disconnected | C11: calldispo_disconnected | D11: Phone was disconnected or out of service. | E11: =LEN(D11) -> 41 | F11: NA | G11: NA | H11: NA | I11: NA | J11: End Poll Disconnected | K11: NA | L11: NA | R11: no | V11: 0 | W11: =IF(V11="","",V11*O11) -> 0 | X11: =IF(R11="yes",W11,"")
A12: NA | B12: resp_language | C12: resp_language | D12: Which language do you wish to proceed with? [OPERATOR: READ ANSWER CHOICES. SINGLE RESPONSE.] 1)English 2)other options [add as many as necessary] | E12: =LEN(D12) -> 148 | F12: Single Choice | G12: NA | H12: NA | I12: Form Type - Buttons | J12: 1 = introduction [English] 2 = introduction [languages & add more if needed] | K12: NA | L12: For any response, go to introduction | N12: Insert most common national languages here [max 4 for translation with GeoPoll]. | R12: no | V12: 3.1032724 | W12: =IF(V12="","",V12*O12) -> 0 | X12: =IF(R12="yes",W12,"")
A13: NA | B13: introduction | C13: introduction | D13: Hello sir/ma'am, my name is #OPERATOR#, and I am calling from GeoPoll Polling Agency on behalf of the Food and Agriculture Organization of the United Nations [FAO] and the World Food Programme (WFP). We are conducting a survey on household livelihoods and the ability to access food in your area. I would like to ask you some questions about your household. The survey usually takes 15/20 minutes to complete. Any information that you provide will be kept strictly confidential, only used for the purpose of the survey and will not be shown to other people. Your voluntary participation in the outcome of this interview is NOT IN ANY WAY linked to your personal chance of receiving any assistance. This is voluntary and you can choose not to answer any or all of the questions if you want. However, we hope that you will participate since your views are important. You will receive #TOPUP#! of communication credit as an incentive for the participation of the survey. Please note that this call may be recorded for quality purposes. Do you have any questions? [OPERATOR: ADDRESS QUESTIONS FROM RESPONDENT, IF ANY.] 1)CONTINUE | E13: =LEN(D13) -> 1133 | F13: Single Choice | G13: NA | H13: NA | I13: Form Type - Buttons | J13: 1 = Agree | K13: NA | L13: For any response, go to Agree | N13: Set the amount of incentive here, if any. | R13: no | V13: 37.418449 | W13: =IF(V13="","",V13*O13) -> 0 | X13: =IF(R13="yes",W13,"")
A14: NA | B14: Agree | C14: resp_agree | D14: Are you interested in participating in this survey? [OPERATOR: SINGLE RESPONSE] 1)Yes 2)Not now but another time in the week 3)No | E14: =LEN(D14) -> 134 | F14: StartRecording | G14: NA | H14: NA | I14: Form Type - Buttons | J14: 1 = resp_firstname 2 = WhenCallBack 3 = resp_refusalwhy | K14: NA | L14: if Agree = 1, go to resp_firstname if Agree = 2, go to WhenCallBack if Agree = 3, go to resp_refusalwhy | O14: 1 | R14: no | V14: 3.8059516 | W14: =IF(V14="","",V14*O14) -> 3.8059516 | X14: =IF(R14="yes",W14,"")
A15: NA | B15: resp_refusalwhy | C15: resp_refusalwhy | D15: Please let us know why you have REFUSED to take the survey. [OPERATOR: SINGLE RESPONSE] 1)Not interested 2)Do not want to be recorded 3)Other [specify] | E15: =LEN(D15) -> 153 | F15: Open Ended - Single Choice | G15: NA | H15: NA | I15: Form Type - RadioList | J15: Any Response = Refusal | K15: NA | L15: For any response, go to Refusal | O15: 1 | R15: no | V15: 0 | W15: =IF(V15="","",V15*O15) -> 0 | X15: =IF(R15="yes",W15,"")
A16: NA | B16: WhenCallBack | C16: resp_whencallback | D16: When would it be a good time to call you back? [RECORD HH/MM/DD/MM OF CALLBACK] | E16: =LEN(D16) -> 80 | F16: Open Ended | G16: NA | H16: NA | I16: Form Type - TextBox IsCallBackDemographic | J16: Any Response = CallbackMessageEN | K16: NA | L16: For any response, go to CallbackMessageEN | O16: 1 | R16: no | V16: 0 | W16: =IF(V16="","",V16*O16) -> 0 | X16: =IF(R16="yes",W16,"")
A17: NA | B17: CallbackMessageEN | C17: callbackmessage_en | D17: Thank you, we will call you back at {WhenCallBack} you requested. Thank you again and have a great day! [OPERATOR: ENTER CALL NOTES BELOW, WHO YOU SPOKE TO AND WHAT THEY SAID] | E17: =LEN(D17) -> 176 | F17: Open Ended | G17: NA | H17: NA | I17: Form Type - TextBox | J17: Any Response = End poll callback | K17: NA | L17: NA | O17: 1 | R17: no | V17: 0 | W17: =IF(V17="","",V17*O17) -> 0 | X17: =IF(R17="yes",W17,"")
A18: NA | B18: Ineligible | C18: NA | D18: You are ineligible for this survey. Thank you for your time and please look out for future surveys! | E18: =LEN(D18) -> 99 | F18: NA | G18: NA | H18: NA | I18: NA | J18: End Poll Ineligible | K18: NA | L18: NA | O18: 1 | R18: no | V18: 0 | W18: =IF(V18="","",V18*O18) -> 0 | X18: =IF(R18="yes",W18,"")
A19: NA | B19: Refusal | C19: NA | D19: Thank you for your time, you will be removed from today's survey. | E19: =LEN(D19) -> 65 | F19: NA | G19: NA | H19: NA | I19: NA | J19: End poll declined | K19: NA | L19: NA | O19: 1 | R19: no | V19: 0 | W19: =IF(V19="","",V19*O19) -> 0 | X19: =IF(R19="yes",W19,"")
A20: B. GENERAL INFORMATION & ELIGIBILITY CRITERIA | W20: =IF(V20="","",V20*O20) | X20: =IF(R20="yes",W20,"")
A21: 1 | B21: resp_age | C21: resp_age | D21: How old are you? [OPERATOR: RECORD AGE IN NUMBER OF YEARS. ROUND UP TO NEAREST WHOLE NUMBER. IF THE RESPONDENT GIVES BIRTH YEAR, REPEAT THE QUESTION. ENTER 00 FOR DON'T KNOW.] | E21: =LEN(D21) -> 177 | F21: Range | G21: NA | H21: NA | I21: Form Type - TextBox | J21: 0-17 = Ineligible 18-100 = resp_gender 00 = Ineligible | K21: NA | L21: Only respondents from 18-100 will be eligible for the survey. | O21: =1 -> 1 | R21: yes | V21: 9.8907185 | W21: =IF(V21="","",V21*O21) -> 9.8907185 | X21: =IF(R21="yes",W21,"") -> 9.8907185
A22: =A21+1 -> 2 | B22: resp_gender | C22: resp_gender | D22: What is the gender of the respondent? [OPERATOR: DO NOT ASK THIS QUESTION OUT LOUD. LISTEN TO THE VOICE AND SELECT THE GENDER.] 1)Male 2)Female 3)DON'T KNOW 4)REFUSED | E22: =LEN(D22) -> 168 | F22: Single Choice | G22: NA | H22: NA | I22: Form Type - Buttons | J22: 1-4 = phone_number_conf | K22: NA | L22: For any response, go to phone_number_conf | O22: =1 -> 1 | R22: yes | V22: 1.7156482 | W22: =IF(V22="","",V22*O22) -> 1.7156482 | X22: =IF(R22="yes",W22,"") -> 1.7156482
O23: =1 -> 1 | W23: =IF(V23="","",V23*O23) | X23: =IF(R23="yes",W23,"")
O24: =1 -> 1 | W24: =IF(V24="","",V24*O24) | X24: =IF(R24="yes",W24,"")
A25: 3 | B25: hh_admin1 | C25: hh_admin1 | D25: Currently, in which State/Region does your household reside? [OPERATOR: SINGLE SELECTION.] [HINT: HOUSEHOLD CONSISTS OF ALL MEMBERS LIVING TOGETHER, SHARING RESOURCES & EATING FROM THE SAME POT.] 1)ADMIN1 2)DON'T KNOW 3)REFUSED | E25: =LEN(D25) -> 230 | F25: Single Choice | G25: NA | H25: NA | I25: Form Type - Buttons IsDemographic - ADM1 | J25: 1 = hh_admin2_1 2-3 = Ineligible | K25: NA | L25: The administrative information will be updated by GeoPoll based on the sample design document and the administrative boundaries provided by the dashboard team after the questionnaire validation. | O25: =1 -> 1 | R25: yes | V25: 13.957259 | W25: =IF(V25="","",V25*O25) -> 13.957259 | X25: =IF(R25="yes",W25,"") -> 13.957259
A26: =A25+1 -> 4 | B26: hh_admin2_1 | C26: hh_admin2_1 | D26: Currently, in which Township does your household reside? [OPERATOR: SINGLE RESPONSE.] 1)ADMIN2 2)DON'T KNOW 3)REFUSED | E26: =LEN(D26) -> 120 | F26: Single Choice | G26: NA | H26: NA | I26: Form Type - Buttons IsDemographic - ADM2 | J26: 1 = hh_agricactivity 2-3 = Ineligible | K26: NA | O26: =1 -> 1 | R26: yes | V26: 7.954999 | W26: =IF(V26="","",V26*O26) -> 7.954999 | X26: =IF(R26="yes",W26,"") -> 7.954999
B27: quotareached | C27: quotareached | D27: [OPERATOR: DO NOT READ. ANSWER QUESTION BELOW.] THIS RESPONDENT REPORTED THEY LIVE IN: {ADM1} {ADM2} 1)THE GOAL FOR THIS LOCATION HAS BEEN ACHIEVED - END SURVEY 2)THE GOAL FOR THIS LOCATION IS OPEN - CONTINUE SURVEY | E27: =LEN(D27) -> 218 | F27: Single Choice | G27: NA | H27: NA | I27: Form Type - Buttons | J27: 1 = End Poll Quota Reached 2 = hh_agricactivity | K27: NA
A28: =#REF!+1 -> #REF! | B28: hh_agricactivity | C28: hh_agricactivity | D28: Has anybody in your household produced crops or livestock for household consumption or for sale in the past 12 months, including household members currently away for transhumance? [OPERATOR: SINGLE RESPONSE. THIS IS THE MAIN SCREENING QUESTION.] [HINT FOR PROBING: Do you cultivate any plants to sale or consume? Do you raise any animals with the intent of selling or consuming them or their products like meat, milk, wool or leather? Is one of your household member currently away with cattle or other animals for transhumance?] 1)Yes - crop production 2)Yes - livestock production 3)Yes - both crop and livestock production 4)No 5)DON'T KNOW 6)REFUSED | E28: =LEN(D28) -> 658 | F28: Single Choice | G28: NA | H28: NA | I28: Form Type - Buttons | J28: 1-4 = resp_id 5-6 = Ineligible | K28: NA | L28: if hh_agricactivity = 1-4, go to resp_id. Otherwise, the respondent is ineligible. | O28: =1 -> 1 | R28: yes | V28: 24.410839 | W28: =IF(V28="","",V28*O28) -> 24.410839 | X28: =IF(R28="yes",W28,"") -> 24.410839
B29: o_cyclaffected | D29: Has your household or community being impacted by Cyclone MOCHA and affected your household ability to raise income and/or to produce food for self consumption? [OPERATOR: SINGLE RESPONSE.] 1)YES 2)NO 3)DON'T KNOW 4)REFUSED | E29: =LEN(D29) -> 226 | F29: Single Choice | O29: =1 -> 1 | W29: =IF(V29="","",V29*O29) | X29: =IF(R29="yes",W29,"")
A31: B. GENERAL HOUSEHOLD INFORMATION | W31: =IF(V31="","",V31*O31) | X31: =IF(R31="yes",W31,"")
O32: =1 -> 1 | W32: =IF(V32="","",V32*O32) | X32: =IF(R32="yes",W32,"")
A33: =#REF!+1 -> #REF! | B33: hh_gender | C33: hh_gender | D33: Is the head of your household male or female? [OPERATOR: SINGLE RESPONSE.] 1)Male 2)Female 3)DON'T KNOW 4)REFUSED | E33: =LEN(D33) -> 116 | F33: Single Choice | G33: NA | H33: NA | I33: Form Type - Buttons | J33: 1-4 = hh_education | K33: NA | L33: if hh_gender = 1-4, go to hh_education. | O33: =1 -> 1 | R33: yes | V33: 10.504534 | W33: =IF(V33="","",V33*O33) -> 10.504534 | X33: =IF(R33="yes",W33,"") -> 10.504534
B34: RuralUrban | D34: Are you living in a rural or urban area? [OPERATOR: CHOOSE ONLY ONE OPTION] 1)RURAL [Village] AREA 2)URBAN [Ward] AREA 3)DON'T KNOW 4)REFUSED | F34: Single Choice | O34: =1 -> 1 | W34: =IF(V34="","",V34*O34) | X34: =IF(R34="yes",W34,"")
A35: =A190+1 -> #REF! | B35: hh_size | C35: hh_size | D35: How many people are part of the household? [OPERATOR: RECORD NUMBER OF MEMBERS IN HOUSEHOLD. ENTER 88 FOR DON'T KNOW & 99 FOR REFUSED.] [HINT: TO BE A PART OF THE SAME HOUSEHOLD, MEMBERS MUST LIVE UNDER THE SAME ROOF, SHARE THE SAME RESOURCES & EAT FROM THE SAME POT.] | E35: =LEN(D35) -> 269 | F35: Range | G35: NA | H35: NA | I35: Form Type - TextBox | J35: 1-50 = hh_asset_prod 88-88 = hh_asset_prod 99-99 = hh_asset_prod | K35: NA | L35: For any response, go to [next question] | O35: =1 -> 1 | R35: no | V35: 16.902294 | W35: =IF(V35="","",V35*O35) -> 16.902294 | X35: =IF(R35="yes",W35,"")
A36: =A35+1 -> #REF! | B36: o_HHSize04 | C36: o_HHSize04 | D36: What is the total number of children aged 0 to 4 years old (0-59 months) in your household? [OPERATOR: RECORD NUMBER GIVEN] | E36: =LEN(D36) -> 124 | F36: Range | N36: GeoPoll: Confirm if we need to add validation rules here. Please note that if we are to add validation rules, we will need to do away with this instruction at hh_size "ENTER 88 FOR DON'T KNOW &99 FOE REFUSED], so as not to interfere with the validations should any of these be selected.
A37: =A36+1 -> #REF! | B37: o_HHSize5_15 | C37: o_HHSize5_15 | D37: What is the total number of members aged 5 to 15 years old in your household? [OPERATOR: RECORD NUMBER GIVEN] | E37: =LEN(D37) -> 110 | F37: Range
A38: =A37+1 -> #REF! | B38: o_HHSize16_59 | C38: o_HHSize16_59 | D38: What is the total number of members aged 16 to 59 years old in your household? [OPERATOR: RECORD NUMBER GIVEN] | E38: =LEN(D38) -> 111 | F38: Range
A39: =A38+1 -> #REF! | B39: o_HHSize60 | C39: o_HHSize60 | D39: What is the total number of members aged 60 years old and older in your household? [OPERATOR: RECORD NUMBER GIVEN] | E39: =LEN(D39) -> 116 | F39: Range
A40: =A39+1 -> #REF! | B40: o_HHDisability | C40: o_HHDisability | D40: How many members of your household have a disability? Note: to count as a disability the person must have a lot of difficulty or cannot do at all, any of the following: seeing (even if wearing glasses), hearing (even if wearing hearing aids), walking or climbing steps, remembering or concentrating, self-care (such as washing or dressing) or communicating (understanding or being understood). [OPERATOR: RECORD THE NUMBER GIVEN] | E40: =LEN(D40) -> 432 | F40: Range | N40: GeoPoll: Same feedback as above.
A41: =#REF!+1 -> #REF! | B41: hh_age | C41: hh_age | D41: How old is the head of household? [OPERATOR: SINGLE RESPONSE.] 1)Under 18 2)18 to 40 3)41 to 65 4)Over 65 5)DON'T KNOW 6)REFUSED | E41: =LEN(D41) -> 133 | F41: Single Choice | G41: NA | H41: NA | I41: Form Type - Buttons | J41: 1-6 = income_main | K41: NA | L41: For any response, go to [next question] | O41: =1 -> 1 | R41: no | V41: 7.0248413 | W41: =IF(V41="","",V41*O41) -> 7.0248413 | X41: =IF(R41="yes",W41,"")
...

Sheet New Durations
A1: question | B1: duration | C1: responded % | D1: weighted time
A2: introduction | B2: 50.82254 | C2: 1 | D2: 50.82254
A3: agree | B3: 3.4964738 | C3: 0.79698741 | D3: 2.7866456
A4: resp_age | B4: 13.753073 | C4: 1 | D4: 13.753073
A5: resp_gender | B5: 2.1173561 | C5: 1 | D5: 2.1173561
A6: quotareached | B6: 2.28425 | C6: 0.79698741 | D6: 1.8205185
A7: hh_agricactivity | B7: 31.372377 | C7: 1 | D7: 31.372377
A8: hh_milieu | B8: 7.9225454 | C8: 0.15190348 | D8: 1.2034622
A9: hh_gender | B9: 10.085732 | C9: 1 | D9: 10.085732
A10: hh_education | B10: 12.894034 | C10: 1 | D10: 12.894034
A11: hh_wealth_water | B11: 15.265829 | C11: 0.63796463 | D11: 9.739059
A12: hh_wealth_toilet | B12: 15.123718 | C12: 0.59180156 | D12: 8.95024
A13: hh_wealthwall | B13: 12.821411 | C13: 0.15190348 | D13: 1.9476169
... A164: adm1_name | B164: 10.743817 | C164: 0.20301259 | D164: 2.1811302
A165: adm2_name | C165: 0 | D165: 0
A166: covid | B166: 56.471024 | C166: 0.20301259 | D166: 11.464329
A167: crp_landright | B167: 31 | C167: 0.0040467626 | D167: 0.12544964
A168: crp_seed | B168: 30.833334 | C168: 0.0040467626 | D168: 0.12477518
A169: crp_proddif | B169: 16.882986 | C169: 0.11848022 | D169: 2.0002998
A170: crp_salesdif | B170: 16.82699 | C170: 0.086630695 | D170: 1.4577339
A171: crp_saledif_2 | B171: 39.486874 | C171: 0.03139988 | D171: 1.2398831
A172: ls_proddif | B172: 15.938099 | C172: 0.10169365 | D172: 1.6208034
A173: ls_salesdif | B173: 13.330855 | C173: 0.060476619 | D173: 0.80620506
A174: ls_proc | B174: 16.437651 | C174: 0.0625 | D174: 1.0273532
A175: ls_proc_fac_state | B175: 8.666667 | C175: 0.00067446043 | D175: 0.005845324
A176: fish_proddif | B176: 12.523809 | C176: 0.001573741 | D176: 0.019709232
A177: cs_spentsavings | B177: 22.220184 | C177: 0.0081684652 | D177: 0.1815048
... A193: ls_proddif_2_covid19 | B193: 3.3438249 | C193: 1 | D193: 3.3438249

Sheet Crop list
C3: Select top 10 crops | D3: GeoPoll code | E3: Dataset code | F3: Label (EN)
C4: x | D4: {=_xlfn.SEQUENCE(90,1,1,1)} -> 1 | E4: 1.1 | F4: Rice
C5: x | D5: 2 | E5: 1.2 | F5: Wheat
D6: 3 | E6: 1.3 | F6: Millet
D7: 4 | E7: 1.4 | F7: Sorghum
C8: x | D8: 5 | E8: 1.5 | F8: Maize
D9: 6 | E9: 1.6 | F9: Barley
D10: 7 | E10: 1.99 | F10: Other Cereal
D11: 8 | E11: 2.1 | F11: Cassava
C12: x | D12: 9 | E12: 2.2 | F12: Potatoe
D13: 10 | E13: 2.3 | F13: Sweet Potatoes
D14: 11 | E14: 2.4 | F14: Yams
D15: 12 | E15: 2.5 | F15: Carrots
D16: 13 | E16: 2.6 | F16: Cocoyam
D17: 14 | E17: 2.99 | F17: Other tubers
C18: x | D18: 15 | E18: 3.1 | F18: Beans
D19: 16 | E19: 3.2 | F19: Lentils
D20: 17 | E20: 3.3 | F20: Peas
D21: 18 | E21: 3.4 | F21: Soybeans
D22: 19 | E22: 3.5 | F22: Chickpeas
D23: 20 | E23: 3.6 | F23: Fava beans
D24: 21 | E24: 3.7 | F24: Broad beans
D25: 22 | E25: 3.99 | F25: Other pulses
D26: 23 | E26: 4.1 | F26: Cabbage
D27: 24 | E27: 4.2 | F27: Lettuce
D28: 25 | E28: 4.3 | F28: Spinach-Amaranth
D29: 26 | E29: 4.4 | F29: Cassava leaves
D30: 27 | E30: 4.5 | F30: Potatoe leaves
... D42: 39 | E42: 5.7 | F42: Bell pepper
C43: x | D43: 40 | E43: 5.8 | F43: Onions
D44: 41 | E44: 5.9 | F44: Haricot
D45: 42 | E45: 5.101 | F45: Green peas
D46: 43 | E46: 5.11 | F46: Fava beans green
D47: 44 | E47: 5.99 | F47: Other non leafy vegs
D48: 45 | E48: 6.1 | F48: Orange
D49: 46 | E49: 6.2 | F49: Lemon
D50: 47 | E50: 6.3 | F50: Grapefruit
D51: 48 | E51: 6.4 | F51: Mandarins/clementines
D52: 49 | E52: 6.99 | F52: Other citrus fruit
D53: 50 | E53: 7.1 | F53: Sweet Banana
...

Sheet Additional information
C2: Original | D2: Replacement | E2: Comment | F2: Examples
B3: FOR CORE QUESTIONS . (Mandatory to fill out) . | C3: ADMIN1 | D3: State/Region | E3: The first subdivision of the country, after national level; region; province; governorate; etc. | F3: region
C4: ADMIN2 | D4: Township | E4: The second subdivision of the country; district; municipality; LGA; etc. | F4: district
C5: reference year | D5: a normal year | E5: Comparison questions will need need a reference year. Select whether you want to use "last year" or "a normal year" as a baseline. A "normal year" should refers to an average year from the past 5 years - make sure to train the enumerators accordingly. | F5: a normal year
C6: season | D6: monsoon season | E6: Name the crop season(s) of interest if there are several cropping seasons in the country (e.g. Meher and Belg in Ethiopia, rainy season / flood-recession cropping / irrigated dry season in the Sahel). You can refer to the “last season” or “ongoing season". | F6: wet season
C7: season phase | D7: Early growing | E7: Indicate the phase of the season at the time of data collection. If the harvest from the season has not yet occurred, the question on crop harvest (crp_harv_change) will include the word “expected” (where #expected or nothing# is located). If the harvest has occured, "expected" will not be inserted in the question. | F7: Harvesting
C8: local measurement unit | D8: Arces, square meter | E8: Specify the local measurement unit for land size, other than acres, hectares, square meters and square feet. If no other unit of measurement is needed, keep this cell blank. | F8: Jeribs
C9: local measurement unit conversion | E9: Include the conversion of the local measurement unit to hectares. In other words, how many local measurement units are in 1 ha. | F9: 0.2
B10: FOR OPTIONAL QUESTIONS . (Fill out if applicable) . | C10: currency | D10: MMK | E10: The name of the main currency used nationally; USD; Naira; Rial; Pesos; etc. | F10: Naira
C11: MIN AMOUNT | D11: 100 | E11: The minimum amount for an income source should be set at 0 or any value below which it is not possible to do a transaction. For example, the smallest coin/banknote in a currency can be 1000, in which case you would set the minimum at 1000. Provide this input in the same currency as specified above. Only digits should be inputted. | F11: 5
C12: MAX AMOUNT | D12: 5000000 | E12: Set the maximum amount for an income source over 3 months. Enumerators will not be able to input values above this amount in questions related to income amounts. Using previous representative surveys for this population, you can estimate this amount by using the mean income plus five (5) standard deviations, unless the country has high inflation. In the latter case, set the maximum value based on your country context (higher than the proposed approach). Provide this input in the same currency as specified above. Only digits should be inputted. | F12: 5000000
C13: THRESHOLD | E13: The threshold salary should be calculated to flag outliers (responses that look suspiciously high). Using previous representative surveys for this population, a good estimate is the average plus three (3) standard deviations, which should give the threshold for the 3 or 4% highest income values. Provide this input in the same currency as specified above. Only digits should be inputted. | F13: 1200000
C14: local vegetables | D14: carrot, red pepper, pumpkin, orange sweet potatoes, spinach | E14: Input some common local vegetables [to be used as examples in the food consumption score indicator]. | F14: eggplants, zucchini, cauliflower
C15: local fruits | D15: banana, apple, mango, papaya | E15: Input some common local fruits [to be used as examples in the food consumption score indicator]. | F15: apples, bananas, oranges
B17: FILL OUT FOR QUESTIONNAIRE DURATION ESTIMATION . | C17: Expected percentage of respondents cultivating crops | D17: 0.91 | E17: If the survey is representative and has no quotas, write the proportion of rural households cultivating crops at country level, or if the survey follows a previous round with identical sample design, just report the percentage from the previous round. If you are using quotas, calculate the ratio of the quota over the minimum sample size at the level where the quota is implemented (so if you have a minimum sample size per strata of 110 with a quota of 100 crop producers, then it's 100/110 = 91% (the maximum you should write is 100%). | F17: 0.91
C18: Expected percentage of respondents raising livestock | D18: 0.91 | E18: If the survey is representative and has no quotas, write the proportion of rural households raising livestock at country level, or if the survey follows a previous round with identical sample design, just report the percentage from the previous round. If you are using quotas, calculate the ratio of the quota over the minimum sample size at the level where the quota is implemented (so if you have a minimum sample size of 110 but a quota of 100 livestock producers, then it's 100/110 = 91% (the maximum you should write is 100%) | F18: 0.91
C19: Expected percentage of respondents involved in fishery | D19: 0.05 | E19: If the survey is representative and has no quotas, write the proportion of rural households involved in fisheries or aquaculture, otherwise if you are using quotas, calculate the ratio of the quota over the sample size at the level where the quota is implemented. (so if you haven't set a quota, and you expect to have a representative proportion of fishermen, just write the percentage of fishermen in the population you are targeting, in the example to the right, 5%) | F19: 0.05

Sheet Admin 3 info
A1: adm3_name | B1: adm3_name_local | C1: adm3_pcode | D1: adm2_name | E1: adm2_pcode | F1: adm1_name | G1: adm1_pcode | H1: adm0_name | I1: adm0_ISO3
A2: Muse | B2: မူဆယ် | C2: MMR015009 | D2: Muse | E2: MMR015D002 | F2: Shan | G2: MMR222 | H2: Myanmar | I2: MMR
A3: Kunlong | B3: ကွမ်းလုံ | C3: MMR015020 | D3: Lashio | E3: MMR015D001 | F3: Shan | G3: MMR222 | H3: Myanmar | I3: MMR
A4: Hseni | B4: သိန္နီ | C4: MMR015002 | D4: Lashio | E4: MMR015D001 | F4: Shan | G4: MMR222 | H4: Myanmar | I4: MMR
A5: Mongkaing | B5: မိုင်းကိုင် | C5: MMR014016 | D5: Loilen | E5: MMR014D002 | F5: Shan | G5: MMR222 | H5: Myanmar | I5: MMR
A6: Laihka | B6: လဲချား | C6: MMR014012 | D6: Loilen | E6: MMR014D002 | F6: Shan | G6: MMR222 | H6: Myanmar | I6: MMR
A7: Seikphyu | B7: ဆိပ်ဖြူ | C7: MMR009022 | D7: Pakokku | E7: MMR009D004 | F7: Magway | G7: MMR009 | H7: Myanmar | I7: MMR
A8: Kale | B8: ကလေး | C8: MMR005027 | D8: Kale | E8: MMR005D005 | F8: Sagaing | G8: MMR005 | H8: Myanmar | I8: MMR
A9: Minbu | B9: မင်းဘူး | C9: MMR009007 | D9: Minbu | E9: MMR009D002 | F9: Magway | G9: MMR009 | H9: Myanmar | I9: MMR
A10: Wundwin | B10: ဝမ်းတွင်း | C10: MMR010031 | D10: Meiktila | E10: MMR010D007 | F10: Mandalay | G10: MMR010 | H10: Myanmar | I10: MMR
A11: Kyaukpadaung | B11: ကျောက်ပန်းတောင်း | C11: MMR010020 | D11: Nyaung-U | E11: MMR010D005 | F11: Mandalay | G11: MMR010 | H11: Myanmar | I11: MMR
A12: Taze | B12: တန့်ဆည် | C12: MMR005011 | D12: Shwebo | E12: MMR005D002 | F12: Sagaing | G12: MMR005 | H12: Myanmar | I12: MMR
... A331: Ramree | B331: ရမ်းဗြဲ | C331: MMR012013 | D331: Kyaukpyu | E331: MMR012D003 | F331: Rakhine | G331: MMR012 | H331: Myanmar | I331: MMR
