Workbook

Sheet survey
A1: type | B1: name | C1: label::English (en) | D1: label::Spanish (es) | E1: label:: | F1: hint::English (en) | G1: hint::Spanish (es) | H1: hint:: | I1: required | J1: appearance | K1: constraint | L1: constraint_message | M1: relevant | N1: choice_filter | O1: parameters | P1: calculation | U1: Mandatory | W1: New question duration (sec) | X1: Estimated percentage of repondents | Y1: Weighted time | Z1: Weighted time for core vars
A2: start | B2: start | Y2: =IF(W2<>"",W2*X2,"") | Z2: =IF(AND(W2<>"",U2="yes"),W2*X2,"")
A3: end | B3: end | Y3: =IF(W3<>"",W3*X3,"") | Z3: =IF(AND(W3<>"",U3="yes"),W3*X3,"")
A4: today | B4: today | Y4: =IF(W4<>"",W4*X4,"") | Z4: =IF(AND(W4<>"",U4="yes"),W4*X4,"")
A5: deviceid | B5: deviceid | Y5: =IF(W5<>"",W5*X5,"") | Z5: =IF(AND(W5<>"",U5="yes"),W5*X5,"")
A6: audit | B6: audit
A7: calculate | B7: audio_random | P7: once(random())
A8: background-audio | B8: background-audio | M8: ${audio_random}<=0.02 | O8: quality=low
A9: select_one enumteam | B9: enum_team | C9: Enumerator team number or code | D9: Número o código del equipo de encuestadores
A10: select_one enumerator | B10: enumerator | C10: Name of enumerator | D10: Nombre del encuestador | I10: true | N10: my_filter_admin=${enum_team} | U10: yes | Y10: =IF(W10<>"",W10*X10,"") | Z10: =IF(AND(W10<>"",U10="yes"),W10*X10,"")
A11: calculate | B11: enumerator_ | P11: jr:choice-name(${enumerator},'${enumerator}') | U11: yes | Y11: =IF(W11<>"",W11*X11,"") | Z11: =IF(AND(W11<>"",U11="yes"),W11*X11,"")
A13: note | B13: introduction | C13: Hello sir/ma'am, my name is ${enumerator_}. On behalf of the Food and Agriculture Organization of the United Nations (FAO), we are conducting a survey on household livelihoods and the ability to access food in your area. I would like to ask you some questions about your household. The survey usually takes 20 / 30 minutes to complete. Any information that you provide will be kept strictly confidential, only used for the purpose of the survey and will not be shown to other people. Your voluntary participation in the outcome of this interview is NOT IN ANY WAY linked to your personal chance of receiving any assistance. This is voluntary and you can choose not to answer any or all of the questions if you want. However, we hope that you will participate since your views are important. Do you have any questions? | D13: Buenos días/tardes señor/señora, mi nombre es ${encuestador_}. En nombre de la Organización de las Naciones Unidas para la Alimentación y la Agricultura (FAO), estamos realizando una encuesta sobre los medios de vida de los hogares y la capacidad de acceder a alimentos en su área. Me gustaría hacerle algunas preguntas acerca de su hogar. La encuesta normalmente toma entre 15 / 20 minutes. Toda la información provista será estrictamente guardada con confidencialidad, será utilizada únicamente para los propósitos de la encuesta y no será compartida. Su participación voluntaria en el resultado de esta encuesta, NO ESTÁ DE NINGÚN MODO vinculada a la posibilidad de recibir algún tipo de asistencia o ayuda. Esto es voluntario y puede optar por no responder alguna o todas las preguntas si así lo desea. Sin embargo, esperamos que participe ya que su opinión es muy importante. ¿Tiene alguna pregunta? | F13: [INSTRUCTIONS: ADDRESS QUESTIONS FROM RESPONDENT, IF ANY.] | G13: [ENCUESTADOR/A: RESPONDA LAS PREGUNTAS DEL ENCUESTADO, SI LAS HAY.] | I13: false | U13: no | W13: 50.82254 | Y13: =IF(W13<>"",W13*X13,"") -> 0 | Z13: =IF(AND(W13<>"",U13="yes"),W13*X13,"")
A14: select_one yesno | B14: resp_agree | C14: Are you interested in participating in this survey? | D14: ¿Está interesado en participar en esta encuesta? | I14: false | U14: yes | W14: 3.5 | X14: =1 -> 1 | Y14: =IF(W14<>"",W14*X14,"") -> 3.5 | Z14: =IF(AND(W14<>"",U14="yes"),W14*X14,"") -> 3.5
A15: note | B15: Refusal | C15: Thank you for your time, you will be removed from today's survey. | D15: Gracias por su tiempo, será descartado para la encuesta de hoy. | I15: false | M15: ${resp_agree} = '2' | U15: no | W15: 0 | X15: 1 | Y15: =IF(W15<>"",W15*X15,"") -> 0 | Z15: =IF(AND(W15<>"",U15="yes"),W15*X15,"")
Y16: =IF(W16<>"",W16*X16,"") | Z16: =IF(AND(W16<>"",U16="yes"),W16*X16,"")
A17: begin_group | B17: eligibility | C17: ELIGIBILITY CRITERIA | D17: Criterios de eligibilidad | I17: false | M17: ${resp_agree} = '1' | U17: yes | Y17: =IF(W17<>"",W17*X17,"") | Z17: =IF(AND(W17<>"",U17="yes"),W17*X17,"")
Y18: =IF(W18<>"",W18*X18,"") | Z18: =IF(AND(W18<>"",U18="yes"),W18*X18,"")
A19: text | B19: resp_firstname | C19: What is your first name? | D19: ¿Cuál es su nombre? | F19: [INSTRUCTIONS: RECORD THE RESPONDENT'S FIRST NAME. ENTER 999 FOR REFUSED] | G19: [ENCUESTADOR/A: REGISTRE EL NOMBRE DEL ENCUESTADO.ESCRIBA 999 PARA "NO RESPONDE"] | I19: true | U19: yes | W19: 10 | X19: =1 -> 1 | Y19: =IF(W19<>"",W19*X19,"") -> 10 | Z19: =IF(AND(W19<>"",U19="yes"),W19*X19,"") -> 10
A20: text | B20: resp_lastname | C20: What is your last name? | D20: ¿Cuál es su apellido? | F20: [INSTRUCTIONS: RECORD THE RESPONDENT'S LAST NAME. ENTER 999 FOR REFUSED] | G20: [ENCUESTADOR/A: REGISTRE EL APELLIDO DEL ENCUESTADO.ESCRIBA 999 PARA "NO RESPONDE"] | I20: true | U20: yes | W20: 10 | X20: =1 -> 1 | Y20: =IF(W20<>"",W20*X20,"") -> 10 | Z20: =IF(AND(W20<>"",U20="yes"),W20*X20,"") -> 10
X21: =1 -> 1 | Y21: =IF(W21<>"",W21*X21,"") | Z21: =IF(AND(W21<>"",U21="yes"),W21*X21,"")
A22: integer | B22: resp_age | C22: How old are you? | D22: ¿Qué edad tiene? | F22: [INSTRUCTIONS: RECORD AGE IN NUMBER OF YEARS. ROUND UP TO NEAREST WHOLE NUMBER. IF THE RESPONDENT GIVES BIRTH YEAR, REPEAT THE QUESTION. ENTER 888 FOR DON'T KNOW.] | G22: [ENCUESTADOR/A: REGISTRE LA EDAD EN AÑOS. REDONDEE AL NÚMERO ENTERO MÁS CERCANO. SI EL ENCUESTADO DA SU FECHA DE NACIMIENTO, VUELVA A REPETIR LA PREGUNTA. ESCRIBA 888 PARA "NO SABE"] | I22: true | K22: (. >= 18 and . <= 100) or . = 888 | U22: yes | W22: 13.753073 | X22: =1 -> 1 | Y22: =IF(W22<>"",W22*X22,"") -> 13.753073 | Z22: =IF(AND(W22<>"",U22="yes"),W22*X22,"") -> 13.753073
X23: =1 -> 1 | Y23: =IF(W23<>"",W23*X23,"") | Z23: =IF(AND(W23<>"",U23="yes"),W23*X23,"")
A24: select_one gender | B24: resp_gender | C24: What is the gender of the respondent? | D24: ¿Cuál es el género del encuestado? | F24: [INSTRUCTIONS: DO NOT ASK THIS QUESTION OUT LOUD. SELECT THE GENDER OF THE RESPONDENT.] | G24: [ENCUESTADOR/A: NO LEA LA PREGUNTA EN VOZ ALTA. SELECCIONE EL GENERO DEL ENCUESTADO.] | I24: true | U24: no | W24: 2.1173561 | X24: =1 -> 1 | Y24: =IF(W24<>"",W24*X24,"") -> 2.1173561 | Z24: =IF(AND(W24<>"",U24="yes"),W24*X24,"")
X25: =1 -> 1 | Y25: =IF(W25<>"",W25*X25,"") | Z25: =IF(AND(W25<>"",U25="yes"),W25*X25,"")
X26: =1 -> 1 | Y26: =IF(W26<>"",W26*X26,"") | Z26: =IF(AND(W26<>"",U26="yes"),W26*X26,"")
A27: select_one admin1 | B27: adm1_pcode | C27: Currently, in which Department does your household reside? | D27: Actualmente, ¿en qué Departamento reside su hogar? | F27: [HINT: HOUSEHOLD CONSISTS OF ALL MEMBERS LIVING TOGETHER, SHARING RESOURCES & EATING FROM THE SAME POT.] | G27: [PISTA: EL HOGAR ES EL ESPACIO DONDE TODOS LOS MIEMBROS VIVEN JUNTOS, COMPARTEN RECURSOS Y COMEN DE LA MISMA OLLA.] | I27: true | J27: autocomplete | U27: yes | W27: 8.8 | X27: =1 -> 1 | Y27: =IF(W27<>"",W27*X27,"") -> 8.8 | Z27: =IF(AND(W27<>"",U27="yes"),W27*X27,"") -> 8.8
A28: calculate | B28: adm1_name | P28: jr:choice-name(${adm1_pcode},'${adm1_pcode}') | U28: yes | X28: =1 -> 1 | Y28: =IF(W28<>"",W28*X28,"") | Z28: =IF(AND(W28<>"",U28="yes"),W28*X28,"")
A29: select_one admin2 | B29: adm2_pcode | C29: Currently, in which Municipality does your household reside? | D29: Actualmente, ¿en qué Municipio reside su hogar? | I29: true | J29: autocomplete | N29: my_filter_admin=${adm1_pcode} | U29: yes | W29: 10.4 | X29: =1 -> 1 | Y29: =IF(W29<>"",W29*X29,"") -> 10.4 | Z29: =IF(AND(W29<>"",U29="yes"),W29*X29,"") -> 10.4
A30: calculate | B30: adm2_name | P30: jr:choice-name(${adm2_pcode},'${adm2_pcode}') | U30: yes | X30: =1 -> 1 | Y30: =IF(W30<>"",W30*X30,"") | Z30: =IF(AND(W30<>"",U30="yes"),W30*X30,"")
A31: select_one yes_no | B31: o_area | C31: Is your household located in the urban downtown area? | D31: ¿Se encuentra su hogar en el casco urbano del municipio? | G31: Casco urbano: Área comprendida por los núcleos poblacionales que circunscriben, en forma continua, la Alcaldía Municipal y que es conocida como casco urbano del municipio. | I31: TRUE | W31: 10 | X31: =1 -> 1 | Y31: 10 | Z31: =IF(AND(W31<>"",U31="yes"),W31*X31,"")
A32: select_one agricactivity | B32: hh_agricactivity | C32: Has anybody in your household produced crops or livestock for household consumption or for sale in the past 12 months, including household members currently away for transhumance? | D32: ¿Alguien de su hogar ha producido cultivos o criado animales para el consumo doméstico o para la venta en los últimos 12 meses, incluyendo aquellos miembros del hogar que se encuentran ausentes por trashumancia? | F32: [INSTRUCTIONS: THIS IS THE MAIN SCREENING QUESTION.] [HINT FOR PROBING: Do you cultivate any plants to sale or consume? Do you raise any animals with the intent of selling or consuming them or their products like meat, milk, wool or leather? Is one of your household member currently away with cattle or other animals for transhumance?] | G32: ESTA ES LA PRINCIPAL PREGUNTA-FILTRO.] [PISTA PARA SONDEAR: ¿Usted cultiva alguna planta para la venta o el consumo? ¿Usted cria algún animal con la intención de venderlo o consumirlo, o sus productos como la carne, leche, lana o cuero? ¿Algún miembro de su hogar está lejos con ganado o por trashumancia?] | I32: true | U32: yes | W32: 31.372377 | X32: =1 -> 1 | Y32: =IF(W32<>"",W32*X32,"") -> 31.372377 | Z32: =IF(AND(W32<>"",U32="yes"),W32*X32,"") -> 31.372377
A33: select_one yes_no | B33: hh_fish | C33: Has anybody in your household been engaged in aquatic production [fish catch or aquaculture farming] for household consumption or for sales in the past 12 months? | D33: Algún miembro de su hogar ha estado involucrado en la producción piscícola [pesca o acuicultura] para el consumo del hogar o para la venta? | F33: [HINT FOR PROBING: It should not include sports fishing. It should be about production of aquatic products [fish catch or aquaculture farming] for household consumption or sales.] | G33: [PISTA PARA VALIDACIÓN: NO DEBE ser incluida la pesca deportiva. Debería tratarse de productos piscícolas [pesca o acuicultura] para el consumo del hogar o para la venta.] | I33: true | U33: no | W33: 17 | X33: =1 -> 1 | Y33: =IF(W33<>"",W33*X33,"") -> 17
X34: =1 -> 1 | Y34: =IF(W34<>"",W34*X34,"") | Z34: =IF(AND(W34<>"",U34="yes"),W34*X34,"")
A35: end_group | Y35: =IF(W35<>"",W35*X35,"") | Z35: =IF(AND(W35<>"",U35="yes"),W35*X35,"")
A36: begin_group | B36: generalInfo | C36: GENERAL INFORMATION | D36: INFORMACIÓN GENERAL | I36: false | M36: ${resp_agree} = '1' and ${hh_agricactivity} != '5' and ${hh_agricactivity} != '6' | U36: yes | Y36: =IF(W36<>"",W36*X36,"") | Z36: =IF(AND(W36<>"",U36="yes"),W36*X36,"")
X37: =1 -> 1 | Y37: =IF(W37<>"",W37*X37,"") | Z37: =IF(AND(W37<>"",U37="yes"),W37*X37,"")
A38: select_one yes_no | B38: resp_id | C38: Are you the head of household? | D38: ¿Es usted la cabeza del hogar? | I38: true | U38: yes
A39: select_one gender | B39: hh_gender | C39: Is the head of your household male or female? | D39: ¿Cuál es el género de la persona cabeza de hogar? | I39: true | M39: ${resp_id} != '1' | U39: yes | W39: 10.085732 | X39: =1 -> 1 | Y39: =IF(W39<>"",W39*X39,"") -> 10.085732 | Z39: =IF(AND(W39<>"",U39="yes"),W39*X39,"") -> 10.085732
X40: =1 -> 1 | Y40: =IF(W40<>"",W40*X40,"") | Z40: =IF(AND(W40<>"",U40="yes"),W40*X40,"")
A41: select_one edu | B41: hh_education | C41: What is the educational level attained by the head of household? | D41: ¿Cuál es el nivel de educación de la persona cabeza de hogar? | I41: true | U41: yes | W41: 12.894034 | X41: =1 -> 1 | Y41: =IF(W41<>"",W41*X41,"") -> 12.894034 | Z41: =IF(AND(W41<>"",U41="yes"),W41*X41,"") -> 12.894034
...

Sheet choices
A1: list_name | B1: name | C1: label::English (en) | D1: label::Spanish (es) | E1: label:: | F1: my_filter_admin
A2: enumteam | B2: 1 | C2: Enumerator team 1 | D2: Equipo de encuestadores 1
A3: enumteam | B3: 2 | C3: Enumerator team 2 | D3: Equipo de encuestadores 2
A4: enumteam | B4: 3 | C4: Enumerator team 3 | D4: Equipo de encuestadores 3
A5: enumteam | B5: 4 | C5: Enumerator team 4 | D5: Equipo de encuestadores 4
A7: enumerator | B7: 1 | C7: enumerator name 1 | D7: nombre de encuestador 1
A8: enumerator | B8: 2 | C8: enumerator name 2 | D8: nombre de encuestador 2
A9: enumerator | B9: 3 | C9: enumerator name 3 | D9: nombre de encuestador 3
A11: yes_no | B11: 1 | C11: Yes | D11: SI
A12: yes_no | B12: 2 | C12: No | D12: NO
A13: yes_no | B13: 3 | C13: DON'T KNOW | D13: NO SABE
A14: yes_no | B14: 4 | C14: REFUSED | D14: NO RESPONDE
A16: continue | B16: continue | C16: continue | D16: continuar
A18: yesno | B18: 1 | C18: Yes | D18: Si
A19: yesno | B19: 2 | C19: No | D19: No
A21: language | B21: en | C21: English | D21: Inglés
A22: language | B22: es | C22: Spanish | D22: Español
A23: language | B23: … | C23: …
A25: gender | B25: 1 | C25: Male | D25: Masculino
A26: gender | B26: 2 | C26: Female | D26: Femenino
A27: gender | B27: 3 | C27: DON'T KNOW | D27: NO SABE
A28: gender | B28: 4 | C28: REFUSED | D28: NO RESPONDE
A30: contact_info | B30: 1 | C30: YES - mine | D30: SI - mio
A31: contact_info | B31: 2 | C31: YES - other household member | D31: SI - De otro miembro del hogar
A32: contact_info | B32: 3 | C32: YES - friend or relative [non-household member] | D32: SI - De un amigo o familiar [no miembro del hogar]
A33: contact_info | B33: 4 | C33: NO | D33: NO
A35: agricactivity | B35: 1 | C35: Yes - crop production | D35: Sí - producción de cultivos
A36: agricactivity | B36: 2 | C36: Yes - livestock production | D36: Sí - producción ganadería/ animales
A37: agricactivity | B37: 3 | C37: Yes - both crop and livestock production | D37: Sí - ambas, producción de cultivos y animal
A38: agricactivity | B38: 4 | C38: No | D38: No
... A86: residence | B86: 7 | C86: REFUSED | D86: NO RESPONDE
A88: asset_prod | B88: process | C88: Processing assets (e.g. grinding/crushing machine, mill, oil press, fish tanks) | D88: Activos para el procesamiento [ej: trituradora, molino, prensa para aceite, tanques para la acuicultura / peceras]
A89: asset_prod | B89: farmmach | C89: Farm or fishing machinery (e.g. tractor, plough, sickle, boats, engines) | D89: Maquinaria agrícola o pesquera [ej: tractor, arado, hoz, botes, motores]
A90: asset_prod | B90: sewing | C90: Sewing machine or weaving tool | D90: Máquina de coser
A91: asset_prod | B91: taxi | C91: Taxi | D91: Taxi
A92: asset_prod | B92: truck | C92: Truck | D92: Camión
A93: asset_prod | B93: other | C93: Other productive machines or assets | D93: Otras máquinas productivas
A94: asset_prod | B94: none | C94: No productive machines or assets | D94: Ningúna máquina porductiva
A95: asset_prod | B95: dk | C95: DON'T KNOW | D95: NO SABE
A96: asset_prod | B96: ref | C96: REFUSED | D96: NO RESPONDE
...

Sheet settings
A1: version | B1: default_language | C1: allow_choice_duplicates | D1: style
A2: vM6cWXyHNhR3djPbARkHWi | B2: Spanish (es) | C2: yes | D2: theme-grid no-text-transform

Sheet Crop list
C3: Select top 10 crops | D3: Dataset code | E3: Label (EN) | F3: Label (ES)
C4: x | D4: 1.1 | E4: Rice | F4: Arroz
D5: 1.2 | E5: Wheat | F5: Trigo
D6: 1.3 | E6: Millet | F6: Mijo
C7: x | D7: 1.4 | E7: Sorghum | F7: Sorgo
C8: x | D8: 1.5 | E8: Maize | F8: Maíz
D9: 1.6 | E9: Barley | F9: Cebada
D10: 1.99 | E10: Other Cereal | F10: Otros cereales
C11: x | D11: 2.1 | E11: Cassava | F11: Yuca
D12: 2.2 | E12: Potatoe | F12: Patatas
D13: 2.3 | E13: Sweet Potatoes | F13: Patatas dulces
D14: 2.4 | E14: Yams | F14: Ñames
D15: 2.5 | E15: Carrots | F15: Zanahorias
D16: 2.6 | E16: Cocoyam | F16: Cocoyam
D17: 2.99 | E17: Other tubers | F17: Otros tubérculos
C18: x | D18: 3.1 | E18: Beans | F18: Frijoles
D19: 3.2 | E19: Lentils | F19: Lentejas
D20: 3.3 | E20: Peas | F20: Guisantes
D21: 3.4 | E21: Soybeans | F21: Soja
D22: 3.5 | E22: Chickpeas | F22: Garbanzos
D23: 3.6 | E23: Fava beans | F23: Habas
D24: 3.7 | E24: Broad beans | F24: Habas
D25: 3.99 | E25: Other pulses | F25: Otras legumbres
D26: 4.1 | E26: Cabbage | F26: Coles
D27: 4.2 | E27: Lettuce | F27: Lechuga
D28: 4.3 | E28: Spinach-Amaranth | F28: Espinacas-amaranto
D29: 4.4 | E29: Cassava leaves | F29: Hojas de yuca/mandioca
D30: 4.5 | E30: Potatoe leaves | F30: Hojas de patata
... D47: 5.99 | E47: Other non leafy vegs | F47: Otras verduras
C48: x | D48: 6.1 | E48: Orange | F48: Naranja
D49: 6.2 | E49: Lemon | F49: Limón
D50: 6.3 | E50: Grapefruit | F50: Pomelo
D51: 6.4 | E51: Mandarins/clementines | F51: Mandarinas
D52: 6.99 | E52: Other citrus fruit | F52: Otros cítricos
D53: 7.1 | E53: Sweet Banana | F53: Plátano dulce / bananas
C54: x | D54: 7.2 | E54: Plantains | F54: Plátano
D55: 7.3 | E55: Papaya | F55: Papaya
D56: 7.4 | E56: Mango | F56: Mango
D57: 7.5 | E57: Guava | F57: Guayaba
D58: 7.6 | E58: Pineapple | F58: Piña
...

Sheet Additional information
C2: Original | D2: Replacement (EN) | E2: Replacement (ES) | F2: Comment (ES) | G2: Comment (EN) | H2: Exemple (ES) | I2: Example(EN)
B3: FOR CORE QUESTIONS . (Mandatory to fill out) . | C3: phone number | D3: 70****** | E3: 70****** | F3: Escriba un número de teléfono de su país en el formato típico, por ejemplo 77******* [por favor, utilice exactamente el número de caracteres que se encuentran en un número de teléfono]. | G3: Type a phone number from your country in typical format, e.g. 77******* [please use exactly the number of characters that are found in a phone number]. | H3: 070****** | I3: 070******
C4: age | D4: 18 | E4: 18 | F4: Edad mínima del encuestado (recomendamos 18 años). | G4: Minimum age of respondent (recommend 18 years old) | H4: 18 | I4: 18
C5: ADMIN1 | D5: Department | E5: Departamento | F5: La primera subdivisión del país, después del nivel nacional; región; provincia; gobernación; etc. Solo una palabra debe ser ingresada - No incluir espacios. | G5: The first subdivision of the country, after national level; region; province; governorate; etc. Only one word should be inputted - Do not include spaces. | H5: departamento | I5: department
C6: ADMIN2 | D6: Municipality | E6: Municipio | F6: La segunda subdivisión del país; distrito; municipio; LGA; etc. Solo una palabra debe ser ingresada - No incluir espacios. | G6: The second subdivision of the country; district; municipality; LGA; etc. Only one word should be inputted - Do not include spaces. | H6: municipio | I6: municipality
C7: reference year | D7: last year | E7: el año pasado | F7: Las preguntas de comparación necesitarán un año de referencia. Seleccione si desea utilizar "el año pasado" o "un año normal" como referencia. Un "año normal" debe referirse a un año promedio de los últimos 5 años; asegúrese de capacitar a los encuestadores en consecuencia. | G7: Comparison questions will need need a reference year. Select whether you want to use "last year" or "a normal year" as a baseline. A "normal year" should refers to an average year from the past 5 years - make sure to train the enumerators accordingly. | H7: un año normal | I7: a normal year
C8: season | D8: First | E8: Primera | F8: Nombre la(s) temporada(s) de cultivo de interés si hay varias temporadas de cultivo en el país (por ejemplo, Meher y Belg en Etiopía, temporada de lluvias/cultivo de recesión por inundación/temporada seca irrigada en el Sahel). Puede referirse a la "última temporada" o "temporada en curso". | G8: Name the crop season(s) of interest if there are several cropping seasons in the country (e.g. Meher and Belg in Ethiopia, rainy season / flood-recession cropping / irrigated dry season in the Sahel). You can refer to the “last season” or “ongoing season". | H8: la temporada de siembra de primera | I8: the first planting season
C9: season phase | D9: Recently Finished | E9: terminado recientemente | F9: Indique la fase de la temporada en el momento de la recogida de datos. Si la cosecha de la temporada aún no ha ocurrido, la pregunta sobre la cosecha del cultivo (crp_harv_change) incluirá la palabra "esperado" (donde se ubica #esperado o nada#). Si la cosecha ha ocurrido, no se insertará "esperado" en la pregunta. | G9: Indicate the phase of the season at the time of data collection. If the harvest from the season has not yet occurred, the question on crop harvest (crp_harv_change) will include the word “expected” (where #expected or nothing# is located). If the harvest has occured, "expected" will not be inserted in the question. | H9: cosecha | I9: Harvesting
C10: local measurement unit | D10: Manzanas | E10: Manzanas | F10: Especifique la unidad de medida local para el area sembrada, que no sean acres, hectáreas, metros cuadrados y pies cuadrados. Si no se necesita otra unidad de medida, deje esta celda en blanco. | G10: Specify the local measurement unit for land size, other than acres, hectares, square meters and square feet. If no other unit of measurement is needed, keep this cell blank. | H10: Manzanas | I10: Manzanas
C11: local measurement unit conversion | D11: 1.43 | E11: 1.43 | F11: Incluir la conversión de la unidad de medida local a hectáreas. En otras palabras, cuántas unidades de medida locales hay en 1 ha. | G11: Include the conversion of the local measurement unit to hectares. In other words, how many local measurement units are in 1 ha. | H11: 1.43 | I11: 1.43
B12: FOR OPTIONAL QUESTIONS . (Fill out if applicable) . | C12: currency | D12: USD | E12: USD | F12: El nombre de la moneda principal utilizada a nivel nacional; USD; quetzales; lempiras; pesos; etc. | G12: The name of the main currency used nationally; USD; Naira; Rial; Pesos; etc. | H12: Pesos | I12: Pesos
C13: MIN AMOUNT | D13: 0 | E13: 0 | F13: El monto mínimo para una fuente de ingresos debe establecerse en 0 o cualquier valor por debajo del cual no sea posible realizar una transacción. Por ejemplo, la moneda/billete más pequeño de una moneda puede valer 1000, en cuyo caso establecería el mínimo en 1000. Proporcione esta entrada en la misma moneda que se especificó anteriormente. Solo se deben ingresar dígitos. | G13: The minimum amount for an income source should be set at 0 or any value below which it is not possible to do a transaction. For example, the smallest coin/banknote in a currency can be 1000, in which case you would set the minimum at 1000. Provide this input in the same currency as specified above. Only digits should be inputted. | H13: 5 | I13: 5
C14: THRESHOLD | D14: 5000 | E14: 5000 | F14: Establezca la cantidad máxima para una fuente de ingresos durante 3 meses. Los encuestadores no podrán ingresar valores por encima de este monto en preguntas relacionadas con montos de ingresos. Usando encuestas representativas anteriores para esta población, puede estimar esta cantidad usando el ingreso medio más cinco (5) desviaciones estándar, a menos que el país tenga una inflación alta. En este último caso, establezca el valor máximo en función del contexto de su país (superior al enfoque propuesto). Proporcione esta entrada en la misma moneda que se especificó anteriormente. Solo se deben ingresar dígitos. | G14: The threshold salary should be calculated to flag outliers (responses that look suspiciously high). Using previous representative surveys for this population, a good estimate is the average plus three (3) standard deviations, which should give the threshold for the 3 or 4% highest income values. Provide this input in the same currency as specified above. Only digits should be inputted. | H14: 1200000 | I14: 1200000
C15: local vegetables | D15: Green chili, onion, pipian, eggplant, carrot, güisquil | E15: Chile verde, cebolla, pipian, berengena, zanahoria, güisquil | F15: Ingrese algunas verduras locales comunes [para usar como ejemplos en el indicador de puntaje de consumo de alimentos]. | G15: Input some common local vegetables [to be used as examples in the food consumption score indicator]. | H15: berenjenas, calabacín, coliflor | I15: eggplants, zucchini, cauliflower
C16: local fruits | D16: mango, apple, jocote, papaya, pineapple, grapes, guava | E16: mango, manzana, jocote, papaya, piña, uvas, guayaba | F16: Ingrese algunas frutas locales comunes [para usar como ejemplos en el indicador de puntaje de consumo de alimentos]. | G16: Input some common local fruits [to be used as examples in the food consumption score indicator]. | H16: manzanas, bananas, naranjas | I16: apples, bananas, oranges
B18: FILL OUT FOR QUESTIONNAIRE DURATION ESTIMATION . | C18: Expected percentage of respondents cultivating crops | D18: 0.35 | E18: 0.35 | F18: Si la encuesta es representativa y no tiene cuotas, escriba la proporción de hogares rurales que cultivan cultivos a nivel nacional, o si la encuesta sigue una ronda anterior con un diseño de muestra idéntico, solo informe el porcentaje de la ronda anterior. Si está utilizando cuotas, calcule la proporción de la cuota sobre el tamaño mínimo de la muestra en el nivel donde se implementa la cuota (por lo que si tiene un tamaño mínimo de muestra por estrato de 110 con una cuota de 100 productores de cultivos, entonces es 100/ 110 = 91% (lo máximo que debe escribir es 100%). | G18: If the survey is representative and has no quotas, write the proportion of rural households cultivating crops at country level, or if the survey follows a previous round with identical sample design, just report the percentage from the previous round. If you are using quotas, calculate the ratio of the quota over the minimum sample size at the level where the quota is implemented (so if you have a minimum sample size per strata of 110 with a quota of 100 crop producers, then it's 100/110 = 91% (the maximum you should write is 100%). | H18: 0.91 | I18: 0.91
C19: Expected percentage of respondents raising livestock | D19: 0.08 | E19: 0.08 | F19: Si la encuesta es representativa y no tiene cuotas, escriba la proporción de hogares rurales que crían animales a nivel nacional, o si la encuesta sigue una ronda anterior con un diseño de muestra idéntico, solo informe el porcentaje de la ronda anterior. Si está utilizando cuotas, calcule la proporción de la cuota sobre el tamaño mínimo de la muestra en el nivel en el que se implementa la cuota (por lo que si tiene un tamaño mínimo de muestra de 110 pero una cuota de 100 productores de ganado, entonces es 100/110 = 91% (lo máximo que debes escribir es 100%) | G19: If the survey is representative and has no quotas, write the proportion of rural households raising livestock at country level, or if the survey follows a previous round with identical sample design, just report the percentage from the previous round. If you are using quotas, calculate the ratio of the quota over the minimum sample size at the level where the quota is implemented (so if you have a minimum sample size of 110 but a quota of 100 livestock producers, then it's 100/110 = 91% (the maximum you should write is 100%) | H19: 0.91 | I19: 0.91
C20: Expected percentage of respondents involved in fishery | D20: 0.01 | E20: 0.01 | F20: Si la encuesta es representativa y no tiene cuotas, escriba la proporción de hogares rurales involucrados en la pesca o la acuicultura; de lo contrario, si está usando cuotas, calcule la proporción de la cuota sobre el tamaño de la muestra en el nivel donde se implementa la cuota. (Entonces, si no ha establecido una cuota y espera tener una proporción representativa de pescadores, simplemente escriba el porcentaje de pescadores en la población a la que se dirige, en el ejemplo a la derecha, 5%) | G20: If the survey is representative and has no quotas, write the proportion of rural households involved in fisheries or aquaculture, otherwise if you are using quotas, calculate the ratio of the quota over the sample size at the level where the quota is implemented. (so if you haven't set a quota, and you expect to have a representative proportion of fishermen, just write the percentage of fishermen in the population you are targeting, in the example to the right, 5%) | H20: 0.05 | I20: 0.05
