Workbook

Sheet survey
A1: type | B1: name | C1: label::Arabic (ar) | D1: label::English (en) | E1: label:: | F1: hint::English (en) | G1: hint::Arabic (ar) | H1: hint:: | I1: required | J1: appearance | K1: constraint | L1: constraint_message::English (en) | M1: constraint_message::Arabic (ar) | N1: relevant | O1: choice_filter | P1: parameters | Q1: calculation | R1: trigger | S1: default | V1: Mandatory | X1: New question duration (sec) | Y1: Estimated percentage of repondents | Z1: Weighted time | AA1: Weighted time for core vars
A2: start | B2: start | Z2: =IF(X2<>"",X2*Y2,"") | AA2: =IF(AND(X2<>"",V2="yes"),X2*Y2,"")
A3: end | B3: end | Z3: =IF(X3<>"",X3*Y3,"") | AA3: =IF(AND(X3<>"",V3="yes"),X3*Y3,"")
A4: today | B4: today | Z4: =IF(X4<>"",X4*Y4,"") | AA4: =IF(AND(X4<>"",V4="yes"),X4*Y4,"")
A5: deviceid | B5: deviceid | Z5: =IF(X5<>"",X5*Y5,"") | AA5: =IF(AND(X5<>"",V5="yes"),X5*Y5,"")
A6: audit | B6: audit
A7: dateTime | B7: Interview_start_Time | C7: وقت بداية المقابلة | D7: Interview Start Time | I7: true | V7: no
A8: select_one enumteam | B8: enum_team | C8: فريق جمع البيانات (حسب المنطقة) | D8: Enumerator team number or code (according to the district) | I8: true
A9: dateTime | B9: First_update_time | Q9: if(${First_update_time}='', now(), ${First_update_time}) | R9: ${enum_team}
A10: select_one enumerator | B10: enumerator | C10: رمز جامع البيانات | D10: Code of enumerator | I10: true | O10: my_filter_admin=${enum_team} | V10: yes | Z10: =IF(X10<>"",X10*Y10,"") | AA10: =IF(AND(X10<>"",V10="yes"),X10*Y10,"")
A11: text | B11: enumerator_ | C11: اسم جامع البيانات | D11: Name of enumerator | I11: true | K11: string-length(.)>=3 | L11: عفوا، الرجاء تقديم نص و شرح اكثر وضوحا. | M11: Sorry, Please provide a much more meaningful text | V11: yes | Z11: =IF(X11<>"",X11*Y11,"") | AA11: =IF(AND(X11<>"",V11="yes"),X11*Y11,"")
A12: note | B12: introduction | C12: مرحبًا سيدي / سيدتي ، اسمي ${enumerator_}. نجري دراسة استقصائية نيابة عن منظمة الأغذية والزراعة للأمم المتحدة (الفاو) حول سبل عيش الأسر والقدرة على الوصول إلى الغذاء في منطقتك. أود أن أطرح عليك بعض الأسئلة حول أسرتك. يستغرق الاستبيان عادةً 30 دقيقة. سيتم الاحتفاظ بسرية تامة بأي معلومات تقدمها ، ولن يتم استخدامها إلا لغرض الدراسة ولن يتم عرضها لأشخاص آخرين. إن مشاركتك الطوعية في نتيجة هذه الدراسة ليست مرتبطة بأي شكل من الأشكال بفرصتك الشخصية في تلقي أي مساعدة. هذا تطوعي ويمكنك اختيار عدم الإجابة على أي من الأسئلة أو جميعها إذا كنت تريد ذلك. ومع ذلك ، نأمل أن تشارك لأن آرائك مهمة. هل لديك اسئلة؟ | D12: Hello sir/ma'am, my name is ${enumerator_}. On behalf of the Food and Agriculture Organization of the United Nations (FAO), we are conducting a survey on household livelihoods and the ability to access food in your area. I would like to ask you some questions about your household. The survey usually takes 30 minutes to complete. Any information that you provide will be kept strictly confidential, only used for the purpose of the survey and will not be shown to other people. Your voluntary participation in the outcome of this interview is NOT IN ANY WAY linked to your personal chance of receiving any assistance. This is voluntary and you can choose not to answer any or all of the questions if you want. However, we hope that you will participate since your views are important. Do you have any questions? | F12: [INSTRUCTIONS: ADDRESS QUESTIONS FROM RESPONDENT, IF ANY.] | G12: [تعليمات: أجب عن أسئلة المُجيب ، إن وجدت] | I12: false | V12: no | X12: 50.82254 | Z12: =IF(X12<>"",X12*Y12,"") | AA12: =IF(AND(X12<>"",V12="yes"),X12*Y12,"")
A13: select_one yesno | B13: resp_agree | C13: هل لديك رغبة في بالمشاركة في هذه الدراسة؟ | D13: Are you interested in participating in this survey? | I13: true | V13: yes | X13: 3.5 | Y13: =1 | Z13: =IF(X13<>"",X13*Y13,"") | AA13: =IF(AND(X13<>"",V13="yes"),X13*Y13,"")
A14: note | B14: Refusal | C14: شكراً جزيلاً على وقتك، سنقوم بحذف إسمك من دراسة اليوم. | D14: Thank you for your time, you will be removed from today's survey. | I14: false | N14: ${resp_agree} = '2' | V14: no | X14: 0 | Y14: 1 | Z14: =IF(X14<>"",X14*Y14,"") | AA14: =IF(AND(X14<>"",V14="yes"),X14*Y14,"")
A15: begin_group | B15: eligibility | C15: 1. معايير الأهلية | D15: 1. ELIGIBILITY CRITERIA | I15: false | N15: ${resp_agree} = '1' | V15: yes | Z15: =IF(X15<>"",X15*Y15,"") | AA15: =IF(AND(X15<>"",V15="yes"),X15*Y15,"")
A16: text | B16: resp_firstname | C16: 1.1 ما اسمك؟ | D16: 1.1 What is your first name? | F16: [INSTRUCTIONS: RECORD THE RESPONDENT'S FIRST NAME. ENTER 999 FOR REFUSED] | G16: [تعليمات: سجل اسم المجيب. أدخل 999 في حالة الرفض] | I16: true | K16: string-length(.)>=3 | L16: عفوا، الرجاء تقديم نص و شرح اكثر وضوحا. | M16: Sorry, Please provide a much more meaningful text | V16: yes | X16: 10 | Y16: =1 | Z16: =IF(X16<>"",X16*Y16,"") | AA16: =IF(AND(X16<>"",V16="yes"),X16*Y16,"")
A17: text | B17: resp_lastname | C17: 1.2 ما هو لقبك\كنيتك؟ | D17: 1.2 What is your last name? | F17: [INSTRUCTIONS: RECORD THE RESPONDENT'S LAST NAME. ENTER 999 FOR REFUSED] | G17: [تعليمات: سجل اسم عائلة المجيب. أدخل 999 في حالة الرفض] | I17: true | K17: string-length(.)>=3 | L17: عفوا، الرجاء تقديم نص و شرح اكثر وضوحا. | M17: Sorry, Please provide a much more meaningful text | V17: yes | X17: 10 | Y17: =1 | Z17: =IF(X17<>"",X17*Y17,"") | AA17: =IF(AND(X17<>"",V17="yes"),X17*Y17,"")
A18: integer | B18: resp_age | C18: 1.3 كم عمرك؟ | D18: 1.3 How old are you? | F18: [INSTRUCTIONS: RECORD AGE IN NUMBER OF YEARS. ROUND UP TO NEAREST WHOLE NUMBER. IF THE RESPONDENT GIVES BIRTH YEAR, REPEAT THE QUESTION. ENTER 888 FOR DON'T KNOW.] | G18: [تعليمات: سجل العمر في عدد السنوات. قم بالتقريب لأقرب رقم كامل. إذا أعطى المجيب سنة الميلاد ، فكرر السؤال. أدخل 888 إذا كان الجواب لا أعرف] | I18: true | K18: (. >= 16 and . <= 100) or . = 888 | V18: yes | X18: 13.753073 | Y18: =1 | Z18: =IF(X18<>"",X18*Y18,"") | AA18: =IF(AND(X18<>"",V18="yes"),X18*Y18,"")
A19: select_one gender | B19: resp_gender | C19: 1.4 ما هو جنس المجيب؟ | D19: 1.4 What is the gender of the respondent? | F19: [INSTRUCTIONS: DO NOT ASK THIS QUESTION OUT LOUD. SELECT THE GENDER OF THE RESPONDENT.] | G19: [تعليمات: لا تطرح هذا السؤال. حدد جنس المجيب] | I19: true | V19: no | X19: 2.1173561 | Y19: =1 | Z19: =IF(X19<>"",X19*Y19,"") | AA19: =IF(AND(X19<>"",V19="yes"),X19*Y19,"")
A20: text | B20: phone_number_personal | C20: 1.5 ما هو رقم هاتفك؟ | D20: 1.5 What is your phone number? | I20: false | J20: numbers | K20: regex(.,'^(\+?( |-|\.)?\d{1,2}( |-|\.)?)?(\(?\d{3}\)?|\d{3})( |-|\.)?(\d{2,3}( |-|\.)?\d{4,6})$') | L20: Please enter a valid phone number | M20: الرجاء ادخال رقم هاتف صحيح | V20: yes - panel | X20: 10 | Y20: =1 | Z20: =IF(X20<>"",X20*Y20,"") | AA20: =IF(AND(X20<>"",V20="yes"),X20*Y20,"")
A21: select_one contact_info | B21: contact_2 | C21: 1.6 هل يمكن أن تعطيني رقم هاتف إضافي يخصك ، أو يخص قريبًا أو صديقًا يمكن الوصول إليك من خلاله؟ | D21: 1.6 Can you give me an additional phone number belonging to you, a relative or a friend at which you can be reached? | I21: false | V21: yes - panel | X21: 10 | Y21: =1 | Z21: =IF(X21<>"",X21*Y21,"") | AA21: =IF(AND(X21<>"",V21="yes"),X21*Y21,"")
A22: text | B22: phone_number_2 | C22: 1.7 ما هو رقم الهاتف الإضافي؟ | D22: 1.7 What is the additional phone number? | I22: false | J22: numbers | K22: regex(.,'^(\+?( |-|\.)?\d{1,2}( |-|\.)?)?(\(?\d{3}\)?|\d{3})( |-|\.)?(\d{2,3}( |-|\.)?\d{4,6})$') | L22: Please enter a valid phone number | M22: الرجاء ادخال رقم هاتف صحيح | N22: ${contact_2} = '1' or ${contact_2} = '2' or ${contact_2} = '3' | V22: yes - panel | X22: 10 | Y22: =1 | Z22: =IF(X22<>"",X22*Y22,"") | AA22: =IF(AND(X22<>"",V22="yes"),X22*Y22,"")
A23: text | B23: contact_2_name | C23: 1.8 ما هو اسم صاحب رقم الهاتف الإضافي الذي قمت بمشاركته؟ | D23: 1.8 What is the name of the contact? | I23: false | K23: string-length(.)>=3 | L23: عفوا، الرجاء تقديم نص و شرح اكثر وضوحا. | M23: Sorry, Please provide a much more meaningful text | N23: ${contact_2} = '2' or ${contact_2} = '3' | V23: yes - panel | X23: 10 | Y23: =1 | Z23: =IF(X23<>"",X23*Y23,"") | AA23: =IF(AND(X23<>"",V23="yes"),X23*Y23,"")
A24: select_one admin1 | B24: adm1_pcode | C24: 1.9 حاليًا ، في أي محافظة تقيم أسرتك؟ | D24: 1.9 Currently, in which Governorate does your household reside? | F24: [HINT: HOUSEHOLD CONSISTS OF ALL MEMBERS LIVING TOGETHER, SHARING RESOURCES & EATING FROM THE SAME POT.] | G24: [ملحوظة: تتكون الأسرة من جميع الأعضاء الذين يعيشون معًا ، ويتشاركون الموارد ويأكلون من نفس القدر] | I24: true | J24: autocomplete | V24: yes | X24: 8.8 | Y24: =1 | Z24: =IF(X24<>"",X24*Y24,"") | AA24: =IF(AND(X24<>"",V24="yes"),X24*Y24,"")
A25: calculate | B25: adm1_name | Q25: jr:choice-name(${adm1_pcode},'${adm1_pcode}') | V25: yes | Y25: =1 | Z25: =IF(X25<>"",X25*Y25,"") | AA25: =IF(AND(X25<>"",V25="yes"),X25*Y25,"")
A26: select_one admin2 | B26: adm2_pcode | C26: 1.10 حاليًا ، في أي منطقة تقيم أسرتك؟ | D26: 1.10 Currently, in which District does your household reside? | F26: [HINT: HOUSEHOLD CONSISTS OF ALL MEMBERS LIVING TOGETHER, SHARING RESOURCES & EATING FROM THE SAME POT.] | G26: [ملحوظة: تتكون الأسرة من جميع الأعضاء الذين يعيشون معًا ، ويتشاركون الموارد ويأكلون من نفس القدر] | I26: true | J26: autocomplete | O26: my_filter_admin=${adm1_pcode} | V26: yes | X26: 10.4 | Y26: =1 | Z26: =IF(X26<>"",X26*Y26,"") | AA26: =IF(AND(X26<>"",V26="yes"),X26*Y26,"")
A27: calculate | B27: adm2_name | Q27: jr:choice-name(${adm2_pcode},'${adm2_pcode}') | V27: yes | Y27: =1 | Z27: =IF(X27<>"",X27*Y27,"") | AA27: =IF(AND(X27<>"",V27="yes"),X27*Y27,"")
A28: select_one admin3 | B28: adm3_pcode | C28: 1.11 حاليًا ، في أي ناحية تقيم أسرتك؟ | D28: 1.11 Currently, in which Sub-District does your household reside? | F28: [HINT: HOUSEHOLD CONSISTS OF ALL MEMBERS LIVING TOGETHER, SHARING RESOURCES & EATING FROM THE SAME POT.] | G28: [ملحوظة: تتكون الأسرة من جميع الأعضاء الذين يعيشون معًا ، ويتشاركون الموارد ويأكلون من نفس القدر] | I28: true | J28: autocomplete | O28: my_filter_admin=${adm2_pcode} | V28: yes | X28: 8.8 | Y28: =1 | Z28: =IF(X28<>"",X28*Y28,"") | AA28: =IF(AND(X28<>"",V28="yes"),X28*Y28,"")
A29: calculate | B29: adm3_name | Q29: jr:choice-name(${adm3_pcode},'${adm3_pcode}') | V29: yes | Y29: =1 | Z29: =IF(X29<>"",X29*Y29,"") | AA29: =IF(AND(X29<>"",V29="yes"),X29*Y29,"")
A30: select_one admin4 | B30: adm4_pcode | C30: 1.12 حاليًا ، في أي مجتمع تقيم أسرتك؟ | D30: 1.12 Currently, in which Community does your household reside? | F30: [HINT: HOUSEHOLD CONSISTS OF ALL MEMBERS LIVING TOGETHER, SHARING RESOURCES & EATING FROM THE SAME POT.] | G30: [ملحوظة: تتكون الأسرة من جميع الأعضاء الذين يعيشون معًا ، ويتشاركون الموارد ويأكلون من نفس القدر] | I30: true | J30: autocomplete | O30: my_filter_admin=${adm3_pcode} | V30: yes | X30: 10.4 | Y30: =1 | Z30: =IF(X30<>"",X30*Y30,"") | AA30: =IF(AND(X30<>"",V30="yes"),X30*Y30,"")
A31: calculate | B31: adm4_name | Q31: jr:choice-name(${adm4_pcode},'${adm4_pcode}') | V31: yes | Y31: =1 | Z31: =IF(X31<>"",X31*Y31,"") | AA31: =IF(AND(X31<>"",V31="yes"),X31*Y31,"")
A32: select_one agricactivity | B32: hh_agricactivity | C32: 1.13 هل قام أي شخص في أسرتك بإنتاج المحاصيل أو الثروة الحيوانية أو الأسماك وتربية الأحياء المائية للاستهلاك المنزلي أو للبيع خلال الاثني عشر شهرًا الماضية ، بما في ذلك أفراد الأسرة الغير موجودين بغرض الرعي؟ | D32: 1.13 Have you or anyone in your household been producing vegetables, crops, livestock or fish and aquaculture for household consumption or for sale in the past 12 months, including household members currently away for transhumance? | F32: [INSTRUCTIONS: THIS IS THE MAIN SCREENING QUESTION.] [HINT FOR PROBING: Do you cultivate any plants to sale or consume? Do you raise any animals with the intent of selling or consuming them or their products like meat, milk, wool or leather? Is one of your household member currently away with cattle or other animals for transhumance?] | G32: [تعليمات: هذا هو سؤال الفرز الرئيسي] [ملحوظة للتحقيق: هل قمت بزراعة أي نباتات للبيع أو الاستهلاك ؟ هل قمت بتربية أي حيوانات بنية البيع أو الاستهلاك أو انتاج منتجات مثل اللحوم و الالبان و الصوف و الجلد ؟ هل أي فرد من أفراد أسرتك حاليا بعيدًا عن الأسرة مع الماشية أو حيوانات أخري بغرض التنقل الرعوي ؟] | I32: true | V32: yes | X32: 31.372377 | Y32: =1 | Z32: =IF(X32<>"",X32*Y32,"") | AA32: =IF(AND(X32<>"",V32="yes"),X32*Y32,"")
A33: select_one yes_no | B33: hh_agricactivity_conflict | C33: 1.14 هل قام أي شخص في أسرتك بإنتاج المحاصيل أو الثروة الحيوانية أو الأسماك وتربية الأحياء المائية للاستهلاك المنزلي أو للبيع منذ بداية الصراع عام ٢٠١١؟ | D33: 1.14 Have you or anyone in your household been producing vegetables, crops, livestock or fish and aquaculture for household consumption or for sale since the start of the conflict in 2011? | F33: [HINT FOR PROBING: Did you cultivate any plants to sale or consume? Did you raise any animals with the intent of selling or consuming them or their products like meat, milk, wool or leather?] | G33: ملحوظة للتحقيق: هل قمت بزراعة أي نباتات للبيع أو الاستهلاك ؟ هل قمت بتربية أي حيوانات بنية البيع أو الاستهلاك أو انتاج منتجات مثل اللحوم و الالبان و الصوف و الجلد ؟ | I33: true | N33: ${hh_agricactivity}='4'
A34: select_one yes_no | B34: hh_agricactivity_ever | C34: 1.15 هل قام أي شخص في أسرتك بإنتاج المحاصيل أو الثروة الحيوانية أو الأسماك وتربية الأحياء المائية للاستهلاك المنزلي أو للبيع من قبل؟ | D34: 1.15 Have you or anyone in your household ever produced vegetables, crops, livestock or fish and aquaculture for household consumption or for sale? | F34: [HINT FOR PROBING: Did you cultivate any plants to sale or consume? Did you raise any animals with the intent of selling or consuming them or their products like meat, milk, wool or leather?] | G34: ملحوظة للتحقيق: هل قمت بزراعة أي نباتات للبيع أو الاستهلاك ؟ هل قمت بتربية أي حيوانات بنية البيع أو الاستهلاك أو انتاج منتجات مثل اللحوم و الالبان و الصوف و الجلد ؟ | I34: true | N34: ${hh_agricactivity_conflict}='2'
A35: select_one agric_checktime | B35: hh_agricactivity_stopduration | C35: 1.16 منذ متى توقفت أسرتك عن الأنشطة الزراعية؟ | D35: 1.16 For how long has your household stopped agricultural activities? | I35: true | N35: ${hh_agricactivity}='4' and (${hh_agricactivity_conflict}='1' or ${hh_agricactivity_ever}='1')
A36: select_one reason_stop | B36: hh_agricactivity_stopreason | C36: 1.17 لماذا أوقفت أسرتك أنشطتها الزراعية؟ | D36: 1.17 Why has your household stopped agricultural activities? | I36: true | N36: ${hh_agricactivity}='4' and (${hh_agricactivity_conflict}='1' or ${hh_agricactivity_ever}='1')
A37: text | B37: hh_agricactivity_stopreason_otherspecify | C37: 1.18 إذا كانت الإجابة "آخر"، حدد | D37: 1.18 If other, specify. | F37: [INSTRUCTIONS: RECORD THE OPEN RESPONSE GIVEN IN FEW WORDS. ENTER 888 FOR DON'T KNOW AND 999 FOR REFUSED] | G37: [تعليمات: سجل في بضع كلمات الاستجابة المفتوحة المعطاة . أدخل 888 للا أعرف و 999 في حالة الرفض] | I37: true | K37: string-length(.)>=3 | L37: عفوا، الرجاء تقديم نص و شرح اكثر وضوحا. | M37: Sorry, Please provide a much more meaningful text | N37: ${hh_agricactivity_stopreason} = 'other' | V37: yes | Y37: ='Additional information'!$C$14 | Z37: =IF(X37<>"",X37*Y37,"") | AA37: =IF(AND(X37<>"",V37="yes"),X37*Y37,"")
A38: select_one yes_no | B38: hh_agricactivity_resume_will | C38: 1.19 هل تنوي استئناف النشاط الزراعي؟ | D38: 1.19 Are you willing to resume agricultural activity ? | I38: true | N38: ${hh_agricactivity}='4' and (${hh_agricactivity_conflict}='1' or ${hh_agricactivity_ever}='1')
A39: select_one agric_checkresume | B39: hh_agricactivity_resume_date | C39: 1.20 متى تعتقد أن أسرتك ستكون قادر على استئناف الأنشطة الزراعية؟ | D39: 1.20 When do you think that your household will be able to resume agricultural activities? | I39: true | N39: ${hh_agricactivity}='4' and (${hh_agricactivity_conflict}='1' or ${hh_agricactivity_ever}='1') and ${hh_agricactivity_resume_will}='1' | Y39: =1 | Z39: =IF(X39<>"",X39*Y39,"") | AA39: =IF(AND(X39<>"",V39="yes"),X39*Y39,"")
A40: end_group | Z40: =IF(X40<>"",X40*Y40,"") | AA40: =IF(AND(X40<>"",V40="yes"),X40*Y40,"")
...

Sheet choices
A1: list_name | B1: name | C1: label::English (en) | D1: label::Arabic (ar) | E1: label:: | F1: my_filter_admin | G1: agfilter1 | H1: agfilter2 | I1: agfilter3 | J1: agfilter4
A2: enumteam | B2: 1 | C2: 1. Al Bab | D2: 1. الباب
A3: enumteam | B3: 2 | C3: 2. Afrin | D3: 2. عفرين
A4: enumteam | B4: 3 | C4: 3. A'zaz | D4: 3. اعزاز
A5: enumteam | B5: 4 | C5: 4. Jarablus | D5: 4. جرابلس
A6: enumteam | B6: 5 | C6: 5. Harim | D6: 5. حارم
A7: enumteam | B7: 6 | C7: 6. Idleb | D7: 6. إدلب
A8: enumteam | B8: 7 | C8: 7. Jebel Saman | D8: 7. جبل سمعان
A10: enumerator | B10: 1 | C10: C1202AS009 | D10: C1202AS009 | F10: 1
A11: enumerator | B11: 2 | C11: C1202BS020 | D11: C1202BS020 | F11: 1
A12: enumerator | B12: 3 | C12: C1202TT013 | D12: C1202TT013 | F12: 1
A13: enumerator | B13: 4 | C13: C1202ME002 | D13: C1202ME002 | F13: 1
A14: enumerator | B14: 5 | C14: C1202BA010 | D14: C1202BA010 | F14: 1
A15: enumerator | B15: 6 | C15: C1202FA003 | D15: C1202FA003 | F15: 1
A16: enumerator | B16: 7 | C16: SY020304MI002 | D16: SY020304MI002 | F16: 2
A17: enumerator | B17: 8 | C17: C1366MM015 | D17: C1366MM015 | F17: 2
A18: enumerator | B18: 9 | C18: C6115FA001 | D18: C6115FA001 | F18: 2
A19: enumerator | B19: 10 | C19: SY020301MI003 | D19: SY020301MI003 | F19: 2
A20: enumerator | B20: 11 | C20: SY020301LA002 | D20: SY020301LA002 | F20: 2
A21: enumerator | B21: 12 | C21: C6287MS002 | D21: C6287MS002 | F21: 2
... A61: enumerator | B61: 52 | C61: C1022BE023 | D61: C1022BE023 | F61: 7
A63: yes_no | B63: 1 | C63: Yes | D63: نعم
A64: yes_no | B64: 2 | C64: No | D64: لا
A65: yes_no | B65: dk | C65: Don't know | D65: لا أعرف
A66: yes_no | B66: ref | C66: Refused | D66: رفض الإجابة
A68: continue | B68: continue | C68: continue | D68: تابع
A70: yesno | B70: 1 | C70: Yes | D70: نعم
A71: yesno | B71: 2 | C71: No | D71: لا
A73: language | B73: en | C73: English | D73: الإنجليزية
A74: language | B74: ar | C74: Arabic | D74: العربية
A76: gender | B76: 1 | C76: Male | D76: ذكر
A77: gender | B77: 2 | C77: Female | D77: أنثى
A78: gender | B78: dk | C78: Don't know | D78: لا أعرف
A79: gender | B79: ref | C79: Refused | D79: رفض الإجابة
A81: contact_info | B81: 1 | C81: YES - mine | D81: نعم - لي
A82: contact_info | B82: 2 | C82: YES - other household member | D82: نعم - فرد اخر من أفراد الأسرة
A83: contact_info | B83: 3 | C83: YES - friend or relative (non-household member) | D83: نعم - أحد الأقارب او الاصدقاء [ ليس فردا من أفراد الأسرة]
A84: contact_info | B84: 4 | C84: NO | D84: لا
C86: Wheat | D86: القمح
C87: Maize | D87: الذرة
...

Sheet settings
A1: version | B1: default_language | C1: allow_choice_duplicates | D1: style
A2: vM6cWXyHNhR3djPbARkHWi | B2: Arabic (ar) | C2: yes | D2: theme-grid no-text-transform

Sheet Crop list
C3: Select top 10 crops / حدد أكبر 10 محاصيل | D3: Dataset code | E3: Label (EN) | F3: Label (AR)
D4: 1.1 | E4: Rice | F4: الرز
C5: x | D5: 1.2 | E5: Wheat | F5: القمح
D6: 1.3 | E6: Millet | F6: الدخن
D7: 1.4 | E7: Sorghum | F7: الذرة الرفيعة
C8: x | D8: 1.5 | E8: Maize | F8: الذرة
C9: x | D9: 1.6 | E9: Barley | F9: الشعير
D10: 1.99 | E10: Other Cereal | F10: الحبوب الأخرى
D11: 2.1 | E11: Cassava | F11: الكسافا
C12: x | D12: 2.2 | E12: Potatoe | F12: البطاطا
D13: 2.3 | E13: Sweet Potatoes | F13: البطاطا الحلوة
D14: 2.4 | E14: Yams | F14: اليام
D15: 2.5 | E15: Carrots | F15: الجزر
D16: 2.6 | E16: Cocoyam | F16: القلقاس
D17: 2.99 | E17: Other tubers | F17: الدرنات الأخرى
C18: x | D18: 3.1 | E18: Beans | F18: الفاصوليا
C19: x | D19: 3.2 | E19: Lentils | F19: العدس
C20: x | D20: 3.3 | E20: Peas | F20: البازيلاء
C21: x | D21: 3.4 | E21: Soybeans | F21: فول الصويا
C22: x | D22: 3.5 | E22: Chickpeas | F22: الحمص
C23: x | D23: 3.6 | E23: Fava beans | F23: الفول
D24: 3.7 | E24: Broad beans | F24: الفاصوليا العريضة
D25: 3.99 | E25: Other pulses | F25: البقول الاخرى
D26: 4.1 | E26: Cabbage | F26: الملفوف
C27: x | D27: 4.2 | E27: Lettuce | F27: الخس
D28: 4.3 | E28: Spinach-Amaranth | F28: السبانخ - القطيفة
D29: 4.4 | E29: Cassava leaves | F29: أوراق الكسافا
D30: 4.5 | E30: Potatoe leaves | F30: أوراق البطاطا
D31: 4.6 | E31: Moringa | F31: المورينجا
D32: 4.7 | E32: Sorrel Hibiscus / Rosselle | F32: الكركديه
C33: x | D33: 4.9 | E33: Green salad herbs (thyme, parsley, mint, rocca, other) | F33: أعشاب السلطة الخضراء [زعتر ، بقدونس ، نعناع ، جرجير ، أنواع أخرى]
D34: 4.101 | E34: Cauliflower | F34: القرنبيط
D35: 4.99 | E35: Other leafy vegetables | F35: الخضار الورقية الأخرى
C36: x | D36: 5.1 | E36: Tomatoes | F36: الطماطم
C37: x | D37: 5.2 | E37: Cucumber | F37: الخيار
D38: 5.3 | E38: Pumpkin | F38: اليقطين
C39: x | D39: 5.4 | E39: Eggplant/aubergine | F39: الباذنجان
C40: x | D40: 5.5 | E40: Zucchini | F40: الكوسة
C41: x | D41: 5.6 | E41: Okra | F41: البامية
C42: x | D42: 5.7 | E42: Bell pepper | F42: الفلفل حلو
...

Sheet Additional information
B2: Original | C2: Replacement (AR) | D2: Replacement (EN) | E2: Comment (AR) | F2: Comment (EN) | G2: Exemple (AR) | H2: Example(EN)
B3: age | C3: 16 | D3: =IF(C3="","",C3) | E3: الحد الأدنى لسن المجيب (يفضل أن يكون عمره 18 عامًا على الأقل). يرجى إدخال الأرقام في الأبجدية اللاتينية (...3, 2, 1). | F3: Minimum age of respondent (recommend 18 years old). Only digits in Latin numbers should be inputted. | G3: 18 | H3: 18
B4: ADMIN1 | C4: المحافظة | D4: Governorate | E4: التقسيم الأول للبلاد ، بعد المستوى الوطني ؛ منطقة؛ محافظة؛ ولاية ؛ إلخ. يجب إدخال كلمة واحدة فقط - لا تقم بتضمين مسافات. | F4: The first subdivision of the country, after national level; region; province; governorate; etc. Only one word should be inputted - Do not include spaces. | G4: منطقة | H4: region
B5: ADMIN2 | C5: المنطقة | D5: District | E5: التقسيم الثاني للبلاد ؛ قضاء؛ بلدية؛ إلخ. يجب إدخال كلمة واحدة فقط - لا تقم بتضمين مسافات. | F5: The second subdivision of the country; district; municipality; LGA; etc. Only one word should be inputted - Do not include spaces. | G5: قضاء | H5: district
B6: ADMIN 3 | C6: الناحية | D6: Sub-District
B7: ADMIN 4 | C7: القرية | D7: Community
B8: reference year | C8: العام العادي | D8: Normal year | E8: سوف تحتاج أسئلة المقارنة إلى سنة مرجعية. حدد ما إذا كنت تريد استخدام "العام الماضي" أو "العام العادي" كخط أساس. يجب أن يشير "العام العادي" إلى متوسط ​​عام من السنوات الخمس الماضية - تأكد من تدريب جامعي البيانات وفقًا لذلك. | F8: Comparison questions will need need a reference year. Select whether you want to use "last year" or "a normal year" as a baseline. A "normal year" should refers to an average year from the past 5 years - make sure to train the enumerators accordingly. | G8: العام العادي | H8: a normal year
B9: season | C9: الموسم الجاري | D9: ongoing season | E9: قم بتسمية موسم (مواسم) المحاصيل ذات الأهمية إذا كان هناك عدة مواسم محصولية في البلد (على سبيل المثال ، Meher و Belg في إثيوبيا ، موسم الأمطار / محاصيل الركود بسبب الفيضانات / موسم الجفاف المروي في منطقة الساحل). يمكنك الرجوع إلى "الموسم الماضي" أو "الموسم الجاري". | F9: Name the crop season(s) of interest if there are several cropping seasons in the country (e.g. Meher and Belg in Ethiopia, rainy season / flood-recession cropping / irrigated dry season in the Sahel). You can refer to the “last season” or “ongoing season". | G9: موسم الأمطار | H9: wet season
B10: local measurement unit | C10: دنم | D10: donum | E10: حدد وحدة القياس المحلية لمساحة الأرض ، بخلاف الفدان والهكتار والمتر المربع والقدم المربع. إذا لم تكن هناك حاجة إلى وحدة قياس أخرى ، احتفظ بهذه الخلية فارغة. | F10: Specify the local measurement unit for land size, other than acres, hectares, square meters and square feet. If no other unit of measurement is needed, keep this cell blank. | G10: جريب | H10: Jeribs
B11: local measurement unit conversion | C11: 0.1 | D11: =IF(C11<>"",C11,"") | E11: قم بتضمين تحويل وحدة القياس المحلية إلى هكتار. بمعنى آخر ، إلى كم هو عدد وحدات القياس المحلية في هكتار واحد. يرجى إدخال الأرقام في الأبجدية اللاتينية (...3, 2, 1). | F11: Include the conversion of the local measurement unit to hectares. In other words, how many local measurement units are in 1 ha. Only digits in Latin numbers should be inputted. | G11: 0.2 | H11: 0.2
B12: currency | C12: دولار أمريكي | D12: USD | E12: اسم العملة الرئيسية المستخدمة وطنيا ؛ دولار أمريكي؛ نيرة؛ الريال؛ بيزو؛ إلخ. | F12: The name of the main currency used nationally; USD; Naira; Rial; Pesos; etc. | G12: نيرة | H12: Naira
B14: Expected percentage of respondents cultivating crops | C14: 0.91 | D14: =IF(C14="","",C14) | E14: إذا كان المسح تمثيليًا وليس له حصص نسبية ، فاكتب نسبة الأسر الريفية التي تزرع محاصيل على المستوى الوطني ، أو إذا كان المسح يتبع جولة سابقة بتصميم عينة متطابق ، فما عليك سوى الإبلاغ عن النسبة المئوية من الجولة السابقة. إذا كنت تستخدم نظام الحصص النسبية ، فاحسب نسبة الحصة إلى الحد الأدنى لحجم العينة على المستوى الذي يتم فيه تنفيذ الحصة (لذلك إذا كان لديك حد أدنى لحجم العينة لكل طبقة 110 مع حصة 100 منتج محصول ، فسيكون 100 / 110 = 91٪ (الحد الأقصى الذي يجب أن تكتبه هو 100٪). | F14: If the survey is representative and has no quotas, write the proportion of rural households cultivating crops at country level, or if the survey follows a previous round with identical sample design, just report the percentage from the previous round. If you are using quotas, calculate the ratio of the quota over the minimum sample size at the level where the quota is implemented (so if you have a minimum sample size per strata of 110 with a quota of 100 crop producers, then it's 100/110 = 91% (the maximum you should write is 100%). | G14: 0.91 | H14: 0.91
B15: Expected percentage of respondents raising livestock | C15: 0.91 | D15: =IF(C15="","",C15) | E15: إذا كان المسح تمثيليًا وليس له حصص نسبية ، فاكتب نسبة الأسر الريفية التي تربي الماشية على المستوى الوطني ، أو إذا كان المسح يتبع جولة سابقة بتصميم عينة متطابق ، فما عليك سوى الإبلاغ عن النسبة المئوية من الجولة السابقة. إذا كنت تستخدم نظام الحصص النسبية ، فاحسب نسبة الحصة إلى الحد الأدنى لحجم العينة على المستوى الذي يتم فيه تنفيذ الحصة (لذلك إذا كان لديك حد أدنى لحجم العينة لكل طبقة 110 مع حصة 100 مربي الماشية ، فسيكون 100 / 110 = 91٪ (الحد الأقصى الذي يجب أن تكتبه هو 100٪). | F15: If the survey is representative and has no quotas, write the proportion of rural households raising livestock at country level, or if the survey follows a previous round with identical sample design, just report the percentage from the previous round. If you are using quotas, calculate the ratio of the quota over the minimum sample size at the level where the quota is implemented (so if you have a minimum sample size of 110 but a quota of 100 livestock producers, then it's 100/110 = 91% (the maximum you should write is 100%) | G15: 0.91 | H15: 0.91
B16: Expected percentage of respondents involved in fishery | C16: 0.05 | D16: =IF(C16="","",C16) | E16: إذا كان المسح تمثيليًا وليس له حصص نسبية ، فاكتب نسبة الأسر الريفية العاملة في مصايد الأسماك أو تربية الأحياء المائية على المستوى الوطني. وإلا إذا كنت تستخدم الحصص النسبية ، فاحسب نسبة الحصة إلى حجم العينة على المستوى الذي يتم فيه تنفيذ الحصة. (لذلك إذا لم تحدد حصة ، وكنت تتوقع أن يكون لديك نسبة تمثيلية من الصيادين ، فاكتب فقط النسبة المئوية للصيادين من السكان الذين تستهدفهم ، في المثال على اليمين ، 5٪). | F16: If the survey is representative and has no quotas, write the proportion of rural households involved in fisheries or aquaculture, otherwise if you are using quotas, calculate the ratio of the quota over the sample size at the level where the quota is implemented. (so if you haven't set a quota, and you expect to have a representative proportion of fishermen, just write the percentage of fishermen in the population you are targeting, in the example to the right, 5%) | G16: 0.05 | H16: 0.05
