Workbook

Sheet survey
A1: GeoPoll Submission Form
A2: FAO - Household Questionnaire | N2: Additional notes
A3: Q # | B3: Q Name | C3: Suggested Qname | D3: English | E3: Length | F3: Q Type | G3: Randomize | H3: Conditional | I3: Programming Instructions | J3: Skip Pattern | K3: Codes | L3: Default skip patterns & conditional | M3: Specify skip pattern variable (from blue text) | O3: Estimated percentage of repondents | R3: Mandatory | V3: Duration (sec) | W3: Weighted duration | X3: Core questions only
A4: A. PRESENTATION OF THE SURVEY AND ELIGIBILITY CRITERIA SELECTION | R4: no | W4: =IF(V4="","",V4*T4) | X4: =IF(R4="yes",W4,"")
A5: NA | B5: Optin | D5: Optin | E5: =LEN(D5) -> 5 | F5: Open Ended | G5: NA | H5: NA | I5: Form Type - TextBox | J5: Any Response = phone_number | K5: NA | L5: NA | R5: no | V5: 0 | W5: =IF(V5="","",V5*O5) -> 0 | X5: =IF(R5="yes",W5,"")
A6: NA | B6: phone_number | C6: phone_number | D6: Input the phone number that you are contacting: | E6: =LEN(D6) -> 48 | F6: Open Ended | G6: NA | H6: NA | I6: Form Type - TextBox | J6: Any Response = calldispo | K6: NA | L6: NA | R6: yes | V6: 0 | W6: =IF(V6="","",V6*O6) -> 0 | X6: =IF(R6="yes",W6,"") -> 0
A7: NA | B7: calldispo | C7: calldispo | D7: Phone number: #CATI_MOBILENUMBER# 1)Someone answers 2)Answering machine 3)No answer 4)Hang up or refusal 5)Call back 6)Under review 7)Disconnected | E7: =LEN(D7) -> 146 | F7: Single Choice | G7: NA | H7: NA | I7: Form Type - Buttons | J7: 1 = resp_language 2 = AnsweringMachine 3 = NoAnswer 4 = Refusal 5 = WhenCallBack 6 = UnderReview 7 = Disconnected | K7: NA | L7: NA | R7: no | V7: 14.695308 | W7: =IF(V7="","",V7*O7) -> 0 | X7: =IF(R7="yes",W7,"")
A8: NA | B8: AnsweringMachine | C8: calldispo_answeringmachine | D8: Reached an answering machine. | E8: =LEN(D8) -> 29 | F8: NA | G8: NA | H8: NA | I8: NA | J8: End Poll AnsweringMachine | K8: NA | L8: NA | R8: no | V8: 0 | W8: =IF(V8="","",V8*O8) -> 0 | X8: =IF(R8="yes",W8,"")
A9: NA | B9: NoAnswer | C9: calldispo_noanswer | D9: Phone rang and no one answered. | E9: =LEN(D9) -> 31 | F9: NA | G9: NA | H9: NA | I9: NA | J9: End Poll NoAnswer | K9: NA | L9: NA | R9: no | V9: 0 | W9: =IF(V9="","",V9*O9) -> 0 | X9: =IF(R9="yes",W9,"")
A10: NA | B10: UnderReview | C10: calldispo_underreview | D10: Case needs review by a supervisor. | E10: =LEN(D10) -> 34 | F10: NA | G10: NA | H10: NA | I10: NA | J10: End Poll UnderReview | K10: NA | L10: NA | R10: no | V10: 0 | W10: =IF(V10="","",V10*O10) -> 0 | X10: =IF(R10="yes",W10,"")
A11: NA | B11: Disconnected | C11: calldispo_disconnected | D11: Phone was disconnected or out of service. | E11: =LEN(D11) -> 41 | F11: NA | G11: NA | H11: NA | I11: NA | J11: End Poll Disconnected | K11: NA | L11: NA | R11: no | V11: 0 | W11: =IF(V11="","",V11*O11) -> 0 | X11: =IF(R11="yes",W11,"")
A12: NA | B12: resp_language | C12: resp_language | D12: Which language do you wish to proceed with? [OPERATOR: READ ANSWER CHOICES. SINGLE RESPONSE.] 1)English 2)other options [add as many as necessary] | E12: =LEN(D12) -> 148 | F12: Single Choice | G12: NA | H12: NA | I12: Form Type - Buttons | J12: 1 = introduction [English] 2 = introduction [languages & add more if needed] | K12: NA | L12: For any response, go to introduction | N12: Insert most common national languages here [max 4 for translation with GeoPoll]. | R12: no | V12: 3.1032724 | W12: =IF(V12="","",V12*O12) -> 0 | X12: =IF(R12="yes",W12,"")
A13: NA | B13: introduction | C13: introduction | D13: Hello sir/ma'am, my name is #OPERATOR#, and I am calling from GeoPoll Polling Agency on behalf of the Food and Agriculture Organization of the United Nations [FAO]. We are conducting a survey on household livelihoods and the ability to access food in your area. I would like to ask you some questions about your household. The survey usually takes 15/20 minutes to complete. Any information that you provide will be kept strictly confidential, only used for the purpose of the survey and will not be shown to other people. Your voluntary participation in the outcome of this interview is NOT IN ANY WAY linked to your personal chance of receiving any assistance. This is voluntary and you can choose not to answer any or all of the questions if you want. However, we hope that you will participate since your views are important. You will receive #TOPUP#! of communication credit as an incentive for the participation of the survey. Please note that this call may be recorded for quality purposes. Do you have any questions? [OPERATOR: ADDRESS QUESTIONS FROM RESPONDENT, IF ANY.] 1)CONTINUE | E13: =LEN(D13) -> 1098 | F13: Single Choice | G13: NA | H13: NA | I13: Form Type - Buttons | J13: 1 = Agree | K13: NA | L13: For any response, go to Agree | N13: Set the amount of incentive here, if any. | R13: no | V13: 37.418449 | W13: =IF(V13="","",V13*O13) -> 0 | X13: =IF(R13="yes",W13,"")
A14: NA | B14: Agree | C14: resp_agree | D14: Are you interested in participating in this survey? [OPERATOR: SINGLE RESPONSE] 1)Yes 2)Not now but another time in the week 3)No | E14: =LEN(D14) -> 134 | F14: StartRecording | G14: NA | H14: NA | I14: Form Type - Buttons | J14: 1 = [id_panel OR resp_firstname] 2 = WhenCallBack 3 = resp_refusalwhy | K14: NA | L14: if Agree = 1, go to id_panel OR resp_firstname if Agree = 2, go to WhenCallBack if Agree = 3, go to resp_refusalwhy | O14: 1 | R14: no | V14: 3.8059516 | W14: =IF(V14="","",V14*O14) -> 3.8059516 | X14: =IF(R14="yes",W14,"")
A15: NA | B15: id_panel | C15: id_panel | D15: Have you or any member of your household received a call on behalf of FAO regarding this topic in the past two years? [OPERATOR: SINGLE RESPONSE.] 1)YES 2)NO 3)DON'T KNOW | E15: =LEN(D15) -> 172 | F15: Single Choice | G15: NA | H15: NA | I15: Form Type - Buttons | J15: 1-3 = resp_firstname | K15: NA | L15: For any response, go to resp_firstname | N15: It is highly recommended to include the question id_panel if a panelist approach is used. | O15: 1 | R15: no
A16: NA | B16: resp_refusalwhy | C16: resp_refusalwhy | D16: Please let us know why you have REFUSED to take the survey. [OPERATOR: SINGLE RESPONSE] 1)Not interested 2)Do not want to be recorded 3)Other [specify] | E16: =LEN(D16) -> 153 | F16: Open Ended - Single Choice | G16: NA | H16: NA | I16: Form Type - RadioList | J16: Any Response = Refusal | K16: NA | L16: For any response, go to Refusal | O16: 1 | R16: no | V16: 0 | W16: =IF(V16="","",V16*O16) -> 0 | X16: =IF(R16="yes",W16,"")
A17: NA | B17: WhenCallBack | C17: resp_whencallback | D17: When would it be a good time to call you back? [RECORD HH/MM/DD/MM OF CALLBACK] | E17: =LEN(D17) -> 80 | F17: Open Ended | G17: NA | H17: NA | I17: Form Type - TextBox IsCallBackDemographic | J17: Any Response = CallbackMessageEN | K17: NA | L17: For any response, go to CallbackMessageEN | O17: 1 | R17: no | V17: 0 | W17: =IF(V17="","",V17*O17) -> 0 | X17: =IF(R17="yes",W17,"")
A18: NA | B18: CallbackMessageEN | C18: callbackmessage_en | D18: Thank you, we will call you back at {WhenCallBack} you requested. Thank you again and have a great day! [OPERATOR: ENTER CALL NOTES BELOW, WHO YOU SPOKE TO AND WHAT THEY SAID] | E18: =LEN(D18) -> 176 | F18: Open Ended | G18: NA | H18: NA | I18: Form Type - TextBox | J18: Any Response = End poll callback | K18: NA | L18: NA | O18: 1 | R18: no | V18: 0 | W18: =IF(V18="","",V18*O18) -> 0 | X18: =IF(R18="yes",W18,"")
A19: NA | B19: Ineligible | C19: NA | D19: You are ineligible for this survey. Thank you for your time and please look out for future surveys! | E19: =LEN(D19) -> 99 | F19: NA | G19: NA | H19: NA | I19: NA | J19: End Poll Ineligible | K19: NA | L19: NA | O19: 1 | R19: no | V19: 0 | W19: =IF(V19="","",V19*O19) -> 0 | X19: =IF(R19="yes",W19,"")
A20: NA | B20: Refusal | C20: NA | D20: Thank you for your time, you will be removed from today's survey. | E20: =LEN(D20) -> 65 | F20: NA | G20: NA | H20: NA | I20: NA | J20: End poll declined | K20: NA | L20: NA | O20: 1 | R20: no | V20: 0 | W20: =IF(V20="","",V20*O20) -> 0 | X20: =IF(R20="yes",W20,"")
A21: B. GENERAL INFORMATION & ELIGIBILITY CRITERIA | W21: =IF(V21="","",V21*O21) | X21: =IF(R21="yes",W21,"")
A22: NA | B22: resp_firstname | C22: resp_firstname | D22: What is your first name? [OPERATOR: RECORD THE RESPONDENT'S FIRST NAME. ENTER 999 FOR REFUSED.] | E22: =LEN(D22) -> 96 | F22: Open Ended | G22: NA | H22: NA | I22: Form Type - TextBox | J22: Any Response = resp_lastname | K22: NA | L22: For any response, go to resp_lastname | O22: =1 -> 1 | R22: yes | V22: 25.874027 | W22: =IF(V22="","",V22*O22) -> 25.874027 | X22: =IF(R22="yes",W22,"") -> 25.874027
A23: NA | B23: resp_lastname | C23: resp_lastname | D23: What is your last name? [OPERATOR: RECORD THE RESPONDENT'S LAST NAME. ENTER 999 FOR REFUSED.] | E23: =LEN(D23) -> 95 | F23: Open Ended | G23: NA | H23: NA | I23: Form Type - TextBox | J23: Any Response = resp_age | K23: NA | L23: For any response, go to resp_age | O23: =1 -> 1 | R23: yes | V23: 8.5994816 | W23: =IF(V23="","",V23*O23) -> 8.5994816 | X23: =IF(R23="yes",W23,"") -> 8.5994816
A24: 1 | B24: resp_age | C24: resp_age | D24: How old are you? [OPERATOR: RECORD AGE IN NUMBER OF YEARS. ROUND UP TO NEAREST WHOLE NUMBER. IF THE RESPONDENT GIVES BIRTH YEAR, REPEAT THE QUESTION. ENTER 00 FOR DON'T KNOW.] | E24: =LEN(D24) -> 177 | F24: Range | G24: NA | H24: NA | I24: Form Type - TextBox | J24: 0-17 = Ineligible 18-100 = resp_gender 00 = Ineligible | K24: NA | L24: Only respondents from 18-100 will be eligible for the survey. | O24: =1 -> 1 | R24: yes | V24: 9.8907185 | W24: =IF(V24="","",V24*O24) -> 9.8907185 | X24: =IF(R24="yes",W24,"") -> 9.8907185
A25: =A24+1 -> 2 | B25: resp_gender | C25: resp_gender | D25: What is the gender of the respondent? [OPERATOR: DO NOT ASK THIS QUESTION OUT LOUD. LISTEN TO THE VOICE AND SELECT THE GENDER.] 1)Male 2)Female 3)DON'T KNOW 4)REFUSED | E25: =LEN(D25) -> 168 | F25: Single Choice | G25: NA | H25: NA | I25: Form Type - Buttons | J25: 1-4 = phone_number_conf | K25: NA | L25: For any response, go to phone_number_conf | O25: =1 -> 1 | R25: yes | V25: 1.7156482 | W25: =IF(V25="","",V25*O25) -> 1.7156482 | X25: =IF(R25="yes",W25,"") -> 1.7156482
O26: =1 -> 1 | W26: =IF(V26="","",V26*O26) | X26: =IF(R26="yes",W26,"")
B27: phone_number_conf | C27: phone_number_conf | D27: Is the phone number I am calling you on yours or a household members? [OPERATOR: SINGLE RESPONSE.] 1)YES 2)NO 3)DON'T KNOW 4)REFUSED | E27: =LEN(D27) -> 134 | F27: Single Choice | G27: NA | H27: NA | I27: Form Type - Buttons | J27: 1 = contact_2 2 = phone_number_personal 3-4 = contact_2 | K27: NA | L27: if phone_number_conf = 1, go to contact_2 if phone_number_conf = 2, go to phone_number_personal if phone_number_conf = 3-4, go to contact_2 | O27: =1 -> 1 | R27: yes - panel | V27: 6.375237 | W27: =IF(V27="","",V27*O27) -> 6.375237 | X27: =IF(R27="yes",W27,"")
B28: phone_number_personal | C28: phone_number_pers | D28: What is your phone number? [OPERATOR: RECORD THE NUMBER GIVEN] | E28: =LEN(D28) -> 63 | F28: Open Ended | G28: NA | H28: NA | I28: Form Type - TextBox | J28: Any Response = contact_2 | K28: NA | L28: For any response, go to contact_2 | O28: =1 -> 1 | R28: yes - panel | V28: 28.700001 | W28: =IF(V28="","",V28*O28) -> 28.700001 | X28: =IF(R28="yes",W28,"")
B29: contact_2 | C29: contact_2 | D29: Can you give me an additonal phone number belonging to you, a relative or a friend at which you can be reached? [OPERATOR: SINGLE RESPONSE.] 1)YES - mine 2)YES - other household member 3)YES - friend or relative [non-household member] 4)NO 5)DON'T KNOW 6)REFUSED | E29: =LEN(D29) -> 265 | F29: Single Choice | G29: NA | H29: NA | I29: Form Type - Buttons | J29: 1-3 = phone_number_2 4-6 = hh_admin1 | K29: NA | L29: if contact_2 = 1-3, go to phone_number_2 if contact_2 = 4-6, go to contact_3 | O29: =1 -> 1 | R29: yes - panel | V29: 10.141817 | W29: =IF(V29="","",V29*O29) -> 10.141817 | X29: =IF(R29="yes",W29,"")
B30: phone_number_2 | C30: phone_number_2 | D30: What is the additional phone number? [OPERATOR: RECORD THE NUMBER GIVEN] | E30: =LEN(D30) -> 73 | F30: Open Ended | G30: NA | H30: NA | I30: Form Type - TextBox | J30: Any Response = contact_2_name | K30: NA | L30: For any response, go to contact_2_name | O30: =1 -> 1 | R30: yes - panel | V30: 21.659983 | W30: =IF(V30="","",V30*O30) -> 21.659983 | X30: =IF(R30="yes",W30,"")
B31: contact_2_name | C31: contact_2_name | D31: What is the name of the contact? [OPERATOR: RECORD THE NAME OF THE CONTACT FOR THE PHONE NUMBER.] | E31: =LEN(D31) -> 98 | F31: Open Ended | G31: NA | H31: Send if "contact_2" "Equals" "YES - other household member" OR "contact_2" "Equals" "YES - friend or relative [non-household member]", if not satisfied go to "contact_3" | I31: Form Type - TextBox | J31: Any Response = contact_3 | K31: NA | L31: Asked if response to contact_2 was "YES - other household member" or "YES - friend or relative [non-household member]". Otherwise, it skips to "contact_3". For any response, go to contact_3 | O31: =1 -> 1 | R31: yes - panel | V31: 11.821796 | W31: =IF(V31="","",V31*O31) -> 11.821796 | X31: =IF(R31="yes",W31,"")
B32: contact_3 | C32: contact_3 | D32: Can you give me an additonal phone number belonging to you, a relative or a friend at which you can be reached? [OPERATOR: SINGLE RESPONSE.] 1)YES - mine 2)YES - other household member 3)YES - friend or relative [non-household member] 4)NO 5)DON'T KNOW 6)REFUSED | E32: =LEN(D32) -> 265 | F32: Single Choice | G32: NA | H32: NA | I32: Form Type - Buttons | J32: 1-3= phone_number_3 4-6 = hh_admin1 | K32: NA | L32: if contact_3 = 1-3, go to phone_number_3 if contact_3 = 4-6, go to hh_admin1 | O32: =1 -> 1 | R32: yes - panel | V32: 3.163594 | W32: =IF(V32="","",V32*O32) -> 3.163594 | X32: =IF(R32="yes",W32,"")
B33: phone_number_3 | C33: phone_number_3 | D33: What is the additional phone number? [OPERATOR: RECORD THE NUMBER GIVEN] | E33: =LEN(D33) -> 73 | F33: Open Ended | G33: NA | H33: NA | I33: Form Type - TextBox | J33: Any Response = contact_3_name | K33: NA | L33: For any response, go to contact_3_name | O33: =1 -> 1 | R33: yes - panel | V33: 10.830144 | W33: =IF(V33="","",V33*O33) -> 10.830144 | X33: =IF(R33="yes",W33,"")
B34: contact_3_name | C34: phone_number_3_name | D34: What is the name of the contact? [OPERATOR: RECORD THE NAME OF THE CONTACT FOR THE PHONE NUMBER.] | E34: =LEN(D34) -> 98 | F34: Open Ended | G34: NA | H34: Send if "contact_3" "Equals" "YES - other household member" OR "contact_3" "Equals" "YES - friend or relative [non-household member]", if not satisfied go to "hh_admin1" | I34: Form Type - TextBox | J34: Any Response = hh_admin1 | K34: NA | L34: Asked if response to contact_3 was "YES - other household member" or "YES - friend or relative [non-household member]". Otherwise, it skips to "hh_admin1". For any response, go to hh_admin1 | O34: =1 -> 1 | R34: yes - panel | V34: 11.260417 | W34: =IF(V34="","",V34*O34) -> 11.260417 | X34: =IF(R34="yes",W34,"")
O35: =1 -> 1 | W35: =IF(V35="","",V35*O35) | X35: =IF(R35="yes",W35,"")
A36: 3 | B36: hh_admin1 | C36: hh_admin1 | D36: Currently, in which Region does your household reside? [OPERATOR: SINGLE SELECTION.] [HINT: HOUSEHOLD CONSISTS OF ALL MEMBERS LIVING TOGETHER, SHARING RESOURCES & EATING FROM THE SAME POT.] 1)ADMIN1 2)DON'T KNOW 3)REFUSED | E36: =LEN(D36) -> 224 | F36: Single Choice | G36: NA | H36: NA | I36: Form Type - Buttons IsDemographic - ADM1 | J36: 1 = hh_admin2_1 2-3 = Ineligible | K36: NA | L36: The administrative information will be updated by GeoPoll based on the sample design document and the administrative boundaries provided by the dashboard team after the questionnaire validation. | O36: =1 -> 1 | R36: yes | V36: 13.957259 | W36: =IF(V36="","",V36*O36) -> 13.957259 | X36: =IF(R36="yes",W36,"") -> 13.957259
A37: =A36+1 -> 4 | B37: hh_admin2_1 | C37: hh_admin2_1 | D37: Currently, in which District does your household reside? [OPERATOR: SINGLE RESPONSE.] 1)ADMIN2 2)DON'T KNOW 3)REFUSED | E37: =LEN(D37) -> 120 | F37: Single Choice | G37: NA | H37: NA | I37: Form Type - Buttons IsDemographic - ADM2 | J37: 1 = hh_agricactivity 2-3 = Ineligible | K37: NA | O37: =1 -> 1 | R37: yes | V37: 7.954999 | W37: =IF(V37="","",V37*O37) -> 7.954999 | X37: =IF(R37="yes",W37,"") -> 7.954999
B38: quotareached | C38: quotareached | D38: [OPERATOR: DO NOT READ. ANSWER QUESTION BELOW.] THIS RESPONDENT REPORTED THEY LIVE IN: {ADM1} {ADM2} 1)THE GOAL FOR THIS LOCATION HAS BEEN ACHIEVED - END SURVEY 2)THE GOAL FOR THIS LOCATION IS OPEN - CONTINUE SURVEY | E38: =LEN(D38) -> 218 | F38: Single Choice | G38: NA | H38: NA | I38: Form Type - Buttons | J38: 1 = End Poll Quota Reached 2 = hh_agricactivity | K38: NA
A39: =#REF!+1 -> #REF! | B39: hh_agricactivity | C39: hh_agricactivity | D39: Has anybody in your household produced crops or livestock for household consumption or for sale in the past 12 months, including household members currently away for transhumance? [OPERATOR: SINGLE RESPONSE. THIS IS THE MAIN SCREENING QUESTION.] [HINT FOR PROBING: Do you cultivate any plants to sale or consume? Do you raise any animals with the intent of selling or consuming them or their products like meat, milk, wool or leather? Is one of your household member currently away with cattle or other animals for transhumance?] 1)Yes - crop production 2)Yes - livestock production 3)Yes - both crop and livestock production 4)No 5)DON'T KNOW 6)REFUSED | E39: =LEN(D39) -> 658 | F39: Single Choice | G39: NA | H39: NA | I39: Form Type - Buttons | J39: 1-4 = resp_id 5-6 = Ineligible | K39: NA | L39: if hh_agricactivity = 1-4, go to resp_id. Otherwise, the respondent is ineligible. | O39: =1 -> 1 | R39: yes | V39: 24.410839 | W39: =IF(V39="","",V39*O39) -> 24.410839 | X39: =IF(R39="yes",W39,"") -> 24.410839
O40: =1 -> 1 | W40: =IF(V40="","",V40*O40) | X40: =IF(R40="yes",W40,"")
...

Sheet New Durations
A1: question | B1: duration | C1: responded % | D1: weighted time
A2: introduction | B2: 50.82254 | C2: 1 | D2: 50.82254
A3: agree | B3: 3.4964738 | C3: 0.79698741 | D3: 2.7866456
A4: resp_age | B4: 13.753073 | C4: 1 | D4: 13.753073
A5: resp_gender | B5: 2.1173561 | C5: 1 | D5: 2.1173561
A6: quotareached | B6: 2.28425 | C6: 0.79698741 | D6: 1.8205185
A7: hh_agricactivity | B7: 31.372377 | C7: 1 | D7: 31.372377
A8: hh_milieu | B8: 7.9225454 | C8: 0.15190348 | D8: 1.2034622
A9: hh_gender | B9: 10.085732 | C9: 1 | D9: 10.085732
A10: hh_education | B10: 12.894034 | C10: 1 | D10: 12.894034
A11: hh_wealth_water | B11: 15.265829 | C11: 0.63796463 | D11: 9.739059
A12: hh_wealth_toilet | B12: 15.123718 | C12: 0.59180156 | D12: 8.95024
A13: hh_wealthwall | B13: 12.821411 | C13: 0.15190348 | D13: 1.9476169
... A164: adm1_name | B164: 10.743817 | C164: 0.20301259 | D164: 2.1811302
A165: adm2_name | C165: 0 | D165: 0
A166: covid | B166: 56.471024 | C166: 0.20301259 | D166: 11.464329
A167: crp_landright | B167: 31 | C167: 0.0040467626 | D167: 0.12544964
A168: crp_seed | B168: 30.833334 | C168: 0.0040467626 | D168: 0.12477518
A169: crp_proddif | B169: 16.882986 | C169: 0.11848022 | D169: 2.0002998
A170: crp_salesdif | B170: 16.82699 | C170: 0.086630695 | D170: 1.4577339
A171: crp_saledif_2 | B171: 39.486874 | C171: 0.03139988 | D171: 1.2398831
A172: ls_proddif | B172: 15.938099 | C172: 0.10169365 | D172: 1.6208034
A173: ls_salesdif | B173: 13.330855 | C173: 0.060476619 | D173: 0.80620506
A174: ls_proc | B174: 16.437651 | C174: 0.0625 | D174: 1.0273532
A175: ls_proc_fac_state | B175: 8.666667 | C175: 0.00067446043 | D175: 0.005845324
A176: fish_proddif | B176: 12.523809 | C176: 0.001573741 | D176: 0.019709232
A177: cs_spentsavings | B177: 22.220184 | C177: 0.0081684652 | D177: 0.1815048
... A193: ls_proddif_2_covid19 | B193: 3.3438249 | C193: 1 | D193: 3.3438249

Sheet Crop list
C3: Select top 10 crops | D3: GeoPoll code | E3: Dataset code | F3: Label (EN)
C4: x | D4: {=_xlfn.SEQUENCE(90,1,1,1)} -> 1 | E4: 1.1 | F4: Rice
D5: 2 | E5: 1.2 | F5: Wheat
D6: 3 | E6: 1.3 | F6: Millet
D7: 4 | E7: 1.4 | F7: Sorghum
C8: x | D8: 5 | E8: 1.5 | F8: Maize
D9: 6 | E9: 1.6 | F9: Barley
D10: 7 | E10: 1.99 | F10: Other Cereal
C11: x | D11: 8 | E11: 2.1 | F11: Cassava
D12: 9 | E12: 2.2 | F12: Potatoe
C13: x | D13: 10 | E13: 2.3 | F13: Sweet Potatoes
D14: 11 | E14: 2.4 | F14: Yams
D15: 12 | E15: 2.5 | F15: Carrots
D16: 13 | E16: 2.6 | F16: Cocoyam
D17: 14 | E17: 2.99 | F17: Other tubers
D18: 15 | E18: 3.1 | F18: Beans
D19: 16 | E19: 3.2 | F19: Lentils
C20: x | D20: 17 | E20: 3.3 | F20: Peas
D21: 18 | E21: 3.4 | F21: Soybeans
D22: 19 | E22: 3.5 | F22: Chickpeas
D23: 20 | E23: 3.6 | F23: Fava beans
D24: 21 | E24: 3.7 | F24: Broad beans
D25: 22 | E25: 3.99 | F25: Other pulses
D26: 23 | E26: 4.1 | F26: Cabbage
D27: 24 | E27: 4.2 | F27: Lettuce
D28: 25 | E28: 4.3 | F28: Spinach-Amaranth
D29: 26 | E29: 4.4 | F29: Cassava leaves
D30: 27 | E30: 4.5 | F30: Potatoe leaves
D31: 28 | E31: 4.6 | F31: Moringa
D32: 29 | E32: 4.7 | F32: Sorrel Hibiscus / Rosselle
... D40: 37 | E40: 5.5 | F40: Zucchini
C41: x | D41: 38 | E41: 5.6 | F41: Okra
D42: 39 | E42: 5.7 | F42: Bell pepper
D43: 40 | E43: 5.8 | F43: Onions
D44: 41 | E44: 5.9 | F44: Haricot
D45: 42 | E45: 5.101 | F45: Green peas
D46: 43 | E46: 5.11 | F46: Fava beans green
D47: 44 | E47: 5.99 | F47: Other non leafy vegs
D48: 45 | E48: 6.1 | F48: Orange
D49: 46 | E49: 6.2 | F49: Lemon
...

Sheet Additional information
C2: Original | D2: Replacement | E2: Comment | F2: Examples
B3: FOR CORE QUESTIONS . (Mandatory to fill out) . | C3: ADMIN1 | D3: Region | E3: The first subdivision of the country, after national level; region; province; governorate; etc. | F3: region
C4: ADMIN2 | D4: District | E4: The second subdivision of the country; district; municipality; LGA; etc. | F4: district
C5: reference year | D5: a normal year | E5: Comparison questions will need need a reference year. Select whether you want to use "last year" or "a normal year" as a baseline. A "normal year" should refers to an average year from the past 5 years - make sure to train the enumerators accordingly. | F5: a normal year
C6: season | D6: rain season | E6: Name the crop season(s) of interest if there are several cropping seasons in the country (e.g. Meher and Belg in Ethiopia, rainy season / flood-recession cropping / irrigated dry season in the Sahel). You can refer to the “last season” or “ongoing season". | F6: wet season
C7: season phase | D7: Planting | E7: Indicate the phase of the season at the time of data collection. If the harvest from the season has not yet occurred, the question on crop harvest (crp_harv_change) will include the word “expected” (where #expected or nothing# is located). If the harvest has occured, "expected" will not be inserted in the question. | F7: Harvesting
C8: local measurement unit | D8: acres | E8: Specify the local measurement unit for land size, other than acres, hectares, square meters and square feet. If no other unit of measurement is needed, keep this cell blank. | F8: Jeribs
C9: local measurement unit conversion | D9: 2.5 | E9: Include the conversion of the local measurement unit to hectares. In other words, how many local measurement units are in 1 ha. | F9: 0.2
B10: FOR OPTIONAL QUESTIONS . (Fill out if applicable) . | C10: currency | D10: Leones | E10: The name of the main currency used nationally; USD; Naira; Rial; Pesos; etc. | F10: Naira
C11: MIN AMOUNT | D11: 50 | E11: The minimum amount for an income source should be set at 0 or any value below which it is not possible to do a transaction. For example, the smallest coin/banknote in a currency can be 1000, in which case you would set the minimum at 1000. Provide this input in the same currency as specified above. Only digits should be inputted. | F11: 5
C12: MAX AMOUNT | D12: 20000 | E12: Set the maximum amount for an income source over 3 months. Enumerators will not be able to input values above this amount in questions related to income amounts. Using previous representative surveys for this population, you can estimate this amount by using the mean income plus five (5) standard deviations, unless the country has high inflation. In the latter case, set the maximum value based on your country context (higher than the proposed approach). Provide this input in the same currency as specified above. Only digits should be inputted. | F12: 5000000
C13: THRESHOLD | D13: 5000 | E13: The threshold salary should be calculated to flag outliers (responses that look suspiciously high). Using previous representative surveys for this population, a good estimate is the average plus three (3) standard deviations, which should give the threshold for the 3 or 4% highest income values. Provide this input in the same currency as specified above. Only digits should be inputted. | F13: 1200000
C14: local vegetables | D14: Okra, cucumber, Tomatoes, egg plants, cabage, carrot, ball peper , onions, cassava leaves, potato leaves | E14: Input some common local vegetables [to be used as examples in the food consumption score indicator]. | F14: eggplants, zucchini, cauliflower
C15: local fruits | D15: Banana, plantain, Papaya, Orange, Grape fruit,Mango, Pineapple, Watermelon | E15: Input some common local fruits [to be used as examples in the food consumption score indicator]. | F15: apples, bananas, oranges
B17: FILL OUT FOR QUESTIONNAIRE DURATION ESTIMATION . | C17: Expected percentage of respondents cultivating crops | D17: 0.91 | E17: If the survey is representative and has no quotas, write the proportion of rural households cultivating crops at country level, or if the survey follows a previous round with identical sample design, just report the percentage from the previous round. If you are using quotas, calculate the ratio of the quota over the minimum sample size at the level where the quota is implemented (so if you have a minimum sample size per strata of 110 with a quota of 100 crop producers, then it's 100/110 = 91% (the maximum you should write is 100%). | F17: 0.91
C18: Expected percentage of respondents raising livestock | D18: 0.91 | E18: If the survey is representative and has no quotas, write the proportion of rural households raising livestock at country level, or if the survey follows a previous round with identical sample design, just report the percentage from the previous round. If you are using quotas, calculate the ratio of the quota over the minimum sample size at the level where the quota is implemented (so if you have a minimum sample size of 110 but a quota of 100 livestock producers, then it's 100/110 = 91% (the maximum you should write is 100%) | F18: 0.91
C19: Expected percentage of respondents involved in fishery | D19: 0.05 | E19: If the survey is representative and has no quotas, write the proportion of rural households involved in fisheries or aquaculture, otherwise if you are using quotas, calculate the ratio of the quota over the sample size at the level where the quota is implemented. (so if you haven't set a quota, and you expect to have a representative proportion of fishermen, just write the percentage of fishermen in the population you are targeting, in the example to the right, 5%) | F19: 0.05

Sheet Admin 2 info
A1: adm2_name | B1: adm2_name_local | C1: adm2_pcode | D1: adm1_name | E1: adm1_pcode | F1: adm0_name | G1: adm0_ISO3
A2: Pujehun | C2: SL0304 | D2: Southern | E2: SL03 | F2: Sierra Leone | G2: SLE
A3: Bonthe | C3: SL0302 | D3: Southern | E3: SL03 | F3: Sierra Leone | G3: SLE
A4: Bo | C4: SL0301 | D4: Southern | E4: SL03 | F4: Sierra Leone | G4: SLE
A5: Kailahun | C5: SL0101 | D5: Eastern | E5: SL01 | F5: Sierra Leone | G5: SLE
A6: Moyamba | C6: SL0303 | D6: Southern | E6: SL03 | F6: Sierra Leone | G6: SLE
A7: Kenema | C7: SL0102 | D7: Eastern | E7: SL01 | F7: Sierra Leone | G7: SLE
A8: Tonkolili | C8: SL0205 | D8: Northern | E8: SL02 | F8: Sierra Leone | G8: SLE
A9: Kono | C9: SL0103 | D9: Eastern | E9: SL01 | F9: Sierra Leone | G9: SLE
A10: Western Area Rural | C10: SL0401 | D10: Western | E10: SL04 | F10: Sierra Leone | G10: SLE
A11: Western Area Urban | C11: SL0402 | D11: Western | E11: SL04 | F11: Sierra Leone | G11: SLE
A12: Falaba | C12: SL0206 | D12: Northern | E12: SL02 | F12: Sierra Leone | G12: SLE
A13: Bombali | C13: SL0201 | D13: Northern | E13: SL02 | F13: Sierra Leone | G13: SLE
... A17: Karene | C17: SL0503 | D17: North Western | E17: SL05 | F17: Sierra Leone | G17: SLE
