Workbook

Sheet survey
A1: GeoPoll Submission Form
A2: FAO - Household Questionnaire | R2: Additional notes
A3: Q # | B3: Q Name | C3: Suggested Qname | D3: English | E3: Length | F3: Arabic | G3: Length | H3: Q Type | I3: Randomize | J3: Conditional | K3: Programming Instructions | L3: Skip Pattern | M3: Codes | N3: GeoPoll Comments | O3: FAO Response | P3: Default skip patterns & conditional | Q3: Specify skip pattern variable (from blue text) | S3: Estimated percentage of repondents | V3: Mandatory | Z3: Duration (sec) | AA3: Weighted duration | AB3: Core questions only
A4: A. PRESENTATION OF THE SURVEY AND ELIGIBILITY CRITERIA SELECTION | V4: no | AA4: =IF(Z4="","",Z4*X4) | AB4: =IF(V4="yes",AA4,"")
A5: NA | B5: Optin | D5: Optin | E5: =LEN(D5) -> 5 | F5: Optin | G5: =LEN(F5) -> 5 | H5: Open Ended | I5: NA | J5: NA | K5: Form Type - TextBox | L5: Any Response = calldispo | M5: NA | P5: NA | V5: no | Z5: 0 | AA5: =IF(Z5="","",Z5*S5) -> 0 | AB5: =IF(V5="yes",AA5,"")
A6: NA | B6: calldispo | C6: calldispo | D6: Phone number: #CATI_MOBILENUMBER# 1)Someone answers 2)Answering machine 3)No answer 4)Hang up or refusal 5)Call back 6)Under review 7)Disconnected | E6: =LEN(D6) -> 146 | F6: رقم الهاتف: #CATI_MOBILENUMBER# 1) يجيب شخص ما 2) جهاز الرد الالي 3) لا جواب 4) إنهاء المكالمة أو الرفض 5) معاودة الاتصال 6) قيد المراجعة 7) قطع الاتصال | G6: =LEN(F6) -> 153 | H6: Single Choice | I6: NA | J6: NA | K6: Form Type - Buttons | L6: 1 = resp_language 2 = AnsweringMachine 3 = NoAnswer 4 = Refusal 5 = WhenCallBack 6 = UnderReview 7 = Disconnected | M6: NA | P6: NA | V6: no | Z6: 14.695308 | AA6: =IF(Z6="","",Z6*S6) -> 0 | AB6: =IF(V6="yes",AA6,"")
A7: NA | B7: AnsweringMachine | C7: calldispo_answeringmachine | D7: Reached an answering machine. | E7: =LEN(D7) -> 29 | F7: لقد تم توجيهك إلى جهاز الرد الالي | G7: =LEN(F7) -> 33 | H7: NA | I7: NA | J7: NA | K7: NA | L7: End Poll AnsweringMachine | M7: NA | P7: NA | V7: no | Z7: 0 | AA7: =IF(Z7="","",Z7*S7) -> 0 | AB7: =IF(V7="yes",AA7,"")
A8: NA | B8: NoAnswer | C8: calldispo_noanswer | D8: Phone rang and no one answered. | E8: =LEN(D8) -> 31 | F8: رن الهاتف ولم يرد أحد | G8: =LEN(F8) -> 21 | H8: NA | I8: NA | J8: NA | K8: NA | L8: End Poll NoAnswer | M8: NA | P8: NA | V8: no | Z8: 0 | AA8: =IF(Z8="","",Z8*S8) -> 0 | AB8: =IF(V8="yes",AA8,"")
A9: NA | B9: UnderReview | C9: calldispo_underreview | D9: Case needs review by a supervisor. | E9: =LEN(D9) -> 34 | F9: الحالة تحتاج إلى مراجعة من قبل مشرف | G9: =LEN(F9) -> 35 | H9: NA | I9: NA | J9: NA | K9: NA | L9: End Poll UnderReview | M9: NA | P9: NA | V9: no | Z9: 0 | AA9: =IF(Z9="","",Z9*S9) -> 0 | AB9: =IF(V9="yes",AA9,"")
A10: NA | B10: Disconnected | C10: calldispo_disconnected | D10: Phone was disconnected or out of service. | E10: =LEN(D10) -> 41 | F10: تم فصل الهاتف أو الهاتف خارج الخدمة | G10: =LEN(F10) -> 35 | H10: NA | I10: NA | J10: NA | K10: NA | L10: End Poll Disconnected | M10: NA | P10: NA | V10: no | Z10: 0 | AA10: =IF(Z10="","",Z10*S10) -> 0 | AB10: =IF(V10="yes",AA10,"")
A11: NA | B11: resp_language | C11: resp_language | D11: Which language do you wish to proceed with? [OPERATOR: READ ANSWER CHOICES. SINGLE RESPONSE.] 1)Arabic 2)English - TESTING | E11: =LEN(D11) -> 124 | F11: ما هي اللغة التي ترغب في المتابعة بها؟ [المُشغل: اقرأ خيارات الإجابة. استجابة واحدة.] 1) العربية 2)English - TESTING | G11: =LEN(F11) -> 118 | H11: Single Choice | I11: NA | J11: NA | K11: Form Type - Buttons | L11: 1 = introduction [Arabic] 2 = introduction [English] | M11: NA | N11: GeoPoll: Added English for testing purpose considering the survey will be running in Arabic only. | O11: OK | P11: For any response, go to introduction | R11: Arabic | V11: no | Z11: 3.1032724 | AA11: =IF(Z11="","",Z11*S11) -> 0 | AB11: =IF(V11="yes",AA11,"")
A12: 1 | B12: introduction | C12: introduction | D12: Hello sir/ma'am, my name is #OPERATOR#, and I am calling on behalf of the Food and Agriculture Organization of the United Nations [FAO] because your name appeared on the organization's beneficiary list in recent years. I would like to ask you some questions about the impact of the current situation on your source of livelihood and your household's ability to obtain food. The survey usually takes 20/25 minutes to complete. Any information that you provide will be kept strictly confidential, only used for the purpose of the survey and will not be shown to other people. Your voluntary participation in the outcome of this interview is NOT IN ANY WAY linked to your personal chance of receiving any assistance. This is voluntary and you can choose not to answer any or all of the questions if you want. However, we hope that you will participate since your views are important. Please note that this call may be recorded for quality purposes. Do you have any questions? [OPERATOR: ADDRESS QUESTIONS FROM RESPONDENT, IF ANY.] 1)CONTINUE | E12: =LEN(D12) -> 1046 | F12: مرحبا، أنا إسمي #OPERATOR# وبحكي معك نيابة عن منظمة الأمم الممتحده للأغذية والزراعة (فاو) لأنه إسمك ورد على قوائم المستفيدين من المنظمة خلال الاعوام الأخيره. بدي أسالك شويه أسئله حول أثر الوضع الحالي على مصدر رزقك وقدرة أسرتك على الحصول على الغذاء. رح آخد من وقتك 25 ل 20 دقيقه. بدي احكيلك انه هاي المعلومات رح تضل سريه وإنه نتبيجه هاي الدراسه ما الها اي علاقه بأي مساعدات بتقدمها المنظمة. من حقك ترفض المشاركه بس يا ريت تشارك لأنه رأيك بهمنا وبحب احكيلك أنه هاي المكالمة رح تكون مسجله لهدف رصد الجودة. يرجى الملاحظة أنه قد يتم تسجيل هذه المكالمة لغاية مراقبة الجودة. عندك أي سؤال الي؟ [المُشغل: أجب على أسئلة المُجيب ، إن وجدت.] 1) تابع | G12: =LEN(F12) -> 643 | H12: Single Choice | I12: NA | J12: NA | K12: Form Type - Buttons | L12: 1 = Agree | M12: NA | N12: GeoPoll [3/18/2024]. Removed the reference to incentives given this will be a non-incentive survey. Kindly also advise if we should include a series of introductory messages to verify that we are speaking with the correct person/beneficiary listed in the database, or if this is not required. Example: "Our records indicate that this is the mobile number of [input name] from [input locality]. Are you this same person? (yes, proceed with interview. No, next screener question) May I speak with this person now? (yes, proceed with interview. No, next screener question) Are you part of the same household as [input name]? (yes, proceed with interview. No, next screener question). GeoPoll [4/11/2024]: Added in QNames Beneficiary - Beneficiary_Confirm2 below. Also updated length of interview to reference 20/25 instead of 15/20.. | O12: Removal of incentives: ok, thanks. Introductory message: Yes, we should verify the respondent (or someone in their household) is indeed a former FAO beneficiary, however we must find an alternative approach. The proposed text is not appropriate as it would provide senstive information (name and location) up front. | P12: For any response, go to Agree | R12: Set the amount of incentive here, if any. | V12: no | Z12: 37.418449 | AA12: =IF(Z12="","",Z12*S12) -> 0 | AB12: =IF(V12="yes",AA12,"")
A13: NA | B13: Agree | C13: resp_agree | D13: Are you interested in participating in this survey? [OPERATOR: SINGLE RESPONSE] 1)Yes 2)Not now but another time in the week 3)No | E13: =LEN(D13) -> 131 | F13: هل لديك رغبة في بالمشاركة في هذه الدراسة؟ [المشغل: استجابة واحدة] 1) نعم 2) ليس الآن ولكن في وقت آخر في الأسبوع 3) لا | G13: =LEN(F13) -> 119 | H13: StartRecording | I13: NA | J13: NA | K13: Form Type - Buttons | L13: 1 = Beneficiary 2 = WhenCallBack 3 = resp_refusalwhy | M13: NA | P13: if Agree = 1, go to id_panel OR resp_firstname if Agree = 2, go to WhenCallBack if Agree = 3, go to resp_refusalwhy | Q13: if Agree = 1, go to resp_age if Agree = 2, go to WhenCallBack if Agree = 3, go to resp_refusalwhy | S13: 1 | V13: no | Z13: 3.8059516 | AA13: =IF(Z13="","",Z13*S13) -> 3.8059516 | AB13: =IF(V13="yes",AA13,"")
A14: NA | B14: resp_refusalwhy | C14: resp_refusalwhy | D14: Please let us know why you have REFUSED to take the survey. [OPERATOR: SINGLE RESPONSE] 1)Not interested 2)Do not want to be recorded 3)Other [specify] | E14: =LEN(D14) -> 153 | F14: يرجى إخبارنا سبب رفضك للمشاركة في هذه الدراسة. [المشغل: استجابة واحدة] 1) غير مهتم 2) لا أريد أن يتم تسجيلي 3) آخر [حدد] | G14: =LEN(F14) -> 122 | H14: Open Ended-Single Choice | I14: NA | J14: NA | K14: Form Type - RadioList | L14: Any Response = Refusal | M14: NA | P14: For any response, go to Refusal | S14: 1 | V14: no | Z14: 0 | AA14: =IF(Z14="","",Z14*S14) -> 0 | AB14: =IF(V14="yes",AA14,"")
A15: NA | B15: WhenCallBack | C15: resp_whencallback | D15: When would it be a good time to call you back? [RECORD HH/MM/DD/MM OF CALLBACK] | E15: =LEN(D15) -> 80 | F15: ما هو التاريخ / الوقت المناسب لمعاودة الاتصال بك؟ [RECORD HH / MM / DD / MM of CALLBACK] | G15: =LEN(F15) -> 89 | H15: Open Ended | I15: NA | J15: NA | K15: Form Type - TextBox IsCallBackDemographic | L15: Any Response = CallbackMessageEN | M15: NA | P15: For any response, go to CallbackMessageEN | S15: 1 | V15: no | Z15: 0 | AA15: =IF(Z15="","",Z15*S15) -> 0 | AB15: =IF(V15="yes",AA15,"")
A16: NA | B16: CallbackMessageEN | C16: callbackmessage_en | D16: Thank you, we will call you back at {WhenCallBack} you requested. Thank you again and have a great day! [OPERATOR: ENTER CALL NOTES BELOW, WHO YOU SPOKE TO AND WHAT THEY SAID] | E16: =LEN(D16) -> 176 | F16: شكرًا لك ، سوف نعاود الاتصال بك في {WhenCallBack} الذي طلبته. شكرا لك مرة أخرى و نتمنى لك يوم جميل! [المُشغل: أدخل ملاحظات الاتصال أدناه ، مع من تحدثت وماذا قالوا] | G16: =LEN(F16) -> 164 | H16: Open Ended | I16: NA | J16: NA | K16: Form Type - TextBox | L16: Any Response = End poll callback | M16: NA | P16: NA | S16: 1 | V16: no | Z16: 0 | AA16: =IF(Z16="","",Z16*S16) -> 0 | AB16: =IF(V16="yes",AA16,"")
A17: NA | B17: Ineligible | C17: NA | D17: You are ineligible for this survey. Thank you for your time and please look out for future surveys! | E17: =LEN(D17) -> 99 | F17: أنت غير مؤهل للمشاركة في هذه الدراسة، شكرًا لك على وقتك. ترقب دراسات GeoPoll المستقبلية! | G17: =LEN(F17) -> 89 | H17: NA | I17: NA | J17: NA | K17: NA | L17: End Poll Ineligible | M17: NA | P17: NA | S17: 1 | V17: no | Z17: 0 | AA17: =IF(Z17="","",Z17*S17) -> 0 | AB17: =IF(V17="yes",AA17,"")
A18: NA | B18: Refusal | C18: NA | D18: Thank you for your time, you will be removed from today's survey. | E18: =LEN(D18) -> 65 | F18: شكراً جزيلاً على وقتك، سنقوم بحذف إسمك من دراسة اليوم. | G18: =LEN(F18) -> 54 | H18: NA | I18: NA | J18: NA | K18: NA | L18: End poll declined | M18: NA | P18: NA | S18: 1 | V18: no | Z18: 0 | AA18: =IF(Z18="","",Z18*S18) -> 0 | AB18: =IF(V18="yes",AA18,"")
A19: B. GENERAL INFORMATION & ELIGIBILITY CRITERIA | AA19: =IF(Z19="","",Z19*S19) | AB19: =IF(V19="yes",AA19,"")
A20: 2 | B20: Beneficiary | C20: Beneficiary | D20: Were you or anyone in your household a beneficiary of a FAO project or Ministry of Agriculture project during the past five years? [OPERATOR: SINGLE RESPONSE] 1)YES 2)NO 3)DON'T KNOW | E20: =LEN(D20) -> 184 | F20: خلال ال 5 سنوات الماضية، هل استفدت انت او أي فرد من افراد اسرتك من أي مشروع نفذته منظمة الأغذية والزراعة – الفاو اأو مشروع تفذته وزارة الزراعة؟ [المشغل: استجابة واحدة] 1) نعم 2) لا 3)لا أعرف | G20: =LEN(F20) -> 192 | H20: Single Choice | I20: NA | J20: NA | K20: Form Type - Buttons | L20: 1=Beneficiary_Confirm1 2=Ineligible 3=Beneficiary_Confirm2 | M20: NA | N20: GeoPoll [4/11/2024]: Added in QNames Beneficiary - Beneficiary_Confirm2. Our team is in the process of inputting the translations. Kindly advise if any further feedback.
A21: 3 | B21: Beneficiary_Confirm1 | C21: Beneficiary_Confirm1 | D21: Thank you. Kindly provide me with their name and location during the period that they were a FAO or Ministry of Agriculture beneficiary. [OPERATOR: LISTEN TO THE NAME AND LOCATION OF THE BENEFICIARY PROVIDED BY THE RESPONDENT. SELECT CONTINUE IF IT IS THE SAME AS THE DATABASE. OTHERWISE, SELECT INELIGIBLE. 1)Continue 2)Ineligible | E21: =LEN(D21) -> 334 | F21: شكرًا لك. يرجى تزويدي باسم المستفيد ومكان سكنه خلال الفترة التي كان بها مستفيد من مشروع الممول من المنذمة الاغذية و الزراعة - الفاو او مشروع وزارة الزراعة [المشغل: استمع إلى اسم مكان سكن المستفيد. حدد متابعة إذا كان هو نفسه الموجود في قاعدة البيانات. بخلاف ذلك، حدد غير مؤهل] 1) تابع 2) غير مؤهل | G21: =LEN(F21) -> 298 | H21: Single Choice | I21: NA | J21: NA | K21: Form Type - Buttons | L21: 1=resp_age 2=Ineligible | M21: NA
A22: 4 | B22: Beneficiary_Confirm2 | C22: Beneficiary_Confirm2 | D22: Our records indicate the beneficiary is [IDENTIFY FIRST NAME BASED ON RESPONDENT ID]. Is this you or a member of your household? [OPERATOR: SINGLE RESPONSE. PROMPT FIRST WITH THE FIRST NAME ONLY, THEN PROCEED TO FAMILY NAME AND LASTLY LOCATION IF PROBING IS REQUIRED. DO NOT REVEAL NAME AND LOCATION AT THE SAME TIME / TAKE CARE TO AVOID REVEALING PERSONAL IDENTIFYING INFORMATION]. 1)YES 2)NO | E22: =LEN(D22) -> 396 | F22: تشير القوائم لدينا إلى أن المستفيد هو [اذكر الاسم الأول فقط من القائمة]. هل هو أنت أو أحد أفراد أسرتك؟ [المشغل: استجابة واحدة. اذكر الاسم الاول للمستميد, و من ثم اسم العائلة و الموقع الجغرافي لاحقا. لا تذكر الاسم و الموقع الجغرافي في ان واحد للحفاظ على عدم كشف معلومات تعريفية شخصية] 1) نعم 2) لا | G22: =LEN(F22) -> 298 | H22: Single Choice | I22: NA | J22: NA | K22: Form Type - Buttons | L22: 1=resp_age 2=Ineligible | M22: NA
A23: 5 | B23: resp_age | C23: resp_age | D23: How old are you? [OPERATOR: RECORD AGE IN NUMBER OF YEARS. ROUND UP TO NEAREST WHOLE NUMBER. IF THE RESPONDENT GIVES BIRTH YEAR, REPEAT THE QUESTION. ENTER 00 FOR DON'T KNOW.] | E23: =LEN(D23) -> 177 | F23: كم عمرك؟ [المُشغل: سجل العمر في عدد السنوات. قم بالتقريب لأقرب رقم كامل. إذا أعطى المجيب سنة الميلاد ، فكرر السؤال. أدخل 00 للا أعرف.] | G23: =LEN(F23) -> 135 | H23: Range | I23: NA | J23: NA | K23: Form Type - TextBox | L23: 0-17 = Ineligible 18-100 = resp_gender 00 = Ineligible | M23: NA | P23: Only respondents from 18-100 will be eligible for the survey. | S23: =1 -> 1 | V23: yes | Z23: 9.8907185 | AA23: =IF(Z23="","",Z23*S23) -> 9.8907185 | AB23: =IF(V23="yes",AA23,"") -> 9.8907185
A24: =A23+1 -> 6 | B24: resp_gender | C24: resp_gender | D24: What is the gender of the respondent? [OPERATOR: DO NOT ASK THIS QUESTION OUT LOUD. LISTEN TO THE VOICE AND SELECT THE GENDER.] 1)Male 2)Female 3)DON'T KNOW 4)REFUSED | E24: =LEN(D24) -> 168 | F24: ما هو جنس المجيب؟ [المُشغل: لا تطرح هذا السؤال. استمع إلى الصوت وحدد المربع الصحيح.] 1) ذكر 2) أنثى 3) لا أعرف 4) رفض الإجابة | G24: =LEN(F24) -> 127 | H24: Single Choice | I24: NA | J24: NA | K24: Form Type - Buttons | L24: 1-4 = hh_admin1 | M24: NA | P24: For any response, go to phone_number_conf | Q24: For any response, go to hh_admin1 | S24: =1 -> 1 | V24: yes | Z24: 1.7156482 | AA24: =IF(Z24="","",Z24*S24) -> 1.7156482 | AB24: =IF(V24="yes",AA24,"") -> 1.7156482
A25: 7 | B25: hh_admin1 | C25: hh_admin1 | D25: Currently, in which Governorate does your household reside in? [OPERATOR: SINGLE SELECTION.] [HINT: HOUSEHOLD CONSISTS OF ALL MEMBERS LIVING TOGETHER, SHARING RESOURCES & EATING FROM THE SAME POT.] 1)HEBRON 2)NABLUS 3)RAMALLAH 4)SALFIT 5)BETHLEHEM 6)JENIN 7)JERICHO 8)JERUSALEM 9)QALQILIA 10)TUBAS 11)TULKARM 12)DON'T KNOW 13)REFUSED | E25: =LEN(D25) -> 338 | F25: حاليًا ، في أي محافظة تقيم أسرتك؟ [المشغل: استجابة واحدة.] [ملحوظة: تتكون الأسرة من جميع الأعضاء الذين يعيشون معًا ، ويتشاركون الموارد ويأكلون من نفس القدر.] 1)الخليل 2)نابلس 3)رام الله 4)سلفيت 5)بيت لحم 6)جنين 7)أريحا 8)القدس [J2] 9)قلقيلية 10)طوباس 11)طولكرم 12) لا أعرف 13) رفض الإجابة | G25: =LEN(F25) -> 291 | H25: Single Choice | I25: NA | J25: NA | K25: Form Type - Dropdown IsDemographic - ADM1 | L25: 1 = hh_admin2_1 2 = hh_admin2_2 3 = hh_admin2_3 4 = hh_admin2_4 5 = hh_admin2_5 6 = hh_admin2_6 7 = hh_admin2_7 8 = hh_admin2_8 9 = hh_admin2_9 10 = hh_admin2_10 11 = hh_admin2_11 12-13 = Ineligible | M25: NA | N25: GeoPoll [4/11/2024]: Added in translation for governorate in Arabic. | P25: The administrative information will be updated by GeoPoll based on the sample design document and the administrative boundaries provided by the dashboard team after the questionnaire validation. | S25: =1 -> 1 | V25: yes | Z25: 13.957259 | AA25: =IF(Z25="","",Z25*S25) -> 13.957259 | AB25: =IF(V25="yes",AA25,"") -> 13.957259
A26: =A25+1 -> 8 | B26: hh_admin2_1 | C26: hh_admin2_1 | D26: Currently, in which locality [village/town/city] does your household reside? [OPERATOR: SINGLE RESPONSE.] 1) 'ANAB AL KABIR 2)AD DEIRAT 3)ADH DHAHIRIYA 4)AL 'ARRUB CAMP 5)AL BAQA 6)AL BOWEREH [AQABAT INJELEH] 7)AL BURJ 8)AL BUWEIB 9)AL FAWWAR CAMP 10)AL HEILA 11)AL KARMIL 12)AL MAJD 13)AN NAJADA 14)AR RAMADIN 15)AR RIHIYA 16)ARAB AL FUREIJAT 17)AS SAMU' 18)AS SURA 19)ASH SHUYUKH 20)AT TUWANI 21)BANI NA'IM 22)BEIT 'AMRA 23)BEIT AR RUSH AL FAUQA 24)BEIT AR RUSH AT TAHTA 25)BEIT 'AWWA 26)BEIT 'EINUN 27)BEIT KAHIL 28)BEIT MAQDUM 29)BEIT MIRSIM 30)BEIT ULA 31)BEIT UMMAR 32)DEIR AL 'ASAL AL FAUQA 33)DEIR AL 'ASAL AT TAHTA 34)DEIR RAZIH 35)DEIR SAMIT 36)DURA 37)FUQEIQIS 38)HADAB AL 'ALAQA 39)HADAB AL FAWWAR 40)HALHUL 41)HAMRUSH 42)HEBRON [AL KHALIL] 43)HITTA 44)IDHNA 45)IMNEIZIL 46)IMREISH 47)JALA 48)KARMA 49)KHALLET AL 'AQED 50)KHALLET AL MAIYYA 51)KHALLET AL MASAFER 52)KHALLET EDAR 53)KHALLET SALIH 54)KHARAS 55)KHASHEM ADARAJ [AL-HATHALEEN] 56)KHEROSHEWESH WAL HADEDEYAH 57)KHIRBET AD DEIR 58)KHIRBET AL FAKHEIT 59)KHIRBET ASAFI 60)KHIRBET BIR AL 'IDD 61)KHIRBET SALAMA 62)KHIRBET TAWIL ASH SHIH 63)KHIRBET ZANUTA 64)KHURSA 65)KURZA 66)MAGHAYIR AL 'ABEED 67)MA'IN 68)MANTIQAT SHI'B AL BATIN 69)MARAH AL BAQQAR 70)NUBA 71)OM ADARAJ [ARAB AL KA’ABNEH] 72)OM AL AMAD [SAHEL WADI ELMA] 73)OM ASHOQHAN 74)QALQAS 75)QLA’A ZETA 76)RABUD 77)SA'IR 78)SHUYUKH AL 'ARRUB 79)SIKKA 80)SURIF 81)TAFFUH 82)TARQUMIYA 83)TARRAMA 84)UM AL-KHAIR 85)UMM AL BUTM 86)UMM LASAFA 87)WADI AL AMAYER 88)WADI AL KILAB 89)WADI ASH SHAJINA 90)WADI 'UBEID 91)YATTA 92)ZIF 93)DON'T KNOW 94)REFUSED | E26: =LEN(D26) -> 1578 | F26: حالياً، في أي تجمع سكاني [قرية/بلدة/مدينة] تقيم أسرتك؟ [المشغل: استجابة واحدة.] 1)عناب الكبير 2)الديرات 3)الظاهرية 4)مخيم العروب 5)البقعة 6)البويرة [عقبة انجيله] 7)البرج 8)البويب 9)مخيم الفوار 10)الحيلة 11)الكرمل 12)المجد 13)النَجادَة 14)الرماضين 15)الريحية 16)عرب الفريجات 17)السموع 18)الصرة 19)الشيوخ 20)التواني 21)بني نعيم 22)بيت عمرة 23)بيت الرش الفوقا 24)بيت الرش التحتا 25)بيت عوا 26)بيت عينون 27)بيت كاحل 28)بيت مقدوم 29)بيت مرسم 30)بيت أولا 31)بيت أومر 32)دير العسل الفوقا 33)دير العسل التحتا 34)دير رازح 35)دير سامت 36)دورا 37)فقيقيس 38)هدب العلقة 39)هدب الفوار 40)حلحول 41)حمروش 42)الخليل 43)حتا 44)إذنا 45)إِمنيزِل 46)إمريش 47)جالا 48)كرمة 49)خلة العقد 50)خلة المية 51)خلة المسافر 52)خلة الدار 53)خلة صالح 54)خاراس 55)خشم درج [الهذالين] 56)خيروشيوش والحديدية 57)خربة الدير 58)خربة الفخيت 59)خربة اصفي 60)خربة بير العد 61)خربة سلامة 62)خربة طويل الشيح 63)خربة زنوتة 64)خرسا 65)كرزه 66)مغاير العبيد 67)معين 68)منطقة شعب الباطن 69)مراح البقار 70)النوبة 71)أم الدرج [عرب الكعابنة] 72)أم العمد [ساحل وادي الماء] 73)أم الشقحان 74)قلقس 75)قلعة زيتا 76)رابود 77)سعير 78)شيوخ العروب 79)سكة 80)صوريف 81)تفوح 82)ترقوميا 83)طرّامة 84)ام الخير 85)أم البطم 86)أم لصفا 87)وادي العماير 88)وادي الكلاب 89)وادي الشاجنة 90)وادي عبيد 91)يطا 92)زيف 93) لا أعرف 94) رفض الإجابة | G26: =LEN(F26) -> 1269 | H26: Single Choice | I26: NA | J26: NA | K26: Form Type - Dropdown IsDemographic - ADM2 | L26: 1-92 = quotareached 93-94 = Ineligible | M26: NA | N26: GeoPoll [4/11/2024]: Added in translation for locality in Arabic. | O26: FAOPAL- kindly provide translation | S26: =1 -> 1 | V26: yes | Z26: 7.954999 | AA26: =IF(Z26="","",Z26*S26) -> 7.954999 | AB26: =IF(V26="yes",AA26,"") -> 7.954999
A27: =A26+1 -> 9 | B27: hh_admin2_2 | C27: hh_admin2_2 | D27: Currently, in which locality [village/town/city] does your household reside? [OPERATOR: SINGLE RESPONSE.] 1) 'AMMURIYA 2) 'ASIRA AL QIBLIYA 3) 'ASIRA ASH SHAMALIYA 4) 'ASKAR CAMP 5) 'AWARTA 6) 'AZMUT 7) 'EIN BEIT EL MA CAMP 8) 'EIN SHIBLI 9) 'EINABUS 10) 'URIF 11)AL 'AQRABANIYA 12)AL BADHAN 13)AL LUBBAN ASH SHARQIYA 14)AN NAQURA 15)AN NASSARIYA 16)AQRABA 17)AR RAJMAN 18)AS SAWIYA 19)BALATA CAMP 20)BEIT DAJAN 21)BEIT FURIK 22)BEIT HASAN 23)BEIT IBA 24)BEIT IMRIN 25)BEIT WAZAN 26)BEITA 27)BIZZARIYA 28)BURIN 29)BURQA 30)DEIR AL HATAB 31)DEIR SHARAF 32)DUMA 33)FURUSH BEIT DAJAN 34)HUWWARA 35)IJNISINYA 36)'IRAQ BURIN 37)JALUD 38)JAMMA'IN 39)JURISH 40)KAFR QALLIL 41)MADAMA 42)MAJDAL BANI FADIL 43)NABLUS 44)NISF JUBEIL 45)ODALA 46)OSARIN 47)QABALAN 48)QARYUT 49)QUSIN 50)QUSRA 51)RUJEIB 52)SABASTIYA 53)SALIM 54)SARRA 55)TALFIT 56)TALL AL KHASHABA 57)TALLUZA 58)TELL 59)YANUN 60)YASID 61)YATMA 62)ZA'TARA 63)ZAWATA 64)ZEITA JAMMA'IN 65)DON'T KNOW 66)REFUSED | E27: =LEN(D27) -> 963 | F27: حالياً، في أي تجمع سكاني [قرية/بلدة/مدينة] تقيم أسرتك؟ [المشغل: استجابة واحدة.] 1)عمورية 2)عصيرة القبلية 3)عصيرة الشمالية 4)مخيم عسكر 5)عورتا 6)عزموط 7)مخيم عين بيت الماء 8)عين شبلي 9)عينبوس 10)عوريف 11)العقربانية 12)الباذان 13)اللبن الشرقية 14)الناقورة 15)النصارية 16)عقربة 17)الرجمان 18)الساوية 19)مخيم بلاطة 20)بيت دجن 21)بيت فوريك 22)بيت حسن 23)بيت إيبا 24)بيت امرين 25)بيت وزان 26)بيتا 27)بزارية 28)بورين 29)برقة 30)دير الحطب 31)دير شرف 32)دوما 33)فروش بيت دجن 34)حوارة 35)إجنيسينيا 36)عراق بورين 37)جالود 38)جماعين 39)جوريش 40)كفر قليل 41)مادما 42)مجدل بني فاضل 43)نابلس 44)نصف جبيل 45)أودلة 46)أوصرين 47)قبلان 48)قريوت 49)قوصين 50)قصرة 51)روجيب 52)سبسطية 53)سالم 54)صرة 55)تلفيت 56)تل الخشبة 57)طلوزة 58)تل 59)يانون 60)ياصيد 61)يتما 62)زعترة 63)زواتا 64)زيتا جماعين 65) لا أعرف 66) رفض الإجابة | G27: =LEN(F27) -> 803 | H27: Single Choice | I27: NA | J27: NA | K27: Form Type - Dropdown IsDemographic - ADM2 | L27: 1-64 = quotareached 65-66 = Ineligible | M27: NA | O27: FAOPAL- kindly provide translation | S27: =1 -> 1 | V27: yes | Z27: 7.954999 | AA27: =IF(Z27="","",Z27*S27) -> 7.954999 | AB27: =IF(V27="yes",AA27,"") -> 7.954999
A28: =A27+1 -> 10 | B28: hh_admin2_3 | C28: hh_admin2_3 | D28: Currently, in which locality [village/town/city] does your household reside? [OPERATOR: SINGLE RESPONSE.] 1) 'ABUD 2) 'ABWEIN 3) 'AJJUL 4) 'ATARA 5) 'EIN QINIYA 6) 'EIN YABRUD 7)ABU QASH 8)AL AM'ARI CAMP 9)AL BIREH 10)AL JALAZUN CAMP 11)AL JANIYA 12)AL LUBBAN AL GHARBI 13)AL MAZRA'A ASH SHARQIYA 14)AL MIDYA 15)AL MUGHAYYIR 16)AL-DOHA 17)AL-ITIHAD 18)AL-ZAYTOUNEH 19)AN NABI SALIH 20)AT TAYBA 21)AT TIRA 22)BADIW AL MU'ARRAJAT 23)BANI ZEID 24)BANI ZEID ASH SHARQIYA 25)BEIT LIQYA 26)BEIT NUBA 27)BEIT SIRA 28)BEIT 'UR AL FAUQA 29)BEIT 'UR AT TAHTA 30)BEITIN 31)BEITUNIYA 32)BIL'IN 33)BIR ZEIT 34)BUDRUS 35)BURHAM 36)BURQA 37)DEIR ABU MASH'AL 38)DEIR 'AMMAR CAMP 39)DEIR AS SUDAN 40)DEIR DIBWAN 41)DEIR IBZI' 42)DEIR JARIR 43)DEIR NIDHAM 44)DEIR QADDIS 45)DURA AL QAR' 46)'EIN 'ARIK 47)'EIN SINIYA 48)JIBIYA 49)JIFNA 50)JILIJLIYA 51)KAFR 'EIN 52)KAFR MALIK 53)KAFR NI'MA 54)KHARBATHA AL MISBAH 55)KHARBATHA BANI HARITH 56)KHIRBET ABU FALAH 57)KOBAR 58)NI'LIN 59)QADDURA CAMP 60)QARAWAT BANI ZEID 61)QIBYA 62)RAMALLAH 63)RAMMUN 64)RANTIS 65)RAS KARKAR 66)SAFFA 67)SHABTIN 68)SHUQBA 69)SILWAD 70)SILWAD CAMP 71)SINJIL 72)SURDA 73)TURMUS'AYYA 74)UMM SAFA 75)YABRUD 76)DON'T KNOW 77)REFUSED | E28: =LEN(D28) -> 1189 | F28: حالياً، في أي تجمع سكاني [قرية/بلدة/مدينة] تقيم أسرتك؟ [المشغل: استجابة واحدة.] 1)عابود 2)عبوين 3)عجول 4)عطارة 5)عين قينيا 6)عين يبرود 7)ابو قش 8)مخيم الأمعري 9)البيرة 10)مخيم الجلزون 11)الجانية 12)اللبن الغربي 13)المزرعة الشرقية 14)المدية 15)المغير 16)الدوحة 17)الاتحاد 18)الزيتونة 19)النبي صالح 20)الطيبة 21)الطيرة 22)بدو المعرّجات 23)بني زيد 24)بني زيد الشرقية 25)بيت لقيا 26)بيت نوبا 27)بيت سيرا 28)بيت عور الفوقا 29)بيت عور التحتا 30)بيتين 31)بيتونيا 32)بلعين 33)بير زيت 34)بدرس 35)برهام 36)برقة 37)دير أبو مشعل 38)مخيم دير عمار 39)دير السودان 40)دير دبوان 41)دير ابزيع 42)دير جرير 43)دير نظام 44)دير قديس 45)دورا القرع 46)عين عريك 47)عين سينيا 48)جيبيا 49)جفنا 50)جليليا 51)كفر عين 52)كفر مالك 53)كفر نعمة 54)خربثا المصباح 55)خربثا بني حارث 56)خربة ابو فلاح 57)كوبر 58)نعلين 59)مخيم قدورة 60)قراوة بني زيد 61)قبية 62)رام الله 63)رمون 64)رنتيس 65)رأس كركر 66)صفا 67)شبتين 68)شقبة 69)سلواد 70)مخيم سلواد 71)سنجل 72)سردا 73)ترمسعيا 74)أم صفا 75)يبرود 76) لا أعرف 77) رفض الإجابة | G28: =LEN(F28) -> 984 | H28: Single Choice | I28: NA | J28: NA | K28: Form Type - Dropdown IsDemographic - ADM2 | L28: 1-75 = quotareached 76-77 = Ineligible | M28: NA | O28: FAOPAL- kindly provide translation | S28: =1 -> 1 | V28: yes | Z28: 7.954999 | AA28: =IF(Z28="","",Z28*S28) -> 7.954999 | AB28: =IF(V28="yes",AA28,"") -> 7.954999
A29: =A28+1 -> 11 | B29: hh_admin2_4 | C29: hh_admin2_4 | D29: Currently, in which locality [village/town/city] does your household reside? [OPERATOR: SINGLE RESPONSE.] 1)AZ ZAWIYA 2)BIDDYA 3)BRUQIN 4)DEIR BALLUT 5)DEIR ISTIYA 6)FARKHA 7)HARIS 8)ISKAKA 9)'IZBAT ABU ADAM 10)KAFR AD DIK 11)KHIRBET QEIS 12)KIFL HARIS 13)MARDA 14)MAS-HA 15)QARAWAT BANI HASSAN 16)QIRA 17)RAFAT 18)SALFIT 19)SARTA 20)YASUF 21)DON'T KNOW 22)REFUSED | E29: =LEN(D29) -> 367 | F29: حالياً، في أي تجمع سكاني [قرية/بلدة/مدينة] تقيم أسرتك؟ [المشغل: استجابة واحدة.] 1)الزاوية 2)بديا 3)بروقين 4)دير بلوط 5)دير استيا 6)فرخة 7)حارس 8)إسكاكا 9)عِزْبِة أبو آدَم 10)كفر الديك 11)خربة قيس 12)كفل حارث 13)مردة 14)مسحة 15)قراوة بني حسان 16)قيرة 17)رافات 18)سلفيت 19)سرطة 20)ياسوف 21) لا أعرف 22) رفض الإجابة | G29: =LEN(F29) -> 315 | H29: Single Choice | I29: NA | J29: NA | K29: Form Type - Dropdown IsDemographic - ADM2 | L29: 1-20 = quotareached 21-22 = Ineligible | M29: NA | O29: FAOPAL- kindly provide translation | S29: =1 -> 1 | V29: yes | Z29: 7.954999 | AA29: =IF(Z29="","",Z29*S29) -> 7.954999 | AB29: =IF(V29="yes",AA29,"") -> 7.954999
A30: =A29+1 -> 12 | B30: hh_admin2_5 | C30: hh_admin2_5 | D30: Currently, in which locality [village/town/city] does your household reside? [OPERATOR: SINGLE RESPONSE.] 1)AD DOHA 2)AD DUHEISHA CAMP 3)AL 'AZA CAMP 4)AL HADDADIYA 5)AL JAB'A 6)AL KHADR 7)AL KHAS 8)AL MANIYA 9)AL MANSHIYA 10)AL MA'SARA 11)AL 'UBEIDIYA 12)AL WALAJA 13)'ARAB AR RASHAYIDA 14)ARTAS 15)ASH SHAWAWRA 16)'AYDA CAMP 17)BATTIR 18)BEIT FAJJAR 19)BEIT JALA 20)BEIT SAHUR 21)BEIT TA'MIR 22)BETHLEHEM [BEIT LAHM] 23)BIR ONAH 24)DAR SALAH 25)HINDAZA 26)HUSAN 27)JANNATAH 28)JUBBET ADH DHIB 29)JURAT ASH SHAM'A 30)KHALLET 'AFANA 31)KHALLET AL HADDAD 32)KHALLET AL LOUZA 33)KHALLET AN NU'MAN 34)KHALLET HAMAMEH 35)KHALLET SAKARIYA 36)KISAN 37)MARAH MA'ALLA 38)MARAH RABAH 39)NAHHALIN 40)TUQU' 41)UMM SALAMUNA 42)WADI AN NIS 43)WADI FUKIN 44)WADI RAHHAL 45)ZA'TARA 46)DON'T KNOW 47)REFUSED | E30: =LEN(D30) -> 795 | F30: حالياً، في أي تجمع سكاني [قرية/بلدة/مدينة] تقيم أسرتك؟ [المشغل: استجابة واحدة.] 1)الدوحة 2)مخيم الدهيشة 3)مخيم العزة 4)الحدادية 5)الجبعة 6)الخضر 7)الخاص 8)المنية 9)المنشية 10)المعصرة 11)العبيدية 12)الولجة 13)عرب الرشايدة 14)ارطاس 15)الشواورة 16)مخيم عايدة 17)بتير 18)بيت فجار 19)بيت جالا 20)بيت ساحور 21)بيت تعمر 22)بيت لحم 23)بئر عونة 24)دار صلاح 25)هندازة 26)حوسان 27)جناتة 28)جبة الديب 29)جورة الشمة 30)خلة عفانة 31)خلة الحداد 32)خلة اللوزة 33)خلة النعمان 34)خلة حمامة 35)خلة سكاريا 36)كيسان 37)مرح معلا 38)مراح رباح 39)نحالين 40)تقوع 41)أم سلمونة 42)وادي النيص 43)وادي فوكين 44)وادي رحال 45)زعترة 46) لا أعرف 47) رفض الإجابة | G30: =LEN(F30) -> 632 | H30: Single Choice | I30: NA | J30: NA | K30: Form Type - Dropdown IsDemographic - ADM2 | L30: 1-45 = quotareached 46-47 = Ineligible | M30: NA | O30: FAOPAL- kindly provide translation | S30: =1 -> 1 | V30: yes | Z30: 7.954999 | AA30: =IF(Z30="","",Z30*S30) -> 7.954999 | AB30: =IF(V30="yes",AA30,"") -> 7.954999
A31: =A30+1 -> 13 | B31: hh_admin2_6 | C31: hh_admin2_6 | D31: Currently, in which locality [village/town/city] does your household reside? [OPERATOR: SINGLE RESPONSE.] 1) 'ARABBUNA 2)'ABA 3)'AJJA 4)AL 'ARAQA 5)AL 'ASA'ASA 6)AL 'ATTARA 7)AL FANDAQUMIYA 8)AL HAFIRA 9)AL HASHIMIYA 10)AL JALAMA 11)AL JAMEELAT 12)AL JARBA 13)AL JUDEIDA 14)AL KHULJAN 15)AL KUFEIR 16)AL MANSURA 17)AL MUGHAYYIR 18)AL MUTILLA 19)AL YAMUN 20)'ANIN 21)'ANZA 22)AR RAMA 23)ARRABA 24)'ARRANA 25)AS SA'AIDA 26)ASH SHUHADA 27)AT TAREM 28)AT TAYBA 29)AZ ZABABIDA 30)AZ ZAWIYA 31)BARTA'A ASH SHARQIYA 32)BEIT QAD 33)BIR AL BASHA 34)BIRQIN 35)DEIR ABU DA'IF 36)DEIR GHAZALA 37)DHAHER AL 'ABED 38)DHAHER AL MALIH 39)FAHMA 40)FAHMA AL JADIDA 41)FAQQU'A 42)IMREIHA 43)JABA' 44)JALBUN 45)JALQAMUS 46)JENIN 47)JENIN CAMP 48)KAFR DAN 49)KAFR QUD 50)KAFR RA'I 51)KHIRBET 'ABDALLAH AL YUNIS 52)KHIRBET AL MUNTAR AL GHARBIYA 53)KHIRBET AL MUNTAR ASH SHARQIYA 54)KHIRBET MAS'UD 55)KHIRBET SURUJ 56)KUFEIRIT 57)MEITHALUN 58)MIRKA 59)MISLIYA 60)NAZLAT ASH SHEIKH ZEID 61)QABATIYA 62)RABA 63)RUMMANA 64)SANUR 65)SILAT ADH DHAHR 66)SILAT AL HARITHIYA 67)SIR 68)SIRIS 69)TELFIT 70)TI'INNIK 71)TURA AL GHARBIYA 72)TURA ASH SHARQIYA 73)UMM AR RIHAN 74)UMM AT TUT 75)UMM DAR 76)WAD AD DABI' 77)WADI DU'OQ 78)YA'BAD 79)ZABDA 80)ZUBUBA 81)DON'T KNOW 82)REFUSED | E31: =LEN(D31) -> 1256 | F31: حالياً، في أي تجمع سكاني [قرية/بلدة/مدينة] تقيم أسرتك؟ [المشغل: استجابة واحدة.] 1)عربّونة 2)عابا 3)عجّه 4)العرقة 5)العصاعصة 6)العطارة 7)الفندقومية 8)الحفيرة 9)الهاشمية 10)الجلمة 11)الجميلات 12)الجربا 13)الجديدة 14)الخلجان 15)الكفير 16)المنصورة 17)المغير 18)المطلة 19)اليامون 20)عنين 21)عنزة 22)الرامة 23)عرّابة 24)عرّانه 25)السعايدة 26)الشهداء 27)الطرم 28)الطيبه 29) الزبابدة 30)الزاوية 31)برطعة الشرقية 32)بيت قاد 33)بئر الباشا 34)برقين 35)دير أبو ضعيف 36)دير غزالة 37)ظهر العبد 38)ظهر المالح 39)فحمة 40)فهمة الجديدة 41)فقوعة 42)إمريحة 43)جبع 44)جلبون 45)جلقموس 46)جنين 47)مخيم جنين 48)كفر دان 49)كفر قود 50)كفر راعي 51)خربة عبد الله اليونس 52)خربة المنطار الغربية 53)خربة المنطار الشرقية 54)خربة مسعود 55)خربة سروج 56)كفيرت 57)ميثالون 58)ميركا 59)مسلية 60)نزلة الشيخ زيد 61)قباطية 62)رابا 63)رمّانة 64)سانور 65)سيلة الظهر 66)سيلة الحارثية 67)سير 68)سيريس 69)تلفيت 70)تعنّك 71)طورة الغربية 72)طورة الشرقية 73)ام الريحان 74)أم التوت 75)أم دار 76)واد الضبع 77)وادي دْعُوق 78)يعبد 79)زبدة 80)زبوبا 81) لا أعرف 82) رفض الإجابة | G31: =LEN(F31) -> 1030 | H31: Single Choice | I31: NA | J31: NA | K31: Form Type - Dropdown IsDemographic - ADM2 | L31: 1-80 = quotareached 81-82 = Ineligible | M31: NA | O31: FAOPAL- kindly provide translation | S31: =1 -> 1 | V31: yes | Z31: 7.954999 | AA31: =IF(Z31="","",Z31*S31) -> 7.954999 | AB31: =IF(V31="yes",AA31,"") -> 7.954999
A32: =A31+1 -> 14 | B32: hh_admin2_7 | C32: hh_admin2_7 | D32: Currently, in which locality [village/town/city] does your household reside? [OPERATOR: SINGLE RESPONSE.] 1)AL 'AUJA 2)AL JIFTLIK 3)AN NABI MUSA 4)AN NUWEI'MA 5)AQBAT JABER CAMP 6)AZ ZUBEIDAT 7)DEIR AL QILT 8)DEIR HAJLA 9)'EIN AD DUYUK AL FAUQA 10)'EIN AS SULTAN CAMP 11)FASAYIL 12)JERICHO [ARIHA] 13)MARJ AL GHAZAL 14)MARJ NA'JA 15)DON'T KNOW 16)REFUSED | E32: =LEN(D32) -> 358 | F32: حالياً، في أي تجمع سكاني [قرية/بلدة/مدينة] تقيم أسرتك؟ [المشغل: استجابة واحدة.] 1)العوجا 2)الجفتلك 3)النبي موسى 4)النويعمة 5)مخيم عقبة جبر 6)الزبيدات 7)دير القلط 8)دير حجلة 9)عين الديوك الفوقا 10) مخيم عين السلطان 11)فصايل 12)أريحا 13)مرج الغزال 14)مرج نعجة 15) لا أعرف 16) رفض الإجابة | G32: =LEN(F32) -> 288 | H32: Single Choice | I32: NA | J32: NA | K32: Form Type - Dropdown IsDemographic - ADM2 | L32: 1-14 = quotareached 15-16 = Ineligible | M32: NA | O32: FAOPAL- kindly provide translation | S32: =1 -> 1 | V32: yes | Z32: 7.954999 | AA32: =IF(Z32="","",Z32*S32) -> 7.954999 | AB32: =IF(V32="yes",AA32,"") -> 7.954999
A33: =A32+1 -> 15 | B33: hh_admin2_8 | C33: hh_admin2_8 | D33: Currently, in which locality [village/town/city] does your household reside? [OPERATOR: SINGLE RESPONSE.] 1) 'ARAB AL JAHALIN 2)ABU DIS 3)AL 'EIZARIYA 4)AL 'ISAWIYA 5)AL JIB 6)AL JUDEIRA 7)AL KA'ABINA [TAJAMMU' BADAWI] 8)AL QUBEIBA 9)AN NABI SAMWIL 10)'ANATA 11)AR RAM & DAHIYAT AL BAREED 12)AS SAWAHIRA AL GHARBIYA 13)AS SAWAHIRA ASH SHARQIYA 14)ASH SHEIKH SA'D 15)ATH THURI 16)AZ ZA'AYYEM 17)BEIT 'ANAN 18)BEIT DUQQU 19)BEIT HANINA 20)BEIT HANINA AL BALAD 21)BEIT IJZA 22)BEIT IKSA 23)BEIT SAFAFA 24)BEIT SURIK 25)BIDDU 26)BIR NABALA 27)HIZMA 28)JABA' 29)JABA' [TAJAMMU' BADAWI] 30)JABAL AL MUKABBIR 31)JERUSALEM [AL QUDS] 32)KAFR 'AQAB 33)KHARAYIB UMM AL LAHIM 34)MIKHMAS 35)QALANDIYA 36)QALANDIYA CAMP 37)QATANNA 38)RAFAT 39)SHARAFAT 40)SHU'FAT 41)SHU'FAT CAMP 42)SILWAN 43)SUR BAHIR 44)UMM TUBA 45)DON'T KNOW 46)REFUSED | E33: =LEN(D33) -> 827 | F33: حالياً، في أي تجمع سكاني [قرية/بلدة/مدينة] تقيم أسرتك؟ [المشغل: استجابة واحدة.] 1)عرب الجهالين 2)ابو ديس 3)العيزرية 4)العيسوية 5)الجيب 6)الجديرة 7)الكعابنة [تجمع البدوي] 8)القبيبة 9)النبي صموئيل 10)عناتا 11)الرام وضاحية البريد 12)السواحرة الغربية 13)السواحرة الشرقية 14)الشيخ سعد 15)الثوري 16)الزعيّم 17)بيت عنان 18)بيت دقو 19)بيت حنينا 20)بيت حنينا البلد 21)بيت اجزا 22)بيت اكسا 23)بيت صفافا 24)بيت سوريك 25)بدو 26)بير نبالا 27)حزما 28)جبع 29)جبع [التجمع البدوي] 30)جبل المكبر 31)القدس 32)كفر عقب 33)خَرائِب أمُّ اللَحْمْ 34)مخماس 35)قلنديا 36)مخيم قلنديا 37)قطنة 38)رافات 39)شرفات 40)شعفاط 41)مخيم شعفاط 42)سلوان 43)صور باهر 44)أم توبا 45) لا أعرف 46) رفض الإجابة | G33: =LEN(F33) -> 668 | H33: Single Choice | I33: NA | J33: NA | K33: Form Type - Dropdown IsDemographic - ADM2 | L33: 1-44 = quotareached 45-46 = Ineligible | M33: NA | O33: FAOPAL- kindly provide translation | S33: =1 -> 1 | V33: yes | Z33: 7.954999 | AA33: =IF(Z33="","",Z33*S33) -> 7.954999 | AB33: =IF(V33="yes",AA33,"") -> 7.954999
A34: =A33+1 -> 16 | B34: hh_admin2_9 | C34: hh_admin2_9 | D34: Currently, in which locality [village/town/city] does your household reside? [OPERATOR: SINGLE RESPONSE.] 1) 'ARAB ABU FARDA 2) 'ARAB AR RAMADIN AL JANUBI 3) 'ARAB AR RAMADIN ASH SHAMALI 4) 'ISLA 5) 'IZBAT AL ASHQAR 6) 'IZBAT AT TABIB 7) 'IZBAT JAL'UD 8)AD DAB'A 9)AL FUNDUQ 10)AL MUDAWWAR 11)AN NABI ELYAS 12)ARAB AL-KHOULEH 13)'AZZUN 14)'AZZUN 'ATMA 15)BAQAT AL HATAB 16)BEIT AMIN 17)FALAMYA 18)FAR'ATA 19)HABLA 20)HAJJA 21)IMMATIN 22)'IZBAT SALMAN 23)JAYYUS 24)JINSAFUT 25)JIT 26)KAFR LAQIF 27)KAFR QADDUM 28)KAFR THULTH 29)KHIRBET SIR 30)QALQILIYA 31)RAS AT TIRA 32)RAS 'ATIYA 33)SANNIRIYA 34)WADI AR RASHA 35)DON'T KNOW 36)REFUSED | E34: =LEN(D34) -> 638 | F34: حالياً، في أي تجمع سكاني [قرية/بلدة/مدينة] تقيم أسرتك؟ [المشغل: استجابة واحدة.] 1)عرب أبو فردة 2)عَرَب الرَماضِين الجَنُوبي 3)عرب الرماضين الشّمالي 4)عسلة 5)عزبة الأشقر 6)عزبة الطبيب 7)عِزْبَة جَالود 8)الضبعة 9)الفندق 10)المدوّر 11)النبي الياس 12)عرب الخولي 13)عزون 14)عزون عتمة 15)باقة الحطب 16)بيت أمين 17)فلامية 18)فرعتا 19)حبلة 20)حجة 21)إيماتين 22)عزبة سلمان 23)جيوس 24)جينسافوط 25)جيت 26)كفر لاقف 27)كفر قدوم 28)كفر ثلث 29)خربة صير 30)قلقيلية 31)راس الطيرة 32)رأس عطية 33)سنيريا 34)وادي الرشا 35) لا أعرف 36) رفض الإجابة | G34: =LEN(F34) -> 529 | H34: Single Choice | I34: NA | J34: NA | K34: Form Type - Dropdown IsDemographic - ADM2 | L34: 1-34 = quotareached 35-36 = Ineligible | M34: NA | O34: FAOPAL- kindly provide translation | S34: =1 -> 1 | V34: yes | Z34: 7.954999 | AA34: =IF(Z34="","",Z34*S34) -> 7.954999 | AB34: =IF(V34="yes",AA34,"") -> 7.954999
A35: =A34+1 -> 17 | B35: hh_admin2_10 | C35: hh_admin2_10 | D35: Currently, in which locality [village/town/city] does your household reside? [OPERATOR: SINGLE RESPONSE.] 1)A’QQABA 2)AL A’QABA 3)AL FARISIYA 4)AL HADIDIYA 5)AL MALIH 6)BARDALA 7)'EIN EL BEIDA 8)EL FARA’A CAMP 9)IBZIQ 10)KARDALA 11)KHIRBET A’TUF 12)RAS AL FAR'A 13)SALHAB 14)TAMMUN 15)TAYASIR 16)TUBAS 17)WADI AL FARA’A 18)DON'T KNOW 19)REFUSED | E35: =LEN(D35) -> 347 | F35: حالياً، في أي تجمع سكاني [قرية/بلدة/مدينة] تقيم أسرتك؟ [المشغل: استجابة واحدة.] 1) العقبة 2) العقبة 3) الفارسية 4) الحديدية 5) المالح 6)بردلة 7) عين البيضاء 8) مخيم الفارعة 9) إبزيق 10) كردلة 11) خربة عاطوف 12) رأس الفارعة 13) سلحب 14) طمّون 15) تياسير 16) طوباس 17) وادي الافرعة 18) لا أعرف 19) رفض الإجابة | G35: =LEN(F35) -> 310 | H35: Single Choice | I35: NA | J35: NA | K35: Form Type - Dropdown IsDemographic - ADM2 | L35: 1-17 = quotareached 18-19 = Ineligible | M35: NA | S35: =1 -> 1 | V35: yes | Z35: 7.954999 | AA35: =IF(Z35="","",Z35*S35) -> 7.954999 | AB35: =IF(V35="yes",AA35,"") -> 7.954999
A36: =A34+1 -> 17 | B36: hh_admin2_11 | C36: hh_admin2_11 | D36: Currently, in which locality [village/town/city] does your household reside? [OPERATOR: SINGLE RESPONSE.] 1) 'AKKABA 2)AL HAFFASI 3)AL JARUSHIYA 4)AL MASQUFA 5)AN NAZLA AL GHARBIYA 6)AN NAZLA AL WUSTA 7)AN NAZLA ASH SHARQIYA 8)ANABTA 9)AR RAS 10)'ATTIL 11)BAL'A 12)BAQA ASH SHARQIYA 13)BEIT LID 14)DEIR AL GHUSUN 15)FAR'UN 16)IKTABA 17)'ILLAR 18)KAFA 19)KAFR 'ABBUSH 20)KAFR AL LABAD 21)KAFR JAMMAL 22)KAFR SUR 23)KAFR ZIBAD 24)KHIRBET JUBARA 25)KUR 26)NAZLAT 'ISA 27)NUR SHAMS CAMP 28)QAFFIN 29)RAMIN 30)SAFFARIN 31)SEIDA 32)SHUFA 33)TULKARM CAMP 34)TULKARM 35)ZEITA 36)DON'T KNOW 37)REFUSED | E36: =LEN(D36) -> 599 | F36: حالياً، في أي تجمع سكاني [قرية/بلدة/مدينة] تقيم أسرتك؟ [المشغل: استجابة واحدة.] 1)العقبة 2)الحفاصي 3)الجاروشية 4)المسقوفة 5)النزلة الغربية 6)النزلة الوسطى 7)النزلة الشرقية 8)عنبتا 9)الراس 10)عتيل 11)بلعة 12)باقة الشرقية 13)بيت ليد 14)دير الغصون 15)فرعون 16)إكتابا 17)عيلار 18)كفا 19)كفر عبوش 20)كفر اللبد 21)كفر جمال 22)كفر صور 23)كفر زيباد 24)خربة جبارة 25)كور 26)نزلة عيسى 27)مخيم نور شمس 28)قفين 29)رامين 30)سفارين 31)صيدا 32)شوفة 33)مخيم طولكرم 34)طولكرم 35)زيتا 36) لا أعرف 37) رفض الإجابة | G36: =LEN(F36) -> 497 | H36: Single Choice | I36: NA | J36: NA | K36: Form Type - Dropdown IsDemographic - ADM2 | L36: 1-35 = quotareached 36-37 = Ineligible | M36: NA | O36: FAOPAL- kindly provide translation | S36: =1 -> 1 | V36: yes | Z36: 7.954999 | AA36: =IF(Z36="","",Z36*S36) -> 7.954999 | AB36: =IF(V36="yes",AA36,"") -> 7.954999
A37: =A36+1 -> 18 | B37: quotareached | C37: quotareached | D37: [OPERATOR: DO NOT READ. ANSWER QUESTION BELOW.] THIS RESPONDENT REPORTED THEY LIVE IN: {ADM1} {ADM2} 1)THE GOAL FOR THIS LOCATION HAS BEEN ACHIEVED - END SURVEY 2)THE GOAL FOR THIS LOCATION IS OPEN - CONTINUE SURVEY | E37: =LEN(D37) -> 218 | F37: [المُشغل: لا تقرأ. أجب على السؤال أدناه.] أبلغ هذا المجيب أنه يعيش في: {ADM1} {ADM2} 1) تم تحقيق الهدف لهذا الموقع - إنه الاستبيان 2) لا يزال يتعين تحقيق الهدف لهذا الموقع - تابع الاستبيان | G37: =LEN(F37) -> 191 | H37: Single Choice | I37: NA | J37: NA | K37: Form Type - Buttons | L37: 1 = End Poll Quota Reached 2 = o_hh_area | M37: NA
A38: =A37+1 -> 19 | B38: o_hh_area | C38: o_hh_area | D38: In which area are you located? [OPERATOR: READ OUT THE OPTIONS. SINGLE RESPONSE.] 1)Area A / B 2)Area C 3)DON'T KNOW 4)REFUSED | E38: =LEN(D38) -> 128 | F38: ما هو تصنيف المنطقعه التي تسكن فيها؟ [المُشغل: اقرأ خيارات الإجابة. استجابة واحدة.] 1) مناطق ألف أو مناطق باء 2)مناطق ج 3)لا أعلم 4)رفض الإجاب’ | G38: =LEN(F38) -> 148 | H38: Single Choice | I38: NA | J38: NA | K38: Form Type - Buttons | L38: 1-4 = hh_agricactivity | M38: NA | Q38: 1-4 = hh_agricactivity | S38: =1 -> 1 | V38: no | Z38: 13.220665 | AA38: =IF(Z38="","",Z38*S38) -> 13.220665 | AB38: =IF(V38="yes",AA38,"")
A39: =A38+1 -> 20 | B39: hh_agricactivity | C39: hh_agricactivity | D39: Has anybody in your household produced crops or livestock for household consumption or for sale in the past 12 months, including household members currently away for transhumance? [OPERATOR: SINGLE RESPONSE. THIS IS THE MAIN SCREENING QUESTION.] [HINT FOR PROBING: Do you cultivate any plants to sale or consume? Do you raise any animals with the intent of selling or consuming them or their products like meat, milk, wool or leather? Is one of your household member currently away with cattle or other animals for transhumance?] 1)Yes - crop production 2)Yes - livestock production 3)Yes - both crop and livestock production 4)No 5)DON'T KNOW 6)REFUSED | E39: =LEN(D39) -> 655 | F39: هل قام أي شخص في أسرتك بإنتاج المحاصيل أو تربية الماشية للاستهلاك المنزلي أو للبيع خلال الاثني عشر شهرًا الماضية ، بما في ذلك أفراد الأسرة الغير موجودين بغرض التنقل الرعوي؟ [المشغل: استجابة واحدة. هذا هو سؤال الفرز الرئيسي.] [ملحوظة للتحقيق: هل قمت بزراعة أي نباتات للبيع أو الاستهلاك ؟ هل قمت بتربية أي حيوانات بنية البيع أو الاستهلاك أو انتاج منتجات مثل اللحوم و الالبان و الصوف و الجلد ؟ هل أي فرد من أفراد أسرتك حاليا بعيدًا عن الأسرة مع الماشية أو حيوانات أخري بغرض التنقل الرعوي ؟] 1) نعم - إنتاج المحاصيل 2) نعم - إنتاج الماشية 3) نعم - كل من إنتاج المحاصيل والماشية 4) لا 5) لا أعرف 6) رفض الإجابة | G39: =LEN(F39) -> 607 | H39: Single Choice | I39: NA | J39: NA | K39: Form Type - Buttons | L39: 1-4 = resp_id 5-6 = Ineligible | M39: NA | N39: GeoPoll [4/11/2024]. Updated skip patterns to make any "no" responses eligible as advised. | O39: "No" responses are still eligible. These respondents should be asked all sections aside from Crop/Livestock modules. | P39: if hh_agricactivity = 1-4, go to resp_id or hh_fish. Otherwise, the respondent is ineligible. | Q39: if hh_agricactivity = 1-4, go to resp_id. Otherwise, the respondent is ineligible. | S39: =1 -> 1 | V39: yes | Z39: 24.410839 | AA39: =IF(Z39="","",Z39*S39) -> 24.410839 | AB39: =IF(V39="yes",AA39,"") -> 24.410839
A40: B. GENERAL HOUSEHOLD INFORMATION | AA40: =IF(Z40="","",Z40*S40) | AB40: =IF(V40="yes",AA40,"")
...

Sheet Crop list
C3: Select top 10 crops | D3: GeoPoll code | E3: Dataset code | F3: Label (EN) | G3: Label (AR)
D4: {=_xlfn.SEQUENCE(90,1,1,1)} -> 1 | E4: 1.1 | F4: Rice | G4: الرز
C5: x | D5: 2 | E5: 1.2 | F5: Wheat | G5: القمح
D6: 3 | E6: 1.3 | F6: Millet | G6: الدخن
D7: 4 | E7: 1.4 | F7: Sorghum | G7: الذرة الرفيعة
D8: 5 | E8: 1.5 | F8: Maize | G8: الذرة
C9: x | D9: 6 | E9: 1.6 | F9: Barley | G9: الشعير
D10: 7 | E10: 1.99 | F10: Other Cereal | G10: الحبوب الأخرى
D11: 8 | E11: 2.1 | F11: Cassava | G11: الكسافا
C12: x | D12: 9 | E12: 2.2 | F12: Potatoe | G12: البطاطا
D13: 10 | E13: 2.3 | F13: Sweet Potatoes | G13: البطاطا الحلوة
D14: 11 | E14: 2.4 | F14: Yams | G14: اليام
D15: 12 | E15: 2.5 | F15: Carrots | G15: الجزر
D16: 13 | E16: 2.6 | F16: Cocoyam | G16: القلقاس
D17: 14 | E17: 2.99 | F17: Other tubers | G17: الدرنات الأخرى
D18: 15 | E18: 3.1 | F18: Beans | G18: الفاصوليا
D19: 16 | E19: 3.2 | F19: Lentils | G19: العدس
C20: x | D20: 17 | E20: 3.3 | F20: Peas | G20: البازيلاء
D21: 18 | E21: 3.4 | F21: Soybeans | G21: فول الصويا
C22: x | D22: 19 | E22: 3.5 | F22: Chickpeas | G22: الحمص
C23: x | D23: 20 | E23: 3.6 | F23: Fava beans | G23: الفول
D24: 21 | E24: 3.7 | F24: Broad beans | G24: الفاصوليا العريضة
D25: 22 | E25: 3.99 | F25: Other pulses | G25: البقول الاخرى
C26: x | D26: 23 | E26: 4.1 | F26: Cabbage | G26: الملفوف
C27: x | D27: 24 | E27: 4.2 | F27: Lettuce | G27: الخس
D28: 25 | E28: 4.3 | F28: Spinach-Amaranth | G28: السبانخ - القطيفة
D29: 26 | E29: 4.4 | F29: Cassava leaves | G29: أوراق الكسافا
D30: 27 | E30: 4.5 | F30: Potatoe leaves | G30: أوراق البطاطا
D31: 28 | E31: 4.6 | F31: Moringa | G31: المورينجا
D32: 29 | E32: 4.7 | F32: Sorrel Hibiscus / Rosselle | G32: الكركديه
D33: 30 | E33: 4.9 | F33: Green salad herbs [thyme, parsley, mint, rocca, other] | G33: أعشاب السلطة الخضراء [زعتر ، بقدونس ، نعناع ، جرجير ، أنواع أخرى]
C34: x | D34: 31 | E34: 4.101 | F34: Cauliflower | G34: القرنبيط
D35: 32 | E35: 4.99 | F35: Other leafy vegetables | G35: الخضار الورقية الأخرى
C36: x | D36: 33 | E36: 5.1 | F36: Tomatoes | G36: الطماطم
C37: x | D37: 34 | E37: 5.2 | F37: Cucumber | G37: الخيار
D38: 35 | E38: 5.3 | F38: Pumpkin | G38: اليقطين
C39: x | D39: 36 | E39: 5.4 | F39: Eggplant/aubergine | G39: الباذنجان
D40: 37 | E40: 5.5 | F40: Zucchini | G40: الكوسة
D41: 38 | E41: 5.6 | F41: Okra | G41: البامية
D42: 39 | E42: 5.7 | F42: Bell pepper | G42: الفلفل حلو
...

Sheet Admin 2 info
A1: adm2_name | B1: adm2_name_local | C1: adm2_pcode | D1: adm1_name | E1: adm1_pcode | F1: adm0_name | G1: adm0_ISO3
A2: North Gaza | C2: PS0255 | D2: Gaza Strip | E2: PS02 | F2: State of Palestine (the) | G2: PSE
A3: Gaza | C3: PS0260 | D3: Gaza Strip | E3: PS02 | F3: State of Palestine (the) | G3: PSE
A4: Deir Al-Balah | C4: PS0265 | D4: Gaza Strip | E4: PS02 | F4: State of Palestine (the) | G4: PSE
A5: Khan Younis | C5: PS0270 | D5: Gaza Strip | E5: PS02 | F5: State of Palestine (the) | G5: PSE
A6: Rafah | C6: PS0275 | D6: Gaza Strip | E6: PS02 | F6: State of Palestine (the) | G6: PSE
A7: Jenin | C7: PS0101 | D7: West Bank | E7: PS01 | F7: State of Palestine (the) | G7: PSE
A8: Tubas | C8: PS0105 | D8: West Bank | E8: PS01 | F8: State of Palestine (the) | G8: PSE
A9: Tulkarm | C9: PS0110 | D9: West Bank | E9: PS01 | F9: State of Palestine (the) | G9: PSE
A10: Nablus | C10: PS0115 | D10: West Bank | E10: PS01 | F10: State of Palestine (the) | G10: PSE
A11: Qalqilya | C11: PS0120 | D11: West Bank | E11: PS01 | F11: State of Palestine (the) | G11: PSE
A12: Salfit | C12: PS0125 | D12: West Bank | E12: PS01 | F12: State of Palestine (the) | G12: PSE
A13: Ramallah | C13: PS0130 | D13: West Bank | E13: PS01 | F13: State of Palestine (the) | G13: PSE
... A17: Hebron | C17: PS0150 | D17: West Bank | E17: PS01 | F17: State of Palestine (the) | G17: PSE

Sheet Admin 1
A1: 1 | B1: Jenin
A2: 5 | B2: Tubas
A3: 10 | B3: Tulkarm
A4: 20 | B4: Qalqilia
A5: 25 | B5: Salfit
A6: 15 | B6: Nablus
A7: 30 | B7: Ramallah
A8: 35 | B8: Jericho
A9: 40 | B9: Jerusalem (J2)
A10: 45 | B10: Bethlehem
A11: 50 | B11: Hebron

Sheet Admin 2
A1: Admin 1 code | B1: Admin 2 Code | C1: Admin 2 name
A2: 1 | B2: 10005 | C2: Zububa
A3: 1 | B3: 10010 | C3: Rummana
A4: 1 | B4: 10015 | C4: Ti'innik
A5: 1 | B5: 10020 | C5: At Tayba
A6: 1 | B6: 10025 | C6: 'Arabbuna
A7: 1 | B7: 10030 | C7: Al Jalama
A8: 1 | B8: 10035 | C8: Silat al Harithiya
A9: 1 | B9: 10040 | C9: As Sa'aida
A10: 1 | B10: 10045 | C10: 'Anin
A11: 1 | B11: 10050 | C11: 'Arrana
A12: 1 | B12: 10055 | C12: Deir Ghazala
A13: 1 | B13: 10060 | C13: Faqqu'a
... A504: 50 | B504: 503405 | C504: 'Arab al Fureijat

Sheet Additional information
C2: Original | D2: Replacement (EN) | E2: Replacement (AR) | F2: Comment (EN) | G2: Comment (AR) | H2: Example (EN) | I2: Example (AR)
B3: FOR CORE QUESTIONS . (Mandatory to fill out) . | C3: ADMIN1 | D3: Region | E3: محافظة | F3: The first subdivision of the country, after national level; region; province; governorate; etc. | G3: التقسيم الأول للبلاد ، بعد المستوى الوطني ؛ منطقة؛ محافظة؛ ولاية ؛ إلخ. | H3: region | I3: منطقة
C4: ADMIN2 | D4: Governorate | E4: تجمع سكاني | F4: The second subdivision of the country; district; municipality; LGA; etc. | G4: التقسيم الثاني للبلاد ؛ قضاء؛ بلدية؛ إلخ. | H4: district | I4: قضاء
C5: reference year | D5: a normal year | E5: العام العادي | F5: Comparison questions will need need a reference year. Select whether you want to use "last year" or "a normal year" as a baseline. A "normal year" should refers to an average year from the past 5 years - make sure to train the enumerators accordingly. | G5: سوف تحتاج أسئلة المقارنة إلى سنة مرجعية. حدد ما إذا كنت تريد استخدام "العام الماضي" أو "العام العادي" كخط أساس. يجب أن يشير "العام العادي" إلى متوسط ​​عام من السنوات الخمس الماضية - تأكد من تدريب جامعي البيانات وفقًا لذلك. | H5: a normal year | I5: العام العادي
C6: season | D6: Winter season | E6: الموسم الشتوي | F6: Name the crop season(s) of interest if there are several cropping seasons in the country (e.g. Meher and Belg in Ethiopia, rainy season / flood-recession cropping / irrigated dry season in the Sahel). You can refer to the “last season” or “ongoing season". | G6: قم بتسمية موسم (مواسم) المحاصيل ذات الأهمية إذا كان هناك عدة مواسم محصولية في البلد (على سبيل المثال ، Meher و Belg في إثيوبيا ، موسم الأمطار / محاصيل الركود بسبب الفيضانات / موسم الجفاف المروي في منطقة الساحل). يمكنك الرجوع إلى "الموسم الماضي" أو "الموسم الجاري". | H6: wet season | I6: موسم الأمطار
C7: season phase | D7: Harvesting | E7: الحصاد | F7: Indicate the phase of the season at the time of data collection. If the harvest from the season has not yet occurred, the question on crop harvest (crp_harv_change) will include the word “expected” (where #expected or nothing# is located). If the harvest has occured, "expected" will not be inserted in the question. | G7: حدد مرحلة الموسم في وقت جمع البيانات. إذا لم يتم الحصاد من الموسم بعد ، فإن السؤال عن حصاد المحاصيل (crp_harv_change) سيتضمن كلمة "متوقع" (حيث يوجد # متوقع أو لا شيء #). إذا تم الحصاد ، لن يتم إدخال "متوقع" في السؤال . | H7: Harvesting | I7: الحصاد
C8: local measurement unit | D8: Dunum | E8: دونم | F8: Specify the local measurement unit for land size, other than acres, hectares, square meters and square feet. If no other unit of measurement is needed, keep this cell blank. | G8: حدد وحدة القياس المحلية لمساحة الأرض ، بخلاف الفدان والهكتار والمتر المربع والقدم المربع. إذا لم تكن هناك حاجة إلى وحدة قياس أخرى ، احتفظ بهذه الخلية فارغة. | H8: Jeribs | I8: جريب
C9: local measurement unit conversion | D9: 0.1 | E9: 0.1 | F9: Include the conversion of the local measurement unit to hectares. In other words, how many local measurement units are in 1 ha. Only digits in Latin numbers should be inputted. | G9: قم بتضمين تحويل وحدة القياس المحلية إلى هكتار. بمعنى آخر ، إلى كم هو عدد وحدات القياس المحلية في هكتار واحد. يرجى إدخال الأرقام في الأبجدية اللاتينية (...3, 2, 1). | H9: 0.2 | I9: 0.2
B10: FOR OPTIONAL QUESTIONS . (Fill out if applicable) . | C10: currency | D10: NIS | E10: شيكل | F10: The name of the main currency used nationally; USD; Naira; Rial; Pesos; etc. | G10: اسم العملة الرئيسية المستخدمة وطنيا ؛ دولار أمريكي؛ نيرة؛ الريال؛ بيزو؛ إلخ. | H10: Naira | I10: نيرة
C11: MIN AMOUNT | D11: 300 | E11: 300 | F11: The minimum amount for an income source should be set at 0 or any value below which it is not possible to do a transaction. For example, the smallest coin/banknote in a currency can be 1000, in which case you would set the minimum at 1000. Provide this input in the same currency as specified above. Only digits in Latin numbers should be inputted. | G11: يجب تعيين الحد الأدنى لمبلغ مصدر الدخل على 0 أو أي قيمة أقل منها لا يمكن إجراء معاملة. على سبيل المثال ، يمكن أن تكون أصغر عملة / ورقة نقدية في عملة ما هي 1000 ، وفي هذه الحالة يمكنك تعيين الحد الأدنى عند 1000. يجب أن يكون هذا المبلغ بنفس العملة المحددة في الصف أعلاه. يرجى إدخال الأرقام في الأبجدية اللاتينية (...3, 2, 1). | H11: 5 | I11: 5
C12: MAX AMOUNT | D12: 1500000 | E12: 1500000 | F12: Set the maximum amount for an income source over 3 months. Enumerators will not be able to input values above this amount in questions related to income amounts. Using previous representative surveys for this population, you can estimate this amount by using the mean income plus five (5) standard deviations, unless the country has high inflation. In the latter case, set the maximum value based on your country context (higher than the proposed approach). Provide this input in the same currency as specified above. Only digits in Latin numbers should be inputted. | G12: حدد الحد الأقصى لمبلغ مصدر الدخل على مدى 3 أشهر. لن يتمكن جامعي البيانات من إدخال قيم أعلى من هذا المبلغ في الأسئلة المتعلقة بمبالغ الدخل. باستخدام المسوح التمثيلية السابقة لهذه الفئة من السكان ، يمكنك تقدير هذا المبلغ باستخدام متوسط ​​الدخل بالإضافة إلى خمسة انحرافات معيارية ما لم يكن هناك تضخم مرتفع في الدولة. في الحالة الأخيرة ، قم بتعيين الحد الأقصى للقيمة بناءً على سياق بلدك (أعلى من النهج المقترح). يجب أن يكون هذا المبلغ بنفس العملة المحددة أعلاه. يرجى إدخال الأرقام في الأبجدية اللاتينية (...3, 2, 1). | H12: 5000000 | I12: 5000000
C13: THRESHOLD | D13: 4000 | E13: 4000 | F13: The threshold salary should be calculated to flag outliers (responses that look suspiciously high). Using previous representative surveys for this population, a good estimate is the average plus three (3) standard deviations, which should give the threshold for the 3 or 4% highest income values. Provide this input in the same currency as specified above. Only digits in Latin numbers should be inputted. | G13: يجب حساب قيمة العتبة للراتب لتحديد القيم المتطرفة (الاستجابات التي تبدو مرتفعة بشكل مثير للريبة). باستخدام المسوح التمثيلية السابقة لهذه الفئة من السكان ، فإن التقدير الجيد هو المتوسط ​​زائد ثلاثة انحرافات معيارية ، والذي يجب أن يعطي قيمة العتبة لقيم الدخل الأعلى بنسبة 3 أو 4٪. يجب أن يكون هذا المبلغ بنفس العملة المحددة أعلاه. يرجى إدخال الأرقام في الأبجدية اللاتينية (...3, 2, 1). | H13: 1200000 | I13: 1200000
C14: local vegetables | D14: Tomatoes, eggplant, zucchini, cauliflower | E14: بندورة، باذنجان، كوسا، قرنبيط | F14: Input some common local vegetables [to be used as examples in the food consumption score indicator]. | G14: أدخل بعض الخضروات المحلية الشائعة [لاستخدامها كأمثلة في مؤشر درجة استهلاك الغذاء]. | H14: eggplants, zucchini, cauliflower | I14: باذنجان ، كوسة ، قرنبيط
C15: local fruits | D15: Apple, banana, orange | E15: تفاح، موز، برتقال | F15: Input some common local fruits [to be used as examples in the food consumption score indicator]. | G15: أدخل بعض الفاكهة المحلية الشائعة [لاستخدامها كأمثلة في مؤشر درجة استهلاك الغذاء]. | H15: apples, bananas, oranges | I15: التفاح والموز والبرتقال
B17: FILL OUT FOR QUESTIONNAIRE DURATION ESTIMATION . | C17: Expected percentage of respondents cultivating crops | D17: 0.91 | E17: 0.91 | F17: If the survey is representative and has no quotas, write the proportion of rural households cultivating crops at country level, or if the survey follows a previous round with identical sample design, just report the percentage from the previous round. If you are using quotas, calculate the ratio of the quota over the minimum sample size at the level where the quota is implemented (so if you have a minimum sample size per strata of 110 with a quota of 100 crop producers, then it's 100/110 = 91% (the maximum you should write is 100%). | G17: إذا كان المسح تمثيليًا وليس له حصص نسبية ، فاكتب نسبة الأسر الريفية التي تزرع محاصيل على المستوى الوطني ، أو إذا كان المسح يتبع جولة سابقة بتصميم عينة متطابق ، فما عليك سوى الإبلاغ عن النسبة المئوية من الجولة السابقة. إذا كنت تستخدم نظام الحصص النسبية ، فاحسب نسبة الحصة إلى الحد الأدنى لحجم العينة على المستوى الذي يتم فيه تنفيذ الحصة (لذلك إذا كان لديك حد أدنى لحجم العينة لكل طبقة 110 مع حصة 100 منتج محصول ، فسيكون 100 / 110 = 91٪ (الحد الأقصى الذي يجب أن تكتبه هو 100٪). | H17: 0.91 | I17: 0.91
C18: Expected percentage of respondents raising livestock | D18: 0.91 | E18: 0.91 | F18: If the survey is representative and has no quotas, write the proportion of rural households raising livestock at country level, or if the survey follows a previous round with identical sample design, just report the percentage from the previous round. If you are using quotas, calculate the ratio of the quota over the minimum sample size at the level where the quota is implemented (so if you have a minimum sample size of 110 but a quota of 100 livestock producers, then it's 100/110 = 91% (the maximum you should write is 100%) | G18: إذا كان المسح تمثيليًا وليس له حصص نسبية ، فاكتب نسبة الأسر الريفية التي تربي الماشية على المستوى الوطني ، أو إذا كان المسح يتبع جولة سابقة بتصميم عينة متطابق ، فما عليك سوى الإبلاغ عن النسبة المئوية من الجولة السابقة. إذا كنت تستخدم نظام الحصص النسبية ، فاحسب نسبة الحصة إلى الحد الأدنى لحجم العينة على المستوى الذي يتم فيه تنفيذ الحصة (لذلك إذا كان لديك حد أدنى لحجم العينة لكل طبقة 110 مع حصة 100 مربي الماشية ، فسيكون 100 / 110 = 91٪ (الحد الأقصى الذي يجب أن تكتبه هو 100٪). | H18: 0.91 | I18: 0.91
C19: Expected percentage of respondents involved in fishery | D19: 0.05 | E19: 0.05 | F19: If the survey is representative and has no quotas, write the proportion of rural households involved in fisheries or aquaculture, otherwise if you are using quotas, calculate the ratio of the quota over the sample size at the level where the quota is implemented. (so if you haven't set a quota, and you expect to have a representative proportion of fishermen, just write the percentage of fishermen in the population you are targeting, in the example to the right, 5%) | G19: إذا كان المسح تمثيليًا وليس له حصص نسبية ، فاكتب نسبة الأسر الريفية العاملة في مصايد الأسماك أو تربية الأحياء المائية على المستوى الوطني. وإلا إذا كنت تستخدم الحصص النسبية ، فاحسب نسبة الحصة إلى حجم العينة على المستوى الذي يتم فيه تنفيذ الحصة. (لذلك إذا لم تحدد حصة ، وكنت تتوقع أن يكون لديك نسبة تمثيلية من الصيادين ، فاكتب فقط النسبة المئوية للصيادين من السكان الذين تستهدفهم ، في المثال على اليمين ، 5٪). | H19: 0.05 | I19: 0.05

Sheet Quotas
A1: Governorate | B1: Livelihoodtype | C1: Sample Size
A2: Jenin | B2: Plant | C2: 140
B3: Livestock | C3: 30
B4: Mixed | C4: 35
A5: Tubas & Northern Valleys | B5: Plant | C5: 35
B6: Livestock | C6: 30
B7: Mixed | C7: 30
A8: Tulkarm/Qalqiliya/Salfit | B8: Plant | C8: 201
B9: Livestock
B10: Mixed | C10: 33
A11: Nablus | B11: Plant | C11: 110
B12: Livestock | C12: 30
B13: Mixed | C13: 30
A14: Ramallah & Al-Bireh | B14: Plant | C14: 115
B15: Livestock | C15: 45
B16: Mixed | C16: 38
A17: Jericho & Al- Aghwar | B17: Plant | C17: 30
B18: Livestock | C18: 30
B19: Mixed | C19: 30
A20: Jerusalem | B20: Plant | C20: 30
B21: Livestock | C21: 30
B22: Mixed | C22: 30
A23: Bethlehem | B23: Plant | C23: 61
B24: Livestock | C24: 30
B25: Mixed | C25: 30
A26: Hebron | B26: Plant | C26: 145
B27: Livestock | C27: 40
B28: Mixed | C28: 45
A29: TOTAL | C29: =SUM(C2:C28) -> 1433
